Workbook

Sheet PLAN BUDGET SAMI-JF
A1: PT. SEMARANG AUTOCOMP MANUFACTURING INDONESIA
A2: BUDGET EXPENSE FORM | N2: EXCHANGE RATE TO USD
A3: PERIODE Jul-25 SD Jun-26 | N3: IDR | O3: 15798.6
A4: DEPARTMENT-SECTION : PGA-TRN | N4: JPY | O4: 151
N5: THB | O5: 34.373
N6: USD | O6: 1
N7: EUR | O7: 0.926
N8: CHF | O8: 0.872
A10: SECTION | B10: BUDGET REF NO | C10: PART_NO | D10: PART NAME | E10: DETAIL PART | F10: FUNGSI / TUJUAN | G10: SECTION CATEGORY | H10: ACC NO. | I10: ACCOUNT DESCRIPTION | J10: CATEGORY | K10: COST CENTER | L10: CARLINE | M10: CARMAKER | N10: UOM | O10: ORG CURR | P10: PRICE ORG CURR | AB10: PRICE USD | AN10: 202507 | AO10: 202508 | AP10: 202509 | AQ10: 202510 | AR10: 202511 | AS10: 202512 | AT10: 202601 | AU10: 202602 | AV10: 202603 | AW10: 202604 | AX10: 202605 | AY10: 202606 | AZ10: TOTAL | BA10: AVERAGE | BC10: 202507 | BD10: 202508 | BE10: 202509 | BF10: 202510 | BG10: 202511 | BH10: 202512 | BI10: 202601 | BJ10: 202602 | BK10: 202603 | BL10: 202604 | BM10: 202605 | BN10: 202606 | BO10: TOTAL | BP10: AVERAGE | BR10: SUB ACCOUNT | BS10: KODE PROSES | BT10: PURCHASING | BU10: LEADTIME
P11: 202507 | Q11: 202508 | R11: 202509 | S11: 202510 | T11: 202511 | U11: 202512 | V11: 202601 | W11: 202602 | X11: 202603 | Y11: 202604 | Z11: 202605 | AA11: 202606 | AB11: 202507 | AC11: 202508 | AD11: 202509 | AE11: 202510 | AF11: 202511 | AG11: 202512 | AH11: 202601 | AI11: 202602 | AJ11: 202603 | AK11: 202604 | AL11: 202605 | AM11: 202606 | AN11: QTY | AO11: QTY | AP11: QTY | AQ11: QTY | AR11: QTY | AS11: QTY | AT11: QTY | AU11: QTY | AV11: QTY | AW11: QTY | AX11: QTY | AY11: QTY | BC11: AMT | BD11: AMT | BE11: AMT | BF11: AMT | BG11: AMT | BH11: AMT | BI11: AMT | BJ11: AMT | BK11: AMT | BL11: AMT | BM11: AMT | BN11: AMT | BU11: PENAWARAN | BV11: PR | BW11: PO | BX11: KEDATANGAN | BY11: VP
A13: PGA-TRN | C13: A-03149 | D13: PLASTIK ID CARD | E13: PLASTIK ID CARD DEPAN SOBEK SAMPING | F13: INCLASS LICENSE | G13: OPEX | J13: RUTIN | K13: JPI000 | L13: ALL | M13: ALL | N13: PCS | O13: IDR | P13: 1670 | Q13: 1670 | R13: 1670 | S13: 1670 | T13: 1670 | U13: 1670 | V13: 1670 | W13: 1670 | X13: 1670 | Y13: 1670 | Z13: 1670 | AA13: 1670 | AB13: 0.10570557 | AC13: 0.10570557 | AD13: 0.10570557 | AE13: 0.10570557 | AF13: 0.10570557 | AG13: 0.10570557 | AH13: 0.10570557 | AI13: 0.10570557 | AJ13: 0.10570557 | AK13: 0.10570557 | AL13: 0.10570557 | AM13: 0.10570557 | AN13: 0 | AO13: 560 | AP13: 0 | AQ13: 0 | AR13: 552 | AS13: 0 | AT13: 0 | AU13: 0 | AV13: 300 | AW13: 0 | AX13: 0 | AY13: 300 | AZ13: =SUM(AN13:AY13) -> 1712 | BA13: =AZ13/12 -> 142.66667 | BC13: 0 | BD13: 59.195119 | BE13: 0 | BF13: 0 | BG13: 58.349474 | BH13: 0 | BI13: 0 | BJ13: 0 | BK13: 31.711671 | BL13: 0 | BM13: 0 | BN13: 31.711671 | BO13: =SUM(BC13:BN13) -> 180.96793 | BP13: =BO13/12 -> 15.080661 | BS13: C | BT13: GA | BU13: 15 | BV13: 10 | BW13: 5 | BX13: 20 | BY13: 5
A14: PGA-TRN | C14: A-03442 | D14: PERJALANAN DINAS | E14: HOTEL DALAM NEGERI (TRAVELING/MEETING) GOL IV | F14: KAIZEN FESTIVAL TMC | G14: OPEX | J14: RUTIN | K14: JPI000 | L14: ALL | M14: ALL | N14: DAY | O14: IDR | P14: 1200000 | Q14: 1200000 | R14: 1200000 | S14: 1200000 | T14: 1200000 | U14: 1200000 | V14: 1200000 | W14: 1200000 | X14: 1200000 | Y14: 1200000 | Z14: 1200000 | AA14: 1200000 | AB14: 75.956097 | AC14: 75.956097 | AD14: 75.956097 | AE14: 75.956097 | AF14: 75.956097 | AG14: 75.956097 | AH14: 75.956097 | AI14: 75.956097 | AJ14: 75.956097 | AK14: 75.956097 | AL14: 75.956097 | AM14: 75.956097 | AN14: 0 | AO14: 0 | AP14: 0 | AQ14: 0 | AR14: 2 | AS14: 0 | AT14: 0 | AU14: 0 | AV14: 0 | AW14: 0 | AX14: 0 | AY14: 0 | AZ14: =SUM(AN14:AY14) -> 2 | BA14: =AZ14/12 -> 0.16666667 | BC14: 0 | BD14: 0 | BE14: 0 | BF14: 0 | BG14: 151.91219 | BH14: 0 | BI14: 0 | BJ14: 0 | BK14: 0 | BL14: 0 | BM14: 0 | BN14: 0 | BO14: =SUM(BC14:BN14) -> 151.91219 | BP14: =BO14/12 -> 12.65935 | BS14: D | BT14: GA | BU14: 0 | BV14: 10 | BW14: 0 | BX14: 0 | BY14: 5
A15: PGA-TRN | C15: A-01223 | D15: POINTER | E15: POINTER | F15: INCLASS TRAINING KELAS | G15: OPEX | J15: RUTIN | K15: JPI000 | L15: ALL | M15: ALL | N15: PCS | O15: IDR | P15: 473800 | Q15: 473800 | R15: 473800 | S15: 473800 | T15: 473800 | U15: 473800 | V15: 473800 | W15: 473800 | X15: 473800 | Y15: 473800 | Z15: 473800 | AA15: 473800 | AB15: 29.989999 | AC15: 29.989999 | AD15: 29.989999 | AE15: 29.989999 | AF15: 29.989999 | AG15: 29.989999 | AH15: 29.989999 | AI15: 29.989999 | AJ15: 29.989999 | AK15: 29.989999 | AL15: 29.989999 | AM15: 29.989999 | AN15: 0 | AO15: 0 | AP15: 2 | AQ15: 0 | AR15: 0 | AS15: 0 | AT15: 0 | AU15: 0 | AV15: 0 | AW15: 0 | AX15: 0 | AY15: 0 | AZ15: =SUM(AN15:AY15) -> 2 | BA15: =AZ15/12 -> 0.16666667 | BC15: 0 | BD15: 0 | BE15: 59.979998 | BF15: 0 | BG15: 0 | BH15: 0 | BI15: 0 | BJ15: 0 | BK15: 0 | BL15: 0 | BM15: 0 | BN15: 0 | BO15: =SUM(BC15:BN15) -> 59.979998 | BP15: =BO15/12 -> 4.9983332 | BS15: C | BT15: GA | BU15: 15 | BV15: 10 | BW15: 5 | BX15: 20 | BY15: 5
A16: PGA-TRN | C16: A-03946 | D16: PERJALANAN DINAS | E16: UANG MAKAN SIANG PD DALAM NEGERI (TRAVELLING & MEETING) GOL III | F16: KAIZEN FESTIVAL TMC | G16: OPEX | J16: RUTIN | K16: JPI000 | L16: ALL | M16: ALL | N16: DAY | O16: IDR | P16: 20000 | Q16: 20000 | R16: 20000 | S16: 20000 | T16: 20000 | U16: 20000 | V16: 20000 | W16: 20000 | X16: 20000 | Y16: 20000 | Z16: 20000 | AA16: 20000 | AB16: 1.265935 | AC16: 1.265935 | AD16: 1.265935 | AE16: 1.265935 | AF16: 1.265935 | AG16: 1.265935 | AH16: 1.265935 | AI16: 1.265935 | AJ16: 1.265935 | AK16: 1.265935 | AL16: 1.265935 | AM16: 1.265935 | AN16: 0 | AO16: 0 | AP16: 0 | AQ16: 0 | AR16: 3 | AS16: 0 | AT16: 0 | AU16: 0 | AV16: 0 | AW16: 0 | AX16: 0 | AY16: 0 | AZ16: =SUM(AN16:AY16) -> 3 | BA16: =AZ16/12 -> 0.25 | BC16: 0 | BD16: 0 | BE16: 0 | BF16: 0 | BG16: 3.7978049 | BH16: 0 | BI16: 0 | BJ16: 0 | BK16: 0 | BL16: 0 | BM16: 0 | BN16: 0 | BO16: =SUM(BC16:BN16) -> 3.7978049 | BP16: =BO16/12 -> 0.31648374 | BS16: D | BT16: GA | BU16: 0 | BV16: 10 | BW16: 0 | BX16: 0 | BY16: 5
A17: PGA-TRN | C17: A-03959 | D17: PERJALANAN DINAS | E17: UANG MAKAN SIANG PD DALAM NEGERI (TRAVELLING & MEETING) GOL IV | F17: KAIZEN FESTIVAL TMC | G17: OPEX | J17: RUTIN | K17: JPI000 | L17: ALL | M17: ALL | N17: DAY | O17: IDR | P17: 27500 | Q17: 27500 | R17: 27500 | S17: 27500 | T17: 27500 | U17: 27500 | V17: 27500 | W17: 27500 | X17: 27500 | Y17: 27500 | Z17: 27500 | AA17: 27500 | AB17: 1.7406606 | AC17: 1.7406606 | AD17: 1.7406606 | AE17: 1.7406606 | AF17: 1.7406606 | AG17: 1.7406606 | AH17: 1.7406606 | AI17: 1.7406606 | AJ17: 1.7406606 | AK17: 1.7406606 | AL17: 1.7406606 | AM17: 1.7406606 | AN17: 0 | AO17: 0 | AP17: 0 | AQ17: 0 | AR17: 3 | AS17: 0 | AT17: 0 | AU17: 0 | AV17: 0 | AW17: 0 | AX17: 0 | AY17: 0 | AZ17: =SUM(AN17:AY17) -> 3 | BA17: =AZ17/12 -> 0.25 | BC17: 0 | BD17: 0 | BE17: 0 | BF17: 0 | BG17: 5.2219817 | BH17: 0 | BI17: 0 | BJ17: 0 | BK17: 0 | BL17: 0 | BM17: 0 | BN17: 0 | BO17: =SUM(BC17:BN17) -> 5.2219817 | BP17: =BO17/12 -> 0.43516514 | BS17: D | BT17: GA | BU17: 0 | BV17: 10 | BW17: 0 | BX17: 0 | BY17: 5
A18: PGA-TRN | C18: A-00704 | D18: MASKER | E18: SAFETY MASK CARBON ACTIVE - LONG | F18: NEOP SIMULASI B3 | G18: OPEX | J18: RUTIN | K18: JPI000 | L18: ALL | M18: ALL | N18: PCS | O18: IDR | P18: 33000 | Q18: 33000 | R18: 33000 | S18: 33000 | T18: 33000 | U18: 33000 | V18: 33000 | W18: 33000 | X18: 33000 | Y18: 33000 | Z18: 33000 | AA18: 33000 | AB18: 2.0887927 | AC18: 2.0887927 | AD18: 2.0887927 | AE18: 2.0887927 | AF18: 2.0887927 | AG18: 2.0887927 | AH18: 2.0887927 | AI18: 2.0887927 | AJ18: 2.0887927 | AK18: 2.0887927 | AL18: 2.0887927 | AM18: 2.0887927 | AN18: 0 | AO18: 0 | AP18: 13 | AQ18: 0 | AR18: 0 | AS18: 0 | AT18: 0 | AU18: 13 | AV18: 0 | AW18: 0 | AX18: 0 | AY18: 0 | AZ18: =SUM(AN18:AY18) -> 26 | BA18: =AZ18/12 -> 2.1666667 | BC18: 0 | BD18: 0 | BE18: 27.154305 | BF18: 0 | BG18: 0 | BH18: 0 | BI18: 0 | BJ18: 27.154305 | BK18: 0 | BL18: 0 | BM18: 0 | BN18: 0 | BO18: =SUM(BC18:BN18) -> 54.30861 | BP18: =BO18/12 -> 4.5257175 | BS18: C | BT18: GA | BU18: 15 | BV18: 10 | BW18: 5 | BX18: 20 | BY18: 5
A19: PGA-TRN | C19: A-03944 | D19: PERJALANAN DINAS | E19: UANG MAKAN PAGI PD DALAM NEGERI (TRAVELLING & MEETING) GOL III | F19: KAIZEN FESTIVAL TMC | G19: OPEX | J19: RUTIN | K19: JPI000 | L19: ALL | M19: ALL | N19: DAY | O19: IDR | P19: 12500 | Q19: 12500 | R19: 12500 | S19: 12500 | T19: 12500 | U19: 12500 | V19: 12500 | W19: 12500 | X19: 12500 | Y19: 12500 | Z19: 12500 | AA19: 12500 | AB19: 0.79120935 | AC19: 0.79120935 | AD19: 0.79120935 | AE19: 0.79120935 | AF19: 0.79120935 | AG19: 0.79120935 | AH19: 0.79120935 | AI19: 0.79120935 | AJ19: 0.79120935 | AK19: 0.79120935 | AL19: 0.79120935 | AM19: 0.79120935 | AN19: 0 | AO19: 0 | AP19: 0 | AQ19: 0 | AR19: 3 | AS19: 0 | AT19: 0 | AU19: 0 | AV19: 0 | AW19: 0 | AX19: 0 | AY19: 0 | AZ19: =SUM(AN19:AY19) -> 3 | BA19: =AZ19/12 -> 0.25 | BC19: 0 | BD19: 0 | BE19: 0 | BF19: 0 | BG19: 2.373628 | BH19: 0 | BI19: 0 | BJ19: 0 | BK19: 0 | BL19: 0 | BM19: 0 | BN19: 0 | BO19: =SUM(BC19:BN19) -> 2.373628 | BP19: =BO19/12 -> 0.19780234 | BS19: D | BT19: GA | BU19: 0 | BV19: 10 | BW19: 0 | BX19: 0 | BY19: 5
A20: PGA-TRN | C20: A-03961 | D20: PERJALANAN DINAS | E20: UANG MAKAN MALAM PD DALAM NEGERI (TRAVELLING & MEETING) GOL IV | F20: KAIZEN FESTIVAL TMC | G20: OPEX | J20: RUTIN | K20: JPI000 | L20: ALL | M20: ALL | N20: DAY | O20: IDR | P20: 27500 | Q20: 27500 | R20: 27500 | S20: 27500 | T20: 27500 | U20: 27500 | V20: 27500 | W20: 27500 | X20: 27500 | Y20: 27500 | Z20: 27500 | AA20: 27500 | AB20: 1.7406606 | AC20: 1.7406606 | AD20: 1.7406606 | AE20: 1.7406606 | AF20: 1.7406606 | AG20: 1.7406606 | AH20: 1.7406606 | AI20: 1.7406606 | AJ20: 1.7406606 | AK20: 1.7406606 | AL20: 1.7406606 | AM20: 1.7406606 | AN20: 0 | AO20: 0 | AP20: 0 | AQ20: 0 | AR20: 3 | AS20: 0 | AT20: 0 | AU20: 0 | AV20: 0 | AW20: 0 | AX20: 0 | AY20: 0 | AZ20: =SUM(AN20:AY20) -> 3 | BA20: =AZ20/12 -> 0.25 | BC20: 0 | BD20: 0 | BE20: 0 | BF20: 0 | BG20: 5.2219817 | BH20: 0 | BI20: 0 | BJ20: 0 | BK20: 0 | BL20: 0 | BM20: 0 | BN20: 0 | BO20: =SUM(BC20:BN20) -> 5.2219817 | BP20: =BO20/12 -> 0.43516514 | BS20: D | BT20: GA | BU20: 0 | BV20: 10 | BW20: 0 | BX20: 0 | BY20: 5
A21: PGA-TRN | C21: A-00451 | D21: FORM | E21: FORMULIR DAFTAR HADIR TRAINING | F21: RECORD TRAINING | G21: OPEX | J21: RUTIN | K21: JPI000 | L21: ALL | M21: ALL | N21: RIM | O21: IDR | P21: 200000 | Q21: 200000 | R21: 200000 | S21: 200000 | T21: 200000 | U21: 200000 | V21: 200000 | W21: 200000 | X21: 200000 | Y21: 200000 | Z21: 200000 | AA21: 200000 | AB21: 12.65935 | AC21: 12.65935 | AD21: 12.65935 | AE21: 12.65935 | AF21: 12.65935 | AG21: 12.65935 | AH21: 12.65935 | AI21: 12.65935 | AJ21: 12.65935 | AK21: 12.65935 | AL21: 12.65935 | AM21: 12.65935 | AN21: 0 | AO21: 0 | AP21: 0 | AQ21: 1 | AR21: 0 | AS21: 0 | AT21: 0 | AU21: 0 | AV21: 0 | AW21: 1 | AX21: 0 | AY21: 0 | AZ21: =SUM(AN21:AY21) -> 2 | BA21: =AZ21/12 -> 0.16666667 | BC21: 0 | BD21: 0 | BE21: 0 | BF21: 12.65935 | BG21: 0 | BH21: 0 | BI21: 0 | BJ21: 0 | BK21: 0 | BL21: 12.65935 | BM21: 0 | BN21: 0 | BO21: =SUM(BC21:BN21) -> 25.318699 | BP21: =BO21/12 -> 2.1098916 | BS21: C | BT21: GA | BU21: 15 | BV21: 10 | BW21: 5 | BX21: 20 | BY21: 5
A22: PGA-TRN | C22: A-00641 | D22: BATTERY | E22: BATTERY CR2032 3V | F22: NEOP BATERAI STOPWATCH | G22: OPEX | J22: RUTIN | K22: JPI000 | L22: ALL | M22: ALL | N22: PCS | O22: IDR | P22: 5000 | Q22: 5000 | R22: 5000 | S22: 5000 | T22: 5000 | U22: 5000 | V22: 5000 | W22: 5000 | X22: 5000 | Y22: 5000 | Z22: 5000 | AA22: 5000 | AB22: 0.31648374 | AC22: 0.31648374 | AD22: 0.31648374 | AE22: 0.31648374 | AF22: 0.31648374 | AG22: 0.31648374 | AH22: 0.31648374 | AI22: 0.31648374 | AJ22: 0.31648374 | AK22: 0.31648374 | AL22: 0.31648374 | AM22: 0.31648374 | AN22: 0 | AO22: 20 | AP22: 0 | AQ22: 0 | AR22: 0 | AS22: 0 | AT22: 20 | AU22: 0 | AV22: 0 | AW22: 0 | AX22: 0 | AY22: 0 | AZ22: =SUM(AN22:AY22) -> 40 | BA22: =AZ22/12 -> 3.3333333 | BC22: 0 | BD22: 6.3296748 | BE22: 0 | BF22: 0 | BG22: 0 | BH22: 0 | BI22: 6.3296748 | BJ22: 0 | BK22: 0 | BL22: 0 | BM22: 0 | BN22: 0 | BO22: =SUM(BC22:BN22) -> 12.65935 | BP22: =BO22/12 -> 1.0549458 | BS22: C | BT22: GA | BU22: 15 | BV22: 10 | BW22: 5 | BX22: 20 | BY22: 5
A23: PGA-TRN | C23: A-03050 | D23: TES BAHASA ASING | E23: JLPT N5 | F23: BAHASA JEPANG JLPT | G23: OPEX | J23: RUTIN | K23: JPI000 | L23: ALL | M23: ALL | N23: PEOPLE | O23: IDR | P23: 140000 | Q23: 140000 | R23: 140000 | S23: 140000 | T23: 140000 | U23: 140000 | V23: 140000 | W23: 140000 | X23: 140000 | Y23: 140000 | Z23: 140000 | AA23: 140000 | AB23: 8.8615447 | AC23: 8.8615447 | AD23: 8.8615447 | AE23: 8.8615447 | AF23: 8.8615447 | AG23: 8.8615447 | AH23: 8.8615447 | AI23: 8.8615447 | AJ23: 8.8615447 | AK23: 8.8615447 | AL23: 8.8615447 | AM23: 8.8615447 | AN23: 0 | AO23: 0 | AP23: 0 | AQ23: 0 | AR23: 0 | AS23: 0 | AT23: 0 | AU23: 0 | AV23: 10 | AW23: 0 | AX23: 0 | AY23: 0 | AZ23: =SUM(AN23:AY23) -> 10 | BA23: =AZ23/12 -> 0.83333333 | BC23: 0 | BD23: 0 | BE23: 0 | BF23: 0 | BG23: 0 | BH23: 0 | BI23: 0 | BJ23: 0 | BK23: 88.615447 | BL23: 0 | BM23: 0 | BN23: 0 | BO23: =SUM(BC23:BN23) -> 88.615447 | BP23: =BO23/12 -> 7.3846206 | BS23: B | BT23: GA | BU23: 0 | BV23: 5 | BW23: 0 | BX23: 15 | BY23: 15
A24: PGA-TRN | C24: A-03610 | D24: BULAN COMPLIANCE | E24: BULAN COMPLIANCE | F24: AKTIFITAS BULAN COMPLIANCE | G24: OPEX | J24: RUTIN | K24: JPI000 | L24: ALL | M24: ALL | N24: PAKET | O24: IDR | P24: 5000000 | Q24: 5000000 | R24: 5000000 | S24: 5000000 | T24: 5000000 | U24: 5000000 | V24: 5000000 | W24: 5000000 | X24: 5000000 | Y24: 5000000 | Z24: 5000000 | AA24: 5000000 | AB24: 316.48374 | AC24: 316.48374 | AD24: 316.48374 | AE24: 316.48374 | AF24: 316.48374 | AG24: 316.48374 | AH24: 316.48374 | AI24: 316.48374 | AJ24: 316.48374 | AK24: 316.48374 | AL24: 316.48374 | AM24: 316.48374 | AN24: 0 | AO24: 0 | AP24: 0 | AQ24: 0 | AR24: 0 | AS24: 0 | AT24: 0 | AU24: 0 | AV24: 0 | AW24: 0 | AX24: 0 | AY24: 1 | AZ24: =SUM(AN24:AY24) -> 1 | BA24: =AZ24/12 -> 0.083333333 | BC24: 0 | BD24: 0 | BE24: 0 | BF24: 0 | BG24: 0 | BH24: 0 | BI24: 0 | BJ24: 0 | BK24: 0 | BL24: 0 | BM24: 0 | BN24: 316.48374 | BO24: =SUM(BC24:BN24) -> 316.48374 | BP24: =BO24/12 -> 26.373645 | BS24: E | BT24: GA | BU24: 0 | BV24: 10 | BW24: 0 | BX24: 10 | BY24: 5
... A34: PGA-TRN | C34: A-02017 | D34: KERTAS | E34: KERTAS UKURAN A5 | F34: NEOP SERTIFIKAT | G34: OPEX | J34: RUTIN | K34: JPI000 | L34: ALL | M34: ALL | N34: RIM | O34: IDR | P34: 35000 | Q34: 35000 | R34: 35000 | S34: 35000 | T34: 35000 | U34: 35000 | V34: 35000 | W34: 35000 | X34: 35000 | Y34: 35000 | Z34: 35000 | AA34: 35000 | AB34: 2.2153862 | AC34: 2.2153862 | AD34: 2.2153862 | AE34: 2.2153862 | AF34: 2.2153862 | AG34: 2.2153862 | AH34: 2.2153862 | AI34: 2.2153862 | AJ34: 2.2153862 | AK34: 2.2153862 | AL34: 2.2153862 | AM34: 2.2153862 | AN34: 0 | AO34: 1 | AP34: 0 | AQ34: 0 | AR34: 1 | AS34: 0 | AT34: 0 | AU34: 1 | AV34: 0 | AW34: 0 | AX34: 1 | AY34: 0 | AZ34: =SUM(AN34:AY34) -> 4 | BA34: =AZ34/12 -> 0.33333333 | BC34: 0 | BD34: 2.2153862 | BE34: 0 | BF34: 0 | BG34: 2.2153862 | BH34: 0 | BI34: 0 | BJ34: 2.2153862 | BK34: 0 | BL34: 0 | BM34: 2.2153862 | BN34: 0 | BO34: =SUM(BC34:BN34) -> 8.8615447 | BP34: =BO34/12 -> 0.73846206 | BS34: C | BT34: GA | BU34: 15 | BV34: 10 | BW34: 5 | BX34: 20 | BY34: 5
A35: PGA-TRN | C35: A-03898 | D35: BIAYA TRAINING | E35: FALSE | F35: BAHASA JEPANG CONVERSATION | G35: OPEX | J35: RUTIN | K35: JPI000 | L35: ALL | M35: ALL | N35: PAX | O35: IDR | P35: 19770000 | Q35: 19770000 | R35: 19770000 | S35: 19770000 | T35: 19770000 | U35: 19770000 | V35: 19770000 | W35: 19770000 | X35: 19770000 | Y35: 19770000 | Z35: 19770000 | AA35: 19770000 | AB35: 1251.3767 | AC35: 1251.3767 | AD35: 1251.3767 | AE35: 1251.3767 | AF35: 1251.3767 | AG35: 1251.3767 | AH35: 1251.3767 | AI35: 1251.3767 | AJ35: 1251.3767 | AK35: 1251.3767 | AL35: 1251.3767 | AM35: 1251.3767 | AN35: 0 | AO35: 1 | AP35: 0 | AQ35: 0 | AR35: 0 | AS35: 1 | AT35: 0 | AU35: 0 | AV35: 0 | AW35: 0 | AX35: 0 | AY35: 0 | AZ35: =SUM(AN35:AY35) -> 2 | BA35: =AZ35/12 -> 0.16666667 | BC35: 0 | BD35: 1251.3767 | BE35: 0 | BF35: 0 | BG35: 0 | BH35: 1251.3767 | BI35: 0 | BJ35: 0 | BK35: 0 | BL35: 0 | BM35: 0 | BN35: 0 | BO35: =SUM(BC35:BN35) -> 2502.7534 | BP35: =BO35/12 -> 208.56278 | BS35: A | BT35: GA | BU35: 15 | BV35: 10 | BW35: 5 | BX35: 20 | BY35: 5
A36: PGA-TRN | C36: A-03890 | D36: LAMPU | E36: LAMPU LED STRIP 12 VOLT | F36: NEOP SIMULASI PRAKTEK | G36: OPEX | J36: RUTIN | K36: JPI000 | L36: ALL | M36: ALL | N36: PCS | O36: IDR | P36: 45000 | Q36: 45000 | R36: 45000 | S36: 45000 | T36: 45000 | U36: 45000 | V36: 45000 | W36: 45000 | X36: 45000 | Y36: 45000 | Z36: 45000 | AA36: 45000 | AB36: 2.8483537 | AC36: 2.8483537 | AD36: 2.8483537 | AE36: 2.8483537 | AF36: 2.8483537 | AG36: 2.8483537 | AH36: 2.8483537 | AI36: 2.8483537 | AJ36: 2.8483537 | AK36: 2.8483537 | AL36: 2.8483537 | AM36: 2.8483537 | AN36: 1 | AO36: 0 | AP36: 0 | AQ36: 0 | AR36: 0 | AS36: 0 | AT36: 0 | AU36: 0 | AV36: 0 | AW36: 0 | AX36: 0 | AY36: 0 | AZ36: =SUM(AN36:AY36) -> 1 | BA36: =AZ36/12 -> 0.083333333 | BC36: 2.8483537 | BD36: 0 | BE36: 0 | BF36: 0 | BG36: 0 | BH36: 0 | BI36: 0 | BJ36: 0 | BK36: 0 | BL36: 0 | BM36: 0 | BN36: 0 | BO36: =SUM(BC36:BN36) -> 2.8483537 | BP36: =BO36/12 -> 0.2373628 | BS36: C | BT36: GA | BU36: 15 | BV36: 10 | BW36: 5 | BX36: 20 | BY36: 5
A37: PGA-TRN | C37: A-03951 | D37: PERJALANAN DINAS | E37: UANG MAKAN MALAM PD DALAM NEGERI (TRAVELLING & MEETING) GOL III | F37: KAIZEN FESTIVAL TMC | G37: OPEX | J37: RUTIN | K37: JPI000 | L37: ALL | M37: ALL | N37: DAY | O37: IDR | P37: 20000 | Q37: 20000 | R37: 20000 | S37: 20000 | T37: 20000 | U37: 20000 | V37: 20000 | W37: 20000 | X37: 20000 | Y37: 20000 | Z37: 20000 | AA37: 20000 | AB37: 1.265935 | AC37: 1.265935 | AD37: 1.265935 | AE37: 1.265935 | AF37: 1.265935 | AG37: 1.265935 | AH37: 1.265935 | AI37: 1.265935 | AJ37: 1.265935 | AK37: 1.265935 | AL37: 1.265935 | AM37: 1.265935 | AN37: 0 | AO37: 0 | AP37: 0 | AQ37: 0 | AR37: 3 | AS37: 0 | AT37: 0 | AU37: 0 | AV37: 0 | AW37: 0 | AX37: 0 | AY37: 0 | AZ37: =SUM(AN37:AY37) -> 3 | BA37: =AZ37/12 -> 0.25 | BC37: 0 | BD37: 0 | BE37: 0 | BF37: 0 | BG37: 3.7978049 | BH37: 0 | BI37: 0 | BJ37: 0 | BK37: 0 | BL37: 0 | BM37: 0 | BN37: 0 | BO37: =SUM(BC37:BN37) -> 3.7978049 | BP37: =BO37/12 -> 0.31648374 | BS37: D | BT37: GA | BU37: 0 | BV37: 10 | BW37: 0 | BX37: 0 | BY37: 5
A38: PGA-TRN | C38: A-03378 | D38: STAND TABLET | E38: STAND TABLET | F38: INCLASS TRAINING KELAS | G38: OPEX | J38: RUTIN | K38: JPI000 | L38: ALL | M38: ALL | N38: PCS | O38: IDR | P38: 920000 | Q38: 920000 | R38: 920000 | S38: 920000 | T38: 920000 | U38: 920000 | V38: 920000 | W38: 920000 | X38: 920000 | Y38: 920000 | Z38: 920000 | AA38: 920000 | AB38: 58.233008 | AC38: 58.233008 | AD38: 58.233008 | AE38: 58.233008 | AF38: 58.233008 | AG38: 58.233008 | AH38: 58.233008 | AI38: 58.233008 | AJ38: 58.233008 | AK38: 58.233008 | AL38: 58.233008 | AM38: 58.233008 | AN38: 0 | AO38: 20 | AP38: 0 | AQ38: 0 | AR38: 0 | AS38: 0 | AT38: 0 | AU38: 0 | AV38: 0 | AW38: 0 | AX38: 0 | AY38: 0 | AZ38: =SUM(AN38:AY38) -> 20 | BA38: =AZ38/12 -> 1.6666667 | BC38: 0 | BD38: 1164.6602 | BE38: 0 | BF38: 0 | BG38: 0 | BH38: 0 | BI38: 0 | BJ38: 0 | BK38: 0 | BL38: 0 | BM38: 0 | BN38: 0 | BO38: =SUM(BC38:BN38) -> 1164.6602 | BP38: =BO38/12 -> 97.055013 | BS38: C | BT38: GA | BU38: 15 | BV38: 10 | BW38: 5 | BX38: 20 | BY38: 5
A39: PGA-TRN | C39: A-00636 | D39: BATTERY | E39: BATTERY AA | F39: INCLASS MOUSE | G39: OPEX | J39: RUTIN | K39: JPI000 | L39: ALL | M39: ALL | N39: SET | O39: IDR | P39: 13694 | Q39: 13694 | R39: 13694 | S39: 13694 | T39: 13694 | U39: 13694 | V39: 13694 | W39: 13694 | X39: 13694 | Y39: 13694 | Z39: 13694 | AA39: 13694 | AB39: 0.86678566 | AC39: 0.86678566 | AD39: 0.86678566 | AE39: 0.86678566 | AF39: 0.86678566 | AG39: 0.86678566 | AH39: 0.86678566 | AI39: 0.86678566 | AJ39: 0.86678566 | AK39: 0.86678566 | AL39: 0.86678566 | AM39: 0.86678566 | AN39: 0 | AO39: 6 | AP39: 0 | AQ39: 0 | AR39: 0 | AS39: 0 | AT39: 6 | AU39: 0 | AV39: 0 | AW39: 0 | AX39: 0 | AY39: 0 | AZ39: =SUM(AN39:AY39) -> 12 | BA39: =AZ39/12 -> 1 | BC39: 0 | BD39: 5.200714 | BE39: 0 | BF39: 0 | BG39: 0 | BH39: 0 | BI39: 5.200714 | BJ39: 0 | BK39: 0 | BL39: 0 | BM39: 0 | BN39: 0 | BO39: =SUM(BC39:BN39) -> 10.401428 | BP39: =BO39/12 -> 0.86678566 | BS39: C | BT39: GA | BU39: 15 | BV39: 10 | BW39: 5 | BX39: 20 | BY39: 5
A40: PGA-TRN | C40: A-00736 | D40: STOPWATCH | E40: STOPWATCH ROX | F40: NEOP SIMULASI CT | G40: OPEX | J40: RUTIN | K40: JPI000 | L40: ALL | M40: ALL | N40: PCS | O40: IDR | P40: 448050 | Q40: 448050 | R40: 448050 | S40: 448050 | T40: 448050 | U40: 448050 | V40: 448050 | W40: 448050 | X40: 448050 | Y40: 448050 | Z40: 448050 | AA40: 448050 | AB40: 28.360108 | AC40: 28.360108 | AD40: 28.360108 | AE40: 28.360108 | AF40: 28.360108 | AG40: 28.360108 | AH40: 28.360108 | AI40: 28.360108 | AJ40: 28.360108 | AK40: 28.360108 | AL40: 28.360108 | AM40: 28.360108 | AN40: 0 | AO40: 10 | AP40: 0 | AQ40: 0 | AR40: 0 | AS40: 0 | AT40: 0 | AU40: 0 | AV40: 0 | AW40: 0 | AX40: 0 | AY40: 0 | AZ40: =SUM(AN40:AY40) -> 10 | BA40: =AZ40/12 -> 0.83333333 | BC40: 0 | BD40: 283.60108 | BE40: 0 | BF40: 0 | BG40: 0 | BH40: 0 | BI40: 0 | BJ40: 0 | BK40: 0 | BL40: 0 | BM40: 0 | BN40: 0 | BO40: =SUM(BC40:BN40) -> 283.60108 | BP40: =BO40/12 -> 23.633423 | BS40: C | BT40: GA | BU40: 15 | BV40: 10 | BW40: 5 | BX40: 20 | BY40: 5
A41: PGA-TRN | C41: A-01272 | D41: BIAYA PROSES VISA | E41: VISA JEPANG (TRAINING) | F41: NEXT GENERATION FM | G41: OPEX | J41: INSIDENTAL | K41: JPI000 | L41: ALL | M41: ALL | N41: PEOPLE | O41: IDR | P41: 0 | Q41: 0 | R41: 0 | S41: 0 | T41: 0 | U41: 0 | V41: 0 | W41: 0 | X41: 0 | Y41: 0 | Z41: 560000 | AA41: 560000 | AB41: 0 | AC41: 0 | AD41: 0 | AE41: 0 | AF41: 0 | AG41: 0 | AH41: 0 | AI41: 0 | AJ41: 0 | AK41: 0 | AL41: 35.446179 | AM41: 35.446179 | AN41: 0 | AO41: 0 | AP41: 0 | AQ41: 0 | AR41: 0 | AS41: 0 | AT41: 0 | AU41: 0 | AV41: 0 | AW41: 0 | AX41: 0 | AY41: 0 | AZ41: =SUM(AN41:AY41) -> 0 | BA41: =AZ41/12 -> 0 | BC41: 0 | BD41: 0 | BE41: 0 | BF41: 0 | BG41: 0 | BH41: 0 | BI41: 0 | BJ41: 0 | BK41: 0 | BL41: 0 | BM41: 0 | BN41: 0 | BO41: =SUM(BC41:BN41) -> 0 | BP41: =BO41/12 -> 0 | BS41: B | BT41: GA | BU41: 0 | BV41: 5 | BW41: 0 | BX41: 15 | BY41: 15
A42: PGA-TRN | C42: A-00725 | D42: SAPU | E42: SAPU | F42: MZ04 | G42: OPEX | J42: PROJECT HVPT | K42: MZ04 | L42: MAZDA J69 | M42: Mazda - Mazda-Japan | N42: PCS | O42: IDR | P42: 57500 | Q42: 57500 | R42: 57500 | S42: 57500 | T42: 57500 | U42: 57500 | V42: 57500 | W42: 57500 | X42: 57500 | Y42: 57500 | Z42: 57500 | AA42: 57500 | AB42: 3.639563 | AC42: 3.639563 | AD42: 3.639563 | AE42: 3.639563 | AF42: 3.639563 | AG42: 3.639563 | AH42: 3.639563 | AI42: 3.639563 | AJ42: 3.639563 | AK42: 3.639563 | AL42: 3.639563 | AM42: 3.639563 | AN42: 0 | AO42: 36 | AP42: 0 | AQ42: 0 | AR42: 0 | AS42: 0 | AT42: 0 | AU42: 0 | AV42: 0 | AW42: 0 | AX42: 0 | AY42: 0 | AZ42: =SUM(AN42:AY42) -> 36 | BA42: =AZ42/12 -> 3 | BC42: 0 | BD42: 131.02427 | BE42: 0 | BF42: 0 | BG42: 0 | BH42: 0 | BI42: 0 | BJ42: 0 | BK42: 0 | BL42: 0 | BM42: 0 | BN42: 0 | BO42: =SUM(BC42:BN42) -> 131.02427 | BP42: =BO42/12 -> 10.918689 | BS42: C | BT42: GA | BU42: 15 | BV42: 10 | BW42: 5 | BX42: 20 | BY42: 5
A43: PGA-TRN | C43: A-00727 | D43: SEROKAN | E43: SEROKAN | F43: MZ04 | G43: OPEX | J43: PROJECT HVPT | K43: MZ04 | L43: MAZDA J69 | M43: Mazda - Mazda-Japan | N43: PCS | O43: IDR | P43: 7500 | Q43: 7500 | R43: 7500 | S43: 7500 | T43: 7500 | U43: 7500 | V43: 7500 | W43: 7500 | X43: 7500 | Y43: 7500 | Z43: 7500 | AA43: 7500 | AB43: 0.47472561 | AC43: 0.47472561 | AD43: 0.47472561 | AE43: 0.47472561 | AF43: 0.47472561 | AG43: 0.47472561 | AH43: 0.47472561 | AI43: 0.47472561 | AJ43: 0.47472561 | AK43: 0.47472561 | AL43: 0.47472561 | AM43: 0.47472561 | AN43: 0 | AO43: 6 | AP43: 0 | AQ43: 0 | AR43: 0 | AS43: 0 | AT43: 0 | AU43: 0 | AV43: 0 | AW43: 0 | AX43: 0 | AY43: 0 | AZ43: =SUM(AN43:AY43) -> 6 | BA43: =AZ43/12 -> 0.5 | BC43: 0 | BD43: 2.8483537 | BE43: 0 | BF43: 0 | BG43: 0 | BH43: 0 | BI43: 0 | BJ43: 0 | BK43: 0 | BL43: 0 | BM43: 0 | BN43: 0 | BO43: =SUM(BC43:BN43) -> 2.8483537 | BP43: =BO43/12 -> 0.2373628 | BS43: C | BT43: GA | BU43: 15 | BV43: 10 | BW43: 5 | BX43: 20 | BY43: 5
A44: PGA-TRN | C44: A-02960 | D44: VACUM CLEANER | E44: VACUM CLEANER MAYAKA | F44: PA MAZDA J69 | G44: OPEX | J44: PROJECT HVPT | K44: MJFPA | L44: MAZDA6, CX-3 | M44: Mazda - Mazda-Japan, Mazda - AAT: Auto Alliance Thailand (Mazda) | N44: UNIT | O44: IDR | P44: 1210000 | Q44: 1210000 | R44: 1210000 | S44: 1210000 | T44: 1210000 | U44: 1210000 | V44: 1210000 | W44: 1210000 | X44: 1210000 | Y44: 1210000 | Z44: 1210000 | AA44: 1210000 | AB44: 76.589065 | AC44: 76.589065 | AD44: 76.589065 | AE44: 76.589065 | AF44: 76.589065 | AG44: 76.589065 | AH44: 76.589065 | AI44: 76.589065 | AJ44: 76.589065 | AK44: 76.589065 | AL44: 76.589065 | AM44: 76.589065 | AN44: 0 | AO44: 1 | AP44: 0 | AQ44: 0 | AR44: 0 | AS44: 0 | AT44: 0 | AU44: 0 | AV44: 0 | AW44: 0 | AX44: 0 | AY44: 0 | AZ44: =SUM(AN44:AY44) -> 1 | BA44: =AZ44/12 -> 0.083333333 | BC44: 0 | BD44: 76.589065 | BE44: 0 | BF44: 0 | BG44: 0 | BH44: 0 | BI44: 0 | BJ44: 0 | BK44: 0 | BL44: 0 | BM44: 0 | BN44: 0 | BO44: =SUM(BC44:BN44) -> 76.589065 | BP44: =BO44/12 -> 6.3824221 | BS44: C | BT44: GA | BU44: 15 | BV44: 10 | BW44: 5 | BX44: 20 | BY44: 5
A45: PGA-TRN | C45: A-01312 | D45: HANDMOP | E45: HANDMOP | F45: MZ03 | G45: OPEX | J45: PROJECT HVPT | K45: MZ03 | L45: MAZDA J69 | M45: Mazda - Mazda-Japan | N45: PCS | O45: IDR | P45: 23063 | Q45: 23063 | R45: 23063 | S45: 23063 | T45: 23063 | U45: 23063 | V45: 23063 | W45: 23063 | X45: 23063 | Y45: 23063 | Z45: 23063 | AA45: 23063 | AB45: 1.4598129 | AC45: 1.4598129 | AD45: 1.4598129 | AE45: 1.4598129 | AF45: 1.4598129 | AG45: 1.4598129 | AH45: 1.4598129 | AI45: 1.4598129 | AJ45: 1.4598129 | AK45: 1.4598129 | AL45: 1.4598129 | AM45: 1.4598129 | AN45: 0 | AO45: 2 | AP45: 0 | AQ45: 0 | AR45: 0 | AS45: 0 | AT45: 0 | AU45: 0 | AV45: 0 | AW45: 0 | AX45: 0 | AY45: 0 | AZ45: =SUM(AN45:AY45) -> 2 | BA45: =AZ45/12 -> 0.16666667 | BC45: 0 | BD45: 2.9196258 | BE45: 0 | BF45: 0 | BG45: 0 | BH45: 0 | BI45: 0 | BJ45: 0 | BK45: 0 | BL45: 0 | BM45: 0 | BN45: 0 | BO45: =SUM(BC45:BN45) -> 2.9196258 | BP45: =BO45/12 -> 0.24330215 | BS45: C | BT45: GA | BU45: 15 | BV45: 10 | BW45: 5 | BX45: 20 | BY45: 5
A46: PGA-TRN | C46: A-01312 | D46: HANDMOP | E46: HANDMOP | F46: MZ04 | G46: OPEX | J46: PROJECT HVPT | K46: MZ04 | L46: MAZDA J69 | M46: Mazda - Mazda-Japan | N46: PCS | O46: IDR | P46: 23063 | Q46: 23063 | R46: 23063 | S46: 23063 | T46: 23063 | U46: 23063 | V46: 23063 | W46: 23063 | X46: 23063 | Y46: 23063 | Z46: 23063 | AA46: 23063 | AB46: 1.4598129 | AC46: 1.4598129 | AD46: 1.4598129 | AE46: 1.4598129 | AF46: 1.4598129 | AG46: 1.4598129 | AH46: 1.4598129 | AI46: 1.4598129 | AJ46: 1.4598129 | AK46: 1.4598129 | AL46: 1.4598129 | AM46: 1.4598129 | AN46: 0 | AO46: 2 | AP46: 0 | AQ46: 0 | AR46: 0 | AS46: 0 | AT46: 0 | AU46: 0 | AV46: 0 | AW46: 0 | AX46: 0 | AY46: 0 | AZ46: =SUM(AN46:AY46) -> 2 | BA46: =AZ46/12 -> 0.16666667 | BC46: 0 | BD46: 2.9196258 | BE46: 0 | BF46: 0 | BG46: 0 | BH46: 0 | BI46: 0 | BJ46: 0 | BK46: 0 | BL46: 0 | BM46: 0 | BN46: 0 | BO46: =SUM(BC46:BN46) -> 2.9196258 | BP46: =BO46/12 -> 0.24330215 | BS46: C | BT46: GA | BU46: 15 | BV46: 10 | BW46: 5 | BX46: 20 | BY46: 5
A47: PGA-TRN | C47: A-02960 | D47: VACUM CLEANER | E47: VACUM CLEANER MAYAKA | F47: MZ03 | G47: OPEX | J47: PROJECT HVPT | K47: MZ03 | L47: MAZDA J69 | M47: Mazda - Mazda-Japan | N47: UNIT | O47: IDR | P47: 1210000 | Q47: 1210000 | R47: 1210000 | S47: 1210000 | T47: 1210000 | U47: 1210000 | V47: 1210000 | W47: 1210000 | X47: 1210000 | Y47: 1210000 | Z47: 1210000 | AA47: 1210000 | AB47: 76.589065 | AC47: 76.589065 | AD47: 76.589065 | AE47: 76.589065 | AF47: 76.589065 | AG47: 76.589065 | AH47: 76.589065 | AI47: 76.589065 | AJ47: 76.589065 | AK47: 76.589065 | AL47: 76.589065 | AM47: 76.589065 | AN47: 0 | AO47: 1 | AP47: 0 | AQ47: 0 | AR47: 0 | AS47: 0 | AT47: 0 | AU47: 0 | AV47: 0 | AW47: 0 | AX47: 0 | AY47: 0 | AZ47: =SUM(AN47:AY47) -> 1 | BA47: =AZ47/12 -> 0.083333333 | BC47: 0 | BD47: 76.589065 | BE47: 0 | BF47: 0 | BG47: 0 | BH47: 0 | BI47: 0 | BJ47: 0 | BK47: 0 | BL47: 0 | BM47: 0 | BN47: 0 | BO47: =SUM(BC47:BN47) -> 76.589065 | BP47: =BO47/12 -> 6.3824221 | BS47: C | BT47: GA | BU47: 15 | BV47: 10 | BW47: 5 | BX47: 20 | BY47: 5
... A56: PGA-TRN | C56: A-00727 | D56: SEROKAN | E56: SEROKAN | F56: MZ03 | G56: OPEX | J56: PROJECT HVPT | K56: MZ03 | L56: MAZDA J69 | M56: Mazda - Mazda-Japan | N56: PCS | O56: IDR | P56: 7500 | Q56: 7500 | R56: 7500 | S56: 7500 | T56: 7500 | U56: 7500 | V56: 7500 | W56: 7500 | X56: 7500 | Y56: 7500 | Z56: 7500 | AA56: 7500 | AB56: 0.47472561 | AC56: 0.47472561 | AD56: 0.47472561 | AE56: 0.47472561 | AF56: 0.47472561 | AG56: 0.47472561 | AH56: 0.47472561 | AI56: 0.47472561 | AJ56: 0.47472561 | AK56: 0.47472561 | AL56: 0.47472561 | AM56: 0.47472561 | AN56: 0 | AO56: 6 | AP56: 0 | AQ56: 0 | AR56: 0 | AS56: 0 | AT56: 0 | AU56: 0 | AV56: 0 | AW56: 0 | AX56: 0 | AY56: 0 | AZ56: =SUM(AN56:AY56) -> 6 | BA56: =AZ56/12 -> 0.5 | BC56: 0 | BD56: 2.8483537 | BE56: 0 | BF56: 0 | BG56: 0 | BH56: 0 | BI56: 0 | BJ56: 0 | BK56: 0 | BL56: 0 | BM56: 0 | BN56: 0 | BO56: =SUM(BC56:BN56) -> 2.8483537 | BP56: =BO56/12 -> 0.2373628 | BS56: C | BT56: GA | BU56: 15 | BV56: 10 | BW56: 5 | BX56: 20 | BY56: 5

Sheet SUMMARY
E7: STP QTY | F7: STP QTY | G7: STP QTY | H7: STP QTY | I7: STP QTY | J7: STP QTY | K7: STP QTY | L7: STP QTY | M7: STP QTY | N7: STP QTY | O7: STP QTY | P7: STP QTY | Q7: STP AMT | R7: STP AMT | S7: STP AMT | T7: STP AMT | U7: STP AMT | V7: STP AMT | W7: STP AMT | X7: STP AMT | Y7: STP AMT | Z7: STP AMT | AA7: STP AMT | AB7: STP AMT | AC7: TERM 85 | AF7: TERM 84
A8: CATEGORY | B8: ACC NO | C8: ACC DESCRIPTION | D8: PART NAME | E8: Jul-25 | F8: Aug-25 | G8: Sep-25 | H8: Oct-25 | I8: Nov-25 | J8: Dec-25 | K8: Jan-26 | L8: Feb-26 | M8: Mar-26 | N8: Apr-26 | O8: May-26 | P8: Jun-26 | Q8: Jul-25 | R8: Aug-25 | S8: Sep-25 | T8: Oct-25 | U8: Nov-25 | V8: Dec-25 | W8: Jan-26 | X8: Feb-26 | Y8: Mar-26 | Z8: Apr-26 | AA8: May-26 | AB8: Jun-26 | AC8: TOTAL QTY | AD8: TOTAL AMT | AF8: TOTAL QTY | AG8: TOTAL AMT | AH8: PERCENTAGE QTY | AI8: PERCENTAGE AMT | AJ8: REMARKS
A9: RUTIN | D9: BATTERY | E9: =SUMIFS('PLAN BUDGET SAMI-JF'!AN13:AN100000,'PLAN BUDGET SAMI-JF'!D13:D100000,SUMMARY!D9,'PLAN BUDGET SAMI-JF'!J13:J100000,SUMMARY!A9&"*") -> 0 | F9: =SUMIFS('PLAN BUDGET SAMI-JF'!AO13:AO100000,'PLAN BUDGET SAMI-JF'!D13:D100000,SUMMARY!D9,'PLAN BUDGET SAMI-JF'!J13:J100000,SUMMARY!A9&"*") -> 34 | G9: =SUMIFS('PLAN BUDGET SAMI-JF'!AP13:AP100000,'PLAN BUDGET SAMI-JF'!D13:D100000,SUMMARY!D9,'PLAN BUDGET SAMI-JF'!J13:J100000,SUMMARY!A9&"*") -> 0 | H9: =SUMIFS('PLAN BUDGET SAMI-JF'!AQ13:AQ100000,'PLAN BUDGET SAMI-JF'!D13:D100000,SUMMARY!D9,'PLAN BUDGET SAMI-JF'!J13:J100000,SUMMARY!A9&"*") -> 0 | I9: =SUMIFS('PLAN BUDGET SAMI-JF'!AR13:AR100000,'PLAN BUDGET SAMI-JF'!D13:D100000,SUMMARY!D9,'PLAN BUDGET SAMI-JF'!J13:J100000,SUMMARY!A9&"*") -> 0 | J9: =SUMIFS('PLAN BUDGET SAMI-JF'!AS13:AS100000,'PLAN BUDGET SAMI-JF'!D13:D100000,SUMMARY!D9,'PLAN BUDGET SAMI-JF'!J13:J100000,SUMMARY!A9&"*") -> 0 | K9: =SUMIFS('PLAN BUDGET SAMI-JF'!AT13:AT100000,'PLAN BUDGET SAMI-JF'!D13:D100000,SUMMARY!D9,'PLAN BUDGET SAMI-JF'!J13:J100000,SUMMARY!A9&"*") -> 34 | L9: =SUMIFS('PLAN BUDGET SAMI-JF'!AU13:AU100000,'PLAN BUDGET SAMI-JF'!D13:D100000,SUMMARY!D9,'PLAN BUDGET SAMI-JF'!J13:J100000,SUMMARY!A9&"*") -> 0 | M9: =SUMIFS('PLAN BUDGET SAMI-JF'!AV13:AV100000,'PLAN BUDGET SAMI-JF'!D13:D100000,SUMMARY!D9,'PLAN BUDGET SAMI-JF'!J13:J100000,SUMMARY!A9&"*") -> 0 | N9: =SUMIFS('PLAN BUDGET SAMI-JF'!AW13:AW100000,'PLAN BUDGET SAMI-JF'!D13:D100000,SUMMARY!D9,'PLAN BUDGET SAMI-JF'!J13:J100000,SUMMARY!A9&"*") -> 0 | O9: =SUMIFS('PLAN BUDGET SAMI-JF'!AX13:AX100000,'PLAN BUDGET SAMI-JF'!D13:D100000,SUMMARY!D9,'PLAN BUDGET SAMI-JF'!J13:J100000,SUMMARY!A9&"*") -> 0 | P9: =SUMIFS('PLAN BUDGET SAMI-JF'!AY13:AY100000,'PLAN BUDGET SAMI-JF'!D13:D100000,SUMMARY!D9,'PLAN BUDGET SAMI-JF'!J13:J100000,SUMMARY!A9&"*") -> 0 | Q9: =SUMIFS('PLAN BUDGET SAMI-JF'!BC13:BC100000,'PLAN BUDGET SAMI-JF'!D13:D100000,SUMMARY!D9,'PLAN BUDGET SAMI-JF'!J13:J100000,SUMMARY!A9&"*") -> 0 | R9: =SUMIFS('PLAN BUDGET SAMI-JF'!BD13:BD100000,'PLAN BUDGET SAMI-JF'!D13:D100000,SUMMARY!D9,'PLAN BUDGET SAMI-JF'!J13:J100000,SUMMARY!A9&"*") -> 18.464674 | S9: =SUMIFS('PLAN BUDGET SAMI-JF'!BE13:BE100000,'PLAN BUDGET SAMI-JF'!D13:D100000,SUMMARY!D9,'PLAN BUDGET SAMI-JF'!J13:J100000,SUMMARY!A9&"*") -> 0 | T9: =SUMIFS('PLAN BUDGET SAMI-JF'!BF13:BF100000,'PLAN BUDGET SAMI-JF'!D13:D100000,SUMMARY!D9,'PLAN BUDGET SAMI-JF'!J13:J100000,SUMMARY!A9&"*") -> 0 | U9: =SUMIFS('PLAN BUDGET SAMI-JF'!BG13:BG100000,'PLAN BUDGET SAMI-JF'!D13:D100000,SUMMARY!D9,'PLAN BUDGET SAMI-JF'!J13:J100000,SUMMARY!A9&"*") -> 0 | V9: =SUMIFS('PLAN BUDGET SAMI-JF'!BH13:BH100000,'PLAN BUDGET SAMI-JF'!D13:D100000,SUMMARY!D9,'PLAN BUDGET SAMI-JF'!J13:J100000,SUMMARY!A9&"*") -> 0 | W9: =SUMIFS('PLAN BUDGET SAMI-JF'!BI13:BI100000,'PLAN BUDGET SAMI-JF'!D13:D100000,SUMMARY!D9,'PLAN BUDGET SAMI-JF'!J13:J100000,SUMMARY!A9&"*") -> 18.464674 | X9: =SUMIFS('PLAN BUDGET SAMI-JF'!BJ13:BJ100000,'PLAN BUDGET SAMI-JF'!D13:D100000,SUMMARY!D9,'PLAN BUDGET SAMI-JF'!J13:J100000,SUMMARY!A9&"*") -> 0 | Y9: =SUMIFS('PLAN BUDGET SAMI-JF'!BK13:BK100000,'PLAN BUDGET SAMI-JF'!D13:D100000,SUMMARY!D9,'PLAN BUDGET SAMI-JF'!J13:J100000,SUMMARY!A9&"*") -> 0 | Z9: =SUMIFS('PLAN BUDGET SAMI-JF'!BL13:BL100000,'PLAN BUDGET SAMI-JF'!D13:D100000,SUMMARY!D9,'PLAN BUDGET SAMI-JF'!J13:J100000,SUMMARY!A9&"*") -> 0 | AA9: =SUMIFS('PLAN BUDGET SAMI-JF'!BM13:BM100000,'PLAN BUDGET SAMI-JF'!D13:D100000,SUMMARY!D9,'PLAN BUDGET SAMI-JF'!J13:J100000,SUMMARY!A9&"*") -> 0 | AB9: =SUMIFS('PLAN BUDGET SAMI-JF'!BN13:BN100000,'PLAN BUDGET SAMI-JF'!D13:D100000,SUMMARY!D9,'PLAN BUDGET SAMI-JF'!J13:J100000,SUMMARY!A9&"*") -> 0 | AC9: =SUM(E9:P9) -> 68 | AD9: =SUM(Q9:AB9) -> 36.929348 | AF9: 59 | AG9: 29.829352 | AH9: =IFERROR((AC9-AF9)/AF9,1) -> 0.15254237 | AI9: =IFERROR((AD9-AG9)/AG9,1) -> 0.23802046 | AJ9: ada kenaikan penggunaan (di pinjam) section lain
A10: RUTIN | D10: POINTER | E10: =SUMIFS('PLAN BUDGET SAMI-JF'!AN13:AN100000,'PLAN BUDGET SAMI-JF'!D13:D100000,SUMMARY!D10,'PLAN BUDGET SAMI-JF'!J13:J100000,SUMMARY!A10&"*") -> 0 | F10: =SUMIFS('PLAN BUDGET SAMI-JF'!AO13:AO100000,'PLAN BUDGET SAMI-JF'!D13:D100000,SUMMARY!D10,'PLAN BUDGET SAMI-JF'!J13:J100000,SUMMARY!A10&"*") -> 0 | G10: =SUMIFS('PLAN BUDGET SAMI-JF'!AP13:AP100000,'PLAN BUDGET SAMI-JF'!D13:D100000,SUMMARY!D10,'PLAN BUDGET SAMI-JF'!J13:J100000,SUMMARY!A10&"*") -> 2 | H10: =SUMIFS('PLAN BUDGET SAMI-JF'!AQ13:AQ100000,'PLAN BUDGET SAMI-JF'!D13:D100000,SUMMARY!D10,'PLAN BUDGET SAMI-JF'!J13:J100000,SUMMARY!A10&"*") -> 0 | I10: =SUMIFS('PLAN BUDGET SAMI-JF'!AR13:AR100000,'PLAN BUDGET SAMI-JF'!D13:D100000,SUMMARY!D10,'PLAN BUDGET SAMI-JF'!J13:J100000,SUMMARY!A10&"*") -> 0 | J10: =SUMIFS('PLAN BUDGET SAMI-JF'!AS13:AS100000,'PLAN BUDGET SAMI-JF'!D13:D100000,SUMMARY!D10,'PLAN BUDGET SAMI-JF'!J13:J100000,SUMMARY!A10&"*") -> 0 | K10: =SUMIFS('PLAN BUDGET SAMI-JF'!AT13:AT100000,'PLAN BUDGET SAMI-JF'!D13:D100000,SUMMARY!D10,'PLAN BUDGET SAMI-JF'!J13:J100000,SUMMARY!A10&"*") -> 0 | L10: =SUMIFS('PLAN BUDGET SAMI-JF'!AU13:AU100000,'PLAN BUDGET SAMI-JF'!D13:D100000,SUMMARY!D10,'PLAN BUDGET SAMI-JF'!J13:J100000,SUMMARY!A10&"*") -> 0 | M10: =SUMIFS('PLAN BUDGET SAMI-JF'!AV13:AV100000,'PLAN BUDGET SAMI-JF'!D13:D100000,SUMMARY!D10,'PLAN BUDGET SAMI-JF'!J13:J100000,SUMMARY!A10&"*") -> 0 | N10: =SUMIFS('PLAN BUDGET SAMI-JF'!AW13:AW100000,'PLAN BUDGET SAMI-JF'!D13:D100000,SUMMARY!D10,'PLAN BUDGET SAMI-JF'!J13:J100000,SUMMARY!A10&"*") -> 0 | O10: =SUMIFS('PLAN BUDGET SAMI-JF'!AX13:AX100000,'PLAN BUDGET SAMI-JF'!D13:D100000,SUMMARY!D10,'PLAN BUDGET SAMI-JF'!J13:J100000,SUMMARY!A10&"*") -> 0 | P10: =SUMIFS('PLAN BUDGET SAMI-JF'!AY13:AY100000,'PLAN BUDGET SAMI-JF'!D13:D100000,SUMMARY!D10,'PLAN BUDGET SAMI-JF'!J13:J100000,SUMMARY!A10&"*") -> 0 | Q10: =SUMIFS('PLAN BUDGET SAMI-JF'!BC13:BC100000,'PLAN BUDGET SAMI-JF'!D13:D100000,SUMMARY!D10,'PLAN BUDGET SAMI-JF'!J13:J100000,SUMMARY!A10&"*") -> 0 | R10: =SUMIFS('PLAN BUDGET SAMI-JF'!BD13:BD100000,'PLAN BUDGET SAMI-JF'!D13:D100000,SUMMARY!D10,'PLAN BUDGET SAMI-JF'!J13:J100000,SUMMARY!A10&"*") -> 0 | S10: =SUMIFS('PLAN BUDGET SAMI-JF'!BE13:BE100000,'PLAN BUDGET SAMI-JF'!D13:D100000,SUMMARY!D10,'PLAN BUDGET SAMI-JF'!J13:J100000,SUMMARY!A10&"*") -> 59.979998 | T10: =SUMIFS('PLAN BUDGET SAMI-JF'!BF13:BF100000,'PLAN BUDGET SAMI-JF'!D13:D100000,SUMMARY!D10,'PLAN BUDGET SAMI-JF'!J13:J100000,SUMMARY!A10&"*") -> 0 | U10: =SUMIFS('PLAN BUDGET SAMI-JF'!BG13:BG100000,'PLAN BUDGET SAMI-JF'!D13:D100000,SUMMARY!D10,'PLAN BUDGET SAMI-JF'!J13:J100000,SUMMARY!A10&"*") -> 0 | V10: =SUMIFS('PLAN BUDGET SAMI-JF'!BH13:BH100000,'PLAN BUDGET SAMI-JF'!D13:D100000,SUMMARY!D10,'PLAN BUDGET SAMI-JF'!J13:J100000,SUMMARY!A10&"*") -> 0 | W10: =SUMIFS('PLAN BUDGET SAMI-JF'!BI13:BI100000,'PLAN BUDGET SAMI-JF'!D13:D100000,SUMMARY!D10,'PLAN BUDGET SAMI-JF'!J13:J100000,SUMMARY!A10&"*") -> 0 | X10: =SUMIFS('PLAN BUDGET SAMI-JF'!BJ13:BJ100000,'PLAN BUDGET SAMI-JF'!D13:D100000,SUMMARY!D10,'PLAN BUDGET SAMI-JF'!J13:J100000,SUMMARY!A10&"*") -> 0 | Y10: =SUMIFS('PLAN BUDGET SAMI-JF'!BK13:BK100000,'PLAN BUDGET SAMI-JF'!D13:D100000,SUMMARY!D10,'PLAN BUDGET SAMI-JF'!J13:J100000,SUMMARY!A10&"*") -> 0 | Z10: =SUMIFS('PLAN BUDGET SAMI-JF'!BL13:BL100000,'PLAN BUDGET SAMI-JF'!D13:D100000,SUMMARY!D10,'PLAN BUDGET SAMI-JF'!J13:J100000,SUMMARY!A10&"*") -> 0 | AA10: =SUMIFS('PLAN BUDGET SAMI-JF'!BM13:BM100000,'PLAN BUDGET SAMI-JF'!D13:D100000,SUMMARY!D10,'PLAN BUDGET SAMI-JF'!J13:J100000,SUMMARY!A10&"*") -> 0 | AB10: =SUMIFS('PLAN BUDGET SAMI-JF'!BN13:BN100000,'PLAN BUDGET SAMI-JF'!D13:D100000,SUMMARY!D10,'PLAN BUDGET SAMI-JF'!J13:J100000,SUMMARY!A10&"*") -> 0 | AC10: =SUM(E10:P10) -> 2 | AD10: =SUM(Q10:AB10) -> 59.979998 | AF10: 2 | AG10: 58.233008 | AH10: =IFERROR((AC10-AF10)/AF10,1) -> 0 | AI10: =IFERROR((AD10-AG10)/AG10,1) -> 0.03 | AJ10: kenaikan harga dari Vendor
A11: RUTIN | D11: PERJALANAN DINAS | E11: =SUMIFS('PLAN BUDGET SAMI-JF'!AN13:AN100000,'PLAN BUDGET SAMI-JF'!D13:D100000,SUMMARY!D11,'PLAN BUDGET SAMI-JF'!J13:J100000,SUMMARY!A11&"*") -> 0 | F11: =SUMIFS('PLAN BUDGET SAMI-JF'!AO13:AO100000,'PLAN BUDGET SAMI-JF'!D13:D100000,SUMMARY!D11,'PLAN BUDGET SAMI-JF'!J13:J100000,SUMMARY!A11&"*") -> 0 | G11: =SUMIFS('PLAN BUDGET SAMI-JF'!AP13:AP100000,'PLAN BUDGET SAMI-JF'!D13:D100000,SUMMARY!D11,'PLAN BUDGET SAMI-JF'!J13:J100000,SUMMARY!A11&"*") -> 0 | H11: =SUMIFS('PLAN BUDGET SAMI-JF'!AQ13:AQ100000,'PLAN BUDGET SAMI-JF'!D13:D100000,SUMMARY!D11,'PLAN BUDGET SAMI-JF'!J13:J100000,SUMMARY!A11&"*") -> 0 | I11: =SUMIFS('PLAN BUDGET SAMI-JF'!AR13:AR100000,'PLAN BUDGET SAMI-JF'!D13:D100000,SUMMARY!D11,'PLAN BUDGET SAMI-JF'!J13:J100000,SUMMARY!A11&"*") -> 24 | J11: =SUMIFS('PLAN BUDGET SAMI-JF'!AS13:AS100000,'PLAN BUDGET SAMI-JF'!D13:D100000,SUMMARY!D11,'PLAN BUDGET SAMI-JF'!J13:J100000,SUMMARY!A11&"*") -> 0 | K11: =SUMIFS('PLAN BUDGET SAMI-JF'!AT13:AT100000,'PLAN BUDGET SAMI-JF'!D13:D100000,SUMMARY!D11,'PLAN BUDGET SAMI-JF'!J13:J100000,SUMMARY!A11&"*") -> 0 | L11: =SUMIFS('PLAN BUDGET SAMI-JF'!AU13:AU100000,'PLAN BUDGET SAMI-JF'!D13:D100000,SUMMARY!D11,'PLAN BUDGET SAMI-JF'!J13:J100000,SUMMARY!A11&"*") -> 0 | M11: =SUMIFS('PLAN BUDGET SAMI-JF'!AV13:AV100000,'PLAN BUDGET SAMI-JF'!D13:D100000,SUMMARY!D11,'PLAN BUDGET SAMI-JF'!J13:J100000,SUMMARY!A11&"*") -> 0 | N11: =SUMIFS('PLAN BUDGET SAMI-JF'!AW13:AW100000,'PLAN BUDGET SAMI-JF'!D13:D100000,SUMMARY!D11,'PLAN BUDGET SAMI-JF'!J13:J100000,SUMMARY!A11&"*") -> 0 | O11: =SUMIFS('PLAN BUDGET SAMI-JF'!AX13:AX100000,'PLAN BUDGET SAMI-JF'!D13:D100000,SUMMARY!D11,'PLAN BUDGET SAMI-JF'!J13:J100000,SUMMARY!A11&"*") -> 0 | P11: =SUMIFS('PLAN BUDGET SAMI-JF'!AY13:AY100000,'PLAN BUDGET SAMI-JF'!D13:D100000,SUMMARY!D11,'PLAN BUDGET SAMI-JF'!J13:J100000,SUMMARY!A11&"*") -> 0 | Q11: =SUMIFS('PLAN BUDGET SAMI-JF'!BC13:BC100000,'PLAN BUDGET SAMI-JF'!D13:D100000,SUMMARY!D11,'PLAN BUDGET SAMI-JF'!J13:J100000,SUMMARY!A11&"*") -> 0 | R11: =SUMIFS('PLAN BUDGET SAMI-JF'!BD13:BD100000,'PLAN BUDGET SAMI-JF'!D13:D100000,SUMMARY!D11,'PLAN BUDGET SAMI-JF'!J13:J100000,SUMMARY!A11&"*") -> 0 | S11: =SUMIFS('PLAN BUDGET SAMI-JF'!BE13:BE100000,'PLAN BUDGET SAMI-JF'!D13:D100000,SUMMARY!D11,'PLAN BUDGET SAMI-JF'!J13:J100000,SUMMARY!A11&"*") -> 0 | T11: =SUMIFS('PLAN BUDGET SAMI-JF'!BF13:BF100000,'PLAN BUDGET SAMI-JF'!D13:D100000,SUMMARY!D11,'PLAN BUDGET SAMI-JF'!J13:J100000,SUMMARY!A11&"*") -> 0 | U11: =SUMIFS('PLAN BUDGET SAMI-JF'!BG13:BG100000,'PLAN BUDGET SAMI-JF'!D13:D100000,SUMMARY!D11,'PLAN BUDGET SAMI-JF'!J13:J100000,SUMMARY!A11&"*") -> 529.16081 | V11: =SUMIFS('PLAN BUDGET SAMI-JF'!BH13:BH100000,'PLAN BUDGET SAMI-JF'!D13:D100000,SUMMARY!D11,'PLAN BUDGET SAMI-JF'!J13:J100000,SUMMARY!A11&"*") -> 0 | W11: =SUMIFS('PLAN BUDGET SAMI-JF'!BI13:BI100000,'PLAN BUDGET SAMI-JF'!D13:D100000,SUMMARY!D11,'PLAN BUDGET SAMI-JF'!J13:J100000,SUMMARY!A11&"*") -> 0 | X11: =SUMIFS('PLAN BUDGET SAMI-JF'!BJ13:BJ100000,'PLAN BUDGET SAMI-JF'!D13:D100000,SUMMARY!D11,'PLAN BUDGET SAMI-JF'!J13:J100000,SUMMARY!A11&"*") -> 0 | Y11: =SUMIFS('PLAN BUDGET SAMI-JF'!BK13:BK100000,'PLAN BUDGET SAMI-JF'!D13:D100000,SUMMARY!D11,'PLAN BUDGET SAMI-JF'!J13:J100000,SUMMARY!A11&"*") -> 0 | Z11: =SUMIFS('PLAN BUDGET SAMI-JF'!BL13:BL100000,'PLAN BUDGET SAMI-JF'!D13:D100000,SUMMARY!D11,'PLAN BUDGET SAMI-JF'!J13:J100000,SUMMARY!A11&"*") -> 0 | AA11: =SUMIFS('PLAN BUDGET SAMI-JF'!BM13:BM100000,'PLAN BUDGET SAMI-JF'!D13:D100000,SUMMARY!D11,'PLAN BUDGET SAMI-JF'!J13:J100000,SUMMARY!A11&"*") -> 0 | AB11: =SUMIFS('PLAN BUDGET SAMI-JF'!BN13:BN100000,'PLAN BUDGET SAMI-JF'!D13:D100000,SUMMARY!D11,'PLAN BUDGET SAMI-JF'!J13:J100000,SUMMARY!A11&"*") -> 0 | AC11: =SUM(E11:P11) -> 24 | AD11: =SUM(Q11:AB11) -> 529.16081 | AF11: 0 | AG11: 0 | AH11: =IFERROR((AC11-AF11)/AF11,1) -> 1 | AI11: =IFERROR((AD11-AG11)/AG11,1) -> 1 | AJ11: Budget di Term 84 tidak ada, sedangkan di Term 85 ada.
A12: RUTIN | D12: SENAR | E12: =SUMIFS('PLAN BUDGET SAMI-JF'!AN13:AN100000,'PLAN BUDGET SAMI-JF'!D13:D100000,SUMMARY!D12,'PLAN BUDGET SAMI-JF'!J13:J100000,SUMMARY!A12&"*") -> 1 | F12: =SUMIFS('PLAN BUDGET SAMI-JF'!AO13:AO100000,'PLAN BUDGET SAMI-JF'!D13:D100000,SUMMARY!D12,'PLAN BUDGET SAMI-JF'!J13:J100000,SUMMARY!A12&"*") -> 0 | G12: =SUMIFS('PLAN BUDGET SAMI-JF'!AP13:AP100000,'PLAN BUDGET SAMI-JF'!D13:D100000,SUMMARY!D12,'PLAN BUDGET SAMI-JF'!J13:J100000,SUMMARY!A12&"*") -> 0 | H12: =SUMIFS('PLAN BUDGET SAMI-JF'!AQ13:AQ100000,'PLAN BUDGET SAMI-JF'!D13:D100000,SUMMARY!D12,'PLAN BUDGET SAMI-JF'!J13:J100000,SUMMARY!A12&"*") -> 0 | I12: =SUMIFS('PLAN BUDGET SAMI-JF'!AR13:AR100000,'PLAN BUDGET SAMI-JF'!D13:D100000,SUMMARY!D12,'PLAN BUDGET SAMI-JF'!J13:J100000,SUMMARY!A12&"*") -> 0 | J12: =SUMIFS('PLAN BUDGET SAMI-JF'!AS13:AS100000,'PLAN BUDGET SAMI-JF'!D13:D100000,SUMMARY!D12,'PLAN BUDGET SAMI-JF'!J13:J100000,SUMMARY!A12&"*") -> 0 | K12: =SUMIFS('PLAN BUDGET SAMI-JF'!AT13:AT100000,'PLAN BUDGET SAMI-JF'!D13:D100000,SUMMARY!D12,'PLAN BUDGET SAMI-JF'!J13:J100000,SUMMARY!A12&"*") -> 0 | L12: =SUMIFS('PLAN BUDGET SAMI-JF'!AU13:AU100000,'PLAN BUDGET SAMI-JF'!D13:D100000,SUMMARY!D12,'PLAN BUDGET SAMI-JF'!J13:J100000,SUMMARY!A12&"*") -> 0 | M12: =SUMIFS('PLAN BUDGET SAMI-JF'!AV13:AV100000,'PLAN BUDGET SAMI-JF'!D13:D100000,SUMMARY!D12,'PLAN BUDGET SAMI-JF'!J13:J100000,SUMMARY!A12&"*") -> 0 | N12: =SUMIFS('PLAN BUDGET SAMI-JF'!AW13:AW100000,'PLAN BUDGET SAMI-JF'!D13:D100000,SUMMARY!D12,'PLAN BUDGET SAMI-JF'!J13:J100000,SUMMARY!A12&"*") -> 0 | O12: =SUMIFS('PLAN BUDGET SAMI-JF'!AX13:AX100000,'PLAN BUDGET SAMI-JF'!D13:D100000,SUMMARY!D12,'PLAN BUDGET SAMI-JF'!J13:J100000,SUMMARY!A12&"*") -> 0 | P12: =SUMIFS('PLAN BUDGET SAMI-JF'!AY13:AY100000,'PLAN BUDGET SAMI-JF'!D13:D100000,SUMMARY!D12,'PLAN BUDGET SAMI-JF'!J13:J100000,SUMMARY!A12&"*") -> 0 | Q12: =SUMIFS('PLAN BUDGET SAMI-JF'!BC13:BC100000,'PLAN BUDGET SAMI-JF'!D13:D100000,SUMMARY!D12,'PLAN BUDGET SAMI-JF'!J13:J100000,SUMMARY!A12&"*") -> 2.2786829 | R12: =SUMIFS('PLAN BUDGET SAMI-JF'!BD13:BD100000,'PLAN BUDGET SAMI-JF'!D13:D100000,SUMMARY!D12,'PLAN BUDGET SAMI-JF'!J13:J100000,SUMMARY!A12&"*") -> 0 | S12: =SUMIFS('PLAN BUDGET SAMI-JF'!BE13:BE100000,'PLAN BUDGET SAMI-JF'!D13:D100000,SUMMARY!D12,'PLAN BUDGET SAMI-JF'!J13:J100000,SUMMARY!A12&"*") -> 0 | T12: =SUMIFS('PLAN BUDGET SAMI-JF'!BF13:BF100000,'PLAN BUDGET SAMI-JF'!D13:D100000,SUMMARY!D12,'PLAN BUDGET SAMI-JF'!J13:J100000,SUMMARY!A12&"*") -> 0 | U12: =SUMIFS('PLAN BUDGET SAMI-JF'!BG13:BG100000,'PLAN BUDGET SAMI-JF'!D13:D100000,SUMMARY!D12,'PLAN BUDGET SAMI-JF'!J13:J100000,SUMMARY!A12&"*") -> 0 | V12: =SUMIFS('PLAN BUDGET SAMI-JF'!BH13:BH100000,'PLAN BUDGET SAMI-JF'!D13:D100000,SUMMARY!D12,'PLAN BUDGET SAMI-JF'!J13:J100000,SUMMARY!A12&"*") -> 0 | W12: =SUMIFS('PLAN BUDGET SAMI-JF'!BI13:BI100000,'PLAN BUDGET SAMI-JF'!D13:D100000,SUMMARY!D12,'PLAN BUDGET SAMI-JF'!J13:J100000,SUMMARY!A12&"*") -> 0 | X12: =SUMIFS('PLAN BUDGET SAMI-JF'!BJ13:BJ100000,'PLAN BUDGET SAMI-JF'!D13:D100000,SUMMARY!D12,'PLAN BUDGET SAMI-JF'!J13:J100000,SUMMARY!A12&"*") -> 0 | Y12: =SUMIFS('PLAN BUDGET SAMI-JF'!BK13:BK100000,'PLAN BUDGET SAMI-JF'!D13:D100000,SUMMARY!D12,'PLAN BUDGET SAMI-JF'!J13:J100000,SUMMARY!A12&"*") -> 0 | Z12: =SUMIFS('PLAN BUDGET SAMI-JF'!BL13:BL100000,'PLAN BUDGET SAMI-JF'!D13:D100000,SUMMARY!D12,'PLAN BUDGET SAMI-JF'!J13:J100000,SUMMARY!A12&"*") -> 0 | AA12: =SUMIFS('PLAN BUDGET SAMI-JF'!BM13:BM100000,'PLAN BUDGET SAMI-JF'!D13:D100000,SUMMARY!D12,'PLAN BUDGET SAMI-JF'!J13:J100000,SUMMARY!A12&"*") -> 0 | AB12: =SUMIFS('PLAN BUDGET SAMI-JF'!BN13:BN100000,'PLAN BUDGET SAMI-JF'!D13:D100000,SUMMARY!D12,'PLAN BUDGET SAMI-JF'!J13:J100000,SUMMARY!A12&"*") -> 0 | AC12: =SUM(E12:P12) -> 1 | AD12: =SUM(Q12:AB12) -> 2.2786829 | AF12: 0 | AG12: 0 | AH12: =IFERROR((AC12-AF12)/AF12,1) -> 1 | AI12: =IFERROR((AD12-AG12)/AG12,1) -> 1 | AJ12: Budget di Term 84 tidak ada, sedangkan di Term 85 ada.
A13: RUTIN | D13: STOPWATCH | E13: =SUMIFS('PLAN BUDGET SAMI-JF'!AN13:AN100000,'PLAN BUDGET SAMI-JF'!D13:D100000,SUMMARY!D13,'PLAN BUDGET SAMI-JF'!J13:J100000,SUMMARY!A13&"*") -> 0 | F13: =SUMIFS('PLAN BUDGET SAMI-JF'!AO13:AO100000,'PLAN BUDGET SAMI-JF'!D13:D100000,SUMMARY!D13,'PLAN BUDGET SAMI-JF'!J13:J100000,SUMMARY!A13&"*") -> 10 | G13: =SUMIFS('PLAN BUDGET SAMI-JF'!AP13:AP100000,'PLAN BUDGET SAMI-JF'!D13:D100000,SUMMARY!D13,'PLAN BUDGET SAMI-JF'!J13:J100000,SUMMARY!A13&"*") -> 0 | H13: =SUMIFS('PLAN BUDGET SAMI-JF'!AQ13:AQ100000,'PLAN BUDGET SAMI-JF'!D13:D100000,SUMMARY!D13,'PLAN BUDGET SAMI-JF'!J13:J100000,SUMMARY!A13&"*") -> 0 | I13: =SUMIFS('PLAN BUDGET SAMI-JF'!AR13:AR100000,'PLAN BUDGET SAMI-JF'!D13:D100000,SUMMARY!D13,'PLAN BUDGET SAMI-JF'!J13:J100000,SUMMARY!A13&"*") -> 0 | J13: =SUMIFS('PLAN BUDGET SAMI-JF'!AS13:AS100000,'PLAN BUDGET SAMI-JF'!D13:D100000,SUMMARY!D13,'PLAN BUDGET SAMI-JF'!J13:J100000,SUMMARY!A13&"*") -> 0 | K13: =SUMIFS('PLAN BUDGET SAMI-JF'!AT13:AT100000,'PLAN BUDGET SAMI-JF'!D13:D100000,SUMMARY!D13,'PLAN BUDGET SAMI-JF'!J13:J100000,SUMMARY!A13&"*") -> 0 | L13: =SUMIFS('PLAN BUDGET SAMI-JF'!AU13:AU100000,'PLAN BUDGET SAMI-JF'!D13:D100000,SUMMARY!D13,'PLAN BUDGET SAMI-JF'!J13:J100000,SUMMARY!A13&"*") -> 0 | M13: =SUMIFS('PLAN BUDGET SAMI-JF'!AV13:AV100000,'PLAN BUDGET SAMI-JF'!D13:D100000,SUMMARY!D13,'PLAN BUDGET SAMI-JF'!J13:J100000,SUMMARY!A13&"*") -> 0 | N13: =SUMIFS('PLAN BUDGET SAMI-JF'!AW13:AW100000,'PLAN BUDGET SAMI-JF'!D13:D100000,SUMMARY!D13,'PLAN BUDGET SAMI-JF'!J13:J100000,SUMMARY!A13&"*") -> 0 | O13: =SUMIFS('PLAN BUDGET SAMI-JF'!AX13:AX100000,'PLAN BUDGET SAMI-JF'!D13:D100000,SUMMARY!D13,'PLAN BUDGET SAMI-JF'!J13:J100000,SUMMARY!A13&"*") -> 0 | P13: =SUMIFS('PLAN BUDGET SAMI-JF'!AY13:AY100000,'PLAN BUDGET SAMI-JF'!D13:D100000,SUMMARY!D13,'PLAN BUDGET SAMI-JF'!J13:J100000,SUMMARY!A13&"*") -> 0 | Q13: =SUMIFS('PLAN BUDGET SAMI-JF'!BC13:BC100000,'PLAN BUDGET SAMI-JF'!D13:D100000,SUMMARY!D13,'PLAN BUDGET SAMI-JF'!J13:J100000,SUMMARY!A13&"*") -> 0 | R13: =SUMIFS('PLAN BUDGET SAMI-JF'!BD13:BD100000,'PLAN BUDGET SAMI-JF'!D13:D100000,SUMMARY!D13,'PLAN BUDGET SAMI-JF'!J13:J100000,SUMMARY!A13&"*") -> 283.60108 | S13: =SUMIFS('PLAN BUDGET SAMI-JF'!BE13:BE100000,'PLAN BUDGET SAMI-JF'!D13:D100000,SUMMARY!D13,'PLAN BUDGET SAMI-JF'!J13:J100000,SUMMARY!A13&"*") -> 0 | T13: =SUMIFS('PLAN BUDGET SAMI-JF'!BF13:BF100000,'PLAN BUDGET SAMI-JF'!D13:D100000,SUMMARY!D13,'PLAN BUDGET SAMI-JF'!J13:J100000,SUMMARY!A13&"*") -> 0 | U13: =SUMIFS('PLAN BUDGET SAMI-JF'!BG13:BG100000,'PLAN BUDGET SAMI-JF'!D13:D100000,SUMMARY!D13,'PLAN BUDGET SAMI-JF'!J13:J100000,SUMMARY!A13&"*") -> 0 | V13: =SUMIFS('PLAN BUDGET SAMI-JF'!BH13:BH100000,'PLAN BUDGET SAMI-JF'!D13:D100000,SUMMARY!D13,'PLAN BUDGET SAMI-JF'!J13:J100000,SUMMARY!A13&"*") -> 0 | W13: =SUMIFS('PLAN BUDGET SAMI-JF'!BI13:BI100000,'PLAN BUDGET SAMI-JF'!D13:D100000,SUMMARY!D13,'PLAN BUDGET SAMI-JF'!J13:J100000,SUMMARY!A13&"*") -> 0 | X13: =SUMIFS('PLAN BUDGET SAMI-JF'!BJ13:BJ100000,'PLAN BUDGET SAMI-JF'!D13:D100000,SUMMARY!D13,'PLAN BUDGET SAMI-JF'!J13:J100000,SUMMARY!A13&"*") -> 0 | Y13: =SUMIFS('PLAN BUDGET SAMI-JF'!BK13:BK100000,'PLAN BUDGET SAMI-JF'!D13:D100000,SUMMARY!D13,'PLAN BUDGET SAMI-JF'!J13:J100000,SUMMARY!A13&"*") -> 0 | Z13: =SUMIFS('PLAN BUDGET SAMI-JF'!BL13:BL100000,'PLAN BUDGET SAMI-JF'!D13:D100000,SUMMARY!D13,'PLAN BUDGET SAMI-JF'!J13:J100000,SUMMARY!A13&"*") -> 0 | AA13: =SUMIFS('PLAN BUDGET SAMI-JF'!BM13:BM100000,'PLAN BUDGET SAMI-JF'!D13:D100000,SUMMARY!D13,'PLAN BUDGET SAMI-JF'!J13:J100000,SUMMARY!A13&"*") -> 0 | AB13: =SUMIFS('PLAN BUDGET SAMI-JF'!BN13:BN100000,'PLAN BUDGET SAMI-JF'!D13:D100000,SUMMARY!D13,'PLAN BUDGET SAMI-JF'!J13:J100000,SUMMARY!A13&"*") -> 0 | AC13: =SUM(E13:P13) -> 10 | AD13: =SUM(Q13:AB13) -> 283.60108 | AF13: 10 | AG13: 265.84634 | AH13: =IFERROR((AC13-AF13)/AF13,1) -> 0 | AI13: =IFERROR((AD13-AG13)/AG13,1) -> 0.066785714 | AJ13: kenaikan harga dari Vendor
A14: RUTIN | D14: ENTERTAIN | E14: =SUMIFS('PLAN BUDGET SAMI-JF'!AN13:AN100000,'PLAN BUDGET SAMI-JF'!D13:D100000,SUMMARY!D14,'PLAN BUDGET SAMI-JF'!J13:J100000,SUMMARY!A14&"*") -> 0 | F14: =SUMIFS('PLAN BUDGET SAMI-JF'!AO13:AO100000,'PLAN BUDGET SAMI-JF'!D13:D100000,SUMMARY!D14,'PLAN BUDGET SAMI-JF'!J13:J100000,SUMMARY!A14&"*") -> 0 | G14: =SUMIFS('PLAN BUDGET SAMI-JF'!AP13:AP100000,'PLAN BUDGET SAMI-JF'!D13:D100000,SUMMARY!D14,'PLAN BUDGET SAMI-JF'!J13:J100000,SUMMARY!A14&"*") -> 0 | H14: =SUMIFS('PLAN BUDGET SAMI-JF'!AQ13:AQ100000,'PLAN BUDGET SAMI-JF'!D13:D100000,SUMMARY!D14,'PLAN BUDGET SAMI-JF'!J13:J100000,SUMMARY!A14&"*") -> 0 | I14: =SUMIFS('PLAN BUDGET SAMI-JF'!AR13:AR100000,'PLAN BUDGET SAMI-JF'!D13:D100000,SUMMARY!D14,'PLAN BUDGET SAMI-JF'!J13:J100000,SUMMARY!A14&"*") -> 0 | J14: =SUMIFS('PLAN BUDGET SAMI-JF'!AS13:AS100000,'PLAN BUDGET SAMI-JF'!D13:D100000,SUMMARY!D14,'PLAN BUDGET SAMI-JF'!J13:J100000,SUMMARY!A14&"*") -> 0 | K14: =SUMIFS('PLAN BUDGET SAMI-JF'!AT13:AT100000,'PLAN BUDGET SAMI-JF'!D13:D100000,SUMMARY!D14,'PLAN BUDGET SAMI-JF'!J13:J100000,SUMMARY!A14&"*") -> 0 | L14: =SUMIFS('PLAN BUDGET SAMI-JF'!AU13:AU100000,'PLAN BUDGET SAMI-JF'!D13:D100000,SUMMARY!D14,'PLAN BUDGET SAMI-JF'!J13:J100000,SUMMARY!A14&"*") -> 0 | M14: =SUMIFS('PLAN BUDGET SAMI-JF'!AV13:AV100000,'PLAN BUDGET SAMI-JF'!D13:D100000,SUMMARY!D14,'PLAN BUDGET SAMI-JF'!J13:J100000,SUMMARY!A14&"*") -> 0 | N14: =SUMIFS('PLAN BUDGET SAMI-JF'!AW13:AW100000,'PLAN BUDGET SAMI-JF'!D13:D100000,SUMMARY!D14,'PLAN BUDGET SAMI-JF'!J13:J100000,SUMMARY!A14&"*") -> 0 | O14: =SUMIFS('PLAN BUDGET SAMI-JF'!AX13:AX100000,'PLAN BUDGET SAMI-JF'!D13:D100000,SUMMARY!D14,'PLAN BUDGET SAMI-JF'!J13:J100000,SUMMARY!A14&"*") -> 10 | P14: =SUMIFS('PLAN BUDGET SAMI-JF'!AY13:AY100000,'PLAN BUDGET SAMI-JF'!D13:D100000,SUMMARY!D14,'PLAN BUDGET SAMI-JF'!J13:J100000,SUMMARY!A14&"*") -> 0 | Q14: =SUMIFS('PLAN BUDGET SAMI-JF'!BC13:BC100000,'PLAN BUDGET SAMI-JF'!D13:D100000,SUMMARY!D14,'PLAN BUDGET SAMI-JF'!J13:J100000,SUMMARY!A14&"*") -> 0 | R14: =SUMIFS('PLAN BUDGET SAMI-JF'!BD13:BD100000,'PLAN BUDGET SAMI-JF'!D13:D100000,SUMMARY!D14,'PLAN BUDGET SAMI-JF'!J13:J100000,SUMMARY!A14&"*") -> 0 | S14: =SUMIFS('PLAN BUDGET SAMI-JF'!BE13:BE100000,'PLAN BUDGET SAMI-JF'!D13:D100000,SUMMARY!D14,'PLAN BUDGET SAMI-JF'!J13:J100000,SUMMARY!A14&"*") -> 0 | T14: =SUMIFS('PLAN BUDGET SAMI-JF'!BF13:BF100000,'PLAN BUDGET SAMI-JF'!D13:D100000,SUMMARY!D14,'PLAN BUDGET SAMI-JF'!J13:J100000,SUMMARY!A14&"*") -> 0 | U14: =SUMIFS('PLAN BUDGET SAMI-JF'!BG13:BG100000,'PLAN BUDGET SAMI-JF'!D13:D100000,SUMMARY!D14,'PLAN BUDGET SAMI-JF'!J13:J100000,SUMMARY!A14&"*") -> 0 | V14: =SUMIFS('PLAN BUDGET SAMI-JF'!BH13:BH100000,'PLAN BUDGET SAMI-JF'!D13:D100000,SUMMARY!D14,'PLAN BUDGET SAMI-JF'!J13:J100000,SUMMARY!A14&"*") -> 0 | W14: =SUMIFS('PLAN BUDGET SAMI-JF'!BI13:BI100000,'PLAN BUDGET SAMI-JF'!D13:D100000,SUMMARY!D14,'PLAN BUDGET SAMI-JF'!J13:J100000,SUMMARY!A14&"*") -> 0 | X14: =SUMIFS('PLAN BUDGET SAMI-JF'!BJ13:BJ100000,'PLAN BUDGET SAMI-JF'!D13:D100000,SUMMARY!D14,'PLAN BUDGET SAMI-JF'!J13:J100000,SUMMARY!A14&"*") -> 0 | Y14: =SUMIFS('PLAN BUDGET SAMI-JF'!BK13:BK100000,'PLAN BUDGET SAMI-JF'!D13:D100000,SUMMARY!D14,'PLAN BUDGET SAMI-JF'!J13:J100000,SUMMARY!A14&"*") -> 0 | Z14: =SUMIFS('PLAN BUDGET SAMI-JF'!BL13:BL100000,'PLAN BUDGET SAMI-JF'!D13:D100000,SUMMARY!D14,'PLAN BUDGET SAMI-JF'!J13:J100000,SUMMARY!A14&"*") -> 0 | AA14: =SUMIFS('PLAN BUDGET SAMI-JF'!BM13:BM100000,'PLAN BUDGET SAMI-JF'!D13:D100000,SUMMARY!D14,'PLAN BUDGET SAMI-JF'!J13:J100000,SUMMARY!A14&"*") -> 94.945122 | AB14: =SUMIFS('PLAN BUDGET SAMI-JF'!BN13:BN100000,'PLAN BUDGET SAMI-JF'!D13:D100000,SUMMARY!D14,'PLAN BUDGET SAMI-JF'!J13:J100000,SUMMARY!A14&"*") -> 0 | AC14: =SUM(E14:P14) -> 10 | AD14: =SUM(Q14:AB14) -> 94.945122 | AF14: 478 | AG14: 2079.2982 | AH14: =IFERROR((AC14-AF14)/AF14,1) -> -0.9790795 | AI14: =IFERROR((AD14-AG14)/AG14,1) -> -0.9543379 | AJ14: ada training eksternal di term 84 ada tapi di tem 85 tidak ada
A15: RUTIN | D15: MASKER | E15: =SUMIFS('PLAN BUDGET SAMI-JF'!AN13:AN100000,'PLAN BUDGET SAMI-JF'!D13:D100000,SUMMARY!D15,'PLAN BUDGET SAMI-JF'!J13:J100000,SUMMARY!A15&"*") -> 0 | F15: =SUMIFS('PLAN BUDGET SAMI-JF'!AO13:AO100000,'PLAN BUDGET SAMI-JF'!D13:D100000,SUMMARY!D15,'PLAN BUDGET SAMI-JF'!J13:J100000,SUMMARY!A15&"*") -> 0 | G15: =SUMIFS('PLAN BUDGET SAMI-JF'!AP13:AP100000,'PLAN BUDGET SAMI-JF'!D13:D100000,SUMMARY!D15,'PLAN BUDGET SAMI-JF'!J13:J100000,SUMMARY!A15&"*") -> 13 | H15: =SUMIFS('PLAN BUDGET SAMI-JF'!AQ13:AQ100000,'PLAN BUDGET SAMI-JF'!D13:D100000,SUMMARY!D15,'PLAN BUDGET SAMI-JF'!J13:J100000,SUMMARY!A15&"*") -> 0 | I15: =SUMIFS('PLAN BUDGET SAMI-JF'!AR13:AR100000,'PLAN BUDGET SAMI-JF'!D13:D100000,SUMMARY!D15,'PLAN BUDGET SAMI-JF'!J13:J100000,SUMMARY!A15&"*") -> 0 | J15: =SUMIFS('PLAN BUDGET SAMI-JF'!AS13:AS100000,'PLAN BUDGET SAMI-JF'!D13:D100000,SUMMARY!D15,'PLAN BUDGET SAMI-JF'!J13:J100000,SUMMARY!A15&"*") -> 0 | K15: =SUMIFS('PLAN BUDGET SAMI-JF'!AT13:AT100000,'PLAN BUDGET SAMI-JF'!D13:D100000,SUMMARY!D15,'PLAN BUDGET SAMI-JF'!J13:J100000,SUMMARY!A15&"*") -> 0 | L15: =SUMIFS('PLAN BUDGET SAMI-JF'!AU13:AU100000,'PLAN BUDGET SAMI-JF'!D13:D100000,SUMMARY!D15,'PLAN BUDGET SAMI-JF'!J13:J100000,SUMMARY!A15&"*") -> 13 | M15: =SUMIFS('PLAN BUDGET SAMI-JF'!AV13:AV100000,'PLAN BUDGET SAMI-JF'!D13:D100000,SUMMARY!D15,'PLAN BUDGET SAMI-JF'!J13:J100000,SUMMARY!A15&"*") -> 0 | N15: =SUMIFS('PLAN BUDGET SAMI-JF'!AW13:AW100000,'PLAN BUDGET SAMI-JF'!D13:D100000,SUMMARY!D15,'PLAN BUDGET SAMI-JF'!J13:J100000,SUMMARY!A15&"*") -> 0 | O15: =SUMIFS('PLAN BUDGET SAMI-JF'!AX13:AX100000,'PLAN BUDGET SAMI-JF'!D13:D100000,SUMMARY!D15,'PLAN BUDGET SAMI-JF'!J13:J100000,SUMMARY!A15&"*") -> 0 | P15: =SUMIFS('PLAN BUDGET SAMI-JF'!AY13:AY100000,'PLAN BUDGET SAMI-JF'!D13:D100000,SUMMARY!D15,'PLAN BUDGET SAMI-JF'!J13:J100000,SUMMARY!A15&"*") -> 0 | Q15: =SUMIFS('PLAN BUDGET SAMI-JF'!BC13:BC100000,'PLAN BUDGET SAMI-JF'!D13:D100000,SUMMARY!D15,'PLAN BUDGET SAMI-JF'!J13:J100000,SUMMARY!A15&"*") -> 0 | R15: =SUMIFS('PLAN BUDGET SAMI-JF'!BD13:BD100000,'PLAN BUDGET SAMI-JF'!D13:D100000,SUMMARY!D15,'PLAN BUDGET SAMI-JF'!J13:J100000,SUMMARY!A15&"*") -> 0 | S15: =SUMIFS('PLAN BUDGET SAMI-JF'!BE13:BE100000,'PLAN BUDGET SAMI-JF'!D13:D100000,SUMMARY!D15,'PLAN BUDGET SAMI-JF'!J13:J100000,SUMMARY!A15&"*") -> 27.154305 | T15: =SUMIFS('PLAN BUDGET SAMI-JF'!BF13:BF100000,'PLAN BUDGET SAMI-JF'!D13:D100000,SUMMARY!D15,'PLAN BUDGET SAMI-JF'!J13:J100000,SUMMARY!A15&"*") -> 0 | U15: =SUMIFS('PLAN BUDGET SAMI-JF'!BG13:BG100000,'PLAN BUDGET SAMI-JF'!D13:D100000,SUMMARY!D15,'PLAN BUDGET SAMI-JF'!J13:J100000,SUMMARY!A15&"*") -> 0 | V15: =SUMIFS('PLAN BUDGET SAMI-JF'!BH13:BH100000,'PLAN BUDGET SAMI-JF'!D13:D100000,SUMMARY!D15,'PLAN BUDGET SAMI-JF'!J13:J100000,SUMMARY!A15&"*") -> 0 | W15: =SUMIFS('PLAN BUDGET SAMI-JF'!BI13:BI100000,'PLAN BUDGET SAMI-JF'!D13:D100000,SUMMARY!D15,'PLAN BUDGET SAMI-JF'!J13:J100000,SUMMARY!A15&"*") -> 0 | X15: =SUMIFS('PLAN BUDGET SAMI-JF'!BJ13:BJ100000,'PLAN BUDGET SAMI-JF'!D13:D100000,SUMMARY!D15,'PLAN BUDGET SAMI-JF'!J13:J100000,SUMMARY!A15&"*") -> 27.154305 | Y15: =SUMIFS('PLAN BUDGET SAMI-JF'!BK13:BK100000,'PLAN BUDGET SAMI-JF'!D13:D100000,SUMMARY!D15,'PLAN BUDGET SAMI-JF'!J13:J100000,SUMMARY!A15&"*") -> 0 | Z15: =SUMIFS('PLAN BUDGET SAMI-JF'!BL13:BL100000,'PLAN BUDGET SAMI-JF'!D13:D100000,SUMMARY!D15,'PLAN BUDGET SAMI-JF'!J13:J100000,SUMMARY!A15&"*") -> 0 | AA15: =SUMIFS('PLAN BUDGET SAMI-JF'!BM13:BM100000,'PLAN BUDGET SAMI-JF'!D13:D100000,SUMMARY!D15,'PLAN BUDGET SAMI-JF'!J13:J100000,SUMMARY!A15&"*") -> 0 | AB15: =SUMIFS('PLAN BUDGET SAMI-JF'!BN13:BN100000,'PLAN BUDGET SAMI-JF'!D13:D100000,SUMMARY!D15,'PLAN BUDGET SAMI-JF'!J13:J100000,SUMMARY!A15&"*") -> 0 | AC15: =SUM(E15:P15) -> 26 | AD15: =SUM(Q15:AB15) -> 54.30861 | AF15: 12 | AG15: 22.027268 | AH15: =IFERROR((AC15-AF15)/AF15,1) -> 1.1666667 | AI15: =IFERROR((AD15-AG15)/AG15,1) -> 1.4655172 | AJ15: Budget di Term 84 tidak ada, sedangkan di Term 85 ada.
