Workbook

Sheet TAHAP 1
U1: A
B2: PT. SEMARANG AUTOCOMP MANUFACTURING INDONESIA | H2: FORM/CHECKSHEET | I2: NO. DOKUMEN | J2: : 083/PGA/GS/FORM/RPBPD | N2: APPROVED II | P2: APPROVED I | R2: CHECKED | T2: PREPARED
B3: REQUEST PERHITUNGAN BIAYA PERJALANAN DINAS | I3: REVISI | J3: : 0 | N3: APPROVED
I4: TANGGAL | J4: : 05-07-2023
I5: HALAMAN | J5: : 1
I6: MASA BERLAKU | J6: : 04-07-2024 | N6: AWI | P6: FYH | R6: SMK | T6: Renny
B8: TUJUAN PERJALANAN DINAS | G8: : JAI & SAI
B9: KEPENTINGAN | G9: : KOMPARE DATA IDL & DATA HR
B11: 1. MEMBER YANG AKAN PERJALANAN DINAS
B12: NO | C12: TANGGAL | G12: DEPT. / SECT. | I12: JABATAN | K12: NIK | M12: NAMA
B13: 1 | C13: 45264 | D13: s/d | F13: 45268 | G13: PGA / PED | I13: SPV | K13: 2412 | M13: NUNING DIAN PERTIWI
B14: 2 | C14: =+C13 -> 45264 | D14: s/d | F14: =+F13 -> 45268 | G14: PGA / QS | I14: SPV | K14: 1158 | M14: DARMUJI
B15: 3 | C15: =+C14 -> 45264 | D15: s/d | F15: =+F14 -> 45268 | G15: PRD | I15: MGR | K15: 1651 | M15: AHMAD MUBARAK
B16: 4 | C16: =+C15 -> 45264 | D16: s/d | F16: =+F15 -> 45268 | G16: PRD | I16: SMGR | K16: 27106 | M16: YUICHIRO SUZUKI
B17: 5 | C17: =+C16 -> 45264 | D17: s/d | F17: =+F16 -> 45268 | G17: PRD | I17: GL | K17: 20205 | M17: ERWIN DWI PAMUNGKAS
B19: 2. TRANSPORTASI
B20: 2.a Pesawat | K20: 2.b Kereta
B21: NO | C21: TANGGAL | E21: AIR PORT | H21: RANGE TIME | K21: NO | L21: TANGGAL | N21: STATION | R21: RANGE TIME
E22: DEPARTURE | G22: ARRIVAL | H22: DEPARTURE | I22: ARRIVAL | N22: DEPARTURE | P22: ARRIVAL | R22: DEPARTURE | T22: ARRIVAL
B23: 1 | C23: - | K23: 1
B24: 2 | C24: - | K24: 2
B26: 2.c Mobil / Hi Ace / Bus
B27: NO | C27: TANGGAL | G27: JENIS ARMADA | I27: JUMLAH KURSI (PENUMPANG) | J27: WAKTU KEBERANGKATAN | N27: REQUEST KHUSUS
J28: LOKASI | L28: JAM
B29: 1 | C29: =+C13 -> 45264 | D29: s/d | F29: =+F13 -> 45268 | G29: INNOVA | I29: (3) NORMAL | J29: SAMI | L29: 0.58333333 | N29: -
B30: NOTE : Standar kelengkapan armada
B31: No | C31: Point | J31: Mobil | M31: Hi Ace | P31: BUS
B32: 1 | C32: Sabuk Pengaman | J32: ● | M32: ● | P32: ●
B33: 2 | C33: Ban Cadangan | J33: ● | M33: ● | P33: ●
B34: 3 | C34: Segitiga Pengaman (Minimal 2 buah, berwarna merah, dapat memantulkan cahaya) | J34: ● | M34: ● | P34: ●
B35: 4 | C35: Dongkrak | J35: ● | M35: ● | P35: ●
B36: 5 | C36: Pembuka Roda dan | J36: ● | M36: ● | P36: ●
B37: 6 | C37: Kotak P3K(Minimal berisi obat antiseptik, kain kassa, kapas, plester) | J37: ● | M37: ● | P37: ●
B38: 7 | C38: Apar | J38: ● (1x M1 berat 1 Kg) | M38: ● (2x M1 berat 1 Kg) | P38: ● (2x M1 berat 1 Kg)
B39: 8 | C39: Ganjal Ban (Wheel Block) | J39: x | M39: ● (Jika > 3,500 Kg) | P39: ● (Jika > 3,500 Kg)
B40: 9 | C40: Perisai Kolong Belakang | J40: x | M40: x | P40: x
B41: 10 | C41: Perisai Kolong Samping | J41: x | M41: x | P41: x
B42: 11 | C42: Alat Pemantul Cahaya | J42: x | M42: x | P42: x
B43: 12 | C43: Pemecah Kaca / Martil | J43: x | M43: x | P43: x
... B45: 14 | C45: Kernet | J45: x | M45: x | P45: x
...

Sheet TAPAH 2.2 (Rincian)
P1: A
B2: PT. SEMARANG AUTOCOMP MANUFACTURING INDONESIA - TUGU FACTORY | I2: FORM/CHECKSHEET | J2: NO. DOKUMEN | K2: : 023/PGA/GA/FORM/SPDDN | M2: APPROVED II | N2: APPROVED I | O2: CHECKED | P2: PREPARED
B3: SURAT PERJALANAN DINAS DALAM NEGERI | J3: TANGGAL | K3: : 11-07-2023 | M3: APPROVED
J4: REVISI | K4: : 4
J5: HALAMAN | K5: : 2 / 2
J6: MASA BERLAKU | K6: : 10-07-2024 | M6: AWI | N6: FYH | O6: SMK | P6: RENNY
B8: LAMPIRAN (Rincian) | F8: =+'TAHAP 1'!G9 -> : KOMPARE DATA IDL & DATA HR
B10: 1. UPD
B11: NOTE : Standar UPD Dalam Negeri berdasarkan Prosedur Perjalanan Dinas (PGA-GA.PD.02)
B12: Golongan | F12: UANG SAKU | G12: BREAKFAST | H12: LUNCH | I12: DINNER
B13: I | F13: 30000 | G13: 12500 | H13: 20000 | I13: 20000
B14: II | F14: 30000 | G14: 12500 | H14: 20000 | I14: 20000
B15: III | F15: 35000 | G15: 12500 | H15: 20000 | I15: 20000
B16: IV | F16: 40000 | G16: 12500 | H16: 27500 | I16: 27500
B17: V | F17: 50000 | G17: 22500 | H17: 30000 | I17: 30000
B18: VI | F18: 60000 | G18: 22500 | H18: 50000 | I18: 50000
B19: VII | F19: 70000 | G19: 22500 | H19: 60000 | I19: 60000
C21: Rincian Golongan | D21: : | E21: V
B22: NO. | C22: TANGGAL | F22: =+$F$12 -> UANG SAKU | G22: =+$G$12 -> BREAKFAST | H22: =+$H$12 -> LUNCH | I22: =+$I$12 -> DINNER | J22: JUMLAH
B23: 1 | C23: =+'TAHAP 1'!$C$13 -> 45264 | F23: 50000 | G23: 0 | H23: 30000 | I23: 30000 | J23: =SUM(F23:I23) -> 110000
B24: 2 | C24: =+C23+1 -> 45265 | F24: 50000 | G24: di Hotel | H24: di SAI / JAI | I24: 30000 | J24: =SUM(F24:I24) -> 80000
B25: 3 | C25: =+C24+1 -> 45266 | F25: 50000 | G25: di Hotel | H25: di SAI / JAI | I25: 30000 | J25: =SUM(F25:I25) -> 80000
B26: 4 | C26: =+C25+1 -> 45267 | F26: 50000 | G26: di Hotel | H26: di SAI / JAI | I26: 30000 | J26: =SUM(F26:I26) -> 80000
B27: 5 | C27: =+C26+1 -> 45268 | F27: 50000 | G27: di Hotel | H27: 30000 | I27: 30000 | J27: =SUM(F27:I27) -> 110000
B28: TOTAL | F28: =SUM(F23:F27) -> 250000 | G28: =SUM(G23:I27) -> 210000 | J28: =SUM(J23:J27) -> 460000
C30: Rincian Golongan | D30: : | E30: IV
B31: NO. | C31: TANGGAL | F31: =+$F$12 -> UANG SAKU | G31: =+$G$12 -> BREAKFAST | H31: =+$H$12 -> LUNCH | I31: =+$I$12 -> DINNER | J31: JUMLAH
B32: 1 | C32: =+'TAHAP 1'!$C$13 -> 45264 | F32: =VLOOKUP($E$30,B13:$I$19,5,0) -> 40000 | G32: 0 | H32: =VLOOKUP($E$30,B13:$I$19,7,0) -> 27500 | I32: =VLOOKUP($E$30,B13:$I$19,8,0) -> 27500 | J32: =SUM(F32:I32) -> 95000
B33: 2 | C33: =+C32+1 -> 45265 | F33: 40000 | G33: di Hotel | H33: di SAI / JAI | I33: =VLOOKUP($E$30,B14:$I$19,8,0) -> 27500 | J33: =SUM(F33:I33) -> 67500
B34: 3 | C34: =+C33+1 -> 45266 | F34: 40000 | G34: di Hotel | H34: di SAI / JAI | I34: =VLOOKUP($E$30,B15:$I$19,8,0) -> 27500 | J34: =SUM(F34:I34) -> 67500
B35: 4 | C35: =+C34+1 -> 45267 | F35: 40000 | G35: di Hotel | H35: di SAI / JAI | I35: =VLOOKUP($E$30,B16:$I$19,8,0) -> 27500 | J35: =SUM(F35:I35) -> 67500
B36: 5 | C36: =+C35+1 -> 45268 | F36: 40000 | G36: di Hotel | H36: 27500 | I36: 27500 | J36: =SUM(F36:I36) -> 95000
B37: TOTAL | F37: =SUM(F32:F36) -> 200000 | G37: =SUM(G32:I36) -> 192500 | J37: =SUM(J32:J36) -> 392500
C39: Rincian Golongan | D39: : | E39: II
B40: NO. | C40: TANGGAL | F40: =+$F$12 -> UANG SAKU | G40: =+$G$12 -> BREAKFAST | H40: =+$H$12 -> LUNCH | I40: =+$I$12 -> DINNER | J40: JUMLAH
B41: 1 | C41: =+'TAHAP 1'!$C$13 -> 45264 | F41: 30000 | G41: 0 | H41: 20000 | I41: 20000 | J41: =SUM(F41:I41) -> 70000
B42: 2 | C42: =+C41+1 -> 45265 | F42: 30000 | G42: di Hotel | H42: di SAI / JAI | I42: 20000 | J42: =SUM(F42:I42) -> 50000
B43: 3 | C43: =+C42+1 -> 45266 | F43: 30000 | G43: di Hotel | H43: di SAI / JAI | I43: 20000 | J43: =SUM(F43:I43) -> 50000
B44: 4 | C44: =+C43+1 -> 45267 | F44: 30000 | G44: di Hotel | H44: di SAI / JAI | I44: 20000 | J44: =SUM(F44:I44) -> 50000
B45: 5 | C45: =+C44+1 -> 45268 | F45: 30000 | G45: di Hotel | H45: 20000 | I45: 20000 | J45: =SUM(F45:I45) -> 70000
...

Sheet TAHAP 2.1 (SPD)
W1: A
B2: PT. SEMARANG AUTOCOMP MANUFACTURING INDONESIA | K2: FORM/CHECKSHEET | L2: NO. DOKUMEN | N2: : 023/PGA/GA/FORM/SPDDN | R2: APPROVED II | S2: APPROVED I | T2: CHECKED | V2: PREPARED
B3: SURAT PERJALANAN DINAS DALAM NEGERI | L3: TANGGAL | N3: : 11-07-2023 | R3: APPROVED
L4: REVISI | N4: : 4
L5: HALAMAN | N5: : 1/2
L6: MASA BERLAKU | N6: : 10-07-2024 | R6: AWI | S6: FYH | T6: SMK | V6: Renny
B9: TUJUAN PERJALANAN DINAS | I9: =+'TAHAP 1'!G8 -> : JAI & SAI
B10: KEPENTINGAN | I10: =+'TAHAP 1'!G9 -> : KOMPARE DATA IDL & DATA HR
B14: 1. PESERTA
B15: NO | C15: TANGGAL | G15: DEPT. / SECT. | I15: JABATAN | K15: NIK | M15: NAMA | P15: 1 | Q15: 2 | R15: 3 | S15: 4 | T15: 5
P16: YANG MENERIMA PERINTAH | Q16: SPV | R16: MGR | S16: FM / DFM | T16: PRESDIR
B19: 1 | C19: =+'TAHAP 1'!C13 -> 45264 | D19: s/d | F19: =+'TAHAP 1'!E13:F13 -> 45268 | G19: =+'TAHAP 1'!G13:H13 -> PGA / PED | I19: =+'TAHAP 1'!I13:J13 -> SPV | K19: =+'TAHAP 1'!K13:L13 -> 2412 | M19: =+'TAHAP 1'!M13 -> NUNING DIAN PERTIWI | P19: Approved 29-11-2023 | Y19: =+G19 -> PGA / PED | Z19: =+I19 -> SPV | AA19: =+K19 -> 2412 | AB19: =+M19 -> NUNING DIAN PERTIWI
B20: 2 | C20: =+'TAHAP 1'!C14 -> 45264 | D20: s/d | F20: =+'TAHAP 1'!E14:F14 -> 45268 | G20: =+'TAHAP 1'!G14:H14 -> PGA / QS | I20: =+'TAHAP 1'!I14:J14 -> SPV | K20: =+'TAHAP 1'!K14:L14 -> 1158 | M20: =+'TAHAP 1'!M14 -> DARMUJI | Y20: =+G20 -> PGA / QS | Z20: =+I20 -> SPV | AA20: =+K20 -> 1158 | AB20: =+M20 -> DARMUJI
B21: 3 | C21: =+'TAHAP 1'!C15 -> 45264 | D21: s/d | F21: =+'TAHAP 1'!E15:F15 -> 45268 | G21: =+'TAHAP 1'!G15:H15 -> PRD | I21: =+'TAHAP 1'!I15:J15 -> MGR | K21: =+'TAHAP 1'!K15:L15 -> 1651 | M21: =+'TAHAP 1'!M15 -> AHMAD MUBARAK | Y21: =+G21 -> PRD | Z21: =+I21 -> MGR | AA21: =+K21 -> 1651 | AB21: =+M21 -> AHMAD MUBARAK
B22: 3 | C22: =+'TAHAP 1'!C16 -> 45264 | D22: s/d | F22: =+'TAHAP 1'!E16:F16 -> 45268 | G22: =+'TAHAP 1'!G16:H16 -> PRD | I22: =+'TAHAP 1'!I16:J16 -> SMGR | K22: =+'TAHAP 1'!K16:L16 -> 27106 | M22: =+'TAHAP 1'!M16 -> YUICHIRO SUZUKI | P22: YSU | Q22: - | R22: - | S22: TMI | T22: NKA | Y22: =+G22 -> PRD | Z22: =+I22 -> SMGR | AA22: =+K22 -> 27106 | AB22: =+M22 -> YUICHIRO SUZUKI
B23: 3 | C23: =+'TAHAP 1'!C17 -> 45264 | D23: s/d | F23: =+'TAHAP 1'!E17:F17 -> 45268 | G23: =+'TAHAP 1'!G17:H17 -> PRD | I23: =+'TAHAP 1'!I17:J17 -> GL | K23: =+'TAHAP 1'!K17:L17 -> 20205 | M23: =+'TAHAP 1'!M17 -> ERWIN DWI PAMUNGKAS | P23: Erwin | Q23: PLE | R23: YSU | Y23: =+G23 -> PRD | Z23: =+I23 -> GL | AA23: =+K23 -> 20205 | AB23: =+M23 -> ERWIN DWI PAMUNGKAS
B28: 2. BIAYA PERJALANAN DINAS | L28: UPD | O28: TRANSPORTASI | Q28: HOTEL
O29: BY : CAR | Q29: =+'TAPAH 2.2 (Rincian)'!G109 -> FAIRFIELD BY MARRIOTT SURABAYA Jalan Mayjend Sungkono No 178, Surabaya City Center, Surabaya, 60225, Indonesia. CI/CO : 04 - 08 Dec (04 Malam) Guest Room : IDR 851.000/room/night include breakfast
O30: Berangkat : | P30: =+C19 -> 45264
O32: Pulang : | P32: =+F19 -> 45268
B34: NO | C34: NAMA | G34: NIK | H34: NO. REKENING | L34: PRICE | N34: PERIODE BUDGET | O34: ESTIMATED PRICE | P34: PERIODE BUDGET | Q34: ESTIMATED PRICE | R34: PERIODE BUDGET
B35: =+'TAPAH 2.2 (Rincian)'!B50 -> 1 | C35: =+'TAPAH 2.2 (Rincian)'!C50:F50 -> NUNING DIAN PERTIWI | G35: =+'TAHAP 1'!K13 -> 2412 | L35: =+'TAPAH 2.2 (Rincian)'!H50 -> 392500 | O35: =+'TAPAH 2.2 (Rincian)'!I81 -> 8500000 | Q35: =+'TAPAH 2.2 (Rincian)'!J112 -> 3684000
B36: 2 | C36: =+'TAPAH 2.2 (Rincian)'!C51:F51 -> DARMUJI | G36: =+'TAHAP 1'!K14 -> 1158 | L36: =+'TAPAH 2.2 (Rincian)'!H51 -> 392500 | Q36: =+'TAPAH 2.2 (Rincian)'!J113 -> 3684000
B37: =+'TAPAH 2.2 (Rincian)'!B52 -> 3 | C37: =+'TAPAH 2.2 (Rincian)'!C52:F52 -> AHMAD MUBARAK | G37: =+'TAHAP 1'!K15 -> 1651 | L37: =+'TAPAH 2.2 (Rincian)'!H52 -> 392500 | Q37: =+'TAPAH 2.2 (Rincian)'!J114 -> 3684000
B38: 3 | C38: =+'TAPAH 2.2 (Rincian)'!C53:F53 -> YUICHIRO SUZUKI | G38: =+'TAHAP 1'!K16 -> 27106 | L38: =+'TAPAH 2.2 (Rincian)'!H53 -> 460000 | O38: =+'TAPAH 2.2 (Rincian)'!I103 -> 11250000 | Q38: =+'TAPAH 2.2 (Rincian)'!J115 -> 3684000
B39: =+'TAPAH 2.2 (Rincian)'!B54 -> 5 | C39: =+'TAPAH 2.2 (Rincian)'!C54:F54 -> ERWIN DWI PAMUNGKAS | G39: =+'TAHAP 1'!K17 -> 20205 | L39: =+'TAPAH 2.2 (Rincian)'!H54 -> 290000 | Q39: =+'TAPAH 2.2 (Rincian)'!J116 -> 3684000
B40: SUB TOTAL | L40: =SUM(L35:M39) -> 1927500 | O40: =SUM(O35:O39) -> 19750000 | Q40: =SUM(Q35:Q39) -> 18420000
B41: TOTAL | L41: =SUM(L40:R40) -> 40097500
B43: NOTE : 1. Ket. Budget di isi bulan periode budget atau di tulis "additional" jika additional budget 2. Approval diproses oleh User 3. Approval pada form ini akan digunakan sebagai jaminan GA dalam melakukan proses issued ticket dan hotel sebelum user melakukan pembuatan PR (purchase requisition). 4. Pembuatan PR setelah proses issued bertujuan agar tidak terjadi selisih harga PR (purchase requisition) dengan actual. | T43: 6. MENGETAHUI MGR FA
T46: BRI
B55: PERLINDUNGAN HAK CIPTA! Dokumen ini adalah milik dan untuk dipergunakan di lingkungan kerja PT. SAMI . Tidak diperkenankan memindahkan, menyalin, atau menggandakan sebagian ataupun seluruhnya isi dokumen ini dalam bentuk dan dengan cara apapun, tanpa izin tertulis dari Wakil manajemen. | I55: Referensi Prosedur/WI/OS/IS/ : PGA-GA.PD.02 : Prosedur Perjalanan Dinas | M55: 4 | N55: Penggabungan approval perjalanan dinas | Q55: 45118 | R55: Renny
M56: 3 | N56: Update Tgl Masa Berlaku & Rev. No. Dok. | Q56: 44702 | R56: Renny
M57: 2 | N57: New Format | Q57: 44314 | R57: Renny | S57: 3 | T57: =+Q55 -> 45118 | W57: FYH
M58: 1 | N58: Add Actual UPD | Q58: 44147 | R58: Renny | S58: 2 | T58: 44702 | W58: WIN
M59: 0 | N59: New Release | Q59: 45113 | R59: LNA | S59: 1 | T59: 44314 | W59: FYH
M60: REV. | N60: ISI PERUBAHAN | Q60: TANGGAL | R60: PIC | S60: REVIEW | T60: TGL | W60: PIC

Sheet Sheet2
B2: NO | C2: NAMA | D2: NIK | E2: NO. REKENING | F2: PRICE
B3: 1 | C3: SUPRIYONO | D3: 6096 | E3: 1360004496367 | F3: 132500
B4: 2 | C4: MUCHAMAD ROSYID | D4: 13138 | E4: 1350007255753 | F4: 132500
B5: TOTAL | F5: =SUM(F3:F4) -> 265000

Sheet Rincian OT Driver
B2: PT. SEMARANG AUTOCOMP MANUFACTURING INDONESIA
B3: ESTIMASI OVERTIME DRIVER
B4: Di isi oleh : GA
B6: DROP
B7: =+#REF! -> #REF!
B8: PERHITUNGAN OT DRIVER
B10: UMK : | C10: 3060349 | F10: Jam Kerja Efektif : 08.00 - 17.00
B11: 1 TUL = UMK/173 = | E11: =+C10/173 -> 17689.879
B12: HARI | C12: TANGGAL | D12: KET. JAM | E12: OT AWAL | G12: OT AKHIR | I12: SUB TOTAL OT | K12: KET. | L12: RINCIAN PERHITUNGAN | P12: JUMLAH
E13: Start | F13: Finish | G13: Start | H13: Finish | I13: JAM | J13: JAM PENGALI TUL | K13: pengali | L13: 1.5 | M13: 2 | N13: 3 | O13: 4
B14: =TEXT(C14,"aaaaaa") -> Senin | C14: =+'TAHAP 1'!$C$13 -> 45264 | D14: OT : | E14: 0.29166667 | F14: 0.29166667 | G14: 0.66666667 | H14: 0.91666667 | I14: =E16+G16 -> 0.25 | J14: =((HOUR(I14)*60)+MINUTE(I14))/60 -> 6 | K14: jam ke | L14: 1 | M14: =+J14-L14 -> 5
K15: tul | L15: =+L14*$L$13 -> 1.5 | M15: =+M14*$M$13 -> 10 | N15: =+N14*$N$13 -> 0 | O15: =+O14*$O$13 -> 0 | P15: =SUM(L15:O15) -> 11.5
D16: Jumlah | E16: =+F14-E14 -> 0 | G16: =+H14-G14 -> 0.25 | K16: nominal | L16: =+L15*$C$10/173 -> 26534.818 | M16: =+M15*$C$10/173 -> 176898.79 | N16: =+N15*$C$10/173 -> 0 | O16: =+O15*$C$10/173 -> 0 | P16: =SUM(L16:O16) -> 203433.6
B17: =TEXT(C17,"aaaaaa") -> Selasa | C17: =+C14+1 -> 45265 | D17: OT : | E17: 0.25 | F17: 0.29166667 | G17: 0.66666667 | H17: 0.91666667 | I17: =E19+G19 -> 0.29166667 | J17: =((HOUR(I17)*60)+MINUTE(I17))/60 -> 7 | K17: jam ke | L17: 1 | M17: =+J17-L17 -> 6
K18: tul | L18: =+L17*$L$13 -> 1.5 | M18: =+M17*$M$13 -> 12 | N18: =+N17*$N$13 -> 0 | O18: =+O17*$O$13 -> 0 | P18: =SUM(L18:O18) -> 13.5
D19: Jumlah | E19: =+F17-E17 -> 0.041666667 | G19: =+H17-G17 -> 0.25 | K19: nominal | L19: =+L18*$C$10/173 -> 26534.818 | M19: =+M18*$C$10/173 -> 212278.54 | N19: =+N18*$C$10/173 -> 0 | O19: =+O18*$C$10/173 -> 0 | P19: =SUM(L19:O19) -> 238813.36
B20: =TEXT(C20,"aaaaaa") -> Rabu | C20: =+C17+1 -> 45266 | D20: OT : | E20: 0.25 | F20: 0.29166667 | G20: 0.66666667 | H20: 0.91666667 | I20: =E22+G22 -> 0.29166667 | J20: =((HOUR(I20)*60)+MINUTE(I20))/60 -> 7 | K20: jam ke | L20: 1 | M20: =+J20-L20 -> 6
K21: tul | L21: =+L20*$L$13 -> 1.5 | M21: =+M20*$M$13 -> 12 | N21: =+N20*$N$13 -> 0 | O21: =+O20*$O$13 -> 0 | P21: =SUM(L21:O21) -> 13.5
D22: Jumlah | E22: =+F20-E20 -> 0.041666667 | G22: =+H20-G20 -> 0.25 | K22: nominal | L22: =+L21*$C$10/173 -> 26534.818 | M22: =+M21*$C$10/173 -> 212278.54 | N22: =+N21*$C$10/173 -> 0 | O22: =+O21*$C$10/173 -> 0 | P22: =SUM(L22:O22) -> 238813.36
B23: TOTAL TUL | P23: =+P21+P18+P15 -> 38.5 | R23: =+AVERAGE(P16,P19,P22) -> 227020.11
B24: TOTAL BIAYA OVERTIME | P24: =+P22+P19+P16 -> 681060.33 | R24: =+MROUND(R23,100) -> 227000
B27: TUNGGU
B28: =+#REF! -> #REF!
B29: PERHITUNGAN OT DRIVER | N29: NO. POLISI | O29: :
N30: TYPE MOBIL | O30: :
B31: UMK : | C31: 3060349 | F31: Jam Kerja Efektif : 08.00 - 17.00 | N31: DRIVER | O31: :
B32: 1 TUL = UMK/173 = | E32: =+C31/173 -> 17689.879
B33: HARI | C33: TANGGAL | D33: KET. JAM | E33: OT AWAL | G33: OT AKHIR | I33: SUB TOTAL OT | K33: KET. | L33: RINCIAN PERHITUNGAN | P33: JUMLAH
E34: Start | F34: Finish | G34: Start | H34: Finish | I34: JAM | J34: JAM PENGALI TUL | K34: pengali | L34: 1.5 | M34: 2 | N34: 3 | O34: 4
B35: Minggu | C35: 45123 | D35: OT : | E35: 0.25 | F35: 0.29166667 | G35: 0.66666667 | H35: 0.75 | I35: =E37+G37 -> 0.125 | J35: =((HOUR(I35)*60)+MINUTE(I35))/60 -> 3 | K35: jam ke | L35: 1 | M35: =+J35-L35 -> 2
K36: tul | L36: =+L35*$L$13 -> 1.5 | M36: =+M35*$M$13 -> 4 | N36: =+N35*$N$13 -> 0 | O36: =+O35*$O$13 -> 0 | P36: =SUM(L36:O36) -> 5.5
D37: Jumlah | E37: =+F35-E35 -> 0.041666667 | G37: =+H35-G35 -> 0.083333333 | K37: nominal | L37: =+L36*$C$10/173 -> 26534.818 | M37: =+M36*$C$10/173 -> 70759.514 | N37: =+N36*$C$10/173 -> 0 | O37: =+O36*$C$10/173 -> 0 | P37: =SUM(L37:O37) -> 97294.332
B38: Senin | C38: =+C35+1 -> 45124 | D38: OT : | E38: 0.27083333 | F38: 0.29166667 | G38: 0.66666667 | H38: 0.75 | I38: =E40+G40 -> 0.10416667 | J38: =((HOUR(I38)*60)+MINUTE(I38))/60 -> 2.5 | K38: jam ke | L38: 1 | M38: =+J38-L38 -> 1.5
K39: tul | L39: =+L38*$L$13 -> 1.5 | M39: =+M38*$M$13 -> 3 | N39: =+N38*$N$13 -> 0 | O39: =+O38*$O$13 -> 0 | P39: =SUM(L39:O39) -> 4.5
D40: Jumlah | E40: =+F38-E38 -> 0.020833333 | G40: =+H38-G38 -> 0.083333333 | K40: nominal | L40: =+L39*$C$10/173 -> 26534.818 | M40: =+M39*$C$10/173 -> 53069.636 | N40: =+N39*$C$10/173 -> 0 | O40: =+O39*$C$10/173 -> 0 | P40: =SUM(L40:O40) -> 79604.454
B41: Selasa | C41: =+C38+1 -> 45125 | D41: OT : | E41: 0.27083333 | F41: 0.29166667 | G41: 0.66666667 | H41: 0.75 | I41: =E43+G43 -> 0.10416667 | J41: =((HOUR(I41)*60)+MINUTE(I41))/60 -> 2.5 | K41: jam ke | L41: 1 | M41: =+J41-L41 -> 1.5
K42: tul | L42: =+L41*$L$13 -> 1.5 | M42: =+M41*$M$13 -> 3 | N42: =+N41*$N$13 -> 0 | O42: =+O41*$O$13 -> 0 | P42: =SUM(L42:O42) -> 4.5
D43: Jumlah | E43: =+F41-E41 -> 0.020833333 | G43: =+H41-G41 -> 0.083333333 | K43: nominal | L43: =+L42*$C$10/173 -> 26534.818 | M43: =+M42*$C$10/173 -> 53069.636 | N43: =+N42*$C$10/173 -> 0 | O43: =+O42*$C$10/173 -> 0 | P43: =SUM(L43:O43) -> 79604.454
B44: Rabu | C44: =+C41+1 -> 45126 | D44: OT : | E44: 0.27083333 | F44: 0.29166667 | G44: 0.66666667 | H44: 0.75 | I44: =E46+G46 -> 0.10416667 | J44: =((HOUR(I44)*60)+MINUTE(I44))/60 -> 2.5 | K44: jam ke | L44: 1 | M44: =+J44-L44 -> 1.5
K45: tul | L45: =+L44*$L$13 -> 1.5 | M45: =+M44*$M$13 -> 3 | N45: =+N44*$N$13 -> 0 | O45: =+O44*$O$13 -> 0 | P45: =SUM(L45:O45) -> 4.5
...

Sheet Info Affiliate tujuan
B2: PT. SEMARANG AUTOCOMP MANUFACTURING INDONESIA - TUGU FACTORY
B3: TUJUAN PERJALANAN DINAS | G3: : PEMI
B4: KEPENTINGAN | G4: : Transfer System Proses Yaris
B6: 1. MEMBER YANG AKAN PERJALANAN DINAS | V6: HOTEL
B7: NO | C7: TANGGAL | G7: DEPT. / SECT. | I7: JABATAN | K7: NIK | M7: NAMA | R7: ARRIVAL | T7: DEPARTURE | V7: Room Type | W7: Bed | X7: Smoking | Y7: Breakfast | Z7: Qty Room
B8: 1 | C8: 45139 | D8: s/d | F8: 45141 | G8: PGA / IT | I8: CSPV | K8: 8038 | M8: Mr. Abdul Karis | R8: =+C8 -> 45139 | T8: =+F8 -> 45141 | V8: Standar | W8: King | X8: Non Smoking | Y8: Yes | Z8: 1
B9: 2 | C9: 45139 | D9: s/d | F9: 45141 | G9: PRD / KBN | I9: SPV | K9: 6107 | M9: Mr. Yusuf Dwi Susilo | R9: Berangkat : Batik Air ID6339 SRG (08:25) - CKG (09:30) | T9: Pulang : Batik Air ID8346 CKG (15:00 - SRG (16:05) | V9: Standar | W9: King | X9: Non Smoking | Y9: Yes | Z9: 1
B10: 3 | C10: 45139 | D10: s/d | F10: 45141 | G10: QA | I10: SPV | K10: 7094 | M10: Mr. Munhamir | V10: Standar | W10: King | X10: Non Smoking | Y10: Yes | Z10: 1
B11: 4 | C11: 45139 | D11: s/d | F11: 45141 | G11: MTC | I11: LL | K11: 6118 | M11: Mr. Masbikin | V11: Standar | W11: King | X11: Non Smoking | Y11: Yes | Z11: 1

Sheet Sheet1
B3: KET. | C3: YDS | D3: AKA | E3: MUN | F3: MASBIKHIN | G3: TOTAL
B4: PESAWAT | C4: 1956500 | D4: 1956500 | E4: 1956500 | F4: 1956500 | G4: =SUM(C4:F4) -> 7826000
B5: HOTEL | C5: 1510000 | D5: 1510000 | E5: 1510000 | F5: 1110000 | G5: =SUM(C5:F5) -> 5640000
B6: TOTAL | C6: =SUM(C4:C5) -> 3466500 | D6: =SUM(D4:D5) -> 3466500 | E6: =SUM(E4:E5) -> 3466500 | F6: =SUM(F4:F5) -> 3066500
D13: 1000000
D14: 1000000
D15: 300000
D16: 300000
D17: 600000
D18: =SUM(D13:D17) -> 3200000
