Workbook

Sheet TAHAP 1
U1: A
B2: PT. SEMARANG AUTOCOMP MANUFACTURING INDONESIA | H2: FORM/CHECKSHEET | I2: NO. DOKUMEN | J2: : 083/PGA/GS/FORM/RPBPD | N2: APPROVED II | P2: APPROVED I | R2: CHECKED | T2: PREPARED
B3: REQUEST PERHITUNGAN BIAYA PERJALANAN DINAS | I3: REVISI | J3: : 0 | N3: APPROVED
I4: TANGGAL | J4: : 05-07-2023
I5: HALAMAN | J5: : 1
I6: MASA BERLAKU | J6: : 04-07-2024 | N6: AWI | P6: FYH | R6: SMK | T6: Renny
B8: TUJUAN PERJALANAN DINAS | G8: : PEMI
B9: KEPENTINGAN | G9: : MENGIKUTI JISHUKEN GLOBAL PEMI 2024
B11: 1. MEMBER YANG AKAN PERJALANAN DINAS
B12: NO | C12: TANGGAL | G12: DEPT. / SECT. | I12: JABATAN | K12: NIK | M12: NAMA
B13: 1 | C13: 45530 | D13: s/d | F13: 45569 | G13: FA | I13: CSPV | K13: 5533 | M13: NANANG YUDI PRASETYO
B14: 2 | C14: =+C13 -> 45530 | D14: s/d | F14: =+F13 -> 45569 | G14: FA | I14: SPV | K14: 13647 | M14: ADITYA FAHRIZAL
B16: 2. TRANSPORTASI
B17: 2.a Pesawat | K17: 2.b Kereta
B18: NO | C18: TANGGAL | E18: AIR PORT | H18: RANGE TIME | K18: NO | L18: TANGGAL | N18: STATION | R18: RANGE TIME
E19: DEPARTURE | G19: ARRIVAL | H19: DEPARTURE | I19: ARRIVAL | N19: DEPARTURE | P19: ARRIVAL | R19: DEPARTURE | T19: ARRIVAL
B20: 1 | K20: 1
B21: 2 | K21: 2
B23: 2.c Mobil / Hi Ace / Bus
B24: NO | C24: TANGGAL | G24: JENIS ARMADA | I24: JUMLAH KURSI (PENUMPANG) | J24: WAKTU KEBERANGKATAN | N24: REQUEST KHUSUS
J25: LOKASI | L25: JAM
B26: 1 | C26: =C13 -> 45530 | D26: s/d | F26: =F13 -> 45569 | G26: PESAWAT
B27: NOTE : Standar kelengkapan armada
B28: No | C28: Point | J28: Mobil | M28: Hi Ace | P28: BUS
B29: 1 | C29: Sabuk Pengaman | J29: ● | M29: ● | P29: ●
B30: 2 | C30: Ban Cadangan | J30: ● | M30: ● | P30: ●
B31: 3 | C31: Segitiga Pengaman (Minimal 2 buah, berwarna merah, dapat memantulkan cahaya) | J31: ● | M31: ● | P31: ●
B32: 4 | C32: Dongkrak | J32: ● | M32: ● | P32: ●
B33: 5 | C33: Pembuka Roda dan | J33: ● | M33: ● | P33: ●
B34: 6 | C34: Kotak P3K(Minimal berisi obat antiseptik, kain kassa, kapas, plester) | J34: ● | M34: ● | P34: ●
B35: 7 | C35: Apar | J35: ● (1x M1 berat 1 Kg) | M35: ● (2x M1 berat 1 Kg) | P35: ● (2x M1 berat 1 Kg)
B36: 8 | C36: Ganjal Ban (Wheel Block) | J36: x | M36: ● (Jika > 3,500 Kg) | P36: ● (Jika > 3,500 Kg)
B37: 9 | C37: Perisai Kolong Belakang | J37: x | M37: x | P37: x
B38: 10 | C38: Perisai Kolong Samping | J38: x | M38: x | P38: x
B39: 11 | C39: Alat Pemantul Cahaya | J39: x | M39: x | P39: x
B40: 12 | C40: Pemecah Kaca / Martil | J40: x | M40: x | P40: x
... B42: 14 | C42: Kernet | J42: x | M42: x | P42: x
B43: NOTE : Standar transportasi berdasarkan Prosedur Perjalanan Dinas (PGA-GA.PD.02)
B44: KET. | D44: Golongan I - III | H44: Golongan IV - V | K44: Golongan VI - VII
B45: Luar Negeri | D45: Pesawat Udara Kelas Ekonomi | H45: Pesawat Udara Kelas Ekonomi | K45: Pesawat Udara Kelas Bisnis
...

Sheet upd
Q1: A
B2: PT. SEMARANG AUTOCOMP MANUFACTURING INDONESIA - TUGU FACTORY | H2: FORM/CHECKSHEET | I2: NO. DOKUMEN | J2: : 023/PGA/GA/FORM/SPDDN | M2: APPROVED II | N2: APPROVED I | O2: CHECKED | P2: PREPARED
B3: SURAT PERJALANAN DINAS DALAM NEGERI | I3: TANGGAL | J3: : 11-07-2023 | M3: APPROVED
I4: REVISI | J4: : 4
I5: HALAMAN | J5: : 2 / 2
I6: MASA BERLAKU | J6: : 10-07-2024 | M6: AWI | N6: FYH | O6: SMK | P6: RENNY
B8: LAMPIRAN (Rincian) | F8: =+'TAHAP 1'!G9 -> : MENGIKUTI JISHUKEN GLOBAL PEMI 2024
B10: UPD
B11: NOTE : Standar UPD Dalam Negeri berdasarkan Prosedur Perjalanan Dinas (PGA-GA.PD.02)
H12: NO. | I12: TANGGAL | J12: TANGGAL | K12: UPD GOL. IV | P12: PENGINAPAN @Orang
B13: GOL | C13: UANG SAKU | D13: BREAKFAST | E13: LUNCH | F13: DINNER | K13: =+$C$13 -> UANG SAKU | L13: =+$D$13 -> BREAKFAST | M13: =+$E$13 -> LUNCH | N13: =+$F$13 -> DINNER | O13: JUMLAH
B14: I | C14: 30000 | D14: 12500 | E14: 20000 | F14: 20000 | H14: 1 | I14: =TEXT(J14,"dddd") -> Monday | J14: =+'TAHAP 1'!C13 -> 45530 | K14: 0 | L14: 0 | M14: 0 | N14: 0 | O14: =SUM(K14:N14) -> 0 | P14: 125000
B15: II | C15: 30000 | D15: 12500 | E15: 20000 | F15: 20000 | H15: 2 | I15: =TEXT(J15,"dddd") -> Tuesday | J15: =+J14+1 -> 45531 | K15: 40000 | L15: di Rumah | M15: 27500 | N15: 27500 | O15: =SUM(K15:N15) -> 95000 | P15: 125000
B16: III | C16: 35000 | D16: 12500 | E16: 20000 | F16: 20000 | H16: 3 | I16: =TEXT(J16,"dddd") -> Wednesday | J16: =+J15+1 -> 45532 | K16: 40000 | L16: 12500 | M16: di PEMI | N16: 27500 | O16: =SUM(K16:N16) -> 80000 | P16: 125000
B17: IV | C17: 40000 | D17: 12500 | E17: 27500 | F17: 27500 | H17: 4 | I17: =TEXT(J17,"dddd") -> Thursday | J17: =+J16+1 -> 45533 | K17: 40000 | L17: 12500 | M17: di PEMI | N17: 27500 | O17: =SUM(K17:N17) -> 80000 | P17: 125000
B18: V | C18: 50000 | D18: 22500 | E18: 30000 | F18: 30000 | H18: 5 | I18: =TEXT(J18,"dddd") -> Friday | J18: =+J17+1 -> 45534 | K18: 40000 | L18: 12500 | M18: di PEMI | N18: 27500 | O18: =SUM(K18:N18) -> 80000 | P18: 125000
B19: VI | C19: 60000 | D19: 22500 | E19: 50000 | F19: 50000 | H19: 6 | I19: =TEXT(J19,"dddd") -> Saturday | J19: =+J18+1 -> 45535 | K19: 40000 | L19: 12500 | M19: di PEMI | N19: 27500 | O19: =SUM(K19:N19) -> 80000 | P19: 125000
B20: VII | C20: 70000 | D20: 22500 | E20: 60000 | F20: 60000 | H20: 7 | I20: =TEXT(J20,"dddd") -> Sunday | J20: =+J19+1 -> 45536 | K20: 40000 | L20: 12500 | M20: 27500 | N20: 27500 | O20: =SUM(K20:N20) -> 107500 | P20: 125000
H21: 8 | I21: =TEXT(J21,"dddd") -> Monday | J21: =+J20+1 -> 45537 | K21: 40000 | L21: 12500 | M21: 27500 | N21: 27500 | O21: =SUM(K21:N21) -> 107500 | P21: 125000
H22: 9 | I22: =TEXT(J22,"dddd") -> Tuesday | J22: =+J21+1 -> 45538 | K22: 40000 | L22: 12500 | M22: di PEMI | N22: 27500 | O22: =SUM(K22:N22) -> 80000 | P22: 125000
H23: 10 | I23: =TEXT(J23,"dddd") -> Wednesday | J23: =+J22+1 -> 45539 | K23: 40000 | L23: 12500 | M23: di PEMI | N23: 27500 | O23: =SUM(K23:N23) -> 80000 | P23: 125000
H24: 11 | I24: =TEXT(J24,"dddd") -> Thursday | J24: =+J23+1 -> 45540 | K24: 40000 | L24: 12500 | M24: di PEMI | N24: 27500 | O24: =SUM(K24:N24) -> 80000 | P24: 125000
H25: 12 | I25: =TEXT(J25,"dddd") -> Friday | J25: =+J24+1 -> 45541 | K25: 40000 | L25: 12500 | M25: di PEMI | N25: 27500 | O25: =SUM(K25:N25) -> 80000 | P25: 125000
H26: 13 | I26: =TEXT(J26,"dddd") -> Saturday | J26: =+J25+1 -> 45542 | K26: 40000 | L26: 12500 | M26: di PEMI | N26: 27500 | O26: =SUM(K26:N26) -> 80000 | P26: 125000
H27: 14 | I27: =TEXT(J27,"dddd") -> Sunday | J27: =+J26+1 -> 45543 | K27: 40000 | L27: 12500 | M27: 27500 | N27: 27500 | O27: =SUM(K27:N27) -> 107500 | P27: 125000
H28: 15 | I28: =TEXT(J28,"dddd") -> Monday | J28: =+J27+1 -> 45544 | K28: 40000 | L28: 12500 | M28: 27500 | N28: 27500 | O28: =SUM(K28:N28) -> 107500 | P28: 125000
H29: 16 | I29: =TEXT(J29,"dddd") -> Tuesday | J29: =+J28+1 -> 45545 | K29: 40000 | L29: 12500 | M29: di PEMI | N29: 27500 | O29: =SUM(K29:N29) -> 80000 | P29: 125000
H30: 17 | I30: =TEXT(J30,"dddd") -> Wednesday | J30: =+J29+1 -> 45546 | K30: 40000 | L30: 12500 | M30: di PEMI | N30: 27500 | O30: =SUM(K30:N30) -> 80000 | P30: 125000
H31: 18 | I31: =TEXT(J31,"dddd") -> Thursday | J31: =+J30+1 -> 45547 | K31: 40000 | L31: 12500 | M31: di PEMI | N31: 27500 | O31: =SUM(K31:N31) -> 80000 | P31: 125000
H32: 19 | I32: =TEXT(J32,"dddd") -> Friday | J32: =+J31+1 -> 45548 | K32: 40000 | L32: 12500 | M32: di PEMI | N32: 27500 | O32: =SUM(K32:N32) -> 80000 | P32: 125000
H33: 20 | I33: =TEXT(J33,"dddd") -> Saturday | J33: =+J32+1 -> 45549 | K33: 40000 | L33: 12500 | M33: di PEMI | N33: 27500 | O33: =SUM(K33:N33) -> 80000 | P33: 125000
H34: 21 | I34: =TEXT(J34,"dddd") -> Sunday | J34: =+J33+1 -> 45550 | K34: 40000 | L34: 12500 | M34: 27500 | N34: 27500 | O34: =SUM(K34:N34) -> 107500 | P34: 125000
H35: 22 | I35: =TEXT(J35,"dddd") -> Monday | J35: =+J34+1 -> 45551 | K35: 40000 | L35: 12500 | M35: 27500 | N35: 27500 | O35: =SUM(K35:N35) -> 107500 | P35: 125000
H36: 23 | I36: =TEXT(J36,"dddd") -> Tuesday | J36: =+J35+1 -> 45552 | K36: 40000 | L36: 12500 | M36: 27500 | N36: 27500 | O36: =SUM(K36:N36) -> 107500 | P36: 125000
H37: 24 | I37: =TEXT(J37,"dddd") -> Wednesday | J37: =+J36+1 -> 45553 | K37: 40000 | L37: 12500 | M37: di PEMI | N37: 27500 | O37: =SUM(K37:N37) -> 80000 | P37: 125000
H38: 25 | I38: =TEXT(J38,"dddd") -> Thursday | J38: =+J37+1 -> 45554 | K38: 40000 | L38: 12500 | M38: di PEMI | N38: 27500 | O38: =SUM(K38:N38) -> 80000 | P38: 125000
H39: 26 | I39: =TEXT(J39,"dddd") -> Friday | J39: =+J38+1 -> 45555 | K39: 40000 | L39: 12500 | M39: di PEMI | N39: 27500 | O39: =SUM(K39:N39) -> 80000 | P39: 125000
H40: 27 | I40: =TEXT(J40,"dddd") -> Saturday | J40: =+J39+1 -> 45556 | K40: 40000 | L40: 12500 | M40: di PEMI | N40: 27500 | O40: =SUM(K40:N40) -> 80000 | P40: 125000
H41: 28 | I41: =TEXT(J41,"dddd") -> Sunday | J41: =+J40+1 -> 45557 | K41: 40000 | L41: 12500 | M41: 27500 | N41: 27500 | O41: =SUM(K41:N41) -> 107500 | P41: 125000
H42: 29 | I42: =TEXT(J42,"dddd") -> Monday | J42: =+J41+1 -> 45558 | K42: 40000 | L42: 12500 | M42: 27500 | N42: 27500 | O42: =SUM(K42:N42) -> 107500 | P42: 125000
...

Sheet Sheet2
B3: PER-ORANG
B4: TANGGAL | C4: UANG SAKU | D4: UANG MAKAN
D5: PAGI | E5: SIANG | F5: MALAM
B6: 45518 | C6: 0 | D6: 12500 | E6: di JF | F6: 27500
B7: 45519 | C7: 0 | D7: di Hotel | E7: di JF | F7: 27500
B8: TOTAL | C8: =SUM(C6:F7) -> 67500
B10: ALL
B11: NO | C11: NAMA | D11: UPD
B12: 1 | C12: KHE | D12: =+C8 -> 67500
B13: 2 | C13: TZA | D13: =+C8 -> 67500
B14: 3 | C14: MRY | D14: =+C8 -> 67500
B15: TOTAL | D15: =SUM(D12:D14) -> 202500

Sheet TAPAH 2.2 (Rincian)
O1: A
A2: PT. SEMARANG AUTOCOMP MANUFACTURING INDONESIA - TUGU FACTORY | H2: FORM/CHECKSHEET | I2: NO. DOKUMEN | J2: : 023/PGA/GA/FORM/SPDDN | L2: APPROVED II | M2: APPROVED I | N2: CHECKED | O2: PREPARED
A3: SURAT PERJALANAN DINAS DALAM NEGERI | I3: TANGGAL | J3: : 11-07-2023 | L3: APPROVED
I4: REVISI | J4: : 4
I5: HALAMAN | J5: : 2 / 2
I6: MASA BERLAKU | J6: : 10-07-2024 | L6: AWI | M6: FYH | N6: SMK | O6: RENNY
A8: LAMPIRAN (Rincian) | E8: =+'TAHAP 1'!G9 -> : MENGIKUTI JISHUKEN GLOBAL PEMI 2024
A10: 1. UPD
A11: NOTE : Standar UPD Dalam Negeri berdasarkan Prosedur Perjalanan Dinas (PGA-GA.PD.02)
A12: Golongan | E12: UANG SAKU | F12: BREAKFAST | G12: LUNCH | H12: DINNER
A13: I | E13: 30000 | F13: 12500 | G13: 20000 | H13: 20000
A14: II | E14: 30000 | F14: 12500 | G14: 20000 | H14: 20000
A15: III | E15: 35000 | F15: 12500 | G15: 20000 | H15: 20000
A16: IV | E16: 40000 | F16: 12500 | G16: 27500 | H16: 27500
A17: V | E17: 50000 | F17: 22500 | G17: 30000 | H17: 30000
A18: VI | E18: 60000 | F18: 22500 | G18: 50000 | H18: 50000
A19: VII | E19: 70000 | F19: 22500 | G19: 60000 | H19: 60000
B21: Rincian Golongan | C21: :
A22: TERLAMPIR
A28: UPD
A29: NO. | B29: NAMA | F29: GOL | G29: UPD
A30: 1 | B30: ='TAHAP 1'!M13 -> NANANG YUDI PRASETYO | F30: V | G30: =+I26 -> 0
A31: 2 | B31: ='TAHAP 1'!M14 -> ADITYA FAHRIZAL | F31: IV | G31: =+#REF! -> #REF!
A32: TOTAL | G32: =SUM(G30:G31) -> #REF!
A34: 2. TRANSPORTASI (PIC Perjalanan Dinas tanda tangan pada kolom transportasi yang dipilih atau yang diajukan)
A36: 2.1 PESAWAT | B36: KERETA
A37: NO. | B37: KET. | D37: SCHEDULE | J37: PRICE | K37: QTY | L37: JUMLAH | M37: TOTAL
A38: 1 | B38: BERANGKAT | D38: X
A39: 2 | B39: PULANG | D39: X
A43: 3. HOTEL
A44: NO | B44: PERIODE | F44: NAMA HOTEL | J44: KET ROOM | L44: HARGA
B45: Check In | D45: Check Out
A46: 1 | B46: =+'TAHAP 1'!C13 -> 45530 | D46: =+'TAHAP 1'!F13 -> 45569 | F46: Aston Sidoarjo City Hotel and Conference Center Jalan Kahuripan Raya Kav. 14 Sidoarjo, Kahuripan, Sidoarjo, 61252, Indonesia. CI/CO : 21 - 23 Aug (02 Malam) Deluxe : IDR 670.000/room/night include breakfast Executive : IDR 950.000/room/night include breakfast | J46: Deluxe | L46: 670000
J47: Executive | L47: 950000
F48: =+F46 -> Aston Sidoarjo City Hotel and Conference Center Jalan Kahuripan Raya Kav. 14 Sidoarjo, Kahuripan, Sidoarjo, 61252, Indonesia. CI/CO : 21 - 23 Aug (02 Malam) Deluxe : IDR 670.000/room/night include breakfast Executive : IDR 950.000/room/night include breakfast
B49: NAMA | D49: ROOM | E49: QTY ROOM | F49: QTY NIGHT | G49: PRICE | H49: TOTAL | I49: BREAKFAST | J49: SMOKING | K49: LAUNDRY
B51: =B30 -> NANANG YUDI PRASETYO | D51: =+J47 -> Executive | E51: 1 | F51: 2 | G51: =+L47 -> 950000 | H51: =+G51*F51*E51 -> 1900000 | I51: Yes | J51: No | K51: No
B52: =B31 -> ADITYA FAHRIZAL | D52: =+J46 -> Deluxe | E52: 1 | F52: 2 | G52: =+L46 -> 670000 | H52: =+G52*F52*E52 -> 1340000 | I52: Yes | J52: Yes | K52: No
B53: =#REF! -> #REF! | D53: =J46 -> Deluxe | E53: 1 | F53: 2 | G53: =+L46 -> 670000 | H53: =+G53*F53*E53 -> 1340000 | I53: Yes | J53: No | K53: No
B54: =#REF! -> #REF! | D54: =J46 -> Deluxe
...

Sheet TAHAP 2.1 (SPD)
W1: A
B2: PT. SEMARANG AUTOCOMP MANUFACTURING INDONESIA | K2: FORM/CHECKSHEET | L2: NO. DOKUMEN | N2: : 023/PGA/GA/FORM/SPDDN | R2: APPROVED II | S2: APPROVED I | T2: CHECKED | V2: PREPARED
B3: SURAT PERJALANAN DINAS DALAM NEGERI | L3: TANGGAL | N3: : 11-07-2023 | R3: APPROVED
L4: REVISI | N4: : 4
L5: HALAMAN | N5: : 1/2
L6: MASA BERLAKU | N6: : 10-07-2024 | R6: AWI | S6: FYH | T6: SMK | V6: Renny
B9: TUJUAN PERJALANAN DINAS | I9: =+'TAHAP 1'!G8 -> : PEMI
B10: KEPENTINGAN | I10: =+'TAHAP 1'!G9 -> : MENGIKUTI JISHUKEN GLOBAL PEMI 2024
B14: 1. PESERTA
B15: NO | C15: TANGGAL | G15: DEPT. / SECT. | I15: JABATAN | K15: NIK | M15: NAMA | P15: 1 | Q15: 2 | R15: 3 | S15: 4 | T15: 5
P16: YANG MENERIMA PERINTAH | Q16: SPV | R16: MGR | S16: FM / DFM | T16: PRESDIR
B19: 1 | C19: =+'TAHAP 1'!C13 -> 45530 | D19: s/d | F19: =+'TAHAP 1'!F13 -> 45569 | G19: =+'TAHAP 1'!G13:H13 -> FA | I19: =+'TAHAP 1'!I13:J13 -> CSPV | K19: =+'TAHAP 1'!K13:L13 -> 5533 | M19: =+'TAHAP 1'!M13 -> NANANG YUDI PRASETYO | P19: NYP | Q19: - | R19: PAN | S19: MIS | T19: NKA | Y19: =+G19 -> FA | Z19: =+I19 -> CSPV | AA19: =+K19 -> 5533 | AB19: =+M19 -> NANANG YUDI PRASETYO
B20: 2 | C20: =+'TAHAP 1'!C14 -> 45530 | D20: s/d | F20: =+'TAHAP 1'!F14 -> 45569 | G20: =+'TAHAP 1'!G14:H14 -> FA | I20: =+'TAHAP 1'!I14:J14 -> SPV | K20: =+'TAHAP 1'!K14:L14 -> 13647 | M20: =+'TAHAP 1'!M14 -> ADITYA FAHRIZAL | P20: AFA | Q20: - | Y20: =+G20 -> FA | Z20: =+I20 -> SPV | AA20: =+K20 -> 13647 | AB20: =+M20 -> ADITYA FAHRIZAL
B26: 2. BIAYA PERJALANAN DINAS | L26: UPD | O26: TRANSPORTASI | S26: HOTEL
O27: PESAWAT | Q27: UANG CADANGAN | S27: =+'TAPAH 2.2 (Rincian)'!F48 -> Aston Sidoarjo City Hotel and Conference Center Jalan Kahuripan Raya Kav. 14 Sidoarjo, Kahuripan, Sidoarjo, 61252, Indonesia. CI/CO : 21 - 23 Aug (02 Malam) Deluxe : IDR 670.000/room/night include breakfast Executive : IDR 950.000/room/night include breakfast
Q28: -
Q29: -
B33: NO | C33: NAMA | G33: NIK | H33: NO. REKENING | L33: PRICE | N33: PERIODE BUDGET | O33: ESTIMATED PRICE | P33: PERIODE BUDGET | Q33: ESTIMATED PRICE | R33: PERIODE BUDGET | S33: ESTIMATED PRICE | T33: PERIODE BUDGET
B34: =+'TAPAH 2.2 (Rincian)'!A30 -> 1 | C34: ='TAPAH 2.2 (Rincian)'!B30 -> NANANG YUDI PRASETYO | G34: =+'TAHAP 1'!K13 -> 5533 | L34: =+upd!H62 -> 3517500 | O34: =SUM(upd!I62:L62) -> 4385700 | Q34: 0 | S34: =+upd!M62 -> 5250000
B35: 2 | C35: ='TAPAH 2.2 (Rincian)'!B31 -> ADITYA FAHRIZAL | G35: =+'TAHAP 1'!K14 -> 13647 | L35: =+upd!H63 -> 3517500 | O35: =+SUM(upd!I63:L63) -> 4385700 | Q35: 0 | S35: =+upd!M63 -> 5250000
B36: SUB TOTAL | L36: =SUM(L34:M35) -> 7035000 | O36: =SUM(O34:O35) -> 8771400 | Q36: =SUM(Q34:Q35) -> 0 | S36: =SUM(S34:S35) -> 10500000
B37: TOTAL | L37: =SUM(L36:V36) -> 26306400
B40: NOTE : 1. Ket. Budget di isi bulan periode budget atau di tulis "additional" jika additional budget 2. Approval diproses oleh User 3. Approval pada form ini akan digunakan sebagai jaminan GA dalam melakukan proses issued ticket dan hotel sebelum user melakukan pembuatan PR (purchase requisition). 4. Pembuatan PR setelah proses issued bertujuan agar tidak terjadi selisih harga PR (purchase requisition) dengan actual. | T40: 6. MENGETAHUI MGR FA
T43: BRI
B52: PERLINDUNGAN HAK CIPTA! Dokumen ini adalah milik dan untuk dipergunakan di lingkungan kerja PT. SAMI . Tidak diperkenankan memindahkan, menyalin, atau menggandakan sebagian ataupun seluruhnya isi dokumen ini dalam bentuk dan dengan cara apapun, tanpa izin tertulis dari Wakil manajemen. | I52: Referensi Prosedur/WI/OS/IS/ : PGA-GA.PD.02 : Prosedur Perjalanan Dinas | M52: 4 | N52: Penggabungan approval perjalanan dinas | Q52: 45118 | R52: Renny
M53: 3 | N53: Update Tgl Masa Berlaku & Rev. No. Dok. | Q53: 44702 | R53: Renny
M54: 2 | N54: New Format | Q54: 44314 | R54: Renny | S54: 3 | T54: =+Q52 -> 45118 | W54: FYH
M55: 1 | N55: Add Actual UPD | Q55: 44147 | R55: Renny | S55: 2 | T55: 44702 | W55: WIN
M56: 0 | N56: New Release | Q56: 45113 | R56: LNA | S56: 1 | T56: 44314 | W56: FYH
M57: REV. | N57: ISI PERUBAHAN | Q57: TANGGAL | R57: PIC | S57: REVIEW | T57: TGL | W57: PIC
