Workbook

Sheet TAHAP 1
U1: A
B2: PT. SEMARANG AUTOCOMP MANUFACTURING INDONESIA | H2: FORM/CHECKSHEET | I2: NO. DOKUMEN | J2: : 083/PGA/GS/FORM/RPBPD | N2: APPROVED II | P2: APPROVED I | R2: CHECKED | T2: PREPARED
B3: REQUEST PERHITUNGAN BIAYA PERJALANAN DINAS | I3: REVISI | J3: : 0 | N3: APPROVED
I4: TANGGAL | J4: : 05-07-2023
I5: HALAMAN | J5: : 1
I6: MASA BERLAKU | J6: : 04-07-2024 | N6: AWI | P6: FYH | R6: SMK | T6: Renny
B8: TUJUAN PERJALANAN DINAS | G8: : SAI - JAI
B9: KEPENTINGAN | G9: : MAINTEE & ENG MEETING TERM 84
B11: 1. MEMBER YANG AKAN PERJALANAN DINAS
B12: NO | C12: TANGGAL | G12: DEPT. / SECT. | I12: JABATAN | K12: NIK | M12: NAMA
B13: 1 | C13: 45525 | D13: s/d | F13: 45527 | G13: PE / MANAGEMENT | I13: SENIOR MANAGER | K13: 25252 | M13: KENTA KATO
B15: 2. TRANSPORTASI
B16: 2.a Pesawat | K16: 2.b Kereta
B17: NO | C17: TANGGAL | E17: AIR PORT | H17: RANGE TIME | K17: NO | L17: TANGGAL | N17: STATION | R17: RANGE TIME
E18: DEPARTURE | G18: ARRIVAL | H18: DEPARTURE | I18: ARRIVAL | N18: DEPARTURE | P18: ARRIVAL | R18: DEPARTURE | T18: ARRIVAL
B19: 1 | K19: 1
B20: 2 | K20: 2
B22: 2.c Mobil / Hi Ace / Bus
B23: NO | C23: TANGGAL | G23: JENIS ARMADA | I23: JUMLAH KURSI (PENUMPANG) | J23: WAKTU KEBERANGKATAN | N23: REQUEST KHUSUS
J24: LOKASI | L24: JAM
B25: 1 | C25: =C13 -> 45525 | D25: s/d | F25: =F13 -> 45527 | G25: Innova Zenix | I25: 3
B26: NOTE : Standar kelengkapan armada | E26: =VLOOKUP($D$25,A12:$H$16,5,0) -> #N/A
B27: No | C27: Point | J27: Mobil | M27: Hi Ace | P27: BUS
B28: 1 | C28: Sabuk Pengaman | J28: ● | M28: ● | P28: ●
B29: 2 | C29: Ban Cadangan | J29: ● | M29: ● | P29: ●
B30: 3 | C30: Segitiga Pengaman (Minimal 2 buah, berwarna merah, dapat memantulkan cahaya) | J30: ● | M30: ● | P30: ●
B31: 4 | C31: Dongkrak | J31: ● | M31: ● | P31: ●
B32: 5 | C32: Pembuka Roda dan | J32: ● | M32: ● | P32: ●
B33: 6 | C33: Kotak P3K(Minimal berisi obat antiseptik, kain kassa, kapas, plester) | J33: ● | M33: ●
B34: 7 | C34: Apar | J34: ● (1x M1 berat 1 Kg) | M34: ● (2x M1 berat 1 Kg)
B35: 8 | C35: Ganjal Ban (Wheel Block) | J35: x | M35: ● (Jika > 3,500 Kg)
B36: 9 | C36: Perisai Kolong Belakang | J36: x | M36: x | P36: x
B37: 10 | C37: Perisai Kolong Samping | J37: x | M37: x | P37: x
B38: 11 | C38: Alat Pemantul Cahaya | J38: x | M38: x | P38: x
B39: 12 | C39: Pemecah Kaca / Martil | J39: x | M39: x | P39: x
B40: 13 | C40: Usia Driver | J40: 50 Tahun | M40: 50 Tahun | P40: 50 Tahun
B41: 14 | C41: Kernet | J41: x | M41: x | P41: x
B42: NOTE : Standar transportasi berdasarkan Prosedur Perjalanan Dinas (PGA-GA.PD.02)
B43: KET. | D43: Golongan I - III | H43: Golongan IV - V | K43: Golongan VI - VII
B44: Luar Negeri | D44: Pesawat Udara Kelas Ekonomi | H44: Pesawat Udara Kelas Ekonomi | K44: Pesawat Udara Kelas Bisnis
...

Sheet TAHAP 2.2 (Rincian)
O1: A
A2: PT. SEMARANG AUTOCOMP MANUFACTURING INDONESIA - TUGU FACTORY | H2: FORM/CHECKSHEET | I2: NO. DOKUMEN | J2: : 023/PGA/GA/FORM/SPDDN | L2: APPROVED II | M2: APPROVED I | N2: CHECKED | O2: PREPARED
A3: SURAT PERJALANAN DINAS DALAM NEGERI | I3: TANGGAL | J3: : 11-07-2023 | L3: APPROVED
I4: REVISI | J4: : 4
I5: HALAMAN | J5: : 2 / 2
I6: MASA BERLAKU | J6: : 10-07-2024 | L6: AWI | M6: FYH | N6: SMK | O6: RENNY
A8: LAMPIRAN (Rincian) | E8: =+'TAHAP 1'!G9 -> : MAINTEE & ENG MEETING TERM 84
A10: 1. UPD
A11: NOTE : Standar UPD Dalam Negeri berdasarkan Prosedur Perjalanan Dinas (PGA-GA.PD.02)
A12: Golongan | E12: UANG SAKU | F12: BREAKFAST | G12: LUNCH | H12: DINNER
A13: I | E13: 30000 | F13: 12500 | G13: 20000 | H13: 20000
A14: II | E14: 30000 | F14: 12500 | G14: 20000 | H14: 20000
A15: III | E15: 35000 | F15: 12500 | G15: 20000 | H15: 20000
A16: IV | E16: 40000 | F16: 12500 | G16: 27500 | H16: 27500
A17: V | E17: 50000 | F17: 22500 | G17: 30000 | H17: 30000
A18: VI | E18: 60000 | F18: 22500 | G18: 50000 | H18: 50000
A19: VII | E19: 70000 | F19: 22500 | G19: 60000 | H19: 60000
B21: Rincian Golongan | C21: : | D21: V
A22: NO. | B22: TANGGAL | E22: =+$E$12 -> UANG SAKU | F22: =+$F$12 -> BREAKFAST | G22: INNOVA | H22: =+$H$12 -> DINNER | I22: JUMLAH
A23: 1 | B23: =+'TAHAP 1'!$C$13 -> 45525 | E23: =VLOOKUP($D$21,A12:$H$19,5,0) -> 50000 | F23: di Rumah | G23: =VLOOKUP($D$21,A12:$H$19,8,0) -> 30000 | H23: =VLOOKUP($D$21,A12:$H$19,8,0) -> 30000 | I23: =SUM(E23:H23) -> 110000
A24: 2 | B24: =+B23+1 -> 45526 | E24: =VLOOKUP($D$21,A$12:$H19,5,0) -> 50000 | F24: di Hotel | G24: di JAI | H24: =VLOOKUP($D$21,A$12:$H19,8,0) -> 30000 | I24: =SUM(E24:H24) -> 80000
A25: 3 | B25: =+B24+1 -> 45527 | E25: =VLOOKUP($D$21,A$12:$H19,5,0) -> 50000 | F25: di Hotel | G25: di JAI | H25: =VLOOKUP($D$21,A$12:$H19,8,0) -> 30000 | I25: =SUM(E25:H25) -> 80000
A26: TOTAL | I26: =SUM(I23:I25) -> 270000
A27: UPD
A28: NO. | B28: NAMA | F28: GOL | G28: UPD
A29: 1 | B29: ='TAHAP 1'!M13 -> KENTA KATO | F29: V | G29: =I26 -> 270000 | Q29: ='TAHAP 2.2 (Rincian)'!H61 -> 0
A30: TOTAL | G30: =SUM(G29:G29) -> 270000
A32: 2. TRANSPORTASI (PIC Perjalanan Dinas tanda tangan pada kolom transportasi yang dipilih atau yang diajukan)
A34: 2.1 PESAWAT | B34: KERETA
A35: NO. | B35: KET. | D35: SCHEDULE | J35: PRICE | K35: QTY | L35: JUMLAH | M35: TOTAL
A36: 1 | B36: BERANGKAT
A37: 2 | B37: PULANG
A40: 2.2 MOBIL / LOCAL TRANSPORT
A45: NO. | B45: ITEM | E45: HARGA | F45: JML HARI | G45: JML BIAYA
A46: 1
A47: BIAYA SEWA UNIT | H47: =SUM(H40:H46) -> 0
A50: NO. | B50: ITEM | E50: HARGA | F50: JML HARI | G50: JML BIAYA
A51: 1 | B51: Biaya Antar Ambil | E51: 0 | F51: 0 | H51: =+E51*F51 -> 0
A52: 2 | B52: Fee Luar Kota Driver | E52: 0 | F52: 0 | H52: =+E52*F52 -> 0
A53: 3 | B53: Uang Inap | E53: 0 | F53: 0 | H53: =+E53*F53 -> 0
...

Sheet TAHAP 2.1 (SPD)
W1: A
B2: PT. SEMARANG AUTOCOMP MANUFACTURING INDONESIA | K2: FORM/CHECKSHEET | L2: NO. DOKUMEN | N2: : 023/PGA/GA/FORM/SPDDN | R2: APPROVED II | S2: APPROVED I | T2: CHECKED | V2: PREPARED
B3: SURAT PERJALANAN DINAS DALAM NEGERI | L3: TANGGAL | N3: : 11-07-2023 | R3: APPROVED
L4: REVISI | N4: : 4
L5: HALAMAN | N5: : 1/2
L6: MASA BERLAKU | N6: : 10-07-2024 | R6: AWI | S6: FYH | T6: SMK | V6: Renny
B9: TUJUAN PERJALANAN DINAS | I9: =+'TAHAP 1'!G8 -> : SAI - JAI
B10: KEPENTINGAN | I10: =+'TAHAP 1'!G9 -> : MAINTEE & ENG MEETING TERM 84
B14: 1. PESERTA
B15: NO | C15: TANGGAL | G15: DEPT. / SECT. | I15: JABATAN | K15: NIK | M15: NAMA | P15: 1 | Q15: 2 | R15: 3 | S15: 4 | T15: 5
P16: YANG MENERIMA PERINTAH | Q16: SPV | R16: MGR | S16: FM / DFM | T16: PRESDIR
B19: 1 | C19: =+'TAHAP 1'!C13 -> 45525 | D19: s/d | F19: =+'TAHAP 1'!F13 -> 45527 | G19: =+'TAHAP 1'!G13:H13 -> PE / MANAGEMENT | I19: =+'TAHAP 1'!I13:J13 -> SENIOR MANAGER | K19: =+'TAHAP 1'!K13:L13 -> 25252 | M19: =+'TAHAP 1'!M13 -> KENTA KATO | P19: KKA | Q19: - | R19: - | S19: MIS | T19: NKA | Y19: =+G19 -> PE / MANAGEMENT | Z19: =+I19 -> SENIOR MANAGER | AA19: =+K19 -> 25252 | AB19: =+M19 -> KENTA KATO
B25: 2. BIAYA PERJALANAN DINAS | L25: UPD | O25: TRANSPORTASI | S25: HOTEL
O26: BY : KERETA | Q26: UANG CADANGAN | S26: =+'TAHAP 2.2 (Rincian)'!F67 -> Fairfield by Marriott Surabaya Jl. Mayjen Sungkono No. 178, Dukuh Kupang, Kec. Dukuhpakis, Surabaya, Jawa Timur 60225
Q27: * Lokal Transport : 200.000/orang
Q28: * Laundry : 100.000/day | S28: {=+'TAHAP 2.2 (Rincian)'!#REF!} -> #REF! | T28: #REF! | U28: #REF! | V28: #REF!
B32: NO | C32: NAMA | G32: NIK | H32: NO. REKENING | L32: PRICE | N32: PERIODE BUDGET | O32: ESTIMATED PRICE | P32: PERIODE BUDGET | Q32: ESTIMATED PRICE | R32: PERIODE BUDGET | S32: ESTIMATED PRICE | T32: PERIODE BUDGET
B33: =+'TAHAP 2.2 (Rincian)'!A29 -> 1 | C33: ='TAHAP 2.2 (Rincian)'!B29 -> KENTA KATO | G33: =+'TAHAP 1'!K13 -> 25252 | L33: ='TAHAP 2.2 (Rincian)'!G29 -> 270000 | O33: =+'TAHAP 2.2 (Rincian)'!J38 -> 0 | S33: =+'TAHAP 2.2 (Rincian)'!H71 -> 2052000
B34: SUB TOTAL | L34: =SUM(L33:M33) -> 270000 | O34: =SUM(O33:O33) -> 0 | Q34: =SUM(Q33:Q33) -> 0 | S34: =SUM(S33:S33) -> 2052000
B35: TOTAL | L35: =SUM(L34:V34) -> 2322000
B38: NOTE : 1. Ket. Budget di isi bulan periode budget atau di tulis "additional" jika additional budget 2. Approval diproses oleh User 3. Approval pada form ini akan digunakan sebagai jaminan GA dalam melakukan proses issued ticket dan hotel sebelum user melakukan pembuatan PR (purchase requisition). 4. Pembuatan PR setelah proses issued bertujuan agar tidak terjadi selisih harga PR (purchase requisition) dengan actual. | T38: 6. MENGETAHUI MGR FA
T41: BRI
B50: PERLINDUNGAN HAK CIPTA! Dokumen ini adalah milik dan untuk dipergunakan di lingkungan kerja PT. SAMI . Tidak diperkenankan memindahkan, menyalin, atau menggandakan sebagian ataupun seluruhnya isi dokumen ini dalam bentuk dan dengan cara apapun, tanpa izin tertulis dari Wakil manajemen. | I50: Referensi Prosedur/WI/OS/IS/ : PGA-GA.PD.02 : Prosedur Perjalanan Dinas | M50: 4 | N50: Penggabungan approval perjalanan dinas | Q50: 45118 | R50: Renny
M51: 3 | N51: Update Tgl Masa Berlaku & Rev. No. Dok. | Q51: 44702 | R51: Renny
M52: 2 | N52: New Format | Q52: 44314 | R52: Renny | S52: 3 | T52: =+Q50 -> 45118 | W52: FYH
M53: 1 | N53: Add Actual UPD | Q53: 44147 | R53: Renny | S53: 2 | T53: 44702 | W53: WIN
M54: 0 | N54: New Release | Q54: 45113 | R54: LNA | S54: 1 | T54: 44314 | W54: FYH
M55: REV. | N55: ISI PERUBAHAN | Q55: TANGGAL | R55: PIC | S55: REVIEW | T55: TGL | W55: PIC
L70: 1019000
L71: 767000
G77: =L71 -> 767000
G78: =L71 -> 767000
G79: =L71 -> 767000

Sheet Sheet1
B4: NAMA | D4: ROOM | E4: QTY ROOM | F4: QTY NIGHT | G4: BREAKFAST | H4: SMOKING | I4: LAUNDRY
B6: TORU YAMAMOTO | D6: Deluxe | E6: 1 | F6: 2 | G6: Yes | H6: No | I6: No
B7: KENTA KATO | D7: Deluxe | E7: 1 | F7: 2 | G7: Yes | H7: No | I7: No
B8: AGUS NUGROHO | D8: Deluxe | E8: 1 | F8: 2 | G8: Yes | H8: No | I8: No
B9: BONIR ARIO TUBAGUS | D9: Deluxe | E9: 1 | F9: 2 | G9: Yes | H9: No | I9: No
B10: NUR FARID | D10: Deluxe | E10: 1 | F10: 2 | G10: Yes | H10: No | I10: No
