Workbook

Sheet TAHAP 1
U1: A
B2: PT. SEMARANG AUTOCOMP MANUFACTURING INDONESIA | H2: FORM/CHECKSHEET | I2: NO. DOKUMEN | J2: : 083/PGA/GS/FORM/RPBPD | N2: APPROVED II | P2: APPROVED I | R2: CHECKED | T2: PREPARED
B3: REQUEST PERHITUNGAN BIAYA PERJALANAN DINAS | I3: REVISI | J3: : 0 | N3: APPROVED
I4: TANGGAL | J4: : 05-07-2023
I5: HALAMAN | J5: : 1
I6: MASA BERLAKU | J6: : 04-07-2024 | N6: AWI | P6: FYH | R6: SMK | T6: Renny
B8: TUJUAN PERJALANAN DINAS | G8: : SUAI
B9: KEPENTINGAN | G9: : PENGECEKAN RULE DUMMY CHECK
B11: 1. MEMBER YANG AKAN PERJALANAN DINAS
B12: NO | C12: TANGGAL | G12: DEPT. / SECT. | I12: JABATAN | K12: NIK | M12: NAMA
B13: 1 | C13: 45355 | D13: s/d | F13: 45356 | G13: PGA | I13: SM | K13: 25252 | M13: GONDA KATSUHITO
B14: 2 | D14: s/d
B16: 2. TRANSPORTASI
B17: 2.a Pesawat | K17: 2.b Kereta
B18: NO | C18: TANGGAL | E18: AIR PORT | H18: RANGE TIME | K18: NO | L18: TANGGAL | N18: STATION | R18: RANGE TIME
E19: DEPARTURE | G19: ARRIVAL | H19: DEPARTURE | I19: ARRIVAL | N19: DEPARTURE | P19: ARRIVAL | R19: DEPARTURE | T19: ARRIVAL
B20: 1 | K20: 1
B21: 2 | K21: 2 | T21: A
B23: 2.c Mobil / Hi Ace / Bus
B24: NO | C24: TANGGAL | G24: JENIS ARMADA | I24: JUMLAH KURSI (PENUMPANG) | J24: WAKTU KEBERANGKATAN | N24: REQUEST KHUSUS
J25: LOKASI | L25: JAM
B26: 1 | C26: 45355 | D26: s/d | F26: 45356 | G26: MOBIL EXPAT | N26: -
B27: NOTE : Standar kelengkapan armada
B28: No | C28: Point | J28: Mobil | M28: Hi Ace | P28: BUS
B29: 1 | C29: Sabuk Pengaman | J29: ● | M29: ● | P29: ●
B30: 2 | C30: Ban Cadangan | J30: ● | M30: ● | P30: ●
B31: 3 | C31: Segitiga Pengaman (Minimal 2 buah, berwarna merah, dapat memantulkan cahaya) | J31: ● | M31: ● | P31: ●
B32: 4 | C32: Dongkrak | J32: ● | M32: ● | P32: ●
B33: 5 | C33: Pembuka Roda dan | J33: ● | M33: ● | P33: ●
B34: 6 | C34: Kotak P3K(Minimal berisi obat antiseptik, kain kassa, kapas, plester) | J34: ● | M34: ● | P34: ●
B35: 7 | C35: Apar | J35: ● (1x M1 berat 1 Kg) | M35: ● (2x M1 berat 1 Kg) | P35: ● (2x M1 berat 1 Kg)
B36: 8 | C36: Ganjal Ban (Wheel Block) | J36: x | M36: ● (Jika > 3,500 Kg) | P36: ● (Jika > 3,500 Kg)
B37: 9 | C37: Perisai Kolong Belakang | J37: x | M37: x | P37: x
B38: 10 | C38: Perisai Kolong Samping | J38: x | M38: x | P38: x
B39: 11 | C39: Alat Pemantul Cahaya | J39: x | M39: x | P39: x
B40: 12 | C40: Pemecah Kaca / Martil | J40: x | M40: x | P40: x
... B42: 14 | C42: Kernet | J42: x | M42: x | P42: x
B43: NOTE : Standar transportasi berdasarkan Prosedur Perjalanan Dinas (PGA-GA.PD.02)
B44: KET. | D44: Golongan I - III | H44: Golongan IV - V | K44: Golongan VI - VII
B45: Luar Negeri | D45: Pesawat Udara Kelas Ekonomi | H45: Pesawat Udara Kelas Ekonomi | K45: Pesawat Udara Kelas Bisnis
...

Sheet TAPAH 2.2 (Rincian)
P1: A
B2: PT. SEMARANG AUTOCOMP MANUFACTURING INDONESIA - TUGU FACTORY | I2: FORM/CHECKSHEET | J2: NO. DOKUMEN | K2: : 023/PGA/GA/FORM/SPDDN | M2: APPROVED II | N2: APPROVED I | O2: CHECKED | P2: PREPARED
B3: SURAT PERJALANAN DINAS DALAM NEGERI | J3: TANGGAL | K3: : 11-07-2023 | M3: APPROVED
J4: REVISI | K4: : 4
J5: HALAMAN | K5: : 2 / 2
J6: MASA BERLAKU | K6: : 10-07-2024 | M6: AWI | N6: FYH | O6: SMK | P6: RENNY
B8: LAMPIRAN (Rincian) | F8: =+'TAHAP 1'!G9 -> : PENGECEKAN RULE DUMMY CHECK
B10: 1. UPD
B11: NOTE : Standar UPD Dalam Negeri berdasarkan Prosedur Perjalanan Dinas (PGA-GA.PD.02)
B12: Golongan | F12: UANG SAKU | G12: BREAKFAST | H12: LUNCH | I12: DINNER
B13: I | F13: 30000 | G13: 12500 | H13: 20000 | I13: 20000
B14: II | F14: 30000 | G14: 12500 | H14: 20000 | I14: 20000
B15: III | F15: 35000 | G15: 12500 | H15: 20000 | I15: 20000
B16: IV | F16: 40000 | G16: 12500 | H16: 27500 | I16: 27500
B17: V | F17: 50000 | G17: 22500 | H17: 30000 | I17: 30000
B18: VI | F18: 60000 | G18: 22500 | H18: 50000 | I18: 50000
B19: VII | F19: 70000 | G19: 22500 | H19: 60000 | I19: 60000
C21: Rincian Golongan | D21: : | E21: V
B22: NO. | C22: TANGGAL | F22: =+$F$12 -> UANG SAKU | G22: =+$G$12 -> BREAKFAST | H22: =+$H$12 -> LUNCH | I22: =+$I$12 -> DINNER | J22: JUMLAH
B23: 1 | C23: =+'TAHAP 1'!$C$13 -> 45355 | F23: =VLOOKUP($E$21,B12:$I$19,5,0) -> 50000 | G23: =G17 -> 22500 | H23: di SUAI | I23: =VLOOKUP($E$21,B12:$I$19,8,0) -> 30000 | J23: =SUM(F23:I23) -> 102500
B24: 2 | C24: =+C23+1 -> 45356 | F24: =VLOOKUP($E$21,B13:$I$19,5,0) -> 50000 | G24: di Hotel | H24: di SUAI | I24: 30000 | J24: =SUM(F24:I24) -> 80000
B25: 3 | J25: =SUM(F25:I25) -> 0
B26: TOTAL | F26: =SUM(F23:F25) -> 100000 | G26: =SUM(G23:I25) -> 82500 | J26: =SUM(J23:J25) -> 182500
B29: UPD
B30: NO. | C30: NAMA | G30: GOL | H30: UPD
B31: 1 | C31: =+'TAHAP 1'!M13 -> GONDA KATSUHITO | G31: V | H31: =+J26 -> 182500
B32: 2 | C32: =+'TAHAP 1'!M14 -> 0 | H32: 0
B33: TOTAL | H33: =SUM(H31:H32) -> 182500
B35: 2. TRANSPORTASI (PIC Perjalanan Dinas tanda tangan pada kolom transportasi yang dipilih atau yang diajukan)
B37: 2.1 PESAWAT
B38: NO. | C38: KET. | E38: FLIGHT SCHEDULE | K38: PRICE | L38: QTY | M38: JUMLAH | N38: TOTAL
B39: 1 | C39: BERANGKAT | M39: =+K39*L39 -> 0 | N39: =SUM(M39:M40) -> 0
B40: 2 | C40: PULANG
B43: 2.2 MOBIL / LOCAL TRANSPORT
B48: NO. | C48: ITEM | F48: HARGA | G48: JML HARI | H48: JML BIAYA
B49: 1 | C49: Sewa Unit | F49: 0 | G49: 0 | I49: =+F49*G49 -> 0
B50: BIAYA SEWA UNIT | I50: =SUM(I43:I49) -> 0
B53: NO. | C53: ITEM | F53: HARGA | G53: JML HARI | H53: JML BIAYA
B54: 1 | C54: Biaya Antar Ambil | F54: 0 | G54: 0 | I54: =+F54*G54 -> 0
B55: 2 | C55: Fee Luar Kota Driver | F55: 100000 | G55: 2 | I55: =+F55*G55 -> 200000
...

Sheet TAHAP 2.1 (SPD)
W1: A
B2: PT. SEMARANG AUTOCOMP MANUFACTURING INDONESIA | K2: FORM/CHECKSHEET | L2: NO. DOKUMEN | N2: : 023/PGA/GA/FORM/SPDDN | R2: APPROVED II | S2: APPROVED I | T2: CHECKED | V2: PREPARED
B3: SURAT PERJALANAN DINAS DALAM NEGERI | L3: TANGGAL | N3: : 11-07-2023 | R3: APPROVED
L4: REVISI | N4: : 4
L5: HALAMAN | N5: : 1/2
L6: MASA BERLAKU | N6: : 10-07-2024 | R6: AWI | S6: FYH | T6: SMK | V6: Renny
B9: TUJUAN PERJALANAN DINAS | I9: =+'TAHAP 1'!G8 -> : SUAI
B10: KEPENTINGAN | I10: =+'TAHAP 1'!G9 -> : PENGECEKAN RULE DUMMY CHECK
B14: 1. PESERTA
B15: NO | C15: TANGGAL | G15: DEPT. / SECT. | I15: JABATAN | K15: NIK | M15: NAMA | P15: 1 | Q15: 2 | R15: 3 | S15: 4 | T15: 5
P16: YANG MENERIMA PERINTAH | Q16: SPV | R16: MGR | S16: FM / DFM | T16: PRESDIR
B19: 1 | C19: =+'TAHAP 1'!C13 -> 45355 | D19: s/d | F19: =+'TAHAP 1'!E13:F13 -> 45356 | G19: =+'TAHAP 1'!G13:H13 -> PGA | I19: =+'TAHAP 1'!I13:J13 -> SM | K19: 25252 | M19: =+'TAHAP 1'!M13 -> GONDA KATSUHITO | P19: KGO | Q19: - | R19: - | S19: TMI | T19: NKA | Y19: =+G19 -> PGA | Z19: =+I19 -> SM | AA19: =+K19 -> 25252 | AB19: =+M19 -> GONDA KATSUHITO
B20: 2 | D20: s/d | Y20: =+G20 -> 0 | Z20: =+I20 -> 0 | AA20: =+K20 -> 0 | AB20: =+M20 -> 0
B25: 2. BIAYA PERJALANAN DINAS | L25: UPD | O25: TRANSPORTASI | S25: HOTEL
O26: BY : PESAWAT | Q26: LOKAL TRANSPORT | S26: Delonix Hotel Karawang Exit Toll Karawang Barat, Komplek Sedana Golf KM 47 Sukaluyu - Teluk Jambe 41361 Karawang
O27: Berangkat : | P27: =+C19 -> 45355
O28: =+'TAPAH 2.2 (Rincian)'!O39 -> 0
O29: Pulang : | P29: =+F19 -> 45356
O30: =+'TAPAH 2.2 (Rincian)'!O40 -> 0
B31: NO | C31: NAMA | G31: NIK | H31: NO. REKENING | L31: PRICE | N31: PERIODE BUDGET | O31: ESTIMATED PRICE | P31: PERIODE BUDGET | Q31: ESTIMATED PRICE | R31: PERIODE BUDGET | S31: ESTIMATED PRICE | T31: PERIODE BUDGET
B32: =+'TAPAH 2.2 (Rincian)'!B31 -> 1 | C32: =+'TAPAH 2.2 (Rincian)'!C31:F31 -> GONDA KATSUHITO | G32: =+'TAHAP 1'!K13 -> 25252 | L32: =+'TAPAH 2.2 (Rincian)'!H31 -> 182500 | O32: 0 | Q32: =+'TAPAH 2.2 (Rincian)'!F61 -> 0 | T32: -
B33: 2 | C33: =+'TAPAH 2.2 (Rincian)'!C32:F32 -> 0 | G33: =+'TAHAP 1'!K14 -> 0 | L33: =+'TAPAH 2.2 (Rincian)'!H32 -> 0 | O33: =+'TAPAH 2.2 (Rincian)'!K40+'TAPAH 2.2 (Rincian)'!K39 -> 0 | Q33: =+'TAPAH 2.2 (Rincian)'!F61 -> 0 | S33: =+'TAPAH 2.2 (Rincian)'!I75 -> 0 | T33: -
B34: SUB TOTAL | L34: =SUM(L32:M33) -> 182500 | O34: =SUM(O32:O33) -> 0 | Q34: =SUM(Q32:Q33) -> 0 | S34: =SUM(S32:S33) -> 0
B35: TOTAL | L35: =SUM(L34:V34) -> 182500
B37: NOTE : 1. Ket. Budget di isi bulan periode budget atau di tulis "additional" jika additional budget 2. Approval diproses oleh User 3. Approval pada form ini akan digunakan sebagai jaminan GA dalam melakukan proses issued ticket dan hotel sebelum user melakukan pembuatan PR (purchase requisition). 4. Pembuatan PR setelah proses issued bertujuan agar tidak terjadi selisih harga PR (purchase requisition) dengan actual. | T37: 6. MENGETAHUI MGR FA
T40: BRI
B49: PERLINDUNGAN HAK CIPTA! Dokumen ini adalah milik dan untuk dipergunakan di lingkungan kerja PT. SAMI . Tidak diperkenankan memindahkan, menyalin, atau menggandakan sebagian ataupun seluruhnya isi dokumen ini dalam bentuk dan dengan cara apapun, tanpa izin tertulis dari Wakil manajemen. | I49: Referensi Prosedur/WI/OS/IS/ : PGA-GA.PD.02 : Prosedur Perjalanan Dinas | M49: 4 | N49: Penggabungan approval perjalanan dinas | Q49: 45118 | R49: Renny
M50: 3 | N50: Update Tgl Masa Berlaku & Rev. No. Dok. | Q50: 44702 | R50: Renny
M51: 2 | N51: New Format | Q51: 44314 | R51: Renny | S51: 3 | T51: =+Q49 -> 45118 | W51: FYH
M52: 1 | N52: Add Actual UPD | Q52: 44147 | R52: Renny | S52: 2 | T52: 44702 | W52: WIN
M53: 0 | N53: New Release | Q53: 45113 | R53: LNA | S53: 1 | T53: 44314 | W53: FYH
M54: REV. | N54: ISI PERUBAHAN | Q54: TANGGAL | R54: PIC | S54: REVIEW | T54: TGL | W54: PIC
