Workbook

Sheet TAHAP 1
U1: A
B2: PT. SEMARANG AUTOCOMP MANUFACTURING INDONESIA | H2: FORM/CHECKSHEET | I2: NO. DOKUMEN | J2: : 083/PGA/GS/FORM/RPBPD | N2: APPROVED II | P2: APPROVED I | R2: CHECKED | T2: PREPARED
B3: REQUEST PERHITUNGAN BIAYA PERJALANAN DINAS | I3: REVISI | J3: : 0 | N3: APPROVED
I4: TANGGAL | J4: : 05-07-2023
I5: HALAMAN | J5: : 1
I6: MASA BERLAKU | J6: : 04-07-2024 | N6: AWI | P6: FYH | R6: SMK | T6: Renny
B8: TUJUAN PERJALANAN DINAS | G8: : SAI - JAI
B9: KEPENTINGAN | G9: : BENCHMARK
B11: 1. MEMBER YANG AKAN PERJALANAN DINAS
B12: NO | C12: TANGGAL | G12: DEPT. / SECT. | I12: JABATAN | K12: NIK | M12: NAMA
B13: 1 | C13: 45525 | D13: s/d | F13: 45527 | G13: FA | I13: GM | K13: 18663 | M13: BAMBANG RIANTO
B14: 2 | C14: =+C13 -> 45525 | D14: s/d | F14: =+F13 -> 45527 | G14: FA | I14: CSPV | K14: 8381 | M14: MAULVI BARUL MUHITH
B15: 3 | C15: =C13 -> 45525 | D15: s/d | F15: =F13 -> 45527 | G15: FA | I15: SPV | K15: 21229 | M15: AMALIA PUJI RAHAYUNINGSIH
B16: 4 | C16: =C13 -> 45525 | D16: s/d | F16: =F13 -> 45527 | G16: FA | I16: ES | K16: 24995 | M16: AYU INDRASARI SAPUTRI
B18: 2. TRANSPORTASI
B19: 2.a Pesawat | K19: 2.b Kereta
B20: NO | C20: TANGGAL | E20: AIR PORT | H20: RANGE TIME | K20: NO | L20: TANGGAL | N20: STATION | R20: RANGE TIME
E21: DEPARTURE | G21: ARRIVAL | H21: DEPARTURE | I21: ARRIVAL | N21: DEPARTURE | P21: ARRIVAL | R21: DEPARTURE | T21: ARRIVAL
B22: 1 | K22: 1
B23: 2 | K23: 2
B25: 2.c Mobil / Hi Ace / Bus
B26: NO | C26: TANGGAL | G26: JENIS ARMADA | I26: JUMLAH KURSI (PENUMPANG) | J26: WAKTU KEBERANGKATAN | N26: REQUEST KHUSUS
J27: LOKASI | L27: JAM
B28: 1 | C28: =C13 -> 45525 | D28: s/d | F28: =F13 -> 45527 | I28: 4 | J28: SAMI TF | L28: 09.00 WIB
B29: NOTE : Standar kelengkapan armada
B30: No | C30: Point | J30: Mobil | M30: Hi Ace | P30: BUS
B31: 1 | C31: Sabuk Pengaman | J31: ● | M31: ● | P31: ●
B32: 2 | C32: Ban Cadangan | J32: ● | M32: ● | P32: ●
B33: 3 | C33: Segitiga Pengaman (Minimal 2 buah, berwarna merah, dapat memantulkan cahaya) | J33: ● | M33: ● | P33: ●
B34: 4 | C34: Dongkrak | J34: ● | M34: ● | P34: ●
B35: 5 | C35: Pembuka Roda dan | J35: ● | M35: ● | P35: ●
B36: 6 | C36: Kotak P3K(Minimal berisi obat antiseptik, kain kassa, kapas, plester) | J36: ● | M36: ● | P36: ●
B37: 7 | C37: Apar | J37: ● (1x M1 berat 1 Kg) | M37: ● (2x M1 berat 1 Kg) | P37: ● (2x M1 berat 1 Kg)
B38: 8 | C38: Ganjal Ban (Wheel Block) | J38: x | M38: ● (Jika > 3,500 Kg) | P38: ● (Jika > 3,500 Kg)
B39: 9 | C39: Perisai Kolong Belakang | J39: x | M39: x | P39: x
B40: 10 | C40: Perisai Kolong Samping | J40: x | M40: x | P40: x
B41: 11 | C41: Alat Pemantul Cahaya | J41: x | M41: x | P41: x
B42: 12 | C42: Pemecah Kaca / Martil | J42: x | M42: x | P42: x
... B44: 14 | C44: Kernet | J44: x | M44: x | P44: x
B45: NOTE : Standar transportasi berdasarkan Prosedur Perjalanan Dinas (PGA-GA.PD.02)
...

Sheet TAPAH 2.2 (Rincian)
O1: A
A2: PT. SEMARANG AUTOCOMP MANUFACTURING INDONESIA - TUGU FACTORY | H2: FORM/CHECKSHEET | I2: NO. DOKUMEN | J2: : 023/PGA/GA/FORM/SPDDN | L2: APPROVED II | M2: APPROVED I | N2: CHECKED | O2: PREPARED
A3: SURAT PERJALANAN DINAS DALAM NEGERI | I3: TANGGAL | J3: : 11-07-2023 | L3: APPROVED
I4: REVISI | J4: : 4
I5: HALAMAN | J5: : 2 / 2
I6: MASA BERLAKU | J6: : 10-07-2024 | L6: AWI | M6: FYH | N6: SMK | O6: RENNY
A8: LAMPIRAN (Rincian) | E8: =+'TAHAP 1'!G9 -> : BENCHMARK
A10: 1. UPD
A11: NOTE : Standar UPD Dalam Negeri berdasarkan Prosedur Perjalanan Dinas (PGA-GA.PD.02)
A12: Golongan | E12: UANG SAKU | F12: BREAKFAST | G12: LUNCH | H12: DINNER
A13: I | E13: 30000 | F13: 12500 | G13: 20000 | H13: 20000
A14: II | E14: 30000 | F14: 12500 | G14: 20000 | H14: 20000
A15: III | E15: 35000 | F15: 12500 | G15: 20000 | H15: 20000
A16: IV | E16: 40000 | F16: 12500 | G16: 27500 | H16: 27500
A17: V | E17: 50000 | F17: 22500 | G17: 30000 | H17: 30000
A18: VI | E18: 60000 | F18: 22500 | G18: 50000 | H18: 50000
A19: VII | E19: 70000 | F19: 22500 | G19: 60000 | H19: 60000
B21: Rincian Golongan | C21: : | D21: V
A22: NO. | B22: TANGGAL | E22: =+$E$12 -> UANG SAKU | F22: =+$F$12 -> BREAKFAST | G22: =+$G$12 -> LUNCH | H22: =+$H$12 -> DINNER | I22: JUMLAH
A23: 1 | B23: =+'TAHAP 1'!$C$13 -> 45525 | E23: =VLOOKUP($D$21,A12:$H$19,5,0) -> 50000 | F23: di Rumah | G23: =VLOOKUP($D$21,A12:$H$19,8,0) -> 30000 | H23: =VLOOKUP($D$21,A12:$H$19,8,0) -> 30000 | I23: =SUM(E23:H23) -> 110000
A24: 2 | B24: =+B23+1 -> 45526 | E24: =VLOOKUP($D$21,A13:$H$19,5,0) -> 50000 | F24: di Hotel | G24: di SAI | H24: =VLOOKUP($D$21,A13:$H$19,8,0) -> 30000 | I24: =SUM(E24:H24) -> 80000
A25: 3 | B25: =+B24+1 -> 45527 | E25: =VLOOKUP($D$21,A14:$H$19,5,0) -> 50000 | F25: di Hotel | G25: di JAI | H25: =VLOOKUP($D$21,A14:$H$19,8,0) -> 30000 | I25: =SUM(E25:H25) -> 80000
A26: TOTAL | I26: =SUM(I23:I25) -> 270000
B27: Rincian Golongan | C27: : | D27: IV
A28: NO. | B28: TANGGAL | E28: =+$E$12 -> UANG SAKU | F28: =+$F$12 -> BREAKFAST | G28: =+$G$12 -> LUNCH | H28: =+$H$12 -> DINNER | I28: JUMLAH
A29: 1 | B29: =+'TAHAP 1'!$C$13 -> 45525 | E29: =VLOOKUP($D$27,A12:$H$19,5,0) -> 40000 | F29: di Rumah | G29: =VLOOKUP($D$27,A12:$H$19,8,0) -> 27500 | H29: =VLOOKUP($D$27,A12:$H$19,8,0) -> 27500 | I29: =SUM(E29:H29) -> 95000
A30: 2 | B30: =+B29+1 -> 45526 | E30: =VLOOKUP($D$27,A$12:$H19,5,0) -> 40000 | F30: di Hotel | G30: di SAI | H30: =VLOOKUP($D$27,A$12:$H19,8,0) -> 27500 | I30: =SUM(E30:H30) -> 67500
A31: 3 | B31: =+B30+1 -> 45527 | E31: =VLOOKUP($D$27,A$12:$H19,5,0) -> 40000 | F31: di Hotel | G31: di JAI | H31: =VLOOKUP($D$27,A$12:$H19,8,0) -> 27500 | I31: =SUM(E31:H31) -> 67500
A32: TOTAL | I32: =SUM(I29:I31) -> 230000
B33: Rincian Golongan | C33: : | D33: III
A34: NO. | B34: TANGGAL | E34: =+$E$12 -> UANG SAKU | F34: =+$F$12 -> BREAKFAST | G34: =+$G$12 -> LUNCH | H34: =+$H$12 -> DINNER | I34: JUMLAH
A35: 1 | B35: =+'TAHAP 1'!$C$13 -> 45525 | E35: 35000 | F35: di Rumah | G35: 20000 | H35: 20000 | I35: =SUM(E35:H35) -> 75000
A36: 2 | B36: =+B35+1 -> 45526 | E36: 35000 | F36: di Hotel | G36: di SAI | H36: 20000 | I36: =SUM(E36:H36) -> 55000
A37: 3 | B37: =+B36+1 -> 45527 | E37: 35000 | F37: di Hotel | G37: di JAI | H37: 20000 | I37: =SUM(E37:H37) -> 55000
A38: TOTAL | I38: =SUM(I35:I37) -> 185000
A40: UPD
A41: NO. | B41: NAMA | F41: GOL | G41: UPD
A42: 1 | B42: ='TAHAP 1'!M13 -> BAMBANG RIANTO | F42: V | G42: =+I26 -> 270000
A43: 2 | B43: ='TAHAP 1'!M14 -> MAULVI BARUL MUHITH | F43: IV | G43: =+I32 -> 230000
A44: 3 | B44: ='TAHAP 1'!M15 -> AMALIA PUJI RAHAYUNINGSIH | F44: IV | G44: =+I32 -> 230000
...

Sheet TAHAP 2.1 (SPD)
W1: A
B2: PT. SEMARANG AUTOCOMP MANUFACTURING INDONESIA | K2: FORM/CHECKSHEET | L2: NO. DOKUMEN | N2: : 023/PGA/GA/FORM/SPDDN | R2: APPROVED II | S2: APPROVED I | T2: CHECKED | V2: PREPARED
B3: SURAT PERJALANAN DINAS DALAM NEGERI | L3: TANGGAL | N3: : 11-07-2023 | R3: APPROVED
L4: REVISI | N4: : 4
L5: HALAMAN | N5: : 1/2
L6: MASA BERLAKU | N6: : 10-07-2024 | R6: AWI | S6: FYH | T6: SMK | V6: Renny
B9: TUJUAN PERJALANAN DINAS | I9: =+'TAHAP 1'!G8 -> : SAI - JAI
B10: KEPENTINGAN | I10: =+'TAHAP 1'!G9 -> : BENCHMARK
B14: 1. PESERTA
B15: NO | C15: TANGGAL | G15: DEPT. / SECT. | I15: JABATAN | K15: NIK | M15: NAMA | P15: 1 | Q15: 2 | R15: 3 | S15: 4 | T15: 5
P16: YANG MENERIMA PERINTAH | Q16: SPV | R16: MGR | S16: FM / DFM | T16: PRESDIR
B19: 1 | C19: =+'TAHAP 1'!C13 -> 45525 | D19: s/d | F19: =+'TAHAP 1'!F13 -> 45527 | G19: =+'TAHAP 1'!G13:H13 -> FA | I19: =+'TAHAP 1'!I13:J13 -> GM | K19: =+'TAHAP 1'!K13:L13 -> 18663 | M19: =+'TAHAP 1'!M13 -> BAMBANG RIANTO | P19: BRI | Q19: - | R19: - | S19: - | T19: NKA | Y19: =+G19 -> FA | Z19: =+I19 -> GM | AA19: =+K19 -> 18663 | AB19: =+M19 -> BAMBANG RIANTO
B20: 2 | C20: =+'TAHAP 1'!C14 -> 45525 | D20: s/d | F20: =+'TAHAP 1'!F14 -> 45527 | G20: =+'TAHAP 1'!G14:H14 -> FA | I20: =+'TAHAP 1'!I14:J14 -> CSPV | K20: =+'TAHAP 1'!K14:L14 -> 8381 | M20: =+'TAHAP 1'!M14 -> MAULVI BARUL MUHITH | P20: MBM | Q20: - | R20: BRI | S20: MIS | Y20: =+G20 -> FA | Z20: =+I20 -> CSPV | AA20: =+K20 -> 8381 | AB20: =+M20 -> MAULVI BARUL MUHITH
B21: 1 | C21: =+'TAHAP 1'!C15 -> 45525 | D21: s/d | F21: =+'TAHAP 1'!F15 -> 45527 | G21: =+'TAHAP 1'!G15:H15 -> FA | I21: =+'TAHAP 1'!I15:J15 -> SPV | K21: =+'TAHAP 1'!K15:L15 -> 21229 | M21: =+'TAHAP 1'!M15 -> AMALIA PUJI RAHAYUNINGSIH | P21: APR | Q21: - | Y21: =+G21 -> FA | Z21: =+I21 -> SPV | AA21: =+K21 -> 21229 | AB21: =+M21 -> AMALIA PUJI RAHAYUNINGSIH
B22: 2 | C22: =+'TAHAP 1'!C16 -> 45525 | D22: s/d | F22: =+'TAHAP 1'!F16 -> 45527 | G22: =+'TAHAP 1'!G16:H16 -> FA | I22: =+'TAHAP 1'!I16:J16 -> ES | K22: =+'TAHAP 1'!K16:L16 -> 24995 | M22: =+'TAHAP 1'!M16 -> AYU INDRASARI SAPUTRI | P22: Ayu Indrasari S. | Q22: MRU | Y22: =+G22 -> FA | Z22: =+I22 -> ES | AA22: =+K22 -> 24995 | AB22: =+M22 -> AYU INDRASARI SAPUTRI
B28: 2. BIAYA PERJALANAN DINAS | L28: UPD | O28: TRANSPORTASI | S28: HOTEL
O29: BY : CAR | Q29: UANG CADANGAN | S29: =+'TAPAH 2.2 (Rincian)'!F84 -> Aston Sidoarjo City Hotel and Conference Center Jalan Kahuripan Raya Kav. 14 Sidoarjo, Kahuripan, Sidoarjo, 61252, Indonesia. CI/CO : 21 - 23 Aug (02 Malam) Deluxe : IDR 670.000/room/night include breakfast Executive : IDR 950.000/room/night include breakfast
O30: Car : BRI Driver : Operational | Q30: -
Q31: -
B35: NO | C35: NAMA | G35: NIK | H35: NO. REKENING | L35: PRICE | N35: PERIODE BUDGET | O35: ESTIMATED PRICE | P35: PERIODE BUDGET | Q35: ESTIMATED PRICE | R35: PERIODE BUDGET | S35: ESTIMATED PRICE | T35: PERIODE BUDGET
B36: =+'TAPAH 2.2 (Rincian)'!A42 -> 1 | C36: ='TAPAH 2.2 (Rincian)'!B42 -> BAMBANG RIANTO | G36: =+'TAHAP 1'!K13 -> 18663 | H36: 1420007122673 | L36: ='TAPAH 2.2 (Rincian)'!G42 -> 270000 | O36: =+'TAPAH 2.2 (Rincian)'!H77 -> 3500000 | Q36: 0 | S36: =+'TAPAH 2.2 (Rincian)'!H87 -> 1900000
B37: 2 | C37: ='TAPAH 2.2 (Rincian)'!B43 -> MAULVI BARUL MUHITH | G37: =+'TAHAP 1'!K14 -> 8381 | H37: 1360004976962 | L37: ='TAPAH 2.2 (Rincian)'!G43 -> 230000 | Q37: 0 | S37: =+'TAPAH 2.2 (Rincian)'!H88 -> 1340000
B38: 3 | C38: ='TAPAH 2.2 (Rincian)'!B44 -> AMALIA PUJI RAHAYUNINGSIH | G38: =+'TAHAP 1'!K15 -> 21229 | L38: ='TAPAH 2.2 (Rincian)'!G44 -> 230000 | Q38: 0 | S38: =+'TAPAH 2.2 (Rincian)'!H89 -> 1340000
B39: 4 | C39: ='TAPAH 2.2 (Rincian)'!B45 -> AYU INDRASARI SAPUTRI | G39: =+'TAHAP 1'!K16 -> 24995 | H39: 1360018024973 | L39: ='TAPAH 2.2 (Rincian)'!G45 -> 185000 | Q39: 0
B40: SUB TOTAL | L40: =SUM(L36:M39) -> 915000 | O40: =SUM(O36:O37) -> 3500000 | Q40: =SUM(Q36:Q37) -> 0 | S40: =SUM(S36:S39) -> 4580000
B41: TOTAL | L41: =SUM(L40:V40) -> 8995000
B44: NOTE : 1. Ket. Budget di isi bulan periode budget atau di tulis "additional" jika additional budget 2. Approval diproses oleh User 3. Approval pada form ini akan digunakan sebagai jaminan GA dalam melakukan proses issued ticket dan hotel sebelum user melakukan pembuatan PR (purchase requisition). 4. Pembuatan PR setelah proses issued bertujuan agar tidak terjadi selisih harga PR (purchase requisition) dengan actual. | T44: 6. MENGETAHUI MGR FA
T47: BRI
B56: PERLINDUNGAN HAK CIPTA! Dokumen ini adalah milik dan untuk dipergunakan di lingkungan kerja PT. SAMI . Tidak diperkenankan memindahkan, menyalin, atau menggandakan sebagian ataupun seluruhnya isi dokumen ini dalam bentuk dan dengan cara apapun, tanpa izin tertulis dari Wakil manajemen. | I56: Referensi Prosedur/WI/OS/IS/ : PGA-GA.PD.02 : Prosedur Perjalanan Dinas | M56: 4 | N56: Penggabungan approval perjalanan dinas | Q56: 45118 | R56: Renny
M57: 3 | N57: Update Tgl Masa Berlaku & Rev. No. Dok. | Q57: 44702 | R57: Renny
M58: 2 | N58: New Format | Q58: 44314 | R58: Renny | S58: 3 | T58: =+Q56 -> 45118 | W58: FYH
M59: 1 | N59: Add Actual UPD | Q59: 44147 | R59: Renny | S59: 2 | T59: 44702 | W59: WIN
M60: 0 | N60: New Release | Q60: 45113 | R60: LNA | S60: 1 | T60: 44314 | W60: FYH
M61: REV. | N61: ISI PERUBAHAN | Q61: TANGGAL | R61: PIC | S61: REVIEW | T61: TGL | W61: PIC
