Workbook

Sheet TAHAP 1
U1: A
B2: PT. SEMARANG AUTOCOMP MANUFACTURING INDONESIA | H2: FORM/CHECKSHEET | I2: NO. DOKUMEN | J2: : 083/PGA/GS/FORM/RPBPD | N2: APPROVED II | P2: APPROVED I | R2: CHECKED | T2: PREPARED
B3: REQUEST PERHITUNGAN BIAYA PERJALANAN DINAS | I3: REVISI | J3: : 0 | N3: APPROVED
I4: TANGGAL | J4: : 05-07-2023
I5: HALAMAN | J5: : 1
I6: MASA BERLAKU | J6: : 04-07-2024 | N6: AWI | P6: FYH | R6: SMK | T6: Renny
B8: TUJUAN PERJALANAN DINAS | G8: : SAI - JAI
B9: KEPENTINGAN | G9: : BENCHMARK
B11: 1. MEMBER YANG AKAN PERJALANAN DINAS
B12: NO | C12: TANGGAL | G12: DEPT. / SECT. | I12: JABATAN | K12: NIK | M12: NAMA
B13: 1 | C13: 45502 | D13: s/d | F13: 45504 | G13: NYS / JSN | I13: SPV | K13: 1170 | M13: PUDJI IDAYANI
B14: 2 | C14: =+C13 -> 45502 | D14: s/d | F14: =+F13 -> 45504 | G14: NYS / KBN | I14: LL | K14: 6113 | M14: GEDE WIJI SANTOSO
B15: 3 | C15: =C13 -> 45502 | D15: s/d | F15: =F13 -> 45504 | G15: PRD | I15: SPV | K15: 13645 | M15: WIDODO PRASETIO
B16: 4 | C16: =C13 -> 45502 | D16: s/d | F16: =F13 -> 45504 | G16: PRD | I16: SPV | K16: 121 | M16: SUSANTI
B18: 2. TRANSPORTASI
B19: 2.a Pesawat | K19: 2.b Kereta
B20: NO | C20: TANGGAL | E20: AIR PORT | H20: RANGE TIME | K20: NO | L20: TANGGAL | N20: STATION | R20: RANGE TIME
E21: DEPARTURE | G21: ARRIVAL | H21: DEPARTURE | I21: ARRIVAL | N21: DEPARTURE | P21: ARRIVAL | R21: DEPARTURE | T21: ARRIVAL
B22: 1 | K22: 1
B23: 2 | K23: 2
B25: 2.c Mobil / Hi Ace / Bus
B26: NO | C26: TANGGAL | G26: JENIS ARMADA | I26: JUMLAH KURSI (PENUMPANG) | J26: WAKTU KEBERANGKATAN | N26: REQUEST KHUSUS
J27: LOKASI | L27: JAM
B28: 1 | C28: =C13 -> 45502 | D28: s/d | F28: =F13 -> 45504 | G28: Hi Ace | J28: SAMI TF | N28: Hi Ace Dari SAMI-JF
B29: NOTE : Standar kelengkapan armada
B30: No | C30: Point | J30: Mobil | M30: Hi Ace | P30: BUS
B31: 1 | C31: Sabuk Pengaman | J31: ● | M31: ● | P31: ●
B32: 2 | C32: Ban Cadangan | J32: ● | M32: ● | P32: ●
B33: 3 | C33: Segitiga Pengaman (Minimal 2 buah, berwarna merah, dapat memantulkan cahaya) | J33: ● | M33: ● | P33: ●
B34: 4 | C34: Dongkrak | J34: ● | M34: ● | P34: ●
B35: 5 | C35: Pembuka Roda dan | J35: ● | M35: ● | P35: ●
B36: 6 | C36: Kotak P3K(Minimal berisi obat antiseptik, kain kassa, kapas, plester) | J36: ● | M36: ● | P36: ●
B37: 7 | C37: Apar | J37: ● (1x M1 berat 1 Kg) | M37: ● (2x M1 berat 1 Kg) | P37: ● (2x M1 berat 1 Kg)
B38: 8 | C38: Ganjal Ban (Wheel Block) | J38: x | M38: ● (Jika > 3,500 Kg) | P38: ● (Jika > 3,500 Kg)
B39: 9 | C39: Perisai Kolong Belakang | J39: x | M39: x | P39: x
B40: 10 | C40: Perisai Kolong Samping | J40: x | M40: x | P40: x
B41: 11 | C41: Alat Pemantul Cahaya | J41: x | M41: x | P41: x
B42: 12 | C42: Pemecah Kaca / Martil | J42: x | M42: x | P42: x
... B44: 14 | C44: Kernet | J44: x | M44: x | P44: x
B45: NOTE : Standar transportasi berdasarkan Prosedur Perjalanan Dinas (PGA-GA.PD.02)
...

Sheet TAPAH 2.2 (Rincian)
O1: A
A2: PT. SEMARANG AUTOCOMP MANUFACTURING INDONESIA - TUGU FACTORY | H2: FORM/CHECKSHEET | I2: NO. DOKUMEN | J2: : 023/PGA/GA/FORM/SPDDN | L2: APPROVED II | M2: APPROVED I | N2: CHECKED | O2: PREPARED
A3: SURAT PERJALANAN DINAS DALAM NEGERI | I3: TANGGAL | J3: : 11-07-2023 | L3: APPROVED
I4: REVISI | J4: : 4
I5: HALAMAN | J5: : 2 / 2
I6: MASA BERLAKU | J6: : 10-07-2024 | L6: AWI | M6: FYH | N6: SMK | O6: RENNY
A8: LAMPIRAN (Rincian) | E8: =+'TAHAP 1'!G9 -> : BENCHMARK
A10: 1. UPD
A11: NOTE : Standar UPD Dalam Negeri berdasarkan Prosedur Perjalanan Dinas (PGA-GA.PD.02)
A12: Golongan | E12: UANG SAKU | F12: BREAKFAST | G12: LUNCH | H12: DINNER
A13: I | E13: 30000 | F13: 12500 | G13: 20000 | H13: 20000
A14: II | E14: 30000 | F14: 12500 | G14: 20000 | H14: 20000
A15: III | E15: 35000 | F15: 12500 | G15: 20000 | H15: 20000
A16: IV | E16: 40000 | F16: 12500 | G16: 27500 | H16: 27500
A17: V | E17: 50000 | F17: 22500 | G17: 30000 | H17: 30000
A18: VI | E18: 60000 | F18: 22500 | G18: 50000 | H18: 50000
A19: VII | E19: 70000 | F19: 22500 | G19: 60000 | H19: 60000
B21: Rincian Golongan | C21: : | D21: IV
A22: NO. | B22: TANGGAL | E22: =+$E$12 -> UANG SAKU | F22: =+$F$12 -> BREAKFAST | G22: =+$G$12 -> LUNCH | H22: =+$H$12 -> DINNER | I22: JUMLAH
A23: 1 | B23: =+'TAHAP 1'!$C$13 -> 45502 | E23: =VLOOKUP($D$21,A12:$H$19,5,0) -> 40000 | F23: di Rumah | G23: =VLOOKUP($D$21,A12:$H$19,8,0) -> 27500 | H23: =VLOOKUP($D$21,A12:$H$19,8,0) -> 27500 | I23: =SUM(E23:H23) -> 95000
A24: 2 | B24: =+B23+1 -> 45503 | E24: =VLOOKUP($D$21,A13:$H$19,5,0) -> 40000 | F24: di Hotel | G24: di JAI | H24: =VLOOKUP($D$21,A13:$H$19,8,0) -> 27500 | I24: =SUM(E24:H24) -> 67500
A25: 3 | B25: =+B24+1 -> 45504 | E25: =VLOOKUP($D$21,A14:$H$19,5,0) -> 40000 | F25: di Hotel | G25: di JAI | H25: =VLOOKUP($D$21,A14:$H$19,8,0) -> 27500 | I25: =SUM(E25:H25) -> 67500
A26: TOTAL | I26: =SUM(I23:I25) -> 230000
B28: Rincian Golongan | C28: : | D28: II
A29: NO. | B29: TANGGAL | E29: =+$E$12 -> UANG SAKU | F29: =+$F$12 -> BREAKFAST | G29: =+$G$12 -> LUNCH | H29: =+$H$12 -> DINNER | I29: JUMLAH
A30: 1 | B30: =+'TAHAP 1'!$C$13 -> 45502 | E30: =VLOOKUP($D$28,A12:$H$19,5,0) -> 30000 | F30: di Rumah | G30: =VLOOKUP($D$28,A12:$H$19,8,0) -> 20000 | H30: =VLOOKUP($D$28,A12:$H$19,8,0) -> 20000 | I30: =SUM(E30:H30) -> 70000
A31: 2 | B31: =+B30+1 -> 45503 | E31: =VLOOKUP($D$28,A$12:$H19,5,0) -> 30000 | F31: di Hotel | G31: di JAI | H31: =VLOOKUP($D$28,A$12:$H19,8,0) -> 20000 | I31: =SUM(E31:H31) -> 50000
A32: 3 | B32: =+B31+1 -> 45504 | E32: =VLOOKUP($D$28,A$12:$H19,5,0) -> 30000 | F32: di Hotel | G32: di JAI | H32: =VLOOKUP($D$28,A$12:$H19,8,0) -> 20000 | I32: =SUM(E32:H32) -> 50000
A33: TOTAL | I33: =SUM(I30:I32) -> 170000
A34: UPD
A35: NO. | B35: NAMA | F35: GOL | G35: UPD
A36: 1 | B36: ='TAHAP 1'!M13 -> PUDJI IDAYANI | F36: =D21 -> IV | G36: =I26 -> 230000
A37: 2 | B37: ='TAHAP 1'!M14 -> GEDE WIJI SANTOSO | F37: II | G37: =I33 -> 170000
A38: 3 | B38: ='TAHAP 1'!M15 -> WIDODO PRASETIO | F38: IV | G38: =I26 -> 230000
A39: 4 | B39: ='TAHAP 1'!M16 -> SUSANTI | F39: IV | G39: =I26 -> 230000
A40: TOTAL | G40: =SUM(G36:G39) -> 860000
A42: 2. TRANSPORTASI (PIC Perjalanan Dinas tanda tangan pada kolom transportasi yang dipilih atau yang diajukan)
A44: 2.1 PESAWAT | B44: KERETA
A45: NO. | B45: KET. | D45: SCHEDULE | J45: PRICE | K45: QTY | L45: JUMLAH | M45: TOTAL
A46: 1 | B46: BERANGKAT
...

Sheet TAHAP 2.1 (SPD)
W1: A
B2: PT. SEMARANG AUTOCOMP MANUFACTURING INDONESIA | K2: FORM/CHECKSHEET | L2: NO. DOKUMEN | N2: : 023/PGA/GA/FORM/SPDDN | R2: APPROVED II | S2: APPROVED I | T2: CHECKED | V2: PREPARED
B3: SURAT PERJALANAN DINAS DALAM NEGERI | L3: TANGGAL | N3: : 11-07-2023 | R3: APPROVED
L4: REVISI | N4: : 4
L5: HALAMAN | N5: : 1/2
L6: MASA BERLAKU | N6: : 10-07-2024 | R6: AWI | S6: FYH | T6: SMK | V6: Renny
B9: TUJUAN PERJALANAN DINAS | I9: =+'TAHAP 1'!G8 -> : SAI - JAI
B10: KEPENTINGAN | I10: =+'TAHAP 1'!G9 -> : BENCHMARK
B14: 1. PESERTA
B15: NO | C15: TANGGAL | G15: DEPT. / SECT. | I15: JABATAN | K15: NIK | M15: NAMA | P15: 1 | Q15: 2 | R15: 3 | S15: 4 | T15: 5
P16: YANG MENERIMA PERINTAH | Q16: SPV | R16: MGR | S16: FM / DFM | T16: PRESDIR
B19: 1 | C19: =+'TAHAP 1'!C13 -> 45502 | D19: s/d | F19: =+'TAHAP 1'!F13 -> 45504 | G19: =+'TAHAP 1'!G13:H13 -> NYS / JSN | I19: =+'TAHAP 1'!I13:J13 -> SPV | K19: =+'TAHAP 1'!K13:L13 -> 1170 | M19: =+'TAHAP 1'!M13 -> PUDJI IDAYANI | P19: PIY | Q19: ASA | R19: PAN | S19: MIS | T19: NKA | Y19: =+G19 -> NYS / JSN | Z19: =+I19 -> SPV | AA19: =+K19 -> 1170 | AB19: =+M19 -> PUDJI IDAYANI
B20: 2 | C20: =+'TAHAP 1'!C14 -> 45502 | D20: s/d | F20: =+'TAHAP 1'!F14 -> 45504 | G20: =+'TAHAP 1'!G14:H14 -> NYS / KBN | I20: =+'TAHAP 1'!I14:J14 -> LL | K20: =+'TAHAP 1'!K14:L14 -> 6113 | M20: =+'TAHAP 1'!M14 -> GEDE WIJI SANTOSO | P20: GWS | Q20: PIY | Y20: =+G20 -> NYS / KBN | Z20: =+I20 -> LL | AA20: =+K20 -> 6113 | AB20: =+M20 -> GEDE WIJI SANTOSO
B21: 1 | C21: =+'TAHAP 1'!C15 -> 45502 | D21: s/d | F21: =+'TAHAP 1'!F15 -> 45504 | G21: =+'TAHAP 1'!G15:H15 -> PRD | I21: =+'TAHAP 1'!I15:J15 -> SPV | K21: =+'TAHAP 1'!K15:L15 -> 13645 | M21: =+'TAHAP 1'!M15 -> WIDODO PRASETIO | P21: WPR | Q21: JPU | R21: YSU | Y21: =+G21 -> PRD | Z21: =+I21 -> SPV | AA21: =+K21 -> 13645 | AB21: =+M21 -> WIDODO PRASETIO
B22: 2 | C22: =+'TAHAP 1'!C16 -> 45502 | D22: s/d | F22: =+'TAHAP 1'!F16 -> 45504 | G22: =+'TAHAP 1'!G16:H16 -> PRD | I22: =+'TAHAP 1'!I16:J16 -> SPV | K22: =+'TAHAP 1'!K16:L16 -> 121 | M22: =+'TAHAP 1'!M16 -> SUSANTI | P22: SUS | Q22: JPU | Y22: =+G22 -> PRD | Z22: =+I22 -> SPV | AA22: =+K22 -> 121 | AB22: =+M22 -> SUSANTI
B28: 2. BIAYA PERJALANAN DINAS | L28: UPD | O28: TRANSPORTASI | S28: HOTEL
O29: BY : KERETA | Q29: UANG CADANGAN | S29: =+'TAPAH 2.2 (Rincian)'!F77 -> ASTON Sidoarjo City Hotel & Conference Center Jl. Kahuripan Raya Kav. 14, Entalsewu, Kec Buduran, Kab Sidoarjo 61252 Sidoarjo Indonesia, Entalsewu, Surabaya
Q30: * Lokal Transport : 200.000/orang
Q31: * Laundry : 100.000/day
B35: NO | C35: NAMA | G35: NIK | H35: NO. REKENING | L35: PRICE | N35: PERIODE BUDGET | O35: ESTIMATED PRICE | P35: PERIODE BUDGET | Q35: ESTIMATED PRICE | R35: PERIODE BUDGET | S35: ESTIMATED PRICE | T35: PERIODE BUDGET
B36: =+'TAPAH 2.2 (Rincian)'!A36 -> 1 | C36: ='TAPAH 2.2 (Rincian)'!B36 -> PUDJI IDAYANI | G36: =+'TAHAP 1'!K13 -> 1170 | L36: ='TAPAH 2.2 (Rincian)'!G36 -> 230000 | O36: =+'TAPAH 2.2 (Rincian)'!J48 -> 0 | S36: =+'TAPAH 2.2 (Rincian)'!H81 -> 0
B37: 2 | C37: ='TAPAH 2.2 (Rincian)'!B37 -> GEDE WIJI SANTOSO | G37: =+'TAHAP 1'!K14 -> 6113 | L37: ='TAPAH 2.2 (Rincian)'!G37 -> 170000 | O37: =+'TAPAH 2.2 (Rincian)'!J48 -> 0 | S37: =+'TAPAH 2.2 (Rincian)'!H82 -> 0
B38: 3 | C38: ='TAPAH 2.2 (Rincian)'!B38 -> WIDODO PRASETIO | G38: =+'TAHAP 1'!K15 -> 13645 | L38: ='TAPAH 2.2 (Rincian)'!G38 -> 230000 | O38: =+'TAPAH 2.2 (Rincian)'!J50 -> 0 | S38: =+'TAPAH 2.2 (Rincian)'!H83 -> 0
B39: 4 | C39: ='TAPAH 2.2 (Rincian)'!B39 -> SUSANTI | G39: =+'TAHAP 1'!K16 -> 121 | L39: ='TAPAH 2.2 (Rincian)'!G39 -> 230000 | O39: =+'TAPAH 2.2 (Rincian)'!J50 -> 0 | S39: =+'TAPAH 2.2 (Rincian)'!H84 -> 0
B40: SUB TOTAL | L40: =SUM(L36:M39) -> 860000 | O40: =SUM(O36:O37) -> 0 | Q40: =SUM(Q36:Q37) -> 0 | S40: =SUM(S36:S37) -> 0
B41: TOTAL | L41: =SUM(L40:V40) -> 860000
B44: NOTE : 1. Ket. Budget di isi bulan periode budget atau di tulis "additional" jika additional budget 2. Approval diproses oleh User 3. Approval pada form ini akan digunakan sebagai jaminan GA dalam melakukan proses issued ticket dan hotel sebelum user melakukan pembuatan PR (purchase requisition). 4. Pembuatan PR setelah proses issued bertujuan agar tidak terjadi selisih harga PR (purchase requisition) dengan actual. | T44: 6. MENGETAHUI MGR FA
T47: BRI
B56: PERLINDUNGAN HAK CIPTA! Dokumen ini adalah milik dan untuk dipergunakan di lingkungan kerja PT. SAMI . Tidak diperkenankan memindahkan, menyalin, atau menggandakan sebagian ataupun seluruhnya isi dokumen ini dalam bentuk dan dengan cara apapun, tanpa izin tertulis dari Wakil manajemen. | I56: Referensi Prosedur/WI/OS/IS/ : PGA-GA.PD.02 : Prosedur Perjalanan Dinas | M56: 4 | N56: Penggabungan approval perjalanan dinas | Q56: 45118 | R56: Renny
M57: 3 | N57: Update Tgl Masa Berlaku & Rev. No. Dok. | Q57: 44702 | R57: Renny
M58: 2 | N58: New Format | Q58: 44314 | R58: Renny | S58: 3 | T58: =+Q56 -> 45118 | W58: FYH
M59: 1 | N59: Add Actual UPD | Q59: 44147 | R59: Renny | S59: 2 | T59: 44702 | W59: WIN
M60: 0 | N60: New Release | Q60: 45113 | R60: LNA | S60: 1 | T60: 44314 | W60: FYH
M61: REV. | N61: ISI PERUBAHAN | Q61: TANGGAL | R61: PIC | S61: REVIEW | T61: TGL | W61: PIC

Sheet Sheet1
B3: NO | C3: NAMA | D3: JABATAN
B4: 1 | C4: ABDUL KARIS | D4: CSPV
B5: 2 | C5: AGUS FREDDY KURNIAWAN | D5: SPV
B7: NO | C7: DATE | D7: TUJUAN | E7: HOTEL | F7: PENGATURAN PENJEMPUTAN
B8: 1 | C8: 45410 | D8: ARGO BROMO ANGGREK 4, SMT (01:22) - SBI (04:35) | E8: ASTON SIDOARJO | F8: JAI
B9: 2 | C9: 45411 | D9: JAI
B10: 3 | C10: 45412 | D10: JAI
B11: 4 | C11: 45413 | D11: -
B12: 5 | C12: 45414 | D12: SAI | F12: SAI
B13: 6 | C13: 45415 | D13: HARINA 125, SBI (18:10) - SMT (22:06)
