Workbook
Name __VF2: #REF!
Name _1Excel_BuiltIn_Print_Titles_1_1: '[3]SA-1.1'!#REF!
Name _26_1生_CROSS_クエリー1: #REF!
Name _28_出庫リスト_クエリー: #REF!
Name _pp2_313_クエリー: #REF!
Name _Q: [7]_MISSION!$T$1:$BI$245
Name _生新規部品ﾘｽﾄ_クエリー: #REF!
Name a: #REF!
Name A_K1出庫リスト: #REF!
Name A7_UPL: #REF!
Name ASSET_TYPE: [11]System!$A$32:$A$34
Name B9_: #N/A
Name CETAKUNITKERJA_5: "'file:///D:/DATA-E/My Dokuments/Dept Prod C/Manpower/DATABASE local/DAFTAR UNIT KERJA PROD DOMESTIC REV.xls'#$DETAIL.$#REF!$#REF!"
Name CONCEPT: [11]System!$A$255:$A$256
Name COST_DEPT_CLS_CD: [11]System!$A$20:$A$25
Name D: [13]外注計算!$E$5
Name D10_: #N/A
Name D2_: #REF!
Name D2_: #REF!
Name D9_: #N/A
Name DASARDATABASE_12: "$'Meninggalkan Pekerjaan'.$#REF!$#REF!:$#REF!$#REF!"
Name DASARNAMABASE: "$#REF!.$B$10:$F$3608"
Name DASARNAMABASE_10: "$#REF!.$B$10:$F$3608"
Name DASARNIKBASE: "$#REF!.$C$10:$F$3608"
Name DASARNIKBASE_10: "$#REF!.$C$10:$F$3608"
Name data: "$#REF!.$A$10:$AB$3608"
Name data_10: "$#REF!.$A$10:$AB$3608"
Name DEHRFH: #REF!
Name DISP_LANG_CANDIDATE: [11]System!$C$42:$C$44
Name DROPDOWNLIST: [11]System!$A$218:$A$252
Name E: #N/A
Name ECRN2: [15]メーカー検索!#REF!
Name Entity: [16]LIST!$A$4:$A$38
Name Excel_BuiltIn__FilterDatabase_1: #REF!
Name Excel_BuiltIn__FilterDatabase_1_1: #REF!
Name Excel_BuiltIn__FilterDatabase_12_1: "$'Meninggalkan Pekerjaan'.$#REF!$#REF!:$#REF!$#REF!"
Name Excel_BuiltIn_Criteria_12_1: "$'Meninggalkan Pekerjaan'.$#REF!$#REF!:$#REF!$#REF!"
Name Excel_BuiltIn_Extract_12: "$'Meninggalkan Pekerjaan'.$#REF!$#REF!:$#REF!$#REF!"
Name Excel_BuiltIn_Print_Area_2: #REF!
Name Excel_BuiltIn_Print_Area_2_1: #REF!
Name Excel_BuiltIn_Print_Titles_1: #REF!
Name EXPDOM_DEST_CARMKR: [11]System!$A$184:$A$213
Name FIX_VAR_CD: [11]System!$A$28:$A$29
Name G_LEADER: "$#REF!.$B$67:$AB$263"
Name G_LEADER_10: "$#REF!.$B$67:$AB$263"
Name GHJ: #REF!
Name HFM_RCR027: [11]System!$C$52
Name HFM_RCR028: [11]System!$C$53
Name HFM_RCR029: [11]System!$C$54
Name HFM_RCR030: [11]System!$C$55
Name HFM_RCR035: [11]System!$C$56
Name HFM_RCR037: [11]System!$C$57
Name HFM_RCR038: [11]System!$C$58
Name HFM_RCR039: [11]System!$C$59
Name HFM_RCR040: [11]System!$C$60
Name HFM_RCR041: [11]System!$C$61
Name HFM_RCR042: [11]System!$C$62
Name HFM_RCR043: [11]System!$C$63
Name HFM_RPL025: [11]System!$C$124
Name HFM_RPL026: [11]System!$C$125

Sheet MAR'24 (SUAI DES ke APR)
B2: PT. Semarang Autocomp Manufacturing Indonesia
B3: 8D ANALYSIS FOR ADDITIONAL EXPENSE | M3: APPROVED | O3: CHECKED | Q3: PREPARED
B7: No Add | C7: : PP-PP-ADD-2404-002 | M7: SKI | O7: ANS | Q7: WHY
B8: Period | C8: : 202404 | M8: MANAGER | O8: ASS. MANAGER | Q8: COORD. SPV
B10: Problem Description | D10: Containment Action | G10: PIC & DD | H10: Root Cause | J10: Corrective Action | M10: PIC & DD | N10: Prevention | Q10: PIC & DD | R10: Status
B11: Pelaksanaan PD ke SUAI mundur dari Des'23 menjadi Apr'24 | D11: Pengajuan add budget (change periode) dari bulan Des'23 menjadi Apr'24 | G11: WHY (16-Apr-24) | H11: Karena PD ke JAI mundur di bulan Des'23 maka bersamaan dengan plan PD ke SUAI, sehinggan PD ke SUAI mundur di Apr'24 | J11: Membuat add budget (change periode) dari bulan Des'23 menjadi Apr'24 | M11: WHY (16-Apr-24) | N11: Control perjalanan dinas benchmark untuk term selanjutnya | Q11: WHY (16-Apr-24) | R11: OK
B18: Noted :
B19: Apabila dalam 1 departement terdapat manager local dan Jepang, maka :
B20: manager local tanda tangan di Checked, sedangkan manager Jepang tanda tangan di Approved

Sheet Souvenir

Sheet TAHAP 1
U1: A
B2: PT. SEMARANG AUTOCOMP MANUFACTURING INDONESIA | H2: FORM/CHECKSHEET | I2: NO. DOKUMEN | J2: : 083/PGA/GS/FORM/RPBPD | N2: APPROVED II | P2: APPROVED I | R2: CHECKED | T2: PREPARED
B3: REQUEST PERHITUNGAN BIAYA PERJALANAN DINAS | I3: REVISI | J3: : 0 | N3: APPROVED
I4: TANGGAL | J4: : 05-07-2023
I5: HALAMAN | J5: : 1
I6: MASA BERLAKU | J6: : 04-07-2024 | N6: AWI | P6: FYH | R6: SMK | T6: Renny
B8: TUJUAN PERJALANAN DINAS | G8: : SUAI
B9: KEPENTINGAN | G9: : Benchmark PP Activity dan Obeya
B11: 1. MEMBER YANG AKAN PERJALANAN DINAS
B12: NO | C12: TANGGAL | G12: DEPT. / SECT. | I12: JABATAN | K12: NIK | M12: NAMA
B13: 1 | C13: 45411 | D13: s/d | F13: 45412 | G13: PP | I13: SM | K13: 26848 | M13: SINICHI KISHIMOTO
B14: 2 | C14: =+C13 -> 45411 | D14: s/d | F14: =+F13 -> 45412 | G14: PP | I14: Ass. MGR | K14: 3640 | M14: AGUS NANANG SETIAWAN
B15: 3 | C15: =+C14 -> 45411 | D15: s/d | F15: =+F14 -> 45412 | G15: PP | I15: SPV | K15: 7091 | M15: M. HUSNUL MUBAROK
B16: 4 | C16: =+C15 -> 45411 | D16: s/d | F16: =+F15 -> 45412 | G16: PP | I16: OPT | K16: 25998 | M16: ELFIRA LUTFIA W.
B18: 2. TRANSPORTASI
B19: 2.a Pesawat | K19: 2.b Kereta
B20: NO | C20: TANGGAL | E20: AIR PORT | H20: RANGE TIME | K20: NO | L20: TANGGAL | N20: STATION | R20: RANGE TIME
E21: DEPARTURE | G21: ARRIVAL | H21: DEPARTURE | I21: ARRIVAL | N21: DEPARTURE | P21: ARRIVAL | R21: DEPARTURE | T21: ARRIVAL
B22: 1 | K22: 1
B23: 2 | K23: 2
B25: 2.c Mobil / Hi Ace / Bus
B26: NO | C26: TANGGAL | G26: JENIS ARMADA | I26: JUMLAH KURSI (PENUMPANG) | J26: WAKTU KEBERANGKATAN | N26: REQUEST KHUSUS
J27: LOKASI | L27: JAM
B28: 1 | C28: =C13 -> 45411 | D28: s/d | F28: =F13 -> 45412 | G28: INNOVA | I28: NORMAL | J28: SAMI | L28: 0.3125 | N28: -
B29: NOTE : Standar kelengkapan armada
B30: No | C30: Point | J30: Mobil | M30: Hi Ace | P30: BUS
B31: 1 | C31: Sabuk Pengaman | J31: ● | M31: ● | P31: ●
B32: 2 | C32: Ban Cadangan | J32: ● | M32: ● | P32: ●
B33: 3 | C33: Segitiga Pengaman (Minimal 2 buah, berwarna merah, dapat memantulkan cahaya) | J33: ● | M33: ● | P33: ●
B34: 4 | C34: Dongkrak | J34: ● | M34: ● | P34: ●
B35: 5 | C35: Pembuka Roda dan | J35: ● | M35: ● | P35: ●
B36: 6 | C36: Kotak P3K(Minimal berisi obat antiseptik, kain kassa, kapas, plester) | J36: ● | M36: ● | P36: ●
B37: 7 | C37: Apar | J37: ● (1x M1 berat 1 Kg) | M37: ● (2x M1 berat 1 Kg) | P37: ● (2x M1 berat 1 Kg)
B38: 8 | C38: Ganjal Ban (Wheel Block) | J38: x | M38: ● (Jika > 3,500 Kg) | P38: ● (Jika > 3,500 Kg)
B39: 9 | C39: Perisai Kolong Belakang | J39: x | M39: x | P39: x
B40: 10 | C40: Perisai Kolong Samping | J40: x | M40: x | P40: x
B41: 11 | C41: Alat Pemantul Cahaya | J41: x | M41: x | P41: x
B42: 12 | C42: Pemecah Kaca / Martil | J42: x | M42: x | P42: x
... B44: 14 | C44: Kernet | J44: x | M44: x | P44: x
B45: NOTE : Standar transportasi berdasarkan Prosedur Perjalanan Dinas (PGA-GA.PD.02)
...

Sheet TAPAH 2.2 (Rincian)
P1: A
B2: PT. SEMARANG AUTOCOMP MANUFACTURING INDONESIA - TUGU FACTORY | I2: FORM/CHECKSHEET | J2: NO. DOKUMEN | K2: : 023/PGA/GA/FORM/SPDDN | M2: APPROVED II | N2: APPROVED I | O2: CHECKED | P2: PREPARED
B3: SURAT PERJALANAN DINAS DALAM NEGERI | J3: TANGGAL | K3: : 11-07-2023 | M3: APPROVED
J4: REVISI | K4: : 4
J5: HALAMAN | K5: : 2 / 2
J6: MASA BERLAKU | K6: : 10-07-2024 | M6: AWI | N6: FYH | O6: SMK | P6: RENNY
B8: LAMPIRAN (Rincian) | F8: =+'TAHAP 1'!G9 -> : Benchmark PP Activity dan Obeya
B10: 1. UPD
B11: NOTE : Standar UPD Dalam Negeri berdasarkan Prosedur Perjalanan Dinas (PGA-GA.PD.02)
B12: Golongan | F12: UANG SAKU | G12: BREAKFAST | H12: LUNCH | I12: DINNER
B13: I | F13: 30000 | G13: 12500 | H13: 20000 | I13: 20000
B14: II | F14: 30000 | G14: 12500 | H14: 20000 | I14: 20000
B15: III | F15: 35000 | G15: 12500 | H15: 20000 | I15: 20000
B16: IV | F16: 40000 | G16: 12500 | H16: 27500 | I16: 27500
B17: V | F17: 50000 | G17: 22500 | H17: 30000 | I17: 30000
B18: VI | F18: 60000 | G18: 22500 | H18: 50000 | I18: 50000
B19: VII | F19: 70000 | G19: 22500 | H19: 60000 | I19: 60000
C21: Rincian Golongan | D21: : | E21: I
B22: NO. | C22: TANGGAL | F22: =+$F$12 -> UANG SAKU | G22: =+$G$12 -> BREAKFAST | H22: =+$H$12 -> LUNCH | I22: =+$I$12 -> DINNER | J22: JUMLAH
B23: 1 | C23: =+'TAHAP 1'!$C$13 -> 45411 | F23: 30000 | G23: di Rumah | H23: 20000 | I23: 20000 | J23: =SUM(F23:I23) -> 70000
B24: 2 | C24: =+C23+1 -> 45412 | F24: 30000 | G24: di Hotel | H24: di SUAI | I24: 20000 | J24: =SUM(F24:I24) -> 50000
B25: TOTAL | G25: =SUM(G23:I24) -> 60000 | J25: =SUM(J23:J24) -> 120000
C27: Rincian Golongan | D27: : | E27: IV
B28: NO. | C28: TANGGAL | F28: =+$F$12 -> UANG SAKU | G28: =+$G$12 -> BREAKFAST | H28: =+$H$12 -> LUNCH | I28: =+$I$12 -> DINNER | J28: JUMLAH
B29: 1 | C29: =+'TAHAP 1'!$C$13 -> 45411 | F29: =VLOOKUP($E$27,B12:$I$19,5,0) -> 40000 | G29: di Rumah | H29: 27500 | I29: =VLOOKUP($E$27,B12:$I$19,8,0) -> 27500 | J29: =SUM(F29:I29) -> 95000
B30: 2 | C30: =+C29+1 -> 45412 | F30: =VLOOKUP($E$27,B13:$I$19,5,0) -> 40000 | G30: di Hotel | H30: di SUAI | I30: =VLOOKUP($E$27,B13:$I$19,8,0) -> 27500 | J30: =SUM(F30:I30) -> 67500
B31: TOTAL | G31: =SUM(G29:I30) -> 82500 | J31: =SUM(J29:J30) -> 162500
C33: Rincian Golongan | D33: : | E33: V
B34: NO. | C34: TANGGAL | F34: =+$F$12 -> UANG SAKU | G34: =+$G$12 -> BREAKFAST | H34: =+$H$12 -> LUNCH | I34: =+$I$12 -> DINNER | J34: JUMLAH
B35: 1 | C35: =+'TAHAP 1'!$C$13 -> 45411 | F35: 50000 | G35: di Rumah | H35: 30000 | I35: 30000 | J35: =SUM(F35:I35) -> 110000
B36: 2 | C36: =+C35+1 -> 45412 | F36: 50000 | G36: di Hotel | H36: di SUAI | I36: 30000 | J36: =SUM(F36:I36) -> 80000
B37: TOTAL | G37: =SUM(G35:I36) -> 90000 | J37: =SUM(J35:J36) -> 190000
B39: UPD
B40: NO. | C40: NAMA | G40: GOL | H40: UPD
B41: 1 | C41: =+'TAHAP 1'!M13 -> SINICHI KISHIMOTO | G41: V | H41: =+J37 -> 190000
B42: 2 | C42: =+'TAHAP 1'!M14 -> AGUS NANANG SETIAWAN | G42: IV | H42: =+J31 -> 162500
B43: 3 | C43: =+'TAHAP 1'!M15 -> M. HUSNUL MUBAROK | G43: IV | H43: =+J31 -> 162500
B44: 4 | C44: =+'TAHAP 1'!M16 -> ELFIRA LUTFIA W. | G44: I | H44: =+J25 -> 120000
B45: TOTAL | H45: =SUM(H41:H44) -> 635000
B47: 2. TRANSPORTASI (PIC Perjalanan Dinas tanda tangan pada kolom transportasi yang dipilih atau yang diajukan)
...

Sheet TAHAP 2.1 (SPD)
W1: A
B2: PT. SEMARANG AUTOCOMP MANUFACTURING INDONESIA | K2: FORM/CHECKSHEET | L2: NO. DOKUMEN | N2: : 023/PGA/GA/FORM/SPDDN | R2: APPROVED II | S2: APPROVED I | T2: CHECKED | V2: PREPARED
B3: SURAT PERJALANAN DINAS DALAM NEGERI | L3: TANGGAL | N3: : 11-07-2023 | R3: APPROVED
L4: REVISI | N4: : 4
L5: HALAMAN | N5: : 1/2
L6: MASA BERLAKU | N6: : 10-07-2024 | R6: AWI | S6: FYH | T6: SMK | V6: Renny
B9: TUJUAN PERJALANAN DINAS | I9: =+'TAHAP 1'!G8 -> : SUAI
B10: KEPENTINGAN | I10: =+'TAHAP 1'!G9 -> : Benchmark PP Activity dan Obeya
B14: 1. PESERTA
B15: NO | C15: TANGGAL | G15: DEPT. / SECT. | I15: JABATAN | K15: NIK | M15: NAMA | P15: 1 | Q15: 2 | R15: 3 | S15: 4 | T15: 5
P16: YANG MENERIMA PERINTAH | Q16: SPV | R16: MGR | S16: FM / DFM | T16: PRESDIR
B19: 1 | C19: =+'TAHAP 1'!C13 -> 45411 | D19: s/d | F19: =+'TAHAP 1'!F13 -> 45412 | G19: =+'TAHAP 1'!G13:H13 -> PP | I19: =+'TAHAP 1'!I13:J13 -> SM | K19: 25252 | M19: =+'TAHAP 1'!M13 -> SINICHI KISHIMOTO | P19: SKI | Q19: - | R19: - | S19: MIS / TMI | T19: NKA | Y19: =+G19 -> PP | Z19: =+I19 -> SM | AA19: =+K19 -> 25252 | AB19: =+M19 -> SINICHI KISHIMOTO
B20: 2 | C20: =+'TAHAP 1'!C14 -> 45411 | D20: s/d | F20: =+'TAHAP 1'!F14 -> 45412 | G20: =+'TAHAP 1'!G14:H14 -> PP | I20: =+'TAHAP 1'!I14:J14 -> Ass. MGR | K20: 25252 | M20: =+'TAHAP 1'!M14 -> AGUS NANANG SETIAWAN | P20: ANS
B21: 3 | C21: =+'TAHAP 1'!C15 -> 45411 | D21: s/d | F21: =+'TAHAP 1'!F15 -> 45412 | G21: =+'TAHAP 1'!G15:H15 -> PP | I21: =+'TAHAP 1'!I15:J15 -> SPV | K21: 25252 | M21: =+'TAHAP 1'!M15 -> M. HUSNUL MUBAROK | P21: MHM | R21: ANS
B22: 4 | C22: =+'TAHAP 1'!C16 -> 45411 | D22: s/d | F22: =+'TAHAP 1'!F16 -> 45412 | G22: =+'TAHAP 1'!G16:H16 -> PP | I22: =+'TAHAP 1'!I16:J16 -> OPT | K22: 25252 | M22: =+'TAHAP 1'!M16 -> ELFIRA LUTFIA W. | P22: ELFIRA | Q22: WHY | Y22: =+G22 -> PP | Z22: =+I22 -> OPT | AA22: =+K22 -> 25252 | AB22: =+M22 -> ELFIRA LUTFIA W.
B28: 2. BIAYA PERJALANAN DINAS | L28: UPD | O28: TRANSPORTASI | S28: HOTEL
O29: BY : MOBIL / LOCAL TRANSPORT | Q29: UANG CADANGAN | S29: =+'TAPAH 2.2 (Rincian)'!G80 -> HARPER PURWAKARTA BY ASTON Jl. Raya Bungursari No. 122, Bungursari, Purwakarta, 41181, Indonesia.
B34: NO | C34: NAMA | G34: NIK | H34: NO. REKENING | L34: PRICE | N34: PERIODE BUDGET | O34: ESTIMATED PRICE | P34: PERIODE BUDGET | Q34: ESTIMATED PRICE | R34: PERIODE BUDGET | S34: ESTIMATED PRICE | T34: PERIODE BUDGET
B35: =+'TAPAH 2.2 (Rincian)'!B41 -> 1 | C35: =+'TAPAH 2.2 (Rincian)'!C41:F41 -> SINICHI KISHIMOTO | G35: =+'TAHAP 1'!K13 -> 26848 | L35: =+'TAPAH 2.2 (Rincian)'!H41 -> 190000 | N35: 202404 | O35: =+'TAPAH 2.2 (Rincian)'!I74 -> 5250000 | P35: 202404 | Q35: 0 | R35: - | S35: =+'TAPAH 2.2 (Rincian)'!I82 -> 698000 | T35: 202404
B36: =+'TAPAH 2.2 (Rincian)'!B42 -> 2 | C36: =+'TAPAH 2.2 (Rincian)'!C42:F42 -> AGUS NANANG SETIAWAN | G36: =+'TAHAP 1'!K14 -> 3640 | H36: 1360004516321 | L36: =+'TAPAH 2.2 (Rincian)'!H42 -> 162500 | N36: 202404 | P36: 202404 | Q36: 0 | R36: - | S36: =+'TAPAH 2.2 (Rincian)'!I83 -> 698000 | T36: 202404
B37: =+'TAPAH 2.2 (Rincian)'!B43 -> 3 | C37: =+'TAPAH 2.2 (Rincian)'!C43:F43 -> M. HUSNUL MUBAROK | G37: =+'TAHAP 1'!K15 -> 7091 | H37: 1360004574106 | L37: =+'TAPAH 2.2 (Rincian)'!H43 -> 162500 | N37: 202404 | P37: 202404 | Q37: 0 | R37: - | S37: =+'TAPAH 2.2 (Rincian)'!I84 -> 698000 | T37: 202404
B38: =+'TAPAH 2.2 (Rincian)'!B44 -> 4 | C38: =+'TAPAH 2.2 (Rincian)'!C44:F44 -> ELFIRA LUTFIA W. | G38: =+'TAHAP 1'!K16 -> 25998 | L38: =+'TAPAH 2.2 (Rincian)'!H44 -> 120000 | N38: 202404 | P38: 202404 | Q38: 0 | R38: - | S38: =+'TAPAH 2.2 (Rincian)'!I85 -> 698000 | T38: 202404
B39: SUB TOTAL | L39: =SUM(L35:M38) -> 635000 | O39: =SUM(O35:O38) -> 5250000 | Q39: =SUM(Q35:Q38) -> 0 | S39: =SUM(S35:S38) -> 2792000
B40: TOTAL | L40: =SUM(L39:V39) -> 8677000
B43: NOTE : 1. Ket. Budget di isi bulan periode budget atau di tulis "additional" jika additional budget 2. Approval diproses oleh User 3. Approval pada form ini akan digunakan sebagai jaminan GA dalam melakukan proses issued ticket dan hotel sebelum user melakukan pembuatan PR (purchase requisition). 4. Pembuatan PR setelah proses issued bertujuan agar tidak terjadi selisih harga PR (purchase requisition) dengan actual. | T43: 6. MENGETAHUI MGR FA
T46: BRI
B55: PERLINDUNGAN HAK CIPTA! Dokumen ini adalah milik dan untuk dipergunakan di lingkungan kerja PT. SAMI . Tidak diperkenankan memindahkan, menyalin, atau menggandakan sebagian ataupun seluruhnya isi dokumen ini dalam bentuk dan dengan cara apapun, tanpa izin tertulis dari Wakil manajemen. | I55: Referensi Prosedur/WI/OS/IS/ : PGA-GA.PD.02 : Prosedur Perjalanan Dinas | M55: 4 | N55: Penggabungan approval perjalanan dinas | Q55: 45118 | R55: Renny
M56: 3 | N56: Update Tgl Masa Berlaku & Rev. No. Dok. | Q56: 44702 | R56: Renny
M57: 2 | N57: New Format | Q57: 44314 | R57: Renny | S57: 3 | T57: =+Q55 -> 45118 | W57: FYH
M58: 1 | N58: Add Actual UPD | Q58: 44147 | R58: Renny | S58: 2 | T58: 44702 | W58: WIN
M59: 0 | N59: New Release | Q59: 45113 | R59: LNA | S59: 1 | T59: 44314 | W59: FYH
M60: REV. | N60: ISI PERUBAHAN | Q60: TANGGAL | R60: PIC | S60: REVIEW | T60: TGL | W60: PIC
F67: 200000
F69: 900000
F70: 100000 | G70: 2
