Workbook

Sheet TAHAP 1
U1: A
B2: PT. SEMARANG AUTOCOMP MANUFACTURING INDONESIA | H2: FORM/CHECKSHEET | I2: NO. DOKUMEN | J2: : 083/PGA/GS/FORM/RPBPD | N2: APPROVED II | P2: APPROVED I | R2: CHECKED | T2: PREPARED
B3: FORM REQUEST PERHITUNGAN BIAYA PERJALANAN DINAS | I3: REVISI | J3: : 1 | N3: APPROVED
I4: TANGGAL | J4: : 15-10-2024
B5: (form ini digunakan GA sebagai acuan perhitungan biaya perjalanan dinas) | I5: HALAMAN | J5: : 1
I6: MASA BERLAKU | J6: : 14-10-2025 | N6: AWI | P6: FYH | R6: SMK | T6: Renny
B8: TUJUAN PERJALANAN DINAS | G8: : (JIE) Jl. BENYAMIN SUEB, PADEMANGAN TIM, KEC. PADEMANGAN, JAKARTA UTARA
B9: KEPENTINGAN | G9: : PAMERAN TEKNOLOGI INDUSTRI
B11: 1. MEMBER YANG AKAN PERJALANAN DINAS
B12: NO | C12: TANGGAL | G12: DEPT. / SECT. | I12: JABATAN | K12: NIK | M12: NAMA
B13: 1 | C13: 45630 | D13: s/d | F13: 45632 | G13: PE | I13: SPV | K13: 284 | M13: PUDJI SRI SAPUTRI
B14: 2 | C14: =+C13 -> 45630 | D14: s/d | F14: =+F13 -> 45632 | G14: QA | I14: SPV | K14: 12027 | M14: AGIL ZHEGA PRASETYA
B15: 3 | C15: =+C14 -> 45630 | D15: s/d | F15: =+F14 -> 45632 | G15: QA | I15: SPV | K15: 7094 | M15: MUNHAMIR
B16: 4 | C16: =+C15 -> 45630 | D16: s/d | F16: =+F15 -> 45632 | G16: NYS | I16: SPV | K16: 13647 | M16: ADITYA FAHRIZAL
B17: 5 | C17: =+C13 -> 45630 | D17: s/d | F17: =+F13 -> 45632 | G17: PRD | I17: LL | K17: 5550 | M17: SUPRIYANTO
B19: 2. TRANSPORTASI
B20: 2.a Pesawat | K20: 2.b Kereta
B21: NO | C21: TANGGAL | E21: AIR PORT | H21: RANGE TIME | K21: NO | L21: TANGGAL | N21: STATION | R21: RANGE TIME
E22: DEPARTURE | G22: ARRIVAL | H22: DEPARTURE | I22: ARRIVAL | N22: DEPARTURE | P22: ARRIVAL | R22: DEPARTURE | T22: ARRIVAL
B23: 1 | K23: 1
B24: 2 | K24: 2
B26: 2.c Mobil / Hi Ace / Bus
B27: NO | C27: TANGGAL | G27: JENIS ARMADA | I27: JUMLAH KURSI (PENUMPANG) | J27: WAKTU KEBERANGKATAN | N27: REQUEST KHUSUS
J28: LOKASI | L28: JAM
B29: 1 | C29: 45630 | D29: s/d | F29: 45632 | G29: HI ACE | J29: SAMI | M29: 0.33333333
B30: 2 | C30: 45630 | D30: s/d | F30: 45632 | G30: INNOVA REBORN | J30: SAMI | M30: 0.33333333
B31: NOTE : Standar kelengkapan armada
B32: No | C32: Point | J32: Mobil | M32: Hi Ace | P32: BUS
B33: 1 | C33: Sabuk Pengaman | J33: ● | M33: ● | P33: ●
B34: 2 | C34: Ban Cadangan | J34: ● | M34: ● | P34: ●
B35: 3 | C35: Segitiga Pengaman (Minimal 2 buah, berwarna merah, dapat memantulkan cahaya) | J35: ● | M35: ● | P35: ●
B36: 4 | C36: Dongkrak | J36: ● | M36: ● | P36: ●
B37: 5 | C37: Pembuka Roda dan | J37: ● | M37: ● | P37: ●
B38: 6 | C38: Kotak P3K(Minimal berisi obat antiseptik, kain kassa, kapas, plester) | J38: ● | M38: ● | P38: ●
B39: 7 | C39: Apar | J39: ● (1x M1 berat 1 Kg) | M39: ● (2x M1 berat 1 Kg) | P39: ● (2x M1 berat 1 Kg)
B40: 8 | C40: Ganjal Ban (Wheel Block) | J40: x | M40: ● (Jika > 3,500 Kg) | P40: ● (Jika > 3,500 Kg)
B41: 9 | C41: Perisai Kolong Belakang | J41: x | M41: x | P41: x
B42: 10 | C42: Perisai Kolong Samping | J42: x | M42: x | P42: x
B43: 11 | C43: Alat Pemantul Cahaya | J43: x | M43: x | P43: x
B44: 12 | C44: Pemecah Kaca / Martil | J44: x | M44: x | P44: x
...

Sheet TAHAP 2.2 (Rincian)
Q1: A
B2: PT. SEMARANG AUTOCOMP MANUFACTURING INDONESIA - TUGU FACTORY | I2: FORM/CHECKSHEET | J2: NO. DOKUMEN | K2: : 023/PGA/GA/FORM/SPDDN | M2: APPROVED II | N2: APPROVED I | O2: CHECKED | P2: PREPARED
B3: SURAT PERJALANAN DINAS DALAM NEGERI | J3: TANGGAL | K3: : 11-07-2023 | M3: APPROVED
J4: REVISI | K4: : 4
J5: HALAMAN | K5: : 2 / 2
J6: MASA BERLAKU | K6: : 10-07-2025 | M6: AWI | N6: FYH | O6: SMK | P6: RENNY
B8: LAMPIRAN (Rincian) | F8: =+'TAHAP 1'!G9 -> : PAMERAN TEKNOLOGI INDUSTRI
B10: 1. UPD
B11: NOTE : Standar UPD Dalam Negeri berdasarkan Prosedur Perjalanan Dinas (PGA-GA.PD.02)
B12: Golongan | F12: UANG SAKU | G12: BREAKFAST | H12: LUNCH | I12: DINNER
B13: I | F13: 30000 | G13: 12500 | H13: 20000 | I13: 20000
B14: II | F14: 30000 | G14: 12500 | H14: 20000 | I14: 20000
B15: III | F15: 35000 | G15: 12500 | H15: 20000 | I15: 20000
B16: IV | F16: 40000 | G16: 12500 | H16: 27500 | I16: 27500
B17: V | F17: 50000 | G17: 22500 | H17: 30000 | I17: 30000
B18: VI | F18: 60000 | G18: 22500 | H18: 50000 | I18: 50000
B19: VII | F19: 70000 | G19: 22500 | H19: 60000 | I19: 60000
C21: Rincian Golongan | D21: : | E21: IV
B22: NO. | C22: TANGGAL | F22: =+$F$12 -> UANG SAKU | G22: =+$G$12 -> BREAKFAST | H22: =+$H$12 -> LUNCH | I22: =+$I$12 -> DINNER | J22: JUMLAH
B23: 1 | C23: =+'TAHAP 1'!$C$13 -> 45630 | F23: 40000 | G23: 0 | H23: 27500 | I23: 27500 | J23: =SUM(F23:I23) -> 95000
B24: 2 | C24: =+C23+1 -> 45631 | F24: 40000 | G24: di Hotel | H24: 27500 | I24: 27500 | J24: =SUM(F24:I24) -> 95000
B25: 3 | C25: =+C24+1 -> 45632 | F25: 40000 | G25: di Hotel | H25: 27500 | I25: 27500 | J25: =SUM(F25:I25) -> 95000
B26: TOTAL | J26: =SUM(J23:J25) -> 285000
C28: Rincian Golongan | D28: : | E28: III
B29: NO. | C29: TANGGAL | F29: =+$F$12 -> UANG SAKU | G29: =+$G$12 -> BREAKFAST | H29: =+$H$12 -> LUNCH | I29: =+$I$12 -> DINNER | J29: JUMLAH
B30: 1 | C30: =+'TAHAP 1'!$C$13 -> 45630 | F30: 35000 | G30: 0 | H30: 20000 | I30: 20000 | J30: =SUM(F30:I30) -> 75000
B31: 2 | C31: =+C30+1 -> 45631 | F31: 35000 | G31: di Hotel | H31: 20000 | I31: 20000 | J31: =SUM(F31:I31) -> 75000
B32: 3 | C32: =+C31+1 -> 45632 | F32: 35000 | G32: di Hotel | H32: 20000 | I32: 20000 | J32: =SUM(F32:I32) -> 75000
B33: TOTAL | J33: =SUM(J30:J32) -> 225000
B35: UPD
B36: NO. | C36: NAMA | G36: GOL | H36: UPD
B37: 1 | C37: =+'TAHAP 1'!M13 -> PUDJI SRI SAPUTRI | G37: IV | H37: =+J26 -> 285000
B38: 2 | C38: =+'TAHAP 1'!M14 -> AGIL ZHEGA PRASETYA | G38: IV | H38: =+J26 -> 285000
B39: 3 | C39: =+'TAHAP 1'!M15 -> MUNHAMIR | G39: IV | H39: =+J26 -> 285000
B40: 4 | C40: =+'TAHAP 1'!M16 -> ADITYA FAHRIZAL | G40: IV | H40: =+J26 -> 285000
B41: 5 | C41: =+'TAHAP 1'!M17 -> SUPRIYANTO | G41: III | H41: =+J33 -> 225000
B42: TOTAL | H42: =SUM(H37:H41) -> 1365000
B44: 2. TRANSPORTASI (PIC Perjalanan Dinas tanda tangan pada kolom transportasi yang dipilih atau yang diajukan)
B46: 2.1 PESAWAT
B47: NO. | C47: KET. | E47: FLIGHT SCHEDULE | K47: PRICE | L47: QTY | M47: JUMLAH | N47: TOTAL
...

Sheet TAHAP 2.1 (SPD)
W1: A
B2: PT. SEMARANG AUTOCOMP MANUFACTURING INDONESIA | K2: FORM/CHECKSHEET | L2: NO. DOKUMEN | N2: : 023/PGA/GA/FORM/SPDDN | R2: APPROVED II | S2: APPROVED I | T2: CHECKED | V2: PREPARED
B3: SURAT PERJALANAN DINAS DALAM NEGERI | L3: TANGGAL | N3: : 11-07-2023 | R3: APPROVED
L4: REVISI | N4: : 4
L5: HALAMAN | N5: : 1/2
L6: MASA BERLAKU | N6: : 10-07-2025 | R6: AWI | S6: FYH | T6: SMK | V6: Renny
B9: TUJUAN PERJALANAN DINAS | I9: =+'TAHAP 1'!G8 -> : (JIE) Jl. BENYAMIN SUEB, PADEMANGAN TIM, KEC. PADEMANGAN, JAKARTA UTARA
B10: KEPENTINGAN | I10: =+'TAHAP 1'!G9 -> : PAMERAN TEKNOLOGI INDUSTRI
B14: 1. PESERTA
B15: NO | C15: TANGGAL | G15: DEPT. / SECT. | I15: JABATAN | K15: NIK | M15: NAMA | P15: 1 | Q15: 2 | R15: 3 | S15: 4 | T15: 5
P16: YANG MENERIMA PERINTAH | Q16: SPV | R16: MGR | S16: FM / DFM | T16: PRESDIR
B19: 1 | C19: =+'TAHAP 1'!C13 -> 45630 | D19: s/d | F19: =+'TAHAP 1'!E13:F13 -> 45632 | G19: =+'TAHAP 1'!G13:H13 -> PE | I19: =+'TAHAP 1'!I13:J13 -> SPV | K19: =+'TAHAP 1'!K13:L13 -> 284 | M19: =+'TAHAP 1'!M13 -> PUDJI SRI SAPUTRI | P19: PSS | Q19: - | R19: ANG | S19: MIS / TMI | T19: KIW
B20: 2 | C20: =+'TAHAP 1'!C14 -> 45630 | D20: s/d | F20: =+'TAHAP 1'!E14:F14 -> 45632 | G20: =+'TAHAP 1'!G14:H14 -> QA | I20: =+'TAHAP 1'!I14:J14 -> SPV | K20: =+'TAHAP 1'!K14:L14 -> 12027 | M20: =+'TAHAP 1'!M14 -> AGIL ZHEGA PRASETYA | P20: AZP | Q20: - | R20: AMU
B21: 3 | C21: =+'TAHAP 1'!C15 -> 45630 | D21: s/d | F21: =+'TAHAP 1'!E15:F15 -> 45632 | G21: =+'TAHAP 1'!G15:H15 -> QA | I21: =+'TAHAP 1'!I15:J15 -> SPV | K21: =+'TAHAP 1'!K15:L15 -> 7094 | M21: =+'TAHAP 1'!M15 -> MUNHAMIR | P21: MUN | Q21: -
B22: 4 | C22: =+'TAHAP 1'!C16 -> 45630 | D22: s/d | F22: =+'TAHAP 1'!E16:F16 -> 45632 | G22: =+'TAHAP 1'!G16:H16 -> NYS | I22: =+'TAHAP 1'!I16:J16 -> SPV | K22: =+'TAHAP 1'!K16:L16 -> 13647 | M22: =+'TAHAP 1'!M16 -> ADITYA FAHRIZAL | P22: AFA | Q22: - | R22: PAN
B23: 5 | C23: =+'TAHAP 1'!C17 -> 45630 | D23: s/d | F23: =+'TAHAP 1'!E17:F17 -> 45632 | G23: =+'TAHAP 1'!G17:H17 -> PRD | I23: =+'TAHAP 1'!I17:J17 -> LL | K23: =+'TAHAP 1'!K17:L17 -> 5550 | M23: =+'TAHAP 1'!M17 -> SUPRIYANTO | P23: Supriyanto | Q23: SUS | R23: EAS
B28: 2. BIAYA PERJALANAN DINAS | L28: UPD | O28: TRANSPORTASI | S28: HOTEL
O29: BY : CAR | Q29: LOKAL TRANSPORT | S29: BW Kemayoran Hotel & Convention (Formerly Best Western Plus Kemayoran) Jl Benyamin Suaeb Blok A5, Kemayoran - Central Jakarta, Jakarta, 10630, Indonesia. CI/CO : 04 - 06 Dec (02 Malam) Superior Twin : IDR 613.000/room/night include breakfast
O30: INNOVA ZENIX 5 Seat | Q30: -
B34: NO | C34: NAMA | G34: NIK | H34: NO. REKENING | L34: PRICE | N34: PERIODE BUDGET | O34: ESTIMATED PRICE | P34: PERIODE BUDGET | Q34: ESTIMATED PRICE | R34: PERIODE BUDGET | S34: ESTIMATED PRICE | T34: PERIODE BUDGET
B35: 1 | C35: =+'TAHAP 1'!M13 -> PUDJI SRI SAPUTRI | G35: =+'TAHAP 1'!K13 -> 284 | L35: =+'TAHAP 2.2 (Rincian)'!H37 -> 285000 | N35: 45627 | O35: =+'TAHAP 2.2 (Rincian)'!Q71 -> 7925000 | P35: 45627 | Q35: 0 | R35: - | S35: =+'TAHAP 2.2 (Rincian)'!J84 -> 1226000 | T35: 45627
B36: 2 | C36: =+'TAHAP 1'!M14 -> AGIL ZHEGA PRASETYA | G36: =+'TAHAP 1'!K14 -> 12027 | L36: =+'TAHAP 2.2 (Rincian)'!H38 -> 285000 | S36: =+'TAHAP 2.2 (Rincian)'!J85 -> 1226000
B37: 3 | C37: =+'TAHAP 1'!M15 -> MUNHAMIR | G37: =+'TAHAP 1'!K15 -> 7094 | L37: =+'TAHAP 2.2 (Rincian)'!H39 -> 285000 | S37: =+'TAHAP 2.2 (Rincian)'!J86 -> 1226000
B38: 4 | C38: =+'TAHAP 1'!M16 -> ADITYA FAHRIZAL | G38: =+'TAHAP 1'!K16 -> 13647 | L38: =+'TAHAP 2.2 (Rincian)'!H40 -> 285000 | S38: =+'TAHAP 2.2 (Rincian)'!J87 -> 1226000
B39: 5 | C39: =+'TAHAP 1'!M17 -> SUPRIYANTO | G39: =+'TAHAP 1'!K17 -> 5550 | L39: =+'TAHAP 2.2 (Rincian)'!H41 -> 225000 | S39: =+'TAHAP 2.2 (Rincian)'!J88 -> 1226000
B40: SUB TOTAL | L40: =SUM(L35:M39) -> 1365000 | O40: =SUM(O35:O39) -> 7925000 | Q40: =SUM(Q35:Q39) -> 0 | S40: =SUM(S35:S39) -> 6130000
B41: TOTAL | L41: =SUM(L40:V40) -> 15420000
B43: NOTE : 1. Ket. Budget di isi bulan periode budget atau di tulis "additional" jika additional budget 2. Approval diproses oleh User 3. Approval pada form ini akan digunakan sebagai jaminan GA dalam melakukan proses issued ticket dan hotel sebelum user melakukan pembuatan PR (purchase requisition). 4. Pembuatan PR setelah proses issued bertujuan agar tidak terjadi selisih harga PR (purchase requisition) dengan actual. | T43: 6. MENGETAHUI MGR FA
T46: BRI
B55: PERLINDUNGAN HAK CIPTA! Dokumen ini adalah milik dan untuk dipergunakan di lingkungan kerja PT. SAMI . Tidak diperkenankan memindahkan, menyalin, atau menggandakan sebagian ataupun seluruhnya isi dokumen ini dalam bentuk dan dengan cara apapun, tanpa izin tertulis dari Wakil manajemen. | I55: Referensi Prosedur/WI/OS/IS/ : PGA-GA.PD.02 : Prosedur Perjalanan Dinas | M55: 4 | N55: Penggabungan approval perjalanan dinas | Q55: 45118 | R55: Renny
M56: 3 | N56: Update Tgl Masa Berlaku & Rev. No. Dok. | Q56: 44702 | R56: Renny
M57: 2 | N57: New Format | Q57: 44314 | R57: Renny | S57: 3 | T57: =+Q55 -> 45118 | W57: FYH
M58: 1 | N58: Add Actual UPD | Q58: 44147 | R58: Renny | S58: 2 | T58: 44702 | W58: WIN
M59: 0 | N59: New Release | Q59: 45113 | R59: LNA | S59: 1 | T59: 44314 | W59: FYH
M60: REV. | N60: ISI PERUBAHAN | Q60: TANGGAL | R60: PIC | S60: REVIEW | T60: TGL | W60: PIC

Sheet Sheet1
A1: BUDGET MMENGHADIRI PAMERAN INDUSTRI
A3: SEWA UNIT MOBIL LEPAS KUNCI | B3: 750000 | C3: 2 | D3: =B3*C3 -> 1500000
A4: BBM PERJALANAN DINAS | B4: 1100000 | C4: 2 | D4: =B4*C4 -> 2200000
A5: TOL DAN PARKIR PERJALANAN DINAS | B5: 1100000 | C5: 2 | D5: =B5*C5 -> 2200000
A6: UANG LUAR KOTA DRIVER PERJANAN DINAS | B6: 150000 | C6: 2 | D6: =B6*C6 -> 300000
A7: BIAYA INAP DRIVER PERJALANAN DINAS | B7: 200000 | C7: 1 | D7: =B7*C7 -> 200000
A8: OVERTIME DRIVER PERJALANAN DINAS | B8: 250000 | C8: 2 | D8: =B8*C8 -> 500000
D9: =SUM(D3:D8) -> 6900000
A11: HOTEL MEETING/BENCHMARK GOL IV(DALAM NEGERI) | B11: 1200000 | C11: 2 | D11: =B11*C11 -> 2400000
D15: =11690500-6900000 -> 4790500
