Workbook

Sheet summary (3)
A2: No | B2: Supplier | C2: PIC | D2: 44378 | E2: 44409 | F2: 44440 | G2: 44470 | H2: Grand Total | I2: Kontrak Existing | J2: Remark | K2: PIC | L2: STATUS KONTRAK | M2: KETERANGAN | N2: 30/11/21 | O2: TARGET | P2: DRAFT | Q2: LEGAL | R2: SUPPLIER | S2: LEGAL(TRANSLATE) | T2: APPROVAL
A3: 1 | B3: AKIRA DATA PRATAMA,PT | C3: GA | D3: 12709000 | E3: 374000 | H3: 13083000 | I3: X | J3: Tidak rutin tidak perlu dikontrak | K3: =VLOOKUP(B3,'[1]SUMMARY (2)'!B3:H218,7,0) -> GA | L3: TIDAK PERLU
A4: 2 | B4: AMAN MULTI INDONESIA, PT | C4: GA | D4: 1402500 | E4: 18074500 | F4: 4642000 | H4: 24119000 | I4: X | J4: rutin | K4: =VLOOKUP(B4,'[1]SUMMARY (2)'!B4:H219,7,0) -> GA | L4: 44515 | M4: DRAFT DIKIRIM TGL 15 NOV21 KE VENDOR | N4: proses ttd ke presedir plan mba riytgl 1 des 2021
A5: 3 | B5: ASIAN BEARINDO PRIMA, PT | C5: MTP | D5: 1612500 | E5: 83760000 | F5: 3265500 | G5: 2867700 | H5: 91505700 | I5: X | J5: rutin | K5: =VLOOKUP(B5,'[1]SUMMARY (2)'!B5:H220,7,0) -> X | L5: =VLOOKUP('summary (3)'!B5,'[1]SUMMARY (2)'!$B$3:$I$218,8,0) -> 0
A6: 4 | B6: BINA ADIDAYA, PT. | C6: GA | D6: 26855360 | E6: 2420000 | H6: 29275360 | I6: X | J6: rutin | K6: =VLOOKUP(B6,'[1]SUMMARY (2)'!B6:H221,7,0) -> GA | L6: TIDAK PERLU
A7: 5 | B7: BIROTIKA SEMESTA, PT | C7: EXIM | D7: 20974150 | E7: 28172453 | F7: 22024798 | G7: 5711731 | H7: 76883132 | I7: X | J7: rutin | K7: =VLOOKUP(B7,'[1]SUMMARY (2)'!B7:H222,7,0) -> X | L7: =VLOOKUP('summary (3)'!B7,'[1]SUMMARY (2)'!$B$3:$I$218,8,0) -> 0
A8: 6 | B8: CARAKA DAYA | C8: GA | D8: 6432000 | E8: 19488000 | F8: 10785600 | G8: 9504000 | H8: 46209600 | I8: X | J8: OFF | K8: =VLOOKUP(B8,'[1]SUMMARY (2)'!B8:H223,7,0) -> GA | L8: =VLOOKUP('summary (3)'!B8,'[1]SUMMARY (2)'!$B$3:$I$218,8,0) -> OFF
A9: 7 | B9: CENTRAL PLOTTER INDONESIA,PT | C9: GA | F9: 12408000 | G9: 12408000 | H9: 24816000 | I9: X | J9: rutin | K9: =VLOOKUP(B9,'[1]SUMMARY (2)'!B9:H224,7,0) -> GA | L9: 44515 | M9: DRAFT DIKIRIM TGL 15 NOV21 KE VENDOR | N9: belum mbalik dari central
A10: 8 | B10: FICI LAUNDRY | C10: GA | D10: 30000 | F10: 80900 | G10: 28000 | H10: 138900 | I10: X | J10: rutin tapi nilai tiap bulannya tdk mencapai 1jt jadi tidak perlu kontrak | K10: =VLOOKUP(B10,'[1]SUMMARY (2)'!B10:H225,7,0) -> GA | L10: TIDAK PERLU
A11: 9 | B11: FLEXINDO MANDIRI UTAMA, PT | C11: GA | D11: 2229527 | E11: 1380463 | F11: 1130302 | G11: 956309 | H11: 5696601 | I11: X | J11: rutin | K11: =VLOOKUP(B11,'[1]SUMMARY (2)'!B11:H226,7,0) -> GS | L11: TIDAK PERLU | M11: DRAFT DIKIRIM TGL 15 NOV21 KE VENDOR | N11: belum ada balasan dan sudah dihubungi telp pic tidak bisa
A12: 10 | B12: FPC INDONESIA, PT | C12: GA | D12: 26838000 | E12: 1620000 | F12: 3132000 | H12: 31590000 | I12: X | J12: rutin | K12: GS | L12: Wajib | M12: bukan kontrak pembelian(jadi draft berbeda) | N12: bukan kontrak pembelian(jadi draft berbeda)
A13: 11 | B13: HARAPAN MULYA | C13: GA | D13: 1764000 | E13: 2884800 | G13: 161602000 | H13: 166250800 | I13: X | J13: rutin | K13: =VLOOKUP(B13,'[1]SUMMARY (2)'!B13:H227,7,0) -> GA | L13: Wajib | N13: bukan kontrak pembelian(jadi draft berbeda)
A14: 12 | B14: HARUM INDAH SARI TOURS & TRAVEL, PT | C14: GA | D14: 4411000 | E14: 103246000 | F14: 55956000 | H14: 163613000 | I14: X | J14: rutin | K14: GS | L14: Wajib | M14: bukan kontrak pembelian(jadi draft berbeda) | N14: sudah ada dari pasi untuk all aviliat
A15: 13 | B15: INDONESIA BELTING SOLUTION ,PT | C15: MTP | D15: 8366700 | F15: 10212000 | H15: 18578700 | I15: X | J15: rutin | K15: =VLOOKUP(B15,'[1]SUMMARY (2)'!B15:H227,7,0) -> X | L15: =VLOOKUP('summary (3)'!B15,'[1]SUMMARY (2)'!$B$3:$I$218,8,0) -> 0 | N15: bukan kontrak pembelian(jadi draft berbeda)
A16: 14 | B16: INDOSAT TBK,PT | C16: IT | D16: 4320000 | E16: 4320000 | F16: 4400000 | G16: 4400000 | H16: 17440000 | I16: X | J16: rutin | K16: =VLOOKUP(B16,'[1]SUMMARY (2)'!B16:H227,7,0) -> X | L16: =VLOOKUP('summary (3)'!B16,'[1]SUMMARY (2)'!$B$3:$I$218,8,0) -> 0
A17: 15 | B17: JAVAPART ELECTRICAL AUTOMATION, CV | C17: MTP | E17: 1150000 | F17: 128250 | G17: 2300000 | H17: 3578250 | I17: X | J17: rutin | K17: =VLOOKUP(B17,'[1]SUMMARY (2)'!B17:H227,7,0) -> X | L17: =VLOOKUP('summary (3)'!B17,'[1]SUMMARY (2)'!$B$3:$I$218,8,0) -> 0
A18: 16 | B18: JAYA MAKMUR, CV | C18: GA | D18: 7650000 | E18: 2873000 | F18: 2180000 | H18: 12703000 | I18: X | J18: rutin | K18: =VLOOKUP(B18,'[1]SUMMARY (2)'!B18:H227,7,0) -> GA | L18: 44515 | M18: DRAFT DIKIRIM TGL 15 NOV21 KE VENDOR | N18: proses ttd ke presedir plan mba riytgl 1 des 2021
A19: 17 | B19: KAWAN LAMA, PT | C19: GA | D19: 1697100 | E19: 44506000 | F19: 2648850 | H19: 48851950 | I19: X | J19: rutin | K19: =VLOOKUP(B19,'[1]SUMMARY (2)'!B19:H227,7,0) -> GA | L19: 44515 | M19: DRAFT DIKIRIM TGL 15 NOV21 KE VENDOR | N19: proses ttd ke presedir plan mba riytgl 1 des 2021
A20: 18 | B20: KIOS BUNGA TUNGGAK SEMI | C20: GA | E20: 7680100 | F20: 7999400 | H20: 15679500 | I20: X | J20: rutin | K20: =VLOOKUP(B20,'[1]SUMMARY (2)'!B20:H227,7,0) -> GA | L20: 44515 | M20: DRAFT DIKIRIM TGL 15 NOV21 KE VENDOR | N20: proses ttd ke presedir plan mba riytgl 1 des 2021
A21: 19 | B21: KOPERASI KARYAWAN SAMI | C21: GA | E21: 33915000 | F21: 29015000 | H21: 62930000 | I21: X | J21: rutin Ada kontrak namun untuk pengelolaan koperasi | K21: =VLOOKUP(B21,'[1]SUMMARY (2)'!B21:H227,7,0) -> GS | L21: 44515 | M21: DRAFT DIKIRIM TGL 15 NOV21 KE VENDOR | N21: pak sulis belum balas
A22: 20 | B22: KRANINDO TIRTA ABADI, PT | C22: MTP/GA | D22: 19612350 | E22: 1378575 | F22: 2170000 | G22: 6690000 | H22: 29850925 | I22: X | J22: rutin | K22: =VLOOKUP(B22,'[1]SUMMARY (2)'!B22:H227,7,0) -> GA | L22: 44515 | M22: DRAFT DIKIRIM TGL 15 NOV21 KE VENDOR | N22: Kontrak
A23: 21 | B23: LESTARI ENGINEERING CV, | C23: MTP | F23: 650000 | G23: 460000 | H23: 1110000 | I23: X | J23: rutin | K23: =VLOOKUP(B23,'[1]SUMMARY (2)'!B23:H227,7,0) -> X | L23: =VLOOKUP('summary (3)'!B23,'[1]SUMMARY (2)'!$B$3:$I$218,8,0) -> 0
A24: 22 | B24: MANDIRI JAYA MAKMUR | C24: GA | D24: 41750000 | E24: 37500000 | F24: 35500000 | G24: 22750000 | H24: 137500000 | I24: X | J24: OFF | K24: =VLOOKUP(B24,'[1]SUMMARY (2)'!B24:H227,7,0) -> GA | L24: =VLOOKUP('summary (3)'!B24,'[1]SUMMARY (2)'!$B$3:$I$218,8,0) -> OFF
A25: 23 | B25: MAXIMA SURYA ABADI, PT | C25: GA | F25: 28125000 | G25: 37500000 | H25: 65625000 | I25: X | J25: rutin | K25: GA | L25: =VLOOKUP('summary (3)'!B25,'[1]SUMMARY (2)'!$B$3:$I$218,8,0) -> ADA | M25: PROSES APPROVE TMA
A26: 24 | B26: MCL TRANS INDONESIA, PT | C26: EXIM | D26: 17318070 | E26: 44402688 | F26: 46302300 | G26: 152856990 | H26: 260880048 | I26: X | J26: rutin | K26: =VLOOKUP(B26,'[1]SUMMARY (2)'!B26:H227,7,0) -> X | L26: =VLOOKUP('summary (3)'!B26,'[1]SUMMARY (2)'!$B$3:$I$218,8,0) -> 0
A27: 25 | B27: MITRA SEJATI | C27: GA | D27: 3300000 | E27: 2750000 | H27: 6050000 | I27: X | J27: Tidak perlu karena pembelian tidak rutin | K27: =VLOOKUP(B27,'[1]SUMMARY (2)'!B27:H227,7,0) -> GA | L27: =VLOOKUP('summary (3)'!B27,'[1]SUMMARY (2)'!$B$3:$I$218,8,0) -> X
A28: 26 | B28: MOONAIR JAYA ABADI, CV | C28: MTP | D28: 7175000 | F28: 31425000 | H28: 38600000 | I28: X | J28: rutin | K28: =VLOOKUP(B28,'[1]SUMMARY (2)'!B28:H227,7,0) -> X | L28: =VLOOKUP('summary (3)'!B28,'[1]SUMMARY (2)'!$B$3:$I$218,8,0) -> 0
A29: 27 | B29: NASIONAL MAKMUR SEJAHTERA, PT | C29: MTP | D29: 2964000 | F29: 741000 | H29: 3705000 | I29: X | J29: rutin | K29: =VLOOKUP(B29,'[1]SUMMARY (2)'!B29:H227,7,0) -> X | L29: =VLOOKUP('summary (3)'!B29,'[1]SUMMARY (2)'!$B$3:$I$218,8,0) -> 0
A30: 28 | B30: NIHON SAMPOERNA PACKINDO, PT | C30: LD | E30: 25251500 | F30: 35980500 | H30: 61232000 | I30: X | J30: rutin | K30: =VLOOKUP(B30,'[1]SUMMARY (2)'!B30:H227,7,0) -> X | L30: =VLOOKUP('summary (3)'!B30,'[1]SUMMARY (2)'!$B$3:$I$218,8,0) -> X
A31: 29 | B31: PLATINUM JAYA LOGISTIC SEMARANG, PT | C31: EXIM | D31: 5605974 | E31: 18344205 | F31: 50655528 | H31: 74605707 | I31: X | J31: rutin | K31: =VLOOKUP(B31,'[1]SUMMARY (2)'!B31:H227,7,0) -> X | L31: =VLOOKUP('summary (3)'!B31,'[1]SUMMARY (2)'!$B$3:$I$218,8,0) -> 0
A32: 30 | B32: POLY SENTRA, PT | C32: LD/GA | E32: 2989580 | F32: 597410 | G32: 502480 | H32: 4089470 | I32: X | J32: rutin | K32: =VLOOKUP(B32,'[1]SUMMARY (2)'!B32:H227,7,0) -> GA | L32: 44515 | M32: DRAFT DIKIRIM TGL 15 NOV21 KE VENDOR | N32: proses ttd ke presedir plan mba riytgl 1 des 2021
A33: 31 | B33: PUTRA PANDAWA ,CV | C33: GA | D33: 3978340 | E33: 1510000 | F33: 120180804 | G33: 7104804 | H33: 132773948 | I33: X | J33: rutin | K33: =VLOOKUP(B33,'[1]SUMMARY (2)'!B33:H227,7,0) -> GA | L33: Wajib | N33: Kontrak
A34: 32 | B34: REJO MAKMUR | C34: GA | D34: 42500000 | E34: 42500000 | F34: 54000000 | G34: 47000000 | H34: 186000000 | I34: X | J34: OFF | K34: =VLOOKUP(B34,'[1]SUMMARY (2)'!B34:H227,7,0) -> GA | L34: =VLOOKUP('summary (3)'!B34,'[1]SUMMARY (2)'!$B$3:$I$218,8,0) -> OFF
A35: 33 | B35: SATO LABEL SOLUTIONS, PT | C35: GA | E35: 11200000 | F35: 12600000 | H35: 23800000 | I35: X | J35: rutin Ada kontrak namun pembelian barcode printer | K35: =VLOOKUP(B35,'[1]SUMMARY (2)'!B35:H227,7,0) -> GA | L35: 44515 | M35: DRAFT DIKIRIM TGL 15 NOV21 KE VENDOR | N35: proses ttd ke presedir plan mba riytgl 1 des 2021
A36: 34 | B36: SEMARANG TEHNIK ,CV | C36: GA | D36: 40015000 | E36: 42415000 | F36: 5490000 | H36: 87920000 | I36: X | J36: rutin | K36: =VLOOKUP(B36,'[1]SUMMARY (2)'!B36:H227,7,0) -> GA | L36: Wajib | N36: draft nanti untuk pekerjan
A37: 35 | B37: SENTRA LUMASINTI NUSANTARA, PT | C37: MTP | E37: 2007500 | G37: 2810500 | H37: 4818000 | I37: X | J37: rutin | K37: =VLOOKUP(B37,'[1]SUMMARY (2)'!B37:H228,7,0) -> X | L37: =VLOOKUP('summary (3)'!B37,'[1]SUMMARY (2)'!$B$3:$I$218,8,0) -> 0
A38: 36 | B38: SIGMA ELECTRINDO, CV | C38: MTP/GA | D38: 36028800 | E38: 42051900 | F38: 20785300 | G38: 13612000 | H38: 112478000 | I38: X | J38: rutin | K38: =VLOOKUP(B38,'[1]SUMMARY (2)'!B38:H229,7,0) -> GA | L38: 44515 | M38: DRAFT DIKIRIM TGL 15 NOV21 KE VENDOR | N38: proses masih di cek vendor karena pembelian oleh mtp dan ga
A39: 37 | B39: SMART LAB INDONESIA, PT | C39: MTP | E39: 2295000 | G39: 1147500 | H39: 3442500 | I39: X | J39: rutin | K39: =VLOOKUP(B39,'[1]SUMMARY (2)'!B39:H230,7,0) -> X | L39: =VLOOKUP('summary (3)'!B39,'[1]SUMMARY (2)'!$B$3:$I$218,8,0) -> 0
A40: 38 | B40: SUMBER REJEKI KONVEKSI | C40: GA | D40: 5226000 | E40: 681000 | F40: 5576000 | H40: 11483000 | I40: X | J40: rutin | K40: =VLOOKUP(B40,'[1]SUMMARY (2)'!B40:H231,7,0) -> GA | L40: Wajib | N40: draft akan langsung ttd dari vendor isi sama dengan cipta cemerlang
A41: 39 | B41: SURYA ALI BEKEN, CV | C41: GA | D41: 27500000 | E41: 23375000 | F41: 11000000 | H41: 61875000 | I41: X | J41: OFF | K41: =VLOOKUP(B41,'[1]SUMMARY (2)'!B41:H232,7,0) -> GA | L41: =VLOOKUP('summary (3)'!B41,'[1]SUMMARY (2)'!$B$3:$I$218,8,0) -> OFF
...
