Workbook

Sheet TAHAP 1
U1: A
B2: PT. SEMARANG AUTOCOMP MANUFACTURING INDONESIA | H2: FORM/CHECKSHEET | I2: NO. DOKUMEN | J2: : 083/PGA/GS/FORM/RPBPD | N2: APPROVED II | P2: APPROVED I | R2: CHECKED | T2: PREPARED
B3: REQUEST PERHITUNGAN BIAYA PERJALANAN DINAS | I3: REVISI | J3: : 0 | N3: APPROVED
I4: TANGGAL | J4: : 05-07-2023
I5: HALAMAN | J5: : 1
I6: MASA BERLAKU | J6: : 04-07-2024 | N6: AWI | P6: FYH | R6: SMK | T6: Renny
B8: TUJUAN PERJALANAN DINAS | G8: : SAI
B9: KEPENTINGAN | G9: : YIG QUALITY MEETING
B11: 1. MEMBER YANG AKAN PERJALANAN DINAS
B12: NO | C12: TANGGAL | G12: DEPT. / SECT. | I12: JABATAN | K12: NIK | M12: NAMA
B13: 1 | C13: 45498 | D13: s/d | F13: 45499 | G13: QA | I13: CSPV | K13: 703 | M13: ARY SUSANTO
B14: 2 | C14: 45498 | D14: s/d | F14: 45499 | G14: QA | I14: SPV | K14: 13636 | M14: IRAWAN RAHARDIANTO
B15: 3 | D15: s/d
B17: 2. TRANSPORTASI
B18: 2.a Pesawat | K18: 2.b Kereta
B19: NO | C19: TANGGAL | E19: AIR PORT | H19: RANGE TIME | K19: NO | L19: TANGGAL | N19: STATION | R19: RANGE TIME
E20: DEPARTURE | G20: ARRIVAL | H20: DEPARTURE | I20: ARRIVAL | N20: DEPARTURE | P20: ARRIVAL | R20: DEPARTURE | T20: ARRIVAL
B21: 1 | K21: 1
B22: 2 | K22: 2
B24: 2.c Mobil / Hi Ace / Bus
B25: NO | C25: TANGGAL | G25: JENIS ARMADA | I25: JUMLAH KURSI (PENUMPANG) | J25: WAKTU KEBERANGKATAN | N25: REQUEST KHUSUS
J26: LOKASI | L26: JAM
B27: 1 | C27: =C13 -> 45498 | D27: s/d | F27: =F13 -> 45499 | G27: MOBIL | I27: 2 | J27: RUMAH (AST) & SAMI | L27: 0.375 | N27: DARI RUMAH AST JAM 9:00, LANJUT KE SAMI (IRH)
B28: NOTE : Standar kelengkapan armada
B29: No | C29: Point | J29: Mobil | M29: Hi Ace | P29: BUS
B30: 1 | C30: Sabuk Pengaman | J30: ● | M30: ● | P30: ●
B31: 2 | C31: Ban Cadangan | J31: ● | M31: ● | P31: ●
B32: 3 | C32: Segitiga Pengaman (Minimal 2 buah, berwarna merah, dapat memantulkan cahaya) | J32: ● | M32: ● | P32: ●
B33: 4 | C33: Dongkrak | J33: ● | M33: ● | P33: ●
B34: 5 | C34: Pembuka Roda dan | J34: ● | M34: ● | P34: ●
B35: 6 | C35: Kotak P3K(Minimal berisi obat antiseptik, kain kassa, kapas, plester) | J35: ● | M35: ● | P35: ●
B36: 7 | C36: Apar | J36: ● (1x M1 berat 1 Kg) | M36: ● (2x M1 berat 1 Kg) | P36: ● (2x M1 berat 1 Kg)
B37: 8 | C37: Ganjal Ban (Wheel Block) | J37: x | M37: ● (Jika > 3,500 Kg) | P37: ● (Jika > 3,500 Kg)
B38: 9 | C38: Perisai Kolong Belakang | J38: x | M38: x | P38: x
B39: 10 | C39: Perisai Kolong Samping | J39: x | M39: x | P39: x
B40: 11 | C40: Alat Pemantul Cahaya | J40: x | M40: x | P40: x
B41: 12 | C41: Pemecah Kaca / Martil | J41: x | M41: x | P41: x
... B43: 14 | C43: Kernet | J43: x | M43: x | P43: x
B44: NOTE : Standar transportasi berdasarkan Prosedur Perjalanan Dinas (PGA-GA.PD.02)
B45: KET. | D45: Golongan I - III | H45: Golongan IV - V | K45: Golongan VI - VII
...

Sheet TAPAH 2.2 (Rincian)
P1: A
B2: PT. SEMARANG AUTOCOMP MANUFACTURING INDONESIA - TUGU FACTORY | I2: FORM/CHECKSHEET | J2: NO. DOKUMEN | K2: : 023/PGA/GA/FORM/SPDDN | M2: APPROVED II | N2: APPROVED I | O2: CHECKED | P2: PREPARED
B3: SURAT PERJALANAN DINAS DALAM NEGERI | J3: TANGGAL | K3: : 11-07-2023 | M3: APPROVED
J4: REVISI | K4: : 4
J5: HALAMAN | K5: : 2 / 2
J6: MASA BERLAKU | K6: : 10-07-2024 | M6: AWI | N6: FYH | O6: SMK | P6: RENNY
B8: LAMPIRAN (Rincian) | F8: =+'TAHAP 1'!G9 -> : YIG QUALITY MEETING
B10: 1. UPD
B11: NOTE : Standar UPD Dalam Negeri berdasarkan Prosedur Perjalanan Dinas (PGA-GA.PD.02)
B12: Golongan | F12: UANG SAKU | G12: BREAKFAST | H12: LUNCH | I12: DINNER
B13: I | F13: 30000 | G13: 12500 | H13: 20000 | I13: 20000
B14: II | F14: 30000 | G14: 12500 | H14: 20000 | I14: 20000
B15: III | F15: 35000 | G15: 12500 | H15: 20000 | I15: 20000
B16: IV | F16: 40000 | G16: 12500 | H16: 27500 | I16: 27500
B17: V | F17: 50000 | G17: 22500 | H17: 30000 | I17: 30000
B18: VI | F18: 60000 | G18: 22500 | H18: 50000 | I18: 50000
B19: VII | F19: 70000 | G19: 22500 | H19: 60000 | I19: 60000
C21: Rincian Golongan | D21: : | E21: IV
B22: NO. | C22: TANGGAL | F22: =+$F$12 -> UANG SAKU | G22: =+$G$12 -> BREAKFAST | H22: =+$H$12 -> LUNCH | I22: =+$I$12 -> DINNER | J22: JUMLAH
B23: 1 | C23: =+'TAHAP 1'!$C$13 -> 45498 | F23: =VLOOKUP($E$21,B12:$I$19,5,0) -> 40000 | G23: di Rumah | H23: =VLOOKUP($E$21,B12:$I$19,7,0) -> 27500 | I23: =VLOOKUP($E$21,B12:$I$19,8,0) -> 27500 | J23: =SUM(F23:I23) -> 95000
B24: 2 | C24: =+C23+1 -> 45499 | F24: =VLOOKUP($E$21,B12:$I$19,5,0) -> 40000 | G24: di Hotel | H24: =VLOOKUP($E$21,B12:$I$19,7,0) -> 27500 | I24: 0 | J24: =SUM(F24:I24) -> 67500
B25: TOTAL | G25: =SUM(G23:I24) -> 82500 | J25: =SUM(J23:J24) -> 162500
B27: UPD
B28: NO. | C28: NAMA | G28: GOL | H28: UPD
B29: 1 | C29: =+'TAHAP 1'!M13 -> ARY SUSANTO | G29: =E21 -> IV | H29: =J25 -> 162500
B30: 2 | C30: =+'TAHAP 1'!M14 -> IRAWAN RAHARDIANTO | G30: IV | H30: =J25 -> 162500
B31: 3 | C31: =+'TAHAP 1'!M15 -> 0
B32: TOTAL | H32: =SUM(H29:H31) -> 325000
B34: 2. TRANSPORTASI (PIC Perjalanan Dinas tanda tangan pada kolom transportasi yang dipilih atau yang diajukan)
B36: 2.1 PESAWAT
B37: NO. | C37: KET. | E37: FLIGHT SCHEDULE | K37: PRICE | L37: QTY | M37: JUMLAH | N37: TOTAL
B38: 1 | C38: BERANGKAT | M38: =+K38*L38 -> 0 | N38: =SUM(M38:M39) -> 0
B39: 2 | C39: PULANG
B42: 2.2 MOBIL / LOCAL TRANSPORT
B47: NO. | C47: ITEM | F47: HARGA | G47: JML HARI | H47: JML BIAYA
B48: 1 | C48: Sewa Unit | F48: 0 | G48: 0 | I48: =+F48*G48 -> 0
B49: BIAYA SEWA UNIT | I49: =SUM(I42:I48) -> 0
B52: NO. | C52: ITEM | F52: HARGA | G52: JML HARI | H52: JML BIAYA
B53: 1 | C53: Biaya Antar Ambil | F53: 0 | G53: 0 | I53: =+F53*G53 -> 0
B54: 2 | C54: Fee Luar Kota Driver | F54: 100000 | G54: 2 | I54: =+F54*G54 -> 200000
...

Sheet TAHAP 2.1 (SPD)
W1: A
B2: PT. SEMARANG AUTOCOMP MANUFACTURING INDONESIA | K2: FORM/CHECKSHEET | L2: NO. DOKUMEN | N2: : 023/PGA/GA/FORM/SPDDN | R2: APPROVED II | S2: APPROVED I | T2: CHECKED | V2: PREPARED
B3: SURAT PERJALANAN DINAS DALAM NEGERI | L3: TANGGAL | N3: : 11-07-2023 | R3: APPROVED
L4: REVISI | N4: : 4
L5: HALAMAN | N5: : 1/2
L6: MASA BERLAKU | N6: : 10-07-2024 | R6: AWI | S6: FYH | T6: SMK | V6: Renny
B9: TUJUAN PERJALANAN DINAS | I9: =+'TAHAP 1'!G8 -> : SAI
B10: KEPENTINGAN | I10: =+'TAHAP 1'!G9 -> : YIG QUALITY MEETING
B14: 1. PESERTA
B15: NO | C15: TANGGAL | G15: DEPT. / SECT. | I15: JABATAN | K15: NIK | M15: NAMA | P15: 1 | Q15: 2 | R15: 3 | S15: 4 | T15: 5
P16: YANG MENERIMA PERINTAH | Q16: SPV | R16: MGR | S16: FM / DFM | T16: PRESDIR
B19: 1 | C19: =+'TAHAP 1'!C13 -> 45498 | D19: s/d | F19: =+'TAHAP 1'!F13 -> 45499 | G19: =+'TAHAP 1'!G13:H13 -> QA | I19: =+'TAHAP 1'!I13:J13 -> CSPV | K19: ='TAHAP 1'!K13:L13 -> 703 | M19: =+'TAHAP 1'!M13 -> ARY SUSANTO | P19: AST | Q19: - | R19: AMU | Y19: =+G19 -> QA | Z19: =+I19 -> CSPV | AA19: =+K19 -> 703 | AB19: =+M19 -> ARY SUSANTO
B20: 2 | C20: =+'TAHAP 1'!C14 -> 45498 | D20: s/d | F20: =+'TAHAP 1'!F14 -> 45499 | G20: =+'TAHAP 1'!G14:H14 -> QA | I20: =+'TAHAP 1'!I14:J14 -> SPV | K20: ='TAHAP 1'!K14:L14 -> 13636 | M20: =+'TAHAP 1'!M14 -> IRAWAN RAHARDIANTO | P20: IRH | Q20: AST | Y20: =+G20 -> QA | Z20: =+I20 -> SPV | AA20: =+K20 -> 13636 | AB20: =+M20 -> IRAWAN RAHARDIANTO
B21: 3 | Y21: =+G21 -> 0 | Z21: =+I21 -> 0 | AA21: =+K21 -> 0 | AB21: =+M21 -> 0
B27: 2. BIAYA PERJALANAN DINAS | L27: UPD | O27: TRANSPORTASI | S27: HOTEL
O28: BY : CAR | Q28: LOKAL TRANSPORT | S28: Verwood Hotel Surabaya
B33: NO | C33: NAMA | G33: NIK | H33: NO. REKENING | L33: PRICE | N33: PERIODE BUDGET | O33: ESTIMATED PRICE | P33: PERIODE BUDGET | Q33: ESTIMATED PRICE | R33: PERIODE BUDGET | S33: ESTIMATED PRICE | T33: PERIODE BUDGET
B34: =+'TAPAH 2.2 (Rincian)'!B29 -> 1 | C34: =+'TAPAH 2.2 (Rincian)'!C29:F29 -> ARY SUSANTO | G34: =+'TAHAP 1'!K13 -> 703 | L34: =+'TAPAH 2.2 (Rincian)'!H29 -> 162500 | O34: =+'TAPAH 2.2 (Rincian)'!I63 -> 2850000 | Q34: 0
B35: =+'TAPAH 2.2 (Rincian)'!B30 -> 2 | C35: =+'TAPAH 2.2 (Rincian)'!C30:F30 -> IRAWAN RAHARDIANTO | G35: =+'TAHAP 1'!K14 -> 13636 | L35: =+'TAPAH 2.2 (Rincian)'!H30 -> 162500 | O35: 0 | Q35: 0
B36: =+'TAPAH 2.2 (Rincian)'!B31 -> 3 | C36: =+'TAPAH 2.2 (Rincian)'!C31:F31 -> 0 | G36: =+'TAHAP 1'!K15 -> 0 | L36: =+'TAPAH 2.2 (Rincian)'!H31 -> 0 | O36: 0 | Q36: 0
B37: SUB TOTAL | L37: =SUM(L34:M36) -> 325000 | O37: =SUM(O34:O36) -> 2850000 | Q37: =SUM(Q34:Q36) -> 0 | S37: =SUM(S34:S36) -> 0
B38: TOTAL | L38: =SUM(L37:V37) -> 3175000
B41: NOTE : 1. Ket. Budget di isi bulan periode budget atau di tulis "additional" jika additional budget 2. Approval diproses oleh User 3. Approval pada form ini akan digunakan sebagai jaminan GA dalam melakukan proses issued ticket dan hotel sebelum user melakukan pembuatan PR (purchase requisition). 4. Pembuatan PR setelah proses issued bertujuan agar tidak terjadi selisih harga PR (purchase requisition) dengan actual. | T41: 6. MENGETAHUI MGR FA
T44: BRI
B53: PERLINDUNGAN HAK CIPTA! Dokumen ini adalah milik dan untuk dipergunakan di lingkungan kerja PT. SAMI . Tidak diperkenankan memindahkan, menyalin, atau menggandakan sebagian ataupun seluruhnya isi dokumen ini dalam bentuk dan dengan cara apapun, tanpa izin tertulis dari Wakil manajemen. | I53: Referensi Prosedur/WI/OS/IS/ : PGA-GA.PD.02 : Prosedur Perjalanan Dinas | M53: 4 | N53: Penggabungan approval perjalanan dinas | Q53: 45118 | R53: Renny
M54: 3 | N54: Update Tgl Masa Berlaku & Rev. No. Dok. | Q54: 44702 | R54: Renny
M55: 2 | N55: New Format | Q55: 44314 | R55: Renny | S55: 3 | T55: =+Q53 -> 45118 | W55: FYH
M56: 1 | N56: Add Actual UPD | Q56: 44147 | R56: Renny | S56: 2 | T56: 44702 | W56: WIN
M57: 0 | N57: New Release | Q57: 45113 | R57: LNA | S57: 1 | T57: 44314 | W57: FYH
M58: REV. | N58: ISI PERUBAHAN | Q58: TANGGAL | R58: PIC | S58: REVIEW | T58: TGL | W58: PIC
