Workbook

Sheet 78
A2: Now day
A4: NO | B4: BIDANG | C4: NOW DAY
C5: Jml regulasi | D5: Identifikasi | F5: Evaluasi | H5: Implementasi
D6: Jml | E6: % | F6: Jml | G6: % | H6: Jml | I6: %
A7: 1 | B7: CORPORATE MATTERS | C7: ='Detail COMPLIANCE FIELD'!G15 -> 0 | D7: =C7 -> 0 | E7: 1 | F7: ='Detail COMPLIANCE FIELD'!I15 -> 0 | G7: 1 | H7: ='Detail COMPLIANCE FIELD'!K15 -> 0 | I7: 1
A8: 2 | B8: LABOR & HUMAN RIGHTS | C8: ='Detail COMPLIANCE FIELD'!G16 -> 99 | D8: =C8 -> 99 | E8: =D8/C8 -> 1 | F8: ='Detail COMPLIANCE FIELD'!I16 -> 99 | G8: =F8/C8 -> 1 | H8: ='Detail COMPLIANCE FIELD'!K16 -> 98 | I8: =H8/C8 -> 0.98989899
A9: 3 | B9: INTELLECTUAL PROPERTY | C9: ='Detail COMPLIANCE FIELD'!G17 -> 126 | D9: =C9 -> 126 | E9: =D9/C9 -> 1 | F9: ='Detail COMPLIANCE FIELD'!I17 -> 126 | G9: =F9/C9 -> 1 | H9: ='Detail COMPLIANCE FIELD'!K17 -> 122 | I9: =H9/C9 -> 0.96825397
A10: 4 | B10: FAIR TRADING | C10: ='Detail COMPLIANCE FIELD'!G18 -> 7 | D10: =C10 -> 7 | E10: =D10/C10 -> 1 | F10: ='Detail COMPLIANCE FIELD'!I18 -> 7 | G10: =F10/C10 -> 1 | H10: ='Detail COMPLIANCE FIELD'!K18 -> 7 | I10: =H10/C10 -> 1
A11: 5 | B11: SAFETY & HEALTH | C11: ='Detail COMPLIANCE FIELD'!G19 -> 6 | D11: =C11 -> 6 | E11: =D11/C11 -> 1 | F11: ='Detail COMPLIANCE FIELD'!I19 -> 6 | G11: =F11/C11 -> 1 | H11: ='Detail COMPLIANCE FIELD'!K19 -> 6 | I11: =H11/C11 -> 1
A12: 6 | B12: ENVIRONMENT | C12: ='Detail COMPLIANCE FIELD'!G20 -> 37 | D12: =C12 -> 37 | E12: =D12/C12 -> 1 | F12: ='Detail COMPLIANCE FIELD'!I20 -> 37 | G12: =F12/C12 -> 1 | H12: ='Detail COMPLIANCE FIELD'!K20 -> 37 | I12: =H12/C12 -> 1
B13: TOTAL | C13: =SUM(C7:C12) -> 275 | D13: =SUM(D7:D12) -> 275 | E13: =D13/C13 -> 1 | F13: =SUM(F7:F12) -> 275 | G13: =F13/C13 -> 1 | H13: =SUM(H7:H12) -> 270 | I13: =H13/C13 -> 0.98181818
A15: 7 | B15: EXIM MANAGEMENT | C15: ='Detail COMPLIANCE FIELD'!G21 -> 56 | D15: =C15 -> 56 | E15: =D15/C15 -> 1 | F15: ='Detail COMPLIANCE FIELD'!I21 -> 56 | G15: =F15/C15 -> 1 | H15: ='Detail COMPLIANCE FIELD'!K21 -> 56 | I15: =H15/C15 -> 1
A16: 8 | B16: FINANCE ACCOUNTING | C16: ='Detail COMPLIANCE FIELD'!G22 -> 123 | D16: =C16 -> 123 | E16: =D16/C16 -> 1 | F16: ='Detail COMPLIANCE FIELD'!I22 -> 123 | G16: =F16/C16 -> 1 | H16: ='Detail COMPLIANCE FIELD'!K22 -> 116 | I16: =H16/C16 -> 0.94308943
B17: TOTAL | C17: =SUM(C15:C16)+C13 -> 454 | D17: =SUM(D15:D16)+D13 -> 454 | E17: =D17/C17 -> 1 | F17: =SUM(F15:F16)+F13 -> 454 | G17: =F17/C17 -> 1 | H17: =SUM(H15:H16)+H13 -> 442 | I17: =H17/C17 -> 0.97356828
A18: PT. SEMARANG AUTOCOMP MANUFACTURING INDONESIA
A19: KEPATUHAN TERHADAP PERATURAN PERUNDANGAN
A22: NO | B22: BIDANG | C22: 43282 | J22: 43313 | Q22: 43344
C23: Jml regulasi | D23: Identifikasi | F23: Evaluasi | H23: Implementasi | J23: Jml regulasi | K23: Identifikasi | M23: Evaluasi | O23: Implementasi | Q23: Jml regulasi | R23: Identifikasi | T23: Evaluasi | V23: Implementasi
D24: Jml | E24: % | F24: Jml | G24: % | H24: Jml | I24: % | K24: Jml | L24: % | M24: Jml | N24: % | O24: Jml | P24: % | R24: Jml | S24: % | T24: Jml | U24: % | V24: Jml | W24: %
A25: 1 | B25: CORPORATE MATTERS | C25: 22 | D25: 22 | E25: =D25/C25 -> 1 | F25: 22 | G25: =F25/C25 -> 1 | H25: 20 | I25: =H25/C25 -> 0.90909091 | J25: 48 | K25: 48 | L25: =K25/J25 -> 1 | M25: 27 | N25: =M25/J25 -> 0.5625 | O25: 20 | P25: =O25/J25 -> 0.41666667 | Q25: 48 | R25: 48 | S25: =R25/Q25 -> 1 | T25: 27 | U25: =T25/Q25 -> 0.5625 | V25: 25 | W25: =V25/Q25 -> 0.52083333
A26: 2 | B26: LABOR & HUMAN RIGHTS | C26: 21 | D26: 21 | E26: =D26/C26 -> 1 | F26: 0 | G26: =F26/C26 -> 0 | H26: 0 | I26: =H26/C26 -> 0 | J26: 41 | K26: 41 | L26: =K26/J26 -> 1 | M26: 11 | N26: =M26/J26 -> 0.26829268 | O26: 11 | P26: =O26/J26 -> 0.26829268 | Q26: 36 | R26: 36 | S26: =R26/Q26 -> 1 | T26: 11 | U26: =T26/Q26 -> 0.30555556 | V26: 11 | W26: =V26/Q26 -> 0.30555556
A27: 3 | B27: INTELLECTUAL PROPERTY | C27: 2 | D27: 2 | E27: =D27/C27 -> 1 | F27: 2 | G27: =F27/C27 -> 1 | H27: 0 | I27: =H27/C27 -> 0 | J27: 2 | K27: 2 | L27: =K27/J27 -> 1 | M27: 2 | N27: =M27/J27 -> 1 | O27: 2 | P27: =O27/J27 -> 1 | Q27: 2 | R27: 2 | S27: =R27/Q27 -> 1 | T27: 2 | U27: =T27/Q27 -> 1 | V27: 2 | W27: =V27/Q27 -> 1
A28: 4 | B28: FAIR TRADING | C28: 2 | D28: 2 | E28: =D28/C28 -> 1 | F28: 2 | G28: =F28/C28 -> 1 | H28: 0 | I28: =H28/C28 -> 0 | J28: 2 | K28: 2 | L28: =K28/J28 -> 1 | M28: 2 | N28: =M28/J28 -> 1 | O28: 0 | P28: =O28/J28 -> 0 | Q28: 2 | R28: 2 | S28: =R28/Q28 -> 1 | T28: 2 | U28: =T28/Q28 -> 1 | V28: 2 | W28: =V28/Q28 -> 1
A29: 6 | B29: ENVIRONMENT | C29: 50 | D29: 50 | E29: =D29/C29 -> 1 | F29: 50 | G29: =F29/C29 -> 1 | H29: 49 | I29: =H29/C29 -> 0.98 | J29: 57 | K29: 57 | L29: =K29/J29 -> 1 | M29: 50 | N29: =M29/J29 -> 0.87719298 | O29: 49 | P29: =O29/J29 -> 0.85964912 | Q29: 57 | R29: 57 | S29: =R29/Q29 -> 1 | T29: 50 | U29: =T29/Q29 -> 0.87719298 | V29: 49 | W29: =V29/Q29 -> 0.85964912
A30: 7 | B30: SAFETY & HEALTH | C30: 27 | D30: 27 | E30: =D30/C30 -> 1 | F30: 27 | G30: =F30/C30 -> 1 | H30: 27 | I30: =H30/C30 -> 1 | J30: 27 | K30: 27 | L30: =K30/J30 -> 1 | M30: 27 | N30: =M30/J30 -> 1 | O30: 27 | P30: =O30/J30 -> 1 | Q30: 27 | R30: 27 | S30: =R30/Q30 -> 1 | T30: 27 | U30: =T30/Q30 -> 1 | V30: 27 | W30: =V30/Q30 -> 1
B31: TOTAL | C31: =SUM(C25:C30) -> 124 | D31: =SUM(D25:D30) -> 124 | E31: =D31/C31 -> 1 | F31: =SUM(F25:F30) -> 103 | G31: =F31/C31 -> 0.83064516 | H31: =SUM(H25:H30) -> 96 | I31: =H31/C31 -> 0.77419355 | J31: =SUM(J25:J30) -> 177 | K31: =SUM(K25:K30) -> 177 | L31: =K31/J31 -> 1 | M31: =SUM(M25:M30) -> 119 | N31: =M31/J31 -> 0.67231638 | O31: =SUM(O25:O30) -> 109 | P31: =O31/J31 -> 0.61581921 | Q31: =SUM(Q25:Q30) -> 172 | R31: =SUM(R25:R30) -> 172 | S31: =R31/Q31 -> 1 | T31: =SUM(T25:T30) -> 119 | U31: =SUM(U25:U30) -> 4.7452485 | V31: =SUM(V25:V30) -> 116 | W31: =V31/Q31 -> 0.6744186
A33: 5 | B33: EXIM MANAGEMENT | C33: 21 | D33: 21 | E33: =D33/C33 -> 1 | F33: 0 | G33: =F33/C33 -> 0 | H33: 0 | I33: =H33/C33 -> 0 | J33: 21 | K33: 21 | L33: =K33/J33 -> 1 | M33: 0 | N33: =M33/J33 -> 0 | O33: 0 | P33: =O33/J33 -> 0 | Q33: 21 | R33: 21 | S33: =R33/Q33 -> 1 | T33: 0 | U33: =T33/Q33 -> 0 | V33: 0 | W33: =V33/Q33 -> 0
A34: 8 | B34: FINANCE ACCOUNTING | C34: 19 | D34: 19 | E34: =D34/C34 -> 1 | F34: 0 | G34: =F34/C34 -> 0 | H34: 0 | I34: =H34/C34 -> 0 | J34: 19 | K34: 19 | L34: =K34/J34 -> 1 | M34: 0 | N34: =M34/J34 -> 0 | O34: 0 | P34: =O34/J34 -> 0 | Q34: 19 | R34: 19 | S34: =R34/Q34 -> 1 | T34: 0 | U34: =T34/Q34 -> 0 | V34: 0 | W34: =V34/Q34 -> 0
B35: TOTAL | C35: =SUM(C33:C34)+C31 -> 164 | D35: =SUM(D33:D34)+D31 -> 164 | E35: =D35/C35 -> 1 | F35: =SUM(F33:F34)+F31 -> 103 | G35: =F35/C35 -> 0.62804878 | H35: =SUM(H33:H34)+H31 -> 96 | I35: =H35/C35 -> 0.58536585 | J35: =SUM(J33:J34)+J31 -> 217 | K35: =SUM(K33:K34)+K31 -> 217 | L35: =K35/J35 -> 1 | M35: =SUM(M33:M34)+M31 -> 119 | N35: =M35/J35 -> 0.5483871 | O35: =SUM(O33:O34)+O31 -> 109 | P35: =O35/J35 -> 0.50230415 | Q35: =SUM(Q33:Q34)+Q31 -> 212 | R35: =SUM(R33:R34)+R31 -> 212 | S35: =R35/Q35 -> 1 | T35: =SUM(T33:T34)+T31 -> 119 | U35: =T35/Q35 -> 0.56132075 | V35: =SUM(V33:V34)+V31 -> 116 | W35: =V35/Q35 -> 0.54716981
A38: NO | B38: BIDANG | C38: 43374 | J38: 43405 | Q38: 43435
C39: Jml regulasi | D39: Identifikasi | F39: Evaluasi | H39: Implementasi | J39: Jml regulasi | K39: Identifikasi | M39: Evaluasi | O39: Implementasi | Q39: Jml regulasi | R39: Identifikasi | T39: Evaluasi | V39: Implementasi
D40: Jml | E40: % | F40: Jml | G40: % | H40: Jml | I40: % | K40: Jml | L40: % | M40: Jml | N40: % | O40: Jml | P40: % | R40: Jml | S40: % | T40: Jml | U40: % | V40: Jml | W40: %
A41: 1 | B41: CORPORATE MATTERS | C41: 58 | D41: 58 | E41: =D41/C41 -> 1 | F41: 27 | G41: =F41/C41 -> 0.46551724 | H41: 25 | I41: =H41/C41 -> 0.43103448 | J41: 53 | K41: 53 | L41: =K41/J41 -> 1 | M41: 38 | N41: =M41/J41 -> 0.71698113 | O41: 37 | P41: =O41/J41 -> 0.69811321 | Q41: 54 | R41: 54 | S41: =R41/Q41 -> 1 | T41: 54 | U41: =T41/Q41 -> 1 | V41: 53 | W41: =V41/Q41 -> 0.98148148
A42: 2 | B42: LABOR & HUMAN RIGHTS | C42: 39 | D42: 39 | E42: =D42/C42 -> 1 | F42: 22 | G42: =F42/C42 -> 0.56410256 | H42: 22 | I42: =H42/C42 -> 0.56410256 | J42: 42 | K42: 42 | L42: =K42/J42 -> 1 | M42: 22 | N42: =M42/J42 -> 0.52380952 | O42: 22 | P42: =O42/J42 -> 0.52380952 | Q42: 45 | R42: 45 | S42: =R42/Q42 -> 1 | T42: 37 | U42: =T42/Q42 -> 0.82222222 | V42: 35 | W42: =V42/Q42 -> 0.77777778
A43: 3 | B43: INTELLECTUAL PROPERTY | C43: 2 | D43: 2 | E43: =D43/C43 -> 1 | F43: 2 | G43: =F43/C43 -> 1 | H43: 2 | I43: =H43/C43 -> 1 | J43: 2 | K43: 2 | L43: =K43/J43 -> 1 | M43: 2 | N43: =M43/J43 -> 1 | O43: 2 | P43: =O43/J43 -> 1 | Q43: 2 | R43: 2 | S43: =R43/Q43 -> 1 | T43: 2 | U43: =T43/Q43 -> 1 | V43: 2 | W43: =V43/Q43 -> 1
A44: 7 | B44: SAFETY & HEALTH | C44: 27 | D44: 27 | E44: =D44/C44 -> 1 | F44: 27 | G44: =F44/C44 -> 1 | H44: 27 | I44: =H44/C44 -> 1 | J44: 27 | K44: 27 | L44: =K44/J44 -> 1 | M44: 27 | N44: =M44/J44 -> 1 | O44: 27 | P44: =O44/J44 -> 1 | Q44: 25 | R44: 25 | S44: =R44/Q44 -> 1 | T44: 25 | U44: =T44/Q44 -> 1 | V44: 23 | W44: =V44/Q44 -> 0.92
A45: 4 | B45: FAIR TRADING | C45: 2 | D45: 2 | E45: =D45/C45 -> 1 | F45: 2 | G45: =F45/C45 -> 1 | H45: 2 | I45: =H45/C45 -> 1 | J45: 2 | K45: 2 | L45: =K45/J45 -> 1 | M45: 2 | N45: =M45/J45 -> 1 | O45: 2 | P45: =O45/J45 -> 1 | Q45: 2 | R45: 2 | S45: =R45/Q45 -> 1 | T45: 2 | U45: =T45/Q45 -> 1 | V45: 2 | W45: =V45/Q45 -> 1
A46: 6 | B46: ENVIRONMENT | C46: 57 | D46: 57 | E46: =D46/C46 -> 1 | F46: 50 | G46: =F46/C46 -> 0.87719298 | H46: 49 | I46: =H46/C46 -> 0.85964912 | J46: 57 | K46: 57 | L46: =K46/J46 -> 1 | M46: 50 | N46: =M46/J46 -> 0.87719298 | O46: 49 | P46: =O46/J46 -> 0.85964912 | Q46: 57 | R46: 57 | S46: =R46/Q46 -> 1 | T46: 50 | U46: =T46/Q46 -> 0.87719298 | V46: 49 | W46: =V46/Q46 -> 0.85964912
B47: TOTAL | C47: =SUM(C45:C46)+C43 -> 61 | D47: =SUM(D45:D46)+D43 -> 61 | E47: =D47/C47 -> 1 | F47: =SUM(F45:F46)+F43 -> 54 | G47: =F47/C47 -> 0.8852459 | H47: =SUM(H45:H46)+H43 -> 53 | I47: =H47/C47 -> 0.86885246 | J47: =SUM(J45:J46)+J43 -> 61 | K47: =SUM(K45:K46)+K43 -> 61 | L47: =K47/J47 -> 1 | M47: =SUM(M45:M46)+M43 -> 54 | N47: =M47/J47 -> 0.8852459 | O47: =SUM(O45:O46)+O43 -> 53 | P47: =O47/J47 -> 0.86885246 | Q47: =SUM(Q45:Q46)+Q43 -> 61 | R47: =SUM(R45:R46)+R43 -> 61 | S47: =R47/Q47 -> 1 | T47: =SUM(T45:T46)+T43 -> 54 | U47: =T47/Q47 -> 0.8852459 | V47: =SUM(V45:V46)+V43 -> 53 | W47: =V47/Q47 -> 0.86885246
A49: 5 | B49: EXIM MANAGEMENT | C49: 21 | D49: 21 | E49: =D49/C49 -> 1 | F49: 0 | G49: =F49/C49 -> 0 | H49: 0 | I49: =H49/C49 -> 0 | J49: 21 | K49: 21 | L49: =K49/J49 -> 1 | M49: 0 | N49: =M49/J49 -> 0 | O49: 0 | P49: =O49/J49 -> 0 | Q49: 21 | R49: 21 | S49: =R49/Q49 -> 1 | T49: 0 | U49: =T49/Q49 -> 0 | V49: 0 | W49: =V49/Q49 -> 0
...

Sheet 79
A2: Now day
A4: NO | B4: BIDANG | C4: NOW DAY
C5: Jml regulasi | D5: Identifikasi | F5: Evaluasi | H5: Implementasi
D6: Jml | E6: % | F6: Jml | G6: % | H6: Jml | I6: %
A7: 1 | B7: COMPLIANCE IN GENERAL (1) | C7: ='Detail COMPLIANCE FIELD'!G15 -> 0 | D7: =C7 -> 0 | E7: 1 | F7: ='Detail COMPLIANCE FIELD'!I15 -> 0 | G7: 1 | H7: ='Detail COMPLIANCE FIELD'!K15 -> 0 | I7: 1
A8: 2 | B8: LABOR & HUMAN RIGHTS (3) | C8: ='Detail COMPLIANCE FIELD'!G16 -> 99 | D8: =C8 -> 99 | E8: =D8/C8 -> 1 | F8: ='Detail COMPLIANCE FIELD'!I16 -> 99 | G8: =F8/C8 -> 1 | H8: ='Detail COMPLIANCE FIELD'!K16 -> 98 | I8: =H8/C8 -> 0.98989899
A9: 3 | B9: INTELLECTUAL PROPERTY (4) | C9: ='Detail COMPLIANCE FIELD'!G17 -> 126 | D9: =C9 -> 126 | E9: =D9/C9 -> 1 | F9: ='Detail COMPLIANCE FIELD'!I17 -> 126 | G9: =F9/C9 -> 1 | H9: ='Detail COMPLIANCE FIELD'!K17 -> 122 | I9: =H9/C9 -> 0.96825397
A10: 4 | B10: FAIR TRADING (5) | C10: ='Detail COMPLIANCE FIELD'!G18 -> 7 | D10: =C10 -> 7 | E10: =D10/C10 -> 1 | F10: ='Detail COMPLIANCE FIELD'!I18 -> 7 | G10: =F10/C10 -> 1 | H10: ='Detail COMPLIANCE FIELD'!K18 -> 7 | I10: =H10/C10 -> 1
A11: 5 | B11: ENVIRONMENT, SAFETY & HEALTH (8) | C11: ='Detail COMPLIANCE FIELD'!G19 -> 6 | D11: =C11 -> 6 | E11: =D11/C11 -> 1 | F11: ='Detail COMPLIANCE FIELD'!I19 -> 6 | G11: =F11/C11 -> 1 | H11: ='Detail COMPLIANCE FIELD'!K19 -> 6 | I11: =H11/C11 -> 1
A12: 6 | B12: COMPANY /BUSINESS OPERATIONS & LICENSE (2) | C12: ='Detail COMPLIANCE FIELD'!G20 -> 37 | D12: =C12 -> 37 | E12: =D12/C12 -> 1 | F12: ='Detail COMPLIANCE FIELD'!I20 -> 37 | G12: =F12/C12 -> 1 | H12: ='Detail COMPLIANCE FIELD'!K20 -> 37 | I12: =H12/C12 -> 1
B13: TOTAL | C13: =SUM(C7:C12) -> 275 | D13: =SUM(D7:D12) -> 275 | E13: =D13/C13 -> 1 | F13: =SUM(F7:F12) -> 275 | G13: =F13/C13 -> 1 | H13: =SUM(H7:H12) -> 270 | I13: =H13/C13 -> 0.98181818
A15: 7 | B15: EXIM MANAGEMENT (6) | C15: ='Detail COMPLIANCE FIELD'!G21 -> 56 | D15: =C15 -> 56 | E15: =D15/C15 -> 1 | F15: ='Detail COMPLIANCE FIELD'!I21 -> 56 | G15: =F15/C15 -> 1 | H15: ='Detail COMPLIANCE FIELD'!K21 -> 56 | I15: =H15/C15 -> 1
A16: 8 | B16: ACCOUNTING /FINANCE (7) | C16: ='Detail COMPLIANCE FIELD'!G22 -> 123 | D16: =C16 -> 123 | E16: =D16/C16 -> 1 | F16: ='Detail COMPLIANCE FIELD'!I22 -> 123 | G16: =F16/C16 -> 1 | H16: ='Detail COMPLIANCE FIELD'!K22 -> 116 | I16: =H16/C16 -> 0.94308943
B17: TOTAL | C17: =SUM(C15:C16)+C13 -> 454 | D17: =SUM(D15:D16)+D13 -> 454 | E17: =D17/C17 -> 1 | F17: =SUM(F15:F16)+F13 -> 454 | G17: =F17/C17 -> 1 | H17: =SUM(H15:H16)+H13 -> 442 | I17: =H17/C17 -> 0.97356828
A18: PT. SEMARANG AUTOCOMP MANUFACTURING INDONESIA
A19: KEPATUHAN TERHADAP PERATURAN PERUNDANGAN
A21: NO | B21: BIDANG | C21: 43647 | J21: 43678 | Q21: 43709
C22: Jml regulasi | D22: Identifikasi | F22: Evaluasi | H22: Implementasi | J22: Jml regulasi | K22: Identifikasi | M22: Evaluasi | O22: Implementasi | Q22: Jml regulasi | R22: Identifikasi | T22: Evaluasi | V22: Implementasi
D23: Jml | E23: % | F23: Jml | G23: % | H23: Jml | I23: % | K23: Jml | L23: % | M23: Jml | N23: % | O23: Jml | P23: % | R23: Jml | S23: % | T23: Jml | U23: % | V23: Jml | W23: %
A24: 1 | B24: COMPLIANCE IN GENERAL (1) | C24: 0 | D24: 0 | E24: =D24/C24 -> #DIV/0! | F24: 0 | G24: =F24/C24 -> #DIV/0! | H24: 0 | I24: =H24/C24 -> #DIV/0! | J24: 0 | K24: 0 | L24: =K24/J24 -> #DIV/0! | M24: 0 | N24: =M24/J24 -> #DIV/0! | O24: 0 | P24: =O24/J24 -> #DIV/0! | Q24: 0 | R24: 0 | S24: =R24/Q24 -> #DIV/0! | T24: 0 | U24: =T24/Q24 -> #DIV/0! | V24: 0 | W24: =V24/Q24 -> #DIV/0!
A25: 2 | B25: LABOR & HUMAN RIGHTS (3) | C25: 50 | D25: 50 | E25: =D25/C25 -> 1 | F25: 47 | G25: =F25/C25 -> 0.94 | H25: 47 | I25: =H25/C25 -> 0.94 | J25: 51 | K25: 51 | L25: =K25/J25 -> 1 | M25: 47 | N25: =M25/J25 -> 0.92156863 | O25: 47 | P25: =O25/J25 -> 0.92156863 | Q25: 52 | R25: 52 | S25: =R25/Q25 -> 1 | T25: 52 | U25: =T25/Q25 -> 1 | V25: 51 | W25: =V25/Q25 -> 0.98076923
B26: a. HR | Q26: 31 | R26: 31 | S26: =R26/Q26 -> 1 | T26: 31 | U26: =T26/Q26 -> 1 | V26: 31 | W26: =V26/Q26 -> 1
B27: b. Expat | Q27: 20 | R27: 20 | S27: =R27/Q27 -> 1 | T27: 20 | U27: =T27/Q27 -> 1 | V27: 19 | W27: =V27/Q27 -> 0.95
B28: c. TRN | Q28: 1 | R28: 1 | S28: =R28/Q28 -> 1 | T28: 1 | U28: =T28/Q28 -> 1 | V28: 1 | W28: =V28/Q28 -> 1
A29: 3 | B29: INTELLECTUAL PROPERTY (4) | C29: 5 | D29: 5 | E29: =D29/C29 -> 1 | F29: 5 | G29: =F29/C29 -> 1 | H29: 5 | I29: =H29/C29 -> 1 | J29: 5 | K29: 5 | L29: =K29/J29 -> 1 | M29: 5 | N29: =M29/J29 -> 1 | O29: 5 | P29: =O29/J29 -> 1 | Q29: 6 | R29: 6 | S29: =R29/Q29 -> 1 | T29: 6 | U29: =T29/Q29 -> 1 | V29: 6 | W29: =V29/Q29 -> 1
A30: 4 | B30: FAIR TRADING (5) | C30: 3 | D30: 3 | E30: =D30/C30 -> 1 | F30: 2 | G30: =F30/C30 -> 0.66666667 | H30: 2 | I30: =H30/C30 -> 0.66666667 | J30: 3 | K30: 3 | L30: =K30/J30 -> 1 | M30: 2 | N30: =M30/J30 -> 0.66666667 | O30: 2 | P30: =O30/J30 -> 0.66666667 | Q30: 3 | R30: 3 | S30: =R30/Q30 -> 1 | T30: 3 | U30: =T30/Q30 -> 1 | V30: 3 | W30: =V30/Q30 -> 1
A31: 6 | B31: ENVIRONMENT, SAFETY & HEALTH (8) | C31: 76 | D31: 76 | E31: =D31/C31 -> 1 | F31: 73 | G31: =F31/C31 -> 0.96052632 | H31: 70 | I31: =H31/C31 -> 0.92105263 | J31: 109 | K31: 109 | L31: =K31/J31 -> 1 | M31: 75 | N31: =M31/J31 -> 0.68807339 | O31: 70 | P31: =O31/J31 -> 0.64220183 | Q31: 109 | R31: 109 | S31: =R31/Q31 -> 1 | T31: 79 | U31: =T31/Q31 -> 0.72477064 | V31: 75 | W31: =V31/Q31 -> 0.68807339
B32: a. Safety & Health | Q32: 24 | R32: 24 | S32: =R32/Q32 -> 1 | T32: 24 | U32: =T32/Q32 -> 1 | V32: 23 | W32: =V32/Q32 -> 0.95833333
B33: b. Environment | Q33: 77 | R33: 77 | S33: =R33/Q33 -> 1 | T33: 53 | U33: =T33/Q33 -> 0.68831169 | V33: 52 | W33: =V33/Q33 -> 0.67532468
B34: c. SoC | Q34: 8 | R34: 8 | S34: =R34/Q34 -> 1 | T34: 2 | U34: =T34/Q34 -> 0.25 | V34: 0 | W34: =V34/Q34 -> 0
A35: 7 | B35: COMPANY /BUSINESS OPERATIONS & LICENSE (2) | C35: 46 | D35: 46 | E35: =D35/C35 -> 1 | F35: 45 | G35: =F35/C35 -> 0.97826087 | H35: 44 | I35: =H35/C35 -> 0.95652174 | J35: 52 | K35: 52 | L35: =K35/J35 -> 1 | M35: 46 | N35: =M35/J35 -> 0.88461538 | O35: 44 | P35: =O35/J35 -> 0.84615385 | Q35: 51 | R35: 51 | S35: =R35/Q35 -> 1 | T35: 51 | U35: =T35/Q35 -> 1 | V35: 46 | W35: =V35/Q35 -> 0.90196078
B36: TOTAL | C36: =SUM(C24:C35) -> 180 | D36: =SUM(D24:D35) -> 180 | E36: =D36/C36 -> 1 | F36: =SUM(F24:F35) -> 172 | G36: =F36/C36 -> 0.95555556 | H36: =SUM(H24:H35) -> 168 | I36: =H36/C36 -> 0.93333333 | J36: =SUM(J24:J35) -> 220 | K36: =SUM(K24:K35) -> 220 | L36: =K36/J36 -> 1 | M36: =SUM(M24:M35) -> 175 | N36: =M36/J36 -> 0.79545455 | O36: =SUM(O24:O35) -> 168 | P36: =O36/J36 -> 0.76363636 | Q36: =Q24+Q25+Q29+Q30+Q31+Q35 -> 221 | R36: =R24+R25+R29+R30+R31+R35 -> 221 | S36: =R36/Q36 -> 1 | T36: =T24+T25+T29+T30+T31+T35 -> 191 | U36: =T36/Q36 -> 0.86425339 | V36: =V24+V25+V29+V30+V31+V35 -> 181 | W36: =V36/Q36 -> 0.81900452
A38: 5 | B38: EXIM MANAGEMENT (6) | C38: 25 | D38: 25 | E38: =D38/C38 -> 1 | F38: 23 | G38: =F38/C38 -> 0.92 | H38: 23 | I38: =H38/C38 -> 0.92 | J38: 65 | K38: 65 | L38: =K38/J38 -> 1 | M38: 23 | N38: =M38/J38 -> 0.35384615 | O38: 23 | P38: =O38/J38 -> 0.35384615 | Q38: 65 | R38: 65 | S38: =R38/Q38 -> 1 | T38: 23 | U38: =T38/Q38 -> 0.35384615 | V38: 23 | W38: =V38/Q38 -> 0.35384615
A39: 8 | B39: ACCOUNTING /FINANCE (7) | C39: 20 | D39: 20 | E39: =D39/C39 -> 1 | F39: 3 | G39: =F39/C39 -> 0.15 | H39: 3 | I39: =H39/C39 -> 0.15 | J39: 33 | K39: 33 | L39: =K39/J39 -> 1 | M39: 18 | N39: =M39/J39 -> 0.54545455 | O39: 17 | P39: =O39/J39 -> 0.51515152 | Q39: 33 | R39: 33 | S39: =R39/Q39 -> 1 | T39: 18 | U39: =T39/Q39 -> 0.54545455 | V39: 17 | W39: =V39/Q39 -> 0.51515152
B40: TOTAL | C40: =SUM(C38:C39)+C36 -> 225 | D40: =SUM(D38:D39)+D36 -> 225 | E40: =D40/C40 -> 1 | F40: =SUM(F38:F39)+F36 -> 198 | G40: =F40/C40 -> 0.88 | H40: =SUM(H38:H39)+H36 -> 194 | I40: =H40/C40 -> 0.86222222 | J40: =SUM(J38:J39)+J36 -> 318 | K40: =SUM(K38:K39)+K36 -> 318 | L40: =K40/J40 -> 1 | M40: =SUM(M38:M39)+M36 -> 216 | N40: =M40/J40 -> 0.67924528 | O40: =SUM(O38:O39)+O36 -> 208 | P40: =O40/J40 -> 0.65408805 | Q40: =SUM(Q38:Q39)+Q36 -> 319 | R40: =SUM(R38:R39)+R36 -> 319 | S40: =R40/Q40 -> 1 | T40: =SUM(T38:T39)+T36 -> 232 | U40: =T40/Q40 -> 0.72727273 | V40: =SUM(V38:V39)+V36 -> 221 | W40: =V40/Q40 -> 0.69278997
A43: NO | B43: BIDANG | C43: 43739 | J43: 43770 | Q43: 43800
C44: Jml regulasi | D44: Identifikasi | F44: Evaluasi | H44: Implementasi | J44: Jml regulasi | K44: Identifikasi | M44: Evaluasi | O44: Implementasi | Q44: Jml regulasi | R44: Identifikasi | T44: Evaluasi | V44: Implementasi
D45: Jml | E45: % | F45: Jml | G45: % | H45: Jml | I45: % | K45: Jml | L45: % | M45: Jml | N45: % | O45: Jml | P45: % | R45: Jml | S45: % | T45: Jml | U45: % | V45: Jml | W45: %
A46: 1 | B46: COMPLIANCE IN GENERAL (1) | C46: 0 | D46: 0 | E46: =D46/C46 -> #DIV/0! | F46: 0 | G46: =F46/C46 -> #DIV/0! | H46: 0 | I46: =H46/C46 -> #DIV/0! | J46: 0 | K46: 0 | L46: =K46/J46 -> #DIV/0! | M46: 0 | N46: =M46/J46 -> #DIV/0! | O46: 0 | P46: =O46/J46 -> #DIV/0! | Q46: 0 | R46: 0 | S46: =R46/Q46 -> #DIV/0! | T46: 0 | U46: =T46/Q46 -> #DIV/0! | V46: 0 | W46: =V46/Q46 -> #DIV/0!
A47: 2 | B47: LABOR & HUMAN RIGHTS (3) | C47: 53 | D47: 53 | E47: =D47/C47 -> 1 | F47: 53 | G47: =F47/C47 -> 1 | H47: 53 | I47: =H47/C47 -> 1 | J47: 55 | K47: 55 | L47: =K47/J47 -> 1 | M47: 55 | N47: =M47/J47 -> 1 | O47: 55 | P47: =O47/J47 -> 1 | Q47: 58 | R47: 58 | S47: =R47/Q47 -> 1 | T47: 55 | U47: =T47/Q47 -> 0.94827586 | V47: 55 | W47: =V47/Q47 -> 0.94827586
...

Sheet 80
A2: Now day
A4: NO | B4: BIDANG | C4: NOW DAY
C5: Jml regulasi | D5: Identifikasi | F5: Evaluasi | H5: Implementasi
D6: Jml | E6: % | F6: Jml | G6: % | H6: Jml | I6: %
A7: 1 | B7: COMPLIANCE IN GENERAL (1) | C7: ='Detail COMPLIANCE FIELD'!G15 -> 0 | D7: =C7 -> 0 | E7: 1 | F7: ='Detail COMPLIANCE FIELD'!I15 -> 0 | G7: 1 | H7: ='Detail COMPLIANCE FIELD'!K15 -> 0 | I7: 1
A8: 2 | B8: LABOR & HUMAN RIGHTS (3) | C8: ='Detail COMPLIANCE FIELD'!G16 -> 99 | D8: =C8 -> 99 | E8: =D8/C8 -> 1 | F8: ='Detail COMPLIANCE FIELD'!I16 -> 99 | G8: =F8/C8 -> 1 | H8: ='Detail COMPLIANCE FIELD'!K16 -> 98 | I8: =H8/C8 -> 0.98989899
A9: 3 | B9: INTELLECTUAL PROPERTY (4) | C9: ='Detail COMPLIANCE FIELD'!G17 -> 126 | D9: =C9 -> 126 | E9: =D9/C9 -> 1 | F9: ='Detail COMPLIANCE FIELD'!I17 -> 126 | G9: =F9/C9 -> 1 | H9: ='Detail COMPLIANCE FIELD'!K17 -> 122 | I9: =H9/C9 -> 0.96825397
A10: 4 | B10: FAIR TRADING (5) | C10: ='Detail COMPLIANCE FIELD'!G18 -> 7 | D10: =C10 -> 7 | E10: =D10/C10 -> 1 | F10: ='Detail COMPLIANCE FIELD'!I18 -> 7 | G10: =F10/C10 -> 1 | H10: ='Detail COMPLIANCE FIELD'!K18 -> 7 | I10: =H10/C10 -> 1
A11: 5 | B11: ENVIRONMENT, SAFETY & HEALTH (8) | C11: ='Detail COMPLIANCE FIELD'!G19 -> 6 | D11: =C11 -> 6 | E11: =D11/C11 -> 1 | F11: ='Detail COMPLIANCE FIELD'!I19 -> 6 | G11: =F11/C11 -> 1 | H11: ='Detail COMPLIANCE FIELD'!K19 -> 6 | I11: =H11/C11 -> 1
A12: 6 | B12: COMPANY /BUSINESS OPERATIONS & LICENSE (2) | C12: ='Detail COMPLIANCE FIELD'!G20 -> 37 | D12: =C12 -> 37 | E12: =D12/C12 -> 1 | F12: ='Detail COMPLIANCE FIELD'!I20 -> 37 | G12: =F12/C12 -> 1 | H12: ='Detail COMPLIANCE FIELD'!K20 -> 37 | I12: =H12/C12 -> 1
B13: TOTAL | C13: =SUM(C7:C12) -> 275 | D13: =SUM(D7:D12) -> 275 | E13: =D13/C13 -> 1 | F13: =SUM(F7:F12) -> 275 | G13: =F13/C13 -> 1 | H13: =SUM(H7:H12) -> 270 | I13: =H13/C13 -> 0.98181818
A15: 7 | B15: EXIM MANAGEMENT (6) | C15: ='Detail COMPLIANCE FIELD'!G21 -> 56 | D15: =C15 -> 56 | E15: =D15/C15 -> 1 | F15: ='Detail COMPLIANCE FIELD'!I21 -> 56 | G15: =F15/C15 -> 1 | H15: ='Detail COMPLIANCE FIELD'!K21 -> 56 | I15: =H15/C15 -> 1
A16: 8 | B16: ACCOUNTING /FINANCE (7) | C16: ='Detail COMPLIANCE FIELD'!G22 -> 123 | D16: =C16 -> 123 | E16: =D16/C16 -> 1 | F16: ='Detail COMPLIANCE FIELD'!I22 -> 123 | G16: =F16/C16 -> 1 | H16: ='Detail COMPLIANCE FIELD'!K22 -> 116 | I16: =H16/C16 -> 0.94308943
B17: TOTAL | C17: =SUM(C15:C16)+C13 -> 454 | D17: =SUM(D15:D16)+D13 -> 454 | E17: =D17/C17 -> 1 | F17: =SUM(F15:F16)+F13 -> 454 | G17: =F17/C17 -> 1 | H17: =SUM(H15:H16)+H13 -> 442 | I17: =H17/C17 -> 0.97356828
A18: PT. SEMARANG AUTOCOMP MANUFACTURING INDONESIA
A19: KEPATUHAN TERHADAP PERATURAN PERUNDANGAN
A21: NO | B21: BIDANG | C21: 44013 | J21: 44044 | Q21: 44075
C22: Jml regulasi | D22: Identifikasi | F22: Evaluasi | H22: Implementasi | J22: Jml regulasi | K22: Identifikasi | M22: Evaluasi | O22: Implementasi | Q22: Jml regulasi | R22: Identifikasi | T22: Evaluasi | V22: Implementasi
D23: Jml | E23: % | F23: Jml | G23: % | H23: Jml | I23: % | K23: Jml | L23: % | M23: Jml | N23: % | O23: Jml | P23: % | R23: Jml | S23: % | T23: Jml | U23: % | V23: Jml | W23: %
A24: 1 | B24: COMPLIANCE IN GENERAL (1) | C24: 0 | D24: 0 | E24: =D24/C24 -> #DIV/0! | F24: 0 | G24: =F24/C24 -> #DIV/0! | H24: 0 | I24: =H24/C24 -> #DIV/0! | J24: 0 | K24: 0 | L24: =K24/J24 -> #DIV/0! | M24: 0 | N24: =M24/J24 -> #DIV/0! | O24: 0 | P24: =O24/J24 -> #DIV/0! | Q24: 0 | R24: 0 | S24: =R24/Q24 -> #DIV/0! | T24: 0 | U24: =T24/Q24 -> #DIV/0! | V24: 0 | W24: =V24/Q24 -> #DIV/0!
A25: 2 | B25: LABOR & HUMAN RIGHTS (3) | C25: 61 | D25: 61 | E25: =D25/C25 -> 1 | F25: 57 | G25: =F25/C25 -> 0.93442623 | H25: 57 | I25: =H25/C25 -> 0.93442623 | J25: 62 | K25: 62 | L25: =K25/J25 -> 1 | M25: 62 | N25: =M25/J25 -> 1 | O25: 58 | P25: =O25/J25 -> 0.93548387 | Q25: 62 | R25: 62 | S25: =R25/Q25 -> 1 | T25: 62 | U25: =T25/Q25 -> 1 | V25: 62 | W25: =V25/Q25 -> 1
B26: a. HR | C26: 38 | D26: 38 | E26: =D26/C26 -> 1 | F26: 35 | G26: =F26/C26 -> 0.92105263 | H26: 35 | I26: =H26/C26 -> 0.92105263 | J26: 39 | K26: 39 | L26: =K26/J26 -> 1 | M26: 39 | N26: =M26/J26 -> 1 | O26: 35 | P26: =O26/J26 -> 0.8974359 | Q26: 39 | R26: 39 | S26: =R26/Q26 -> 1 | T26: 39 | U26: =T26/Q26 -> 1 | V26: 39 | W26: =V26/Q26 -> 1
B27: b. Expat | C27: 22 | D27: 22 | E27: =D27/C27 -> 1 | F27: 21 | G27: =F27/C27 -> 0.95454545 | H27: 21 | I27: =H27/C27 -> 0.95454545 | J27: 22 | K27: 22 | L27: =K27/J27 -> 1 | M27: 22 | N27: =M27/J27 -> 1 | O27: 21 | P27: =O27/J27 -> 0.95454545 | Q27: 22 | R27: 22 | S27: =R27/Q27 -> 1 | T27: 22 | U27: =T27/Q27 -> 1 | V27: 22 | W27: =V27/Q27 -> 1
B28: c. TRN | C28: 1 | D28: 1 | E28: =D28/C28 -> 1 | F28: 1 | G28: =F28/C28 -> 1 | H28: 1 | I28: =H28/C28 -> 1 | J28: 1 | K28: 1 | L28: =K28/J28 -> 1 | M28: 1 | N28: =M28/J28 -> 1 | O28: 1 | P28: =O28/J28 -> 1 | Q28: 1 | R28: 1 | S28: =R28/Q28 -> 1 | T28: 1 | U28: =T28/Q28 -> 1 | V28: 1 | W28: =V28/Q28 -> 1
A29: 3 | B29: INTELLECTUAL PROPERTY (4) | C29: 5 | D29: 5 | E29: =D29/C29 -> 1 | F29: 5 | G29: =F29/C29 -> 1 | H29: 5 | I29: =H29/C29 -> 1 | J29: 5 | K29: 5 | L29: =K29/J29 -> 1 | M29: 5 | N29: =M29/J29 -> 1 | O29: 5 | P29: =O29/J29 -> 1 | Q29: 5 | R29: 5 | S29: =R29/Q29 -> 1 | T29: 5 | U29: =T29/Q29 -> 1 | V29: 5 | W29: =V29/Q29 -> 1
A30: 4 | B30: FAIR TRADING (5) | C30: 3 | D30: 3 | E30: =D30/C30 -> 1 | F30: 3 | G30: =F30/C30 -> 1 | H30: 3 | I30: =H30/C30 -> 1 | J30: 3 | K30: 3 | L30: =K30/J30 -> 1 | M30: 3 | N30: =M30/J30 -> 1 | O30: 3 | P30: =O30/J30 -> 1 | Q30: 3 | R30: 3 | S30: =R30/Q30 -> 1 | T30: 3 | U30: =T30/Q30 -> 1 | V30: 3 | W30: =V30/Q30 -> 1
A31: 6 | B31: ENVIRONMENT, SAFETY & HEALTH (8) | C31: 100 | D31: 100 | E31: =D31/C31 -> 1 | F31: 97 | G31: =F31/C31 -> 0.97 | H31: 91 | I31: =H31/C31 -> 0.91 | J31: 102 | K31: 102 | L31: =K31/J31 -> 1 | M31: 102 | N31: =M31/J31 -> 1 | O31: 92 | P31: =O31/J31 -> 0.90196078 | Q31: 105 | R31: 105 | S31: =R31/Q31 -> 1 | T31: 105 | U31: =T31/Q31 -> 1 | V31: 99 | W31: =V31/Q31 -> 0.94285714
B32: a. Safety & Health | C32: 30 | D32: 30 | E32: =D32/C32 -> 1 | F32: 29 | G32: =F32/C32 -> 0.96666667 | H32: 25 | I32: =H32/C32 -> 0.83333333 | J32: 31 | K32: 31 | L32: =K32/J32 -> 1 | M32: 31 | N32: =M32/J32 -> 1 | O32: 26 | P32: =O32/J32 -> 0.83870968 | Q32: 34 | R32: 34 | S32: =R32/Q32 -> 1 | T32: 34 | U32: =T32/Q32 -> 1 | V32: 30 | W32: =V32/Q32 -> 0.88235294
B33: b. Environment | C33: 61 | D33: 61 | E33: =D33/C33 -> 1 | F33: 60 | G33: =F33/C33 -> 0.98360656 | H33: 58 | I33: =H33/C33 -> 0.95081967 | J33: 62 | K33: 62 | L33: =K33/J33 -> 1 | M33: 62 | N33: =M33/J33 -> 1 | O33: 58 | P33: =O33/J33 -> 0.93548387 | Q33: 62 | R33: 62 | S33: =R33/Q33 -> 1 | T33: 62 | U33: =T33/Q33 -> 1 | V33: 60 | W33: =V33/Q33 -> 0.96774194
B34: c. SoC | C34: 9 | D34: 9 | E34: =D34/C34 -> 1 | F34: 8 | G34: =F34/C34 -> 0.88888889 | H34: 8 | I34: =H34/C34 -> 0.88888889 | J34: 9 | K34: 9 | L34: =K34/J34 -> 1 | M34: 9 | N34: =M34/J34 -> 1 | O34: 8 | P34: =O34/J34 -> 0.88888889 | Q34: 9 | R34: 9 | S34: =R34/Q34 -> 1 | T34: 9 | U34: =T34/Q34 -> 1 | V34: 9 | W34: =V34/Q34 -> 1
A35: 7 | B35: COMPANY /BUSINESS OPERATIONS & LICENSE (2) | C35: 54 | D35: 54 | E35: =D35/C35 -> 1 | F35: 50 | G35: =F35/C35 -> 0.92592593 | H35: 49 | I35: =H35/C35 -> 0.90740741 | J35: 62 | K35: 62 | L35: =K35/J35 -> 1 | M35: 62 | N35: =M35/J35 -> 1 | O35: 49 | P35: =O35/J35 -> 0.79032258 | Q35: 63 | R35: 63 | S35: =R35/Q35 -> 1 | T35: 63 | U35: =T35/Q35 -> 1 | V35: 54 | W35: =V35/Q35 -> 0.85714286
B36: TOTAL | C36: =C24+C25+C29+C30+C31+C35 -> 223 | D36: =D24+D25+D29+D30+D31+D35 -> 223 | E36: =D36/C36 -> 1 | F36: =F24+F25+F29+F30+F31+F35 -> 212 | G36: =F36/C36 -> 0.95067265 | H36: =H24+H25+H29+H30+H31+H35 -> 205 | I36: =H36/C36 -> 0.91928251 | J36: =J24+J25+J29+J30+J31+J35 -> 234 | K36: =K24+K25+K29+K30+K31+K35 -> 234 | L36: =K36/J36 -> 1 | M36: =M24+M25+M29+M30+M31+M35 -> 234 | N36: =M36/J36 -> 1 | O36: =O24+O25+O29+O30+O31+O35 -> 207 | P36: =O36/J36 -> 0.88461538 | Q36: =Q24+Q25+Q29+Q30+Q31+Q35 -> 238 | R36: =R24+R25+R29+R30+R31+R35 -> 238 | S36: =R36/Q36 -> 1 | T36: =T24+T25+T29+T30+T31+T35 -> 238 | U36: =T36/Q36 -> 1 | V36: =V24+V25+V29+V30+V31+V35 -> 223 | W36: =V36/Q36 -> 0.93697479
A38: 5 | B38: EXIM MANAGEMENT (6) | C38: 13 | D38: 13 | E38: =D38/C38 -> 1 | F38: 11 | G38: =F38/C38 -> 0.84615385 | H38: 11 | I38: =H38/C38 -> 0.84615385 | J38: 15 | K38: 15 | L38: =K38/J38 -> 1 | M38: 15 | N38: =M38/J38 -> 1 | O38: 11 | P38: =O38/J38 -> 0.73333333 | Q38: 15 | R38: 15 | S38: =R38/Q38 -> 1 | T38: 15 | U38: =T38/Q38 -> 1 | V38: 11 | W38: =V38/Q38 -> 0.73333333
A39: 8 | B39: ACCOUNTING /FINANCE (7) | C39: 21 | D39: 21 | E39: =D39/C39 -> 1 | F39: 19 | G39: =F39/C39 -> 0.9047619 | H39: 19 | I39: =H39/C39 -> 0.9047619 | J39: 26 | K39: 26 | L39: =K39/J39 -> 1 | M39: 26 | N39: =M39/J39 -> 1 | O39: 19 | P39: =O39/J39 -> 0.73076923 | Q39: 26 | R39: 26 | S39: =R39/Q39 -> 1 | T39: 26 | U39: =T39/Q39 -> 1 | V39: 26 | W39: =V39/Q39 -> 1
B40: TOTAL | C40: =SUM(C38:C39)+C36 -> 257 | D40: =SUM(D38:D39)+D36 -> 257 | E40: =D40/C40 -> 1 | F40: =SUM(F38:F39)+F36 -> 242 | G40: =F40/C40 -> 0.94163424 | H40: =SUM(H38:H39)+H36 -> 235 | I40: =H40/C40 -> 0.91439689 | J40: =SUM(J38:J39)+J36 -> 275 | K40: =SUM(K38:K39)+K36 -> 275 | L40: =K40/J40 -> 1 | M40: =SUM(M38:M39)+M36 -> 275 | N40: =M40/J40 -> 1 | O40: =SUM(O38:O39)+O36 -> 237 | P40: =O40/J40 -> 0.86181818 | Q40: =SUM(Q38:Q39)+Q36 -> 279 | R40: =SUM(R38:R39)+R36 -> 279 | S40: =R40/Q40 -> 1 | T40: =SUM(T38:T39)+T36 -> 279 | U40: =T40/Q40 -> 1 | V40: =SUM(V38:V39)+V36 -> 260 | W40: =V40/Q40 -> 0.93189964
A43: NO | B43: BIDANG | C43: 44105 | J43: 44136 | Q43: 44166
C44: Jml regulasi | D44: Identifikasi | F44: Evaluasi | H44: Implementasi | J44: Jml regulasi | K44: Identifikasi | M44: Evaluasi | O44: Implementasi | Q44: Jml regulasi | R44: Identifikasi | T44: Evaluasi | V44: Implementasi
D45: Jml | E45: % | F45: Jml | G45: % | H45: Jml | I45: % | K45: Jml | L45: % | M45: Jml | N45: % | O45: Jml | P45: % | R45: Jml | S45: % | T45: Jml | U45: % | V45: Jml | W45: %
A46: 1 | B46: COMPLIANCE IN GENERAL (1) | C46: 0 | D46: 0 | E46: =D46/C46 -> #DIV/0! | F46: 0 | G46: =F46/C46 -> #DIV/0! | H46: 0 | I46: =H46/C46 -> #DIV/0! | J46: 0 | K46: 0 | L46: =K46/J46 -> #DIV/0! | M46: 0 | N46: =M46/J46 -> #DIV/0! | O46: 0 | P46: =O46/J46 -> #DIV/0! | Q46: 0 | R46: 0 | S46: =R46/Q46 -> #DIV/0! | T46: 0 | U46: =T46/Q46 -> #DIV/0! | V46: 0 | W46: =V46/Q46 -> #DIV/0!
A47: 2 | B47: LABOR & HUMAN RIGHTS (3) | C47: 64 | D47: 64 | E47: =D47/C47 -> 1 | F47: 64 | G47: =F47/C47 -> 1 | H47: 63 | I47: =H47/C47 -> 0.984375 | J47: 65 | K47: 65 | L47: =K47/J47 -> 1 | M47: 65 | N47: =M47/J47 -> 1 | O47: 64 | P47: =O47/J47 -> 0.98461538 | Q47: 65 | R47: 65 | S47: =R47/Q47 -> 1 | T47: 65 | U47: =T47/Q47 -> 1 | V47: 64 | W47: =V47/Q47 -> 0.98461538
...

Sheet 81
A2: Now day
A4: NO | B4: BIDANG | C4: NOW DAY
C5: Jml regulasi | D5: Identifikasi | F5: Evaluasi | H5: Implementasi
D6: Jml | E6: % | F6: Jml | G6: % | H6: Jml | I6: %
A7: 1 | B7: COMPLIANCE IN GENERAL (1) | C7: ='Detail COMPLIANCE FIELD'!G15 -> 0 | D7: =C7 -> 0 | E7: 1 | F7: ='Detail COMPLIANCE FIELD'!I15 -> 0 | G7: 1 | H7: ='Detail COMPLIANCE FIELD'!K15 -> 0 | I7: 1
A8: 2 | B8: LABOR & HUMAN RIGHTS (3) | C8: ='Detail COMPLIANCE FIELD'!G16 -> 99 | D8: =C8 -> 99 | E8: =D8/C8 -> 1 | F8: ='Detail COMPLIANCE FIELD'!I16 -> 99 | G8: =F8/C8 -> 1 | H8: ='Detail COMPLIANCE FIELD'!K16 -> 98 | I8: =H8/C8 -> 0.98989899
A9: 3 | B9: INTELLECTUAL PROPERTY (4) | C9: ='Detail COMPLIANCE FIELD'!G17 -> 126 | D9: =C9 -> 126 | E9: =D9/C9 -> 1 | F9: ='Detail COMPLIANCE FIELD'!I17 -> 126 | G9: =F9/C9 -> 1 | H9: ='Detail COMPLIANCE FIELD'!K17 -> 122 | I9: =H9/C9 -> 0.96825397
A10: 4 | B10: FAIR TRADING (5) | C10: ='Detail COMPLIANCE FIELD'!G18 -> 7 | D10: =C10 -> 7 | E10: =D10/C10 -> 1 | F10: ='Detail COMPLIANCE FIELD'!I18 -> 7 | G10: =F10/C10 -> 1 | H10: ='Detail COMPLIANCE FIELD'!K18 -> 7 | I10: =H10/C10 -> 1
A11: 5 | B11: ENVIRONMENT, SAFETY & HEALTH (8) | C11: ='Detail COMPLIANCE FIELD'!G19 -> 6 | D11: =C11 -> 6 | E11: =D11/C11 -> 1 | F11: ='Detail COMPLIANCE FIELD'!I19 -> 6 | G11: =F11/C11 -> 1 | H11: ='Detail COMPLIANCE FIELD'!K19 -> 6 | I11: =H11/C11 -> 1
A12: 6 | B12: COMPANY /BUSINESS OPERATIONS & LICENSE (2) | C12: ='Detail COMPLIANCE FIELD'!G20 -> 37 | D12: =C12 -> 37 | E12: =D12/C12 -> 1 | F12: ='Detail COMPLIANCE FIELD'!I20 -> 37 | G12: =F12/C12 -> 1 | H12: ='Detail COMPLIANCE FIELD'!K20 -> 37 | I12: =H12/C12 -> 1
B13: TOTAL | C13: =SUM(C7:C12) -> 275 | D13: =SUM(D7:D12) -> 275 | E13: =D13/C13 -> 1 | F13: =SUM(F7:F12) -> 275 | G13: =F13/C13 -> 1 | H13: =SUM(H7:H12) -> 270 | I13: =H13/C13 -> 0.98181818
A15: 7 | B15: EXIM MANAGEMENT (6) | C15: ='Detail COMPLIANCE FIELD'!G21 -> 56 | D15: =C15 -> 56 | E15: =D15/C15 -> 1 | F15: ='Detail COMPLIANCE FIELD'!I21 -> 56 | G15: =F15/C15 -> 1 | H15: ='Detail COMPLIANCE FIELD'!K21 -> 56 | I15: =H15/C15 -> 1
A16: 8 | B16: ACCOUNTING /FINANCE (7) | C16: ='Detail COMPLIANCE FIELD'!G22 -> 123 | D16: =C16 -> 123 | E16: =D16/C16 -> 1 | F16: ='Detail COMPLIANCE FIELD'!I22 -> 123 | G16: =F16/C16 -> 1 | H16: ='Detail COMPLIANCE FIELD'!K22 -> 116 | I16: =H16/C16 -> 0.94308943
B17: TOTAL | C17: =SUM(C15:C16)+C13 -> 454 | D17: =SUM(D15:D16)+D13 -> 454 | E17: =D17/C17 -> 1 | F17: =SUM(F15:F16)+F13 -> 454 | G17: =F17/C17 -> 1 | H17: =SUM(H15:H16)+H13 -> 442 | I17: =H17/C17 -> 0.97356828
A18: PT. SEMARANG AUTOCOMP MANUFACTURING INDONESIA
A19: KEPATUHAN TERHADAP PERATURAN PERUNDANGAN
A21: NO | B21: BIDANG | C21: 44378 | J21: 44409 | Q21: 44440
C22: Jml regulasi | D22: Identifikasi | F22: Evaluasi | H22: Implementasi | J22: Jml regulasi | K22: Identifikasi | M22: Evaluasi | O22: Implementasi | Q22: Jml regulasi | R22: Identifikasi | T22: Evaluasi | V22: Implementasi
D23: Jml | E23: % | F23: Jml | G23: % | H23: Jml | I23: % | K23: Jml | L23: % | M23: Jml | N23: % | O23: Jml | P23: % | R23: Jml | S23: % | T23: Jml | U23: % | V23: Jml | W23: %
A24: 1 | B24: COMPLIANCE IN GENERAL (1) | C24: 0 | D24: 0 | E24: =D24/C24 -> #DIV/0! | F24: 0 | G24: =F24/C24 -> #DIV/0! | H24: 0 | I24: =H24/C24 -> #DIV/0! | J24: 0 | K24: 0 | L24: =K24/J24 -> #DIV/0! | M24: 0 | N24: =M24/J24 -> #DIV/0! | O24: 0 | P24: =O24/J24 -> #DIV/0! | Q24: 0 | R24: 0 | S24: =R24/Q24 -> #DIV/0! | T24: 0 | U24: =T24/Q24 -> #DIV/0! | V24: 0 | W24: =V24/Q24 -> #DIV/0!
A25: 2 | B25: LABOR & HUMAN RIGHTS (3) | C25: 81 | D25: 81 | E25: =D25/C25 -> 1 | F25: 81 | G25: =F25/C25 -> 1 | H25: 81 | I25: =H25/C25 -> 1 | J25: 82 | K25: 82 | L25: =K25/J25 -> 1 | M25: 82 | N25: =M25/J25 -> 1 | O25: 82 | P25: =O25/J25 -> 1 | Q25: 82 | R25: 82 | S25: =R25/Q25 -> 1 | T25: 82 | U25: =T25/Q25 -> 1 | V25: 82 | W25: =V25/Q25 -> 1
B26: a. HR | C26: 53 | D26: 53 | E26: =D26/C26 -> 1 | F26: 53 | G26: =F26/C26 -> 1 | H26: 53 | I26: =H26/C26 -> 1 | J26: 54 | K26: 54 | L26: =K26/J26 -> 1 | M26: 54 | N26: =M26/J26 -> 1 | O26: 54 | P26: =O26/J26 -> 1 | Q26: 54 | R26: 54 | S26: =R26/Q26 -> 1 | T26: 54 | U26: =T26/Q26 -> 1 | V26: 54 | W26: =V26/Q26 -> 1
B27: b. Expat | C27: 27 | D27: 27 | E27: =D27/C27 -> 1 | F27: 27 | G27: =F27/C27 -> 1 | H27: 27 | I27: =H27/C27 -> 1 | J27: 27 | K27: 27 | L27: =K27/J27 -> 1 | M27: 27 | N27: =M27/J27 -> 1 | O27: 27 | P27: =O27/J27 -> 1 | Q27: 27 | R27: 27 | S27: =R27/Q27 -> 1 | T27: 27 | U27: =T27/Q27 -> 1 | V27: 27 | W27: =V27/Q27 -> 1
B28: c. TRN | C28: 1 | D28: 1 | E28: =D28/C28 -> 1 | F28: 1 | G28: =F28/C28 -> 1 | H28: 1 | I28: =H28/C28 -> 1 | J28: 1 | K28: 1 | L28: =K28/J28 -> 1 | M28: 1 | N28: =M28/J28 -> 1 | O28: 1 | P28: =O28/J28 -> 1 | Q28: 1 | R28: 1 | S28: =R28/Q28 -> 1 | T28: 1 | U28: =T28/Q28 -> 1 | V28: 1 | W28: =V28/Q28 -> 1
A29: 3 | B29: INTELLECTUAL PROPERTY (4) | C29: 5 | D29: 5 | E29: =D29/C29 -> 1 | F29: 5 | G29: =F29/C29 -> 1 | H29: 5 | I29: =H29/C29 -> 1 | J29: 5 | K29: 5 | L29: =K29/J29 -> 1 | M29: 5 | N29: =M29/J29 -> 1 | O29: 5 | P29: =O29/J29 -> 1 | Q29: 5 | R29: 5 | S29: =R29/Q29 -> 1 | T29: 5 | U29: =T29/Q29 -> 1 | V29: 5 | W29: =V29/Q29 -> 1
A30: 4 | B30: FAIR TRADING (5) | C30: 5 | D30: 5 | E30: =D30/C30 -> 1 | F30: 5 | G30: =F30/C30 -> 1 | H30: 5 | I30: =H30/C30 -> 1 | J30: 5 | K30: 5 | L30: =K30/J30 -> 1 | M30: 5 | N30: =M30/J30 -> 1 | O30: 5 | P30: =O30/J30 -> 1 | Q30: 5 | R30: 5 | S30: =R30/Q30 -> 1 | T30: 5 | U30: =T30/Q30 -> 1 | V30: 5 | W30: =V30/Q30 -> 1
A31: 6 | B31: ENVIRONMENT, SAFETY & HEALTH (8) | C31: 104 | D31: 104 | E31: =D31/C31 -> 1 | F31: 104 | G31: =F31/C31 -> 1 | H31: 99 | I31: =H31/C31 -> 0.95192308 | J31: 104 | K31: 104 | L31: =K31/J31 -> 1 | M31: 104 | N31: =M31/J31 -> 1 | O31: 100 | P31: =O31/J31 -> 0.96153846 | Q31: 104 | R31: 104 | S31: =R31/Q31 -> 1 | T31: 104 | U31: =T31/Q31 -> 1 | V31: 98 | W31: =V31/Q31 -> 0.94230769
B32: a. Safety & Health | C32: 35 | D32: 35 | E32: =D32/C32 -> 1 | F32: 35 | G32: =F32/C32 -> 1 | H32: 32 | I32: =H32/C32 -> 0.91428571 | J32: 35 | K32: 35 | L32: =K32/J32 -> 1 | M32: 35 | N32: =M32/J32 -> 1 | O32: 32 | P32: =O32/J32 -> 0.91428571 | Q32: 35 | R32: 35 | S32: =R32/Q32 -> 1 | T32: 35 | U32: =T32/Q32 -> 1 | V32: 30 | W32: =V32/Q32 -> 0.85714286
B33: b. Environment | C33: 60 | D33: 60 | E33: =D33/C33 -> 1 | F33: 60 | G33: =F33/C33 -> 1 | H33: 58 | I33: =H33/C33 -> 0.96666667 | J33: 60 | K33: 60 | L33: =K33/J33 -> 1 | M33: 60 | N33: =M33/J33 -> 1 | O33: 59 | P33: =O33/J33 -> 0.98333333 | Q33: 60 | R33: 60 | S33: =R33/Q33 -> 1 | T33: 60 | U33: =T33/Q33 -> 1 | V33: 59 | W33: =V33/Q33 -> 0.98333333
B34: c. SoC | C34: 9 | D34: 9 | E34: =D34/C34 -> 1 | F34: 9 | G34: =F34/C34 -> 1 | H34: 9 | I34: =H34/C34 -> 1 | J34: 9 | K34: 9 | L34: =K34/J34 -> 1 | M34: 9 | N34: =M34/J34 -> 1 | O34: 9 | P34: =O34/J34 -> 1 | Q34: 9 | R34: 9 | S34: =R34/Q34 -> 1 | T34: 9 | U34: =T34/Q34 -> 1 | V34: 9 | W34: =V34/Q34 -> 1
A35: 7 | B35: COMPANY /BUSINESS OPERATIONS & LICENSE (2) | C35: 79 | D35: 79 | E35: =D35/C35 -> 1 | F35: 79 | G35: =F35/C35 -> 1 | H35: 70 | I35: =H35/C35 -> 0.88607595 | J35: 81 | K35: 81 | L35: =K35/J35 -> 1 | M35: 81 | N35: =M35/J35 -> 1 | O35: 72 | P35: =O35/J35 -> 0.88888889 | Q35: 81 | R35: 81 | S35: =R35/Q35 -> 1 | T35: 81 | U35: =T35/Q35 -> 1 | V35: 72 | W35: =V35/Q35 -> 0.88888889
B36: TOTAL | C36: =C24+C25+C29+C30+C31+C35 -> 274 | D36: =D24+D25+D29+D30+D31+D35 -> 274 | E36: =D36/C36 -> 1 | F36: =F24+F25+F29+F30+F31+F35 -> 274 | G36: =F36/C36 -> 1 | H36: =H24+H25+H29+H30+H31+H35 -> 260 | I36: =H36/C36 -> 0.94890511 | J36: =J24+J25+J29+J30+J31+J35 -> 277 | K36: =K24+K25+K29+K30+K31+K35 -> 277 | L36: =K36/J36 -> 1 | M36: =M24+M25+M29+M30+M31+M35 -> 277 | N36: =M36/J36 -> 1 | O36: =O24+O25+O29+O30+O31+O35 -> 264 | P36: =O36/J36 -> 0.95306859 | Q36: =Q24+Q25+Q29+Q30+Q31+Q35 -> 277 | R36: =R24+R25+R29+R30+R31+R35 -> 277 | S36: =R36/Q36 -> 1 | T36: =T24+T25+T29+T30+T31+T35 -> 277 | U36: =T36/Q36 -> 1 | V36: =V24+V25+V29+V30+V31+V35 -> 262 | W36: =V36/Q36 -> 0.94584838
A38: 5 | B38: EXIM MANAGEMENT (6) | C38: 15 | D38: 15 | E38: =D38/C38 -> 1 | F38: 15 | G38: =F38/C38 -> 1 | H38: 15 | I38: =H38/C38 -> 1 | J38: 16 | K38: 16 | L38: =K38/J38 -> 1 | M38: 16 | N38: =M38/J38 -> 1 | O38: 16 | P38: =O38/J38 -> 1 | Q38: 16 | R38: 16 | S38: =R38/Q38 -> 1 | T38: 16 | U38: =T38/Q38 -> 1 | V38: 16 | W38: =V38/Q38 -> 1
A39: 8 | B39: ACCOUNTING /FINANCE (7) | C39: 33 | D39: 33 | E39: =D39/C39 -> 1 | F39: 33 | G39: =F39/C39 -> 1 | H39: 33 | I39: =H39/C39 -> 1 | J39: 33 | K39: 33 | L39: =K39/J39 -> 1 | M39: 33 | N39: =M39/J39 -> 1 | O39: 33 | P39: =O39/J39 -> 1 | Q39: 33 | R39: 33 | S39: =R39/Q39 -> 1 | T39: 33 | U39: =T39/Q39 -> 1 | V39: 33 | W39: =V39/Q39 -> 1
B40: TOTAL | C40: =SUM(C38:C39)+C36 -> 322 | D40: =SUM(D38:D39)+D36 -> 322 | E40: =D40/C40 -> 1 | F40: =SUM(F38:F39)+F36 -> 322 | G40: =F40/C40 -> 1 | H40: =SUM(H38:H39)+H36 -> 308 | I40: =H40/C40 -> 0.95652174 | J40: =SUM(J38:J39)+J36 -> 326 | K40: =SUM(K38:K39)+K36 -> 326 | L40: =K40/J40 -> 1 | M40: =SUM(M38:M39)+M36 -> 326 | N40: =M40/J40 -> 1 | O40: =SUM(O38:O39)+O36 -> 313 | P40: =O40/J40 -> 0.9601227 | Q40: =SUM(Q38:Q39)+Q36 -> 326 | R40: =SUM(R38:R39)+R36 -> 326 | S40: =R40/Q40 -> 1 | T40: =SUM(T38:T39)+T36 -> 326 | U40: =T40/Q40 -> 1 | V40: =SUM(V38:V39)+V36 -> 311 | W40: =V40/Q40 -> 0.95398773
A43: NO | B43: BIDANG | C43: 44470 | J43: 44501 | Q43: 44531
C44: Jml regulasi | D44: Identifikasi | F44: Evaluasi | H44: Implementasi | J44: Jml regulasi | K44: Identifikasi | M44: Evaluasi | O44: Implementasi | Q44: Jml regulasi | R44: Identifikasi | T44: Evaluasi | V44: Implementasi
D45: Jml | E45: % | F45: Jml | G45: % | H45: Jml | I45: % | K45: Jml | L45: % | M45: Jml | N45: % | O45: Jml | P45: % | R45: Jml | S45: % | T45: Jml | U45: % | V45: Jml | W45: %
A46: 1 | B46: COMPLIANCE IN GENERAL (1) | C46: 0 | D46: 0 | E46: =D46/C46 -> #DIV/0! | F46: 0 | G46: =F46/C46 -> #DIV/0! | H46: 0 | I46: =H46/C46 -> #DIV/0! | L46: =K46/J46 -> #DIV/0! | N46: =M46/J46 -> #DIV/0! | P46: =O46/J46 -> #DIV/0! | Q46: 0 | R46: 0 | S46: =R46/Q46 -> #DIV/0! | T46: 0 | U46: =T46/Q46 -> #DIV/0! | V46: 0 | W46: =V46/Q46 -> #DIV/0!
A47: 2 | B47: LABOR & HUMAN RIGHTS (3) | C47: 87 | D47: 87 | E47: =D47/C47 -> 1 | F47: 87 | G47: =F47/C47 -> 1 | H47: 87 | I47: =H47/C47 -> 1 | L47: =K47/J47 -> #DIV/0! | N47: =M47/J47 -> #DIV/0! | P47: =O47/J47 -> #DIV/0! | Q47: 90 | R47: 90 | S47: =R47/Q47 -> 1 | T47: 87 | U47: =T47/Q47 -> 0.96666667 | V47: 87 | W47: =V47/Q47 -> 0.96666667
...

Sheet 82
A2: Now day
A4: NO | B4: BIDANG | C4: NOW DAY
C5: Jml regulasi | D5: Identifikasi | F5: Evaluasi | H5: Implementasi
D6: Jml | E6: % | F6: Jml | G6: % | H6: Jml | I6: %
A7: 1 | B7: COMPLIANCE IN GENERAL (1) | C7: ='Detail COMPLIANCE FIELD'!G15 -> 0 | D7: =C7 -> 0 | E7: 1 | F7: ='Detail COMPLIANCE FIELD'!I15 -> 0 | G7: 1 | H7: ='Detail COMPLIANCE FIELD'!K15 -> 0 | I7: 1
A8: 2 | B8: LABOR & HUMAN RIGHTS (3) | C8: ='Detail COMPLIANCE FIELD'!G17 -> 126 | D8: =C8 -> 126 | E8: =D8/C8 -> 1 | F8: ='Detail COMPLIANCE FIELD'!I17 -> 126 | G8: =F8/C8 -> 1 | H8: ='Detail COMPLIANCE FIELD'!K17 -> 122 | I8: =H8/C8 -> 0.96825397
A9: 3 | B9: INTELLECTUAL PROPERTY (4) | C9: ='Detail COMPLIANCE FIELD'!G18 -> 7 | D9: =C9 -> 7 | E9: =D9/C9 -> 1 | F9: ='Detail COMPLIANCE FIELD'!I18 -> 7 | G9: =F9/C9 -> 1 | H9: ='Detail COMPLIANCE FIELD'!K18 -> 7 | I9: =H9/C9 -> 1
A10: 4 | B10: FAIR TRADING (5) | C10: ='Detail COMPLIANCE FIELD'!G19 -> 6 | D10: =C10 -> 6 | E10: =D10/C10 -> 1 | F10: ='Detail COMPLIANCE FIELD'!I19 -> 6 | G10: =F10/C10 -> 1 | H10: ='Detail COMPLIANCE FIELD'!K19 -> 6 | I10: =H10/C10 -> 1
A11: 5 | B11: ENVIRONMENT, SAFETY & HEALTH (8) | C11: ='Detail COMPLIANCE FIELD'!G22 -> 123 | D11: =C11 -> 123 | E11: =D11/C11 -> 1 | F11: ='Detail COMPLIANCE FIELD'!I22 -> 123 | G11: =F11/C11 -> 1 | H11: ='Detail COMPLIANCE FIELD'!K22 -> 116 | I11: =H11/C11 -> 0.94308943
A12: 6 | B12: COMPANY /BUSINESS OPERATIONS & LICENSE (2) | C12: ='Detail COMPLIANCE FIELD'!G16 -> 99 | D12: =C12 -> 99 | E12: =D12/C12 -> 1 | F12: ='Detail COMPLIANCE FIELD'!I16 -> 99 | G12: =F12/C12 -> 1 | H12: ='Detail COMPLIANCE FIELD'!K16 -> 98 | I12: =H12/C12 -> 0.98989899
B13: TOTAL | C13: =SUM(C7:C12) -> 361 | D13: =SUM(D7:D12) -> 361 | E13: =D13/C13 -> 1 | F13: =SUM(F7:F12) -> 361 | G13: =F13/C13 -> 1 | H13: =SUM(H7:H12) -> 349 | I13: =H13/C13 -> 0.966759
A15: 7 | B15: EXIM MANAGEMENT (6) | C15: ='Detail COMPLIANCE FIELD'!G20 -> 37 | D15: =C15 -> 37 | E15: =D15/C15 -> 1 | F15: ='Detail COMPLIANCE FIELD'!I20 -> 37 | G15: =F15/C15 -> 1 | H15: ='Detail COMPLIANCE FIELD'!K20 -> 37 | I15: =H15/C15 -> 1
A16: 8 | B16: ACCOUNTING /FINANCE (7) | C16: ='Detail COMPLIANCE FIELD'!G21 -> 56 | D16: =C16 -> 56 | E16: =D16/C16 -> 1 | F16: ='Detail COMPLIANCE FIELD'!I21 -> 56 | G16: =F16/C16 -> 1 | H16: ='Detail COMPLIANCE FIELD'!K21 -> 56 | I16: =H16/C16 -> 1
B17: TOTAL | C17: =SUM(C15:C16)+C13 -> 454 | D17: =SUM(D15:D16)+D13 -> 454 | E17: =D17/C17 -> 1 | F17: =SUM(F15:F16)+F13 -> 454 | G17: =F17/C17 -> 1 | H17: =SUM(H15:H16)+H13 -> 442 | I17: =H17/C17 -> 0.97356828
A18: PT. SEMARANG AUTOCOMP MANUFACTURING INDONESIA
A19: KEPATUHAN TERHADAP PERATURAN PERUNDANGAN
A21: NO | B21: BIDANG | C21: 44743 | J21: 44774 | Q21: 44805
C22: Jml regulasi | D22: Identifikasi | F22: Evaluasi | H22: Implementasi | J22: Jml regulasi | K22: Identifikasi | M22: Evaluasi | O22: Implementasi | Q22: Jml regulasi | R22: Identifikasi | T22: Evaluasi | V22: Implementasi
D23: Jml | E23: % | F23: Jml | G23: % | H23: Jml | I23: % | K23: Jml | L23: % | M23: Jml | N23: % | O23: Jml | P23: % | R23: Jml | S23: % | T23: Jml | U23: % | V23: Jml | W23: %
A24: 1 | B24: COMPLIANCE IN GENERAL (1) | C24: 0 | D24: 0 | E24: #DIV/0! | F24: 0 | G24: #DIV/0! | H24: 0 | I24: #DIV/0! | J24: 0 | K24: 0 | L24: =K24/J24 -> #DIV/0! | M24: 0 | N24: =M24/J24 -> #DIV/0! | O24: 0 | P24: =O24/J24 -> #DIV/0! | Q24: 0 | R24: 0 | S24: =R24/Q24 -> #DIV/0! | T24: 0 | U24: =T24/Q24 -> #DIV/0! | V24: 0 | W24: =V24/Q24 -> #DIV/0!
A25: 2 | B25: LABOR & HUMAN RIGHTS (3) | C25: 82 | D25: 82 | E25: 1 | F25: 82 | G25: 1 | H25: 75 | I25: 0.91463415 | J25: 82 | K25: 82 | L25: 1 | M25: 82 | N25: 1 | O25: 75 | P25: 0.91463415 | Q25: 85 | R25: 85 | S25: =R25/Q25 -> 1 | T25: 85 | U25: =T25/Q25 -> 1 | V25: 79 | W25: =V25/Q25 -> 0.92941176
B26: a. HR | C26: 50 | D26: 50 | E26: 1 | F26: 50 | G26: 1 | H26: 47 | I26: 0.94 | J26: 50 | K26: 50 | L26: 1 | M26: 50 | N26: 1 | O26: 47 | P26: 0.94 | Q26: 52 | R26: 52 | S26: =R26/Q26 -> 1 | T26: 52 | U26: =T26/Q26 -> 1 | V26: 50 | W26: =V26/Q26 -> 0.96153846
B27: b. Expat | C27: 31 | D27: 31 | E27: 1 | F27: 31 | G27: 1 | H27: 27 | I27: 0.87096774 | J27: 31 | K27: 31 | L27: 1 | M27: 31 | N27: 1 | O27: 27 | P27: 0.87096774 | Q27: 32 | R27: 32 | S27: =R27/Q27 -> 1 | T27: 32 | U27: =T27/Q27 -> 1 | V27: 28 | W27: =V27/Q27 -> 0.875
B28: c. TRN | C28: 1 | D28: 1 | E28: 1 | F28: 1 | G28: 1 | H28: 1 | I28: 1 | J28: 1 | K28: 1 | L28: 1 | M28: 1 | N28: 1 | O28: 1 | P28: 1 | Q28: 1 | R28: 1 | S28: =R28/Q28 -> 1 | T28: 1 | U28: =T28/Q28 -> 1 | V28: 1 | W28: =V28/Q28 -> 1
A29: 3 | B29: INTELLECTUAL PROPERTY (4) | C29: 5 | D29: 5 | E29: 1 | F29: 5 | G29: 1 | H29: 5 | I29: 1 | J29: 5 | K29: 5 | L29: =K29/J29 -> 1 | M29: 5 | N29: =M29/J29 -> 1 | O29: 5 | P29: =O29/J29 -> 1 | Q29: 5 | R29: 5 | S29: =R29/Q29 -> 1 | T29: 5 | U29: =T29/Q29 -> 1 | V29: 5 | W29: =V29/Q29 -> 1
A30: 4 | B30: FAIR TRADING (5) | C30: 6 | D30: 6 | E30: 1 | F30: 6 | G30: 1 | H30: 6 | I30: 1 | J30: 6 | K30: 6 | L30: =K30/J30 -> 1 | M30: 6 | N30: =M30/J30 -> 1 | O30: 6 | P30: =O30/J30 -> 1 | Q30: 6 | R30: 6 | S30: =R30/Q30 -> 1 | T30: 6 | U30: =T30/Q30 -> 1 | V30: 6 | W30: =V30/Q30 -> 1
A31: 6 | B31: ENVIRONMENT, SAFETY & HEALTH (8) | C31: 104 | D31: 104 | E31: 1 | F31: 104 | G31: 1 | H31: 95 | I31: 0.91346154 | J31: 104 | K31: 104 | L31: 1 | M31: 104 | N31: 1 | O31: 95 | P31: 0.91346154 | Q31: 104 | R31: 104 | S31: 1 | T31: 104 | U31: 1 | V31: 95 | W31: 0.91346154
B32: a. Safety & Health | C32: 37 | D32: 37 | E32: 1 | F32: 37 | G32: 1 | H32: 32 | I32: 0.86486486 | J32: 37 | K32: 37 | L32: 1 | M32: 37 | N32: 1 | O32: 32 | P32: 0.86486486 | Q32: 37 | R32: 37 | S32: 1 | T32: 37 | U32: 1 | V32: 32 | W32: 0.86486486
B33: b. Environment | C33: 57 | D33: 57 | E33: 1 | F33: 57 | G33: 1 | H33: 53 | I33: 0.92982456 | J33: 57 | K33: 57 | L33: 1 | M33: 57 | N33: 1 | O33: 53 | P33: 0.92982456 | Q33: 57 | R33: 57 | S33: 1 | T33: 57 | U33: 1 | V33: 53 | W33: 0.92982456
B34: c. SoC | C34: 10 | D34: 10 | E34: 1 | F34: 10 | G34: 1 | H34: 10 | I34: 1 | J34: 10 | K34: 10 | L34: 1 | M34: 10 | N34: 1 | O34: 10 | P34: 1 | Q34: 10 | R34: 10 | S34: 1 | T34: 10 | U34: 1 | V34: 10 | W34: 1
A35: 7 | B35: COMPANY /BUSINESS OPERATIONS & LICENSE (2) | C35: 79 | D35: 79 | E35: 1 | F35: 79 | G35: 1 | H35: 71 | I35: 0.89873418 | J35: 79 | K35: 79 | L35: 1 | M35: 79 | N35: 1 | O35: 71 | P35: 0.89873418 | Q35: 80 | R35: 80 | S35: =R35/Q35 -> 1 | T35: 79 | U35: =T35/Q35 -> 0.9875 | V35: 71 | W35: =V35/Q35 -> 0.8875
B36: TOTAL | C36: 276 | D36: 276 | E36: 1 | F36: 276 | G36: 1 | H36: 252 | I36: 0.91304348 | J36: =J24+J25+J29+J30+J31+J35 -> 276 | K36: =K24+K25+K29+K30+K31+K35 -> 276 | L36: =K36/J36 -> 1 | M36: =M24+M25+M29+M30+M31+M35 -> 276 | N36: =M36/J36 -> 1 | O36: =O24+O25+O29+O30+O31+O35 -> 252 | P36: =O36/J36 -> 0.91304348 | Q36: =Q24+Q25+Q29+Q30+Q31+Q35 -> 280 | R36: =R24+R25+R29+R30+R31+R35 -> 280 | S36: =R36/Q36 -> 1 | T36: =T24+T25+T29+T30+T31+T35 -> 279 | U36: =T36/Q36 -> 0.99642857 | V36: =V24+V25+V29+V30+V31+V35 -> 256 | W36: =V36/Q36 -> 0.91428571
A38: 5 | B38: EXIM MANAGEMENT (6) | C38: 18 | D38: 18 | E38: 1 | F38: 18 | G38: 0.94736842 | H38: 18 | I38: 0.94736842 | J38: 18 | K38: 18 | L38: 1 | M38: 18 | N38: 0.94736842 | O38: 18 | P38: 0.94736842 | Q38: 19 | R38: 19 | S38: =R38/Q38 -> 1 | T38: 18 | U38: =T38/Q38 -> 0.94736842 | V38: 18 | W38: =V38/Q38 -> 0.94736842
A39: 8 | B39: ACCOUNTING /FINANCE (7) | C39: 36 | D39: 36 | E39: 1 | F39: 36 | G39: 0.97222222 | H39: 36 | I39: 0.97222222 | J39: 37 | K39: 37 | L39: =K39/J39 -> 1 | M39: 37 | N39: =M39/J39 -> 1 | O39: 37 | P39: =O39/J39 -> 1 | Q39: 38 | R39: 38 | S39: =R39/Q39 -> 1 | T39: 37 | U39: =T39/Q39 -> 0.97368421 | V39: 37 | W39: =V39/Q39 -> 0.97368421
B40: TOTAL | C40: =SUM(C38:C39)+C36 -> 330 | D40: =SUM(D38:D39)+D36 -> 330 | E40: =D40/C40 -> 1 | F40: =SUM(F38:F39)+F36 -> 330 | G40: =F40/C40 -> 1 | H40: =SUM(H38:H39)+H36 -> 306 | I40: =H40/C40 -> 0.92727273 | J40: =SUM(J38:J39)+J36 -> 331 | K40: =SUM(K38:K39)+K36 -> 331 | L40: =K40/J40 -> 1 | M40: =SUM(M38:M39)+M36 -> 331 | N40: =M40/J40 -> 1 | O40: =SUM(O38:O39)+O36 -> 307 | P40: =O40/J40 -> 0.92749245 | Q40: =SUM(Q38:Q39)+Q36 -> 337 | R40: =SUM(R38:R39)+R36 -> 337 | S40: =R40/Q40 -> 1 | T40: =SUM(T38:T39)+T36 -> 334 | U40: =T40/Q40 -> 0.99109792 | V40: =SUM(V38:V39)+V36 -> 311 | W40: =V40/Q40 -> 0.92284866
A43: NO | B43: BIDANG | C43: 44835 | J43: 44866 | Q43: 44896
C44: Jml regulasi | D44: Identifikasi | F44: Evaluasi | H44: Implementasi | J44: Jml regulasi | K44: Identifikasi | M44: Evaluasi | O44: Implementasi | Q44: Jml regulasi | R44: Identifikasi | T44: Evaluasi | V44: Implementasi
D45: Jml | E45: % | F45: Jml | G45: % | H45: Jml | I45: % | K45: Jml | L45: % | M45: Jml | N45: % | O45: Jml | P45: % | R45: Jml | S45: % | T45: Jml | U45: % | V45: Jml | W45: %
A46: 1 | B46: COMPLIANCE IN GENERAL (1) | C46: 0 | D46: 0 | E46: #DIV/0! | F46: 0 | G46: #DIV/0! | H46: 0 | I46: #DIV/0! | J46: 0 | K46: 0 | L46: #DIV/0! | M46: 0 | N46: #DIV/0! | O46: 0 | P46: #DIV/0! | S46: =R46/Q46 -> #DIV/0! | U46: =T46/Q46 -> #DIV/0! | W46: =V46/Q46 -> #DIV/0!
A47: 2 | B47: LABOR & HUMAN RIGHTS (3) | C47: 91 | D47: 91 | E47: =D47/C47 -> 1 | F47: 91 | G47: =F47/C47 -> 1 | H47: 85 | I47: =H47/C47 -> 0.93406593 | J47: 94 | K47: 94 | L47: =K47/J47 -> 1 | M47: 94 | N47: =M47/J47 -> 1 | O47: 88 | P47: =O47/J47 -> 0.93617021 | S47: =R47/Q47 -> #DIV/0! | U47: =T47/Q47 -> #DIV/0! | W47: =V47/Q47 -> #DIV/0!
...

Sheet 83
A2: Now day
A4: NO | B4: BIDANG | C4: NOW DAY
C5: Jml regulasi | D5: Identifikasi | F5: Evaluasi | H5: Implementasi
D6: Jml | E6: % | F6: Jml | G6: % | H6: Jml | I6: %
A7: 1 | B7: COMPLIANCE IN GENERAL (1) | C7: ='Detail COMPLIANCE FIELD'!G15 -> 0 | D7: =C7 -> 0 | E7: 1 | F7: ='Detail COMPLIANCE FIELD'!I15 -> 0 | G7: 1 | H7: ='Detail COMPLIANCE FIELD'!K15 -> 0 | I7: 1
A8: 2 | B8: LABOR & HUMAN RIGHTS (3) | C8: ='Detail COMPLIANCE FIELD'!G17 -> 126 | D8: =C8 -> 126 | E8: =D8/C8 -> 1 | F8: ='Detail COMPLIANCE FIELD'!I17 -> 126 | G8: =F8/C8 -> 1 | H8: ='Detail COMPLIANCE FIELD'!K17 -> 122 | I8: =H8/C8 -> 0.96825397
A9: 3 | B9: INTELLECTUAL PROPERTY (4) | C9: ='Detail COMPLIANCE FIELD'!G18 -> 7 | D9: =C9 -> 7 | E9: =D9/C9 -> 1 | F9: ='Detail COMPLIANCE FIELD'!I18 -> 7 | G9: =F9/C9 -> 1 | H9: ='Detail COMPLIANCE FIELD'!K18 -> 7 | I9: =H9/C9 -> 1
A10: 4 | B10: FAIR TRADING (5) | C10: ='Detail COMPLIANCE FIELD'!G19 -> 6 | D10: =C10 -> 6 | E10: =D10/C10 -> 1 | F10: ='Detail COMPLIANCE FIELD'!I19 -> 6 | G10: =F10/C10 -> 1 | H10: ='Detail COMPLIANCE FIELD'!K19 -> 6 | I10: =H10/C10 -> 1
A11: 5 | B11: ENVIRONMENT, SAFETY & HEALTH (8) | C11: ='Detail COMPLIANCE FIELD'!G22 -> 123 | D11: =C11 -> 123 | E11: =D11/C11 -> 1 | F11: ='Detail COMPLIANCE FIELD'!I22 -> 123 | G11: =F11/C11 -> 1 | H11: ='Detail COMPLIANCE FIELD'!K22 -> 116 | I11: =H11/C11 -> 0.94308943
A12: 6 | B12: COMPANY /BUSINESS OPERATIONS & LICENSE (2) | C12: ='Detail COMPLIANCE FIELD'!G16 -> 99 | D12: =C12 -> 99 | E12: =D12/C12 -> 1 | F12: ='Detail COMPLIANCE FIELD'!I16 -> 99 | G12: =F12/C12 -> 1 | H12: ='Detail COMPLIANCE FIELD'!K16 -> 98 | I12: =H12/C12 -> 0.98989899
B13: TOTAL | C13: =SUM(C7:C12) -> 361 | D13: =SUM(D7:D12) -> 361 | E13: =D13/C13 -> 1 | F13: =SUM(F7:F12) -> 361 | G13: =F13/C13 -> 1 | H13: =SUM(H7:H12) -> 349 | I13: =H13/C13 -> 0.966759
A15: 7 | B15: EXIM MANAGEMENT (6) | C15: ='Detail COMPLIANCE FIELD'!G20 -> 37 | D15: =C15 -> 37 | E15: =D15/C15 -> 1 | F15: ='Detail COMPLIANCE FIELD'!I20 -> 37 | G15: =F15/C15 -> 1 | H15: ='Detail COMPLIANCE FIELD'!K20 -> 37 | I15: =H15/C15 -> 1
A16: 8 | B16: ACCOUNTING /FINANCE (7) | C16: ='Detail COMPLIANCE FIELD'!G21 -> 56 | D16: =C16 -> 56 | E16: =D16/C16 -> 1 | F16: ='Detail COMPLIANCE FIELD'!I21 -> 56 | G16: =F16/C16 -> 1 | H16: ='Detail COMPLIANCE FIELD'!K21 -> 56 | I16: =H16/C16 -> 1
B17: TOTAL | C17: =SUM(C15:C16)+C13 -> 454 | D17: =SUM(D15:D16)+D13 -> 454 | E17: =D17/C17 -> 1 | F17: =SUM(F15:F16)+F13 -> 454 | G17: =F17/C17 -> 1 | H17: =SUM(H15:H16)+H13 -> 442 | I17: =H17/C17 -> 0.97356828
A18: PT. SEMARANG AUTOCOMP MANUFACTURING INDONESIA
A19: KEPATUHAN TERHADAP PERATURAN PERUNDANGAN
A21: NO | B21: BIDANG | C21: 45108 | J21: 45139 | Q21: 45170
C22: Jml regulasi | D22: Identifikasi | F22: Evaluasi | H22: Implementasi | J22: Jml regulasi | K22: Identifikasi | M22: Evaluasi | O22: Implementasi | Q22: Jml regulasi | R22: Identifikasi | T22: Evaluasi | V22: Implementasi
D23: Jml | E23: % | F23: Jml | G23: % | H23: Jml | I23: % | K23: Jml | L23: % | M23: Jml | N23: % | O23: Jml | P23: % | R23: Jml | S23: % | T23: Jml | U23: % | V23: Jml | W23: %
A24: 1 | B24: COMPLIANCE IN GENERAL (1) | C24: 0 | D24: 0 | E24: #DIV/0! | F24: 0 | G24: #DIV/0! | H24: 0 | I24: #DIV/0! | J24: 0 | K24: 0 | L24: #DIV/0! | M24: 0 | N24: #DIV/0! | O24: 0 | P24: #DIV/0! | S24: =R24/Q24 -> #DIV/0! | U24: =T24/Q24 -> #DIV/0! | W24: =V24/Q24 -> #DIV/0!
A25: 2 | B25: LABOR & HUMAN RIGHTS (3) | C25: 106 | D25: 106 | E25: 1 | F25: 103 | G25: 1 | H25: 95 | I25: 0.91463415 | J25: 107 | K25: 107 | L25: 1 | M25: 103 | N25: 1 | O25: 95 | P25: 0.91463415 | S25: =R25/Q25 -> #DIV/0! | U25: =T25/Q25 -> #DIV/0! | W25: =V25/Q25 -> #DIV/0!
B26: a. HR | C26: 60 | D26: 60 | E26: 1 | F26: 59 | G26: 1 | H26: 57 | I26: 0.94 | J26: 60 | K26: 60 | L26: 1 | M26: 59 | N26: 1 | O26: 57 | P26: 0.94 | S26: =R26/Q26 -> #DIV/0! | U26: =T26/Q26 -> #DIV/0! | W26: =V26/Q26 -> #DIV/0!
B27: b. Expat | C27: 45 | D27: 45 | E27: 1 | F27: 43 | G27: 1 | H27: 37 | I27: 0.87096774 | J27: 46 | K27: 46 | L27: 1 | M27: 43 | N27: 1 | O27: 37 | P27: 0.87096774 | S27: =R27/Q27 -> #DIV/0! | U27: =T27/Q27 -> #DIV/0! | W27: =V27/Q27 -> #DIV/0!
B28: c. TRN | C28: 1 | D28: 1 | E28: 1 | F28: 1 | G28: 1 | H28: 1 | I28: 1 | J28: 1 | K28: 1 | L28: 1 | M28: 1 | N28: 1 | O28: 1 | P28: 1 | S28: =R28/Q28 -> #DIV/0! | U28: =T28/Q28 -> #DIV/0! | W28: =V28/Q28 -> #DIV/0!
A29: 3 | B29: INTELLECTUAL PROPERTY (4) | C29: 5 | D29: 5 | E29: 1 | F29: 5 | G29: 1 | H29: 5 | I29: 1 | J29: 5 | K29: 5 | L29: =K29/J29 -> 1 | M29: 5 | N29: =M29/J29 -> 1 | O29: 5 | P29: =O29/J29 -> 1 | S29: =R29/Q29 -> #DIV/0! | U29: =T29/Q29 -> #DIV/0! | W29: =V29/Q29 -> #DIV/0!
A30: 4 | B30: FAIR TRADING (5) | C30: 6 | D30: 6 | E30: 1 | F30: 6 | G30: 1 | H30: 6 | I30: 1 | J30: 6 | K30: 6 | L30: =K30/J30 -> 1 | M30: 6 | N30: =M30/J30 -> 1 | O30: 6 | P30: =O30/J30 -> 1 | S30: =R30/Q30 -> #DIV/0! | U30: =T30/Q30 -> #DIV/0! | W30: =V30/Q30 -> #DIV/0!
A31: 6 | B31: ENVIRONMENT, SAFETY & HEALTH (8) | C31: 111 | D31: 111 | E31: 1 | F31: 111 | G31: 1 | H31: 104 | I31: 0.91346154 | J31: 113 | K31: 113 | L31: 1 | M31: 111 | N31: 1 | O31: 104 | P31: 0.91346154 | S31: 1 | U31: 1 | W31: 0.91346154
B32: a. Safety & Health | C32: 41 | D32: 41 | E32: 1 | F32: 41 | G32: 1 | H32: 37 | I32: 0.86486486 | J32: 41 | K32: 41 | L32: 1 | M32: 41 | N32: 1 | O32: 37 | P32: 0.86486486 | S32: 1 | U32: 1 | W32: 0.86486486
B33: b. Environment | C33: 60 | D33: 60 | E33: 1 | F33: 60 | G33: 1 | H33: 57 | I33: 0.92982456 | J33: 62 | K33: 62 | L33: 1 | M33: 60 | N33: 1 | O33: 57 | P33: 0.92982456 | S33: 1 | U33: 1 | W33: 0.92982456
B34: c. SoC | C34: 10 | D34: 10 | E34: 1 | F34: 10 | G34: 1 | H34: 10 | I34: 1 | J34: 10 | K34: 10 | L34: 1 | M34: 10 | N34: 1 | O34: 10 | P34: 1 | S34: 1 | U34: 1 | W34: 1
A35: 7 | B35: COMPANY /BUSINESS OPERATIONS & LICENSE (2) | C35: 91 | D35: 91 | E35: 1 | F35: 89 | G35: 1 | H35: 89 | I35: 0.89873418 | J35: 91 | K35: 91 | L35: 1 | M35: 89 | N35: 1 | O35: 89 | P35: 0.89873418 | S35: =R35/Q35 -> #DIV/0! | U35: =T35/Q35 -> #DIV/0! | W35: =V35/Q35 -> #DIV/0!
B36: TOTAL | C36: =C24+C25+C29+C30+C31+C35 -> 319 | D36: =D24+D25+D29+D30+D31+D35 -> 319 | E36: =D36/C36 -> 1 | F36: =F24+F25+F29+F30+F31+F35 -> 314 | G36: =F36/C36 -> 0.98432602 | H36: =H24+H25+H29+H30+H31+H35 -> 299 | I36: =H36/C36 -> 0.93730408 | J36: =J24+J25+J29+J30+J31+J35 -> 322 | K36: =K24+K25+K29+K30+K31+K35 -> 322 | L36: =K36/J36 -> 1 | M36: =M24+M25+M29+M30+M31+M35 -> 314 | N36: =M36/J36 -> 0.97515528 | O36: =O24+O25+O29+O30+O31+O35 -> 299 | P36: =O36/J36 -> 0.92857143 | Q36: =Q24+Q25+Q29+Q30+Q31+Q35 -> 0 | R36: =R24+R25+R29+R30+R31+R35 -> 0 | S36: =R36/Q36 -> #DIV/0! | T36: =T24+T25+T29+T30+T31+T35 -> 0 | U36: =T36/Q36 -> #DIV/0! | V36: =V24+V25+V29+V30+V31+V35 -> 0 | W36: =V36/Q36 -> #DIV/0!
A38: 5 | B38: EXIM MANAGEMENT (6) | C38: 23 | D38: 23 | E38: 1 | F38: 19 | G38: 0.94736842 | H38: 19 | I38: 0.94736842 | J38: 23 | K38: 23 | L38: 1 | M38: 19 | N38: 0.94736842 | O38: 19 | P38: 0.94736842 | S38: =R38/Q38 -> #DIV/0! | U38: =T38/Q38 -> #DIV/0! | W38: =V38/Q38 -> #DIV/0!
A39: 8 | B39: ACCOUNTING /FINANCE (7) | C39: 44 | D39: 44 | E39: 1 | F39: 38 | G39: 0.97222222 | H39: 38 | I39: 0.97222222 | J39: 44 | K39: 44 | L39: 1 | M39: 38 | N39: 0.97222222 | O39: 38 | P39: 0.97222222 | S39: =R39/Q39 -> #DIV/0! | U39: =T39/Q39 -> #DIV/0! | W39: =V39/Q39 -> #DIV/0!
B40: TOTAL | C40: =SUM(C38:C39)+C36 -> 386 | D40: =SUM(D38:D39)+D36 -> 386 | E40: =D40/C40 -> 1 | F40: =SUM(F38:F39)+F36 -> 371 | G40: =F40/C40 -> 0.9611399 | H40: =SUM(H38:H39)+H36 -> 356 | I40: =H40/C40 -> 0.92227979 | J40: =SUM(J38:J39)+J36 -> 389 | K40: =SUM(K38:K39)+K36 -> 389 | L40: =K40/J40 -> 1 | M40: =SUM(M38:M39)+M36 -> 371 | N40: =M40/J40 -> 0.95372751 | O40: =SUM(O38:O39)+O36 -> 356 | P40: =O40/J40 -> 0.9151671 | Q40: =SUM(Q38:Q39)+Q36 -> 0 | R40: =SUM(R38:R39)+R36 -> 0 | S40: =R40/Q40 -> #DIV/0! | T40: =SUM(T38:T39)+T36 -> 0 | U40: =T40/Q40 -> #DIV/0! | V40: =SUM(V38:V39)+V36 -> 0 | W40: =V40/Q40 -> #DIV/0!
A43: NO | B43: BIDANG | C43: 45200 | J43: 45231 | Q43: 45261
C44: Jml regulasi | D44: Identifikasi | F44: Evaluasi | H44: Implementasi | J44: Jml regulasi | K44: Identifikasi | M44: Evaluasi | O44: Implementasi | Q44: Jml regulasi | R44: Identifikasi | T44: Evaluasi | V44: Implementasi
D45: Jml | E45: % | F45: Jml | G45: % | H45: Jml | I45: % | K45: Jml | L45: % | M45: Jml | N45: % | O45: Jml | P45: % | R45: Jml | S45: % | T45: Jml | U45: % | V45: Jml | W45: %
A46: 1 | B46: COMPLIANCE IN GENERAL (1) | E46: #DIV/0! | G46: #DIV/0! | I46: #DIV/0! | L46: #DIV/0! | N46: #DIV/0! | P46: #DIV/0! | S46: =R46/Q46 -> #DIV/0! | U46: =T46/Q46 -> #DIV/0! | W46: =V46/Q46 -> #DIV/0!
A47: 2 | B47: LABOR & HUMAN RIGHTS (3) | E47: =D47/C47 -> #DIV/0! | G47: =F47/C47 -> #DIV/0! | I47: =H47/C47 -> #DIV/0! | L47: =K47/J47 -> #DIV/0! | N47: =M47/J47 -> #DIV/0! | P47: =O47/J47 -> #DIV/0! | S47: =R47/Q47 -> #DIV/0! | U47: =T47/Q47 -> #DIV/0! | W47: =V47/Q47 -> #DIV/0!
...

Sheet Detail COMPLIANCE FIELD
B1: PT Semarang Autocomp Manufacturing Indonesia
I3: No. Doc : LA-RDP-07
I4: No.Rev : 01
I5: Tanggal Eff : 1 Jan 2018
C9: RINGKASAN DAFTAR PERATURAN
AN12: Month | AO12: 45108 | AP12: 45139 | AQ12: 45170 | AR12: 45200 | AS12: 45231 | AT12: 45261 | AU12: 45292 | AV12: 45323 | AW12: 45352 | AX12: 45383 | AY12: 45413 | AZ12: 45444
