Workbook

Sheet INPUT PULANG AWAL
C1: DATA MP PULANG AWAL
C2: BULAN : MEI 2022
A3: DATA MP PULANG AWAL
A4: ="BULAN : "&'list area'!C1&" "&'list area'!C2 -> BULAN : JUNI 2024
C5: HARI/TGL | D5: NIK | E5: NAMA | F5: STATUS | G5: CLASS | H5: CV YANG OFF | I5: SHIFT | J5: JAM PULANG AWAL | K5: JAM KERJA (JAM) | L5: JAM OFF | M5: MH INPUT PULANG AWAL | N5: ALASAN | O5: JENIS
A6: =C6&D6 -> 45446204 | B6: =IF(AND(J6>=TIME(7,30,0),J6<=TIME(16,30,0)),"PAGI","MALAM") -> PAGI | C6: 45446 | D6: 204 | E6: DWI SRI RAHAYU | F6: PRM | G6: PI | H6: CPA MAZDA | I6: B | J6: 0.51736111 | K6: =IF(J6="","",IF(AND(B6="PAGI",J6<=TIME(14,0,0)),(J6-TIME(7,30,0))*24,IF(AND(B6="PAGI",J6>TIME(14,0,0)),((J6-TIME(7,30,0))*24)-1,IF(AND(B6="malam",J6<TIME(3,0,0)),3.75+(J6*24)-0.5,IF(AND(B6="malam",J6<TIME(5,5,0)),3.75+(J6*24)-0.75,(J6-TIME(20,0,0))*24))))) -> 4.9166667 | L6: =IFERROR(8-K6,"") -> 3.0833333 | M6: =L6 -> 3.0833333 | N6: SUDAH SELESIA PERBANTUAN | O6: OTHERS | S6: =COUNTIF(A:A,C6&D6) -> 1
A7: =C7&D7 -> 45446146 | B7: =IF(AND(J7>=TIME(7,30,0),J7<=TIME(16,30,0)),"PAGI","MALAM") -> PAGI | C7: 45446 | D7: 146 | E7: NUNUNG HANDAYANI | F7: PRM | G7: DL | H7: CV M03 | I7: B | J7: 0.375 | K7: =IF(J7="","",IF(AND(B7="PAGI",J7<=TIME(14,0,0)),(J7-TIME(7,30,0))*24,IF(AND(B7="PAGI",J7>TIME(14,0,0)),((J7-TIME(7,30,0))*24)-1,IF(AND(B7="malam",J7<TIME(3,0,0)),3.75+(J7*24)-0.5,IF(AND(B7="malam",J7<TIME(5,5,0)),3.75+(J7*24)-0.75,(J7-TIME(20,0,0))*24))))) -> 1.5 | L7: =IFERROR(8-K7,"") -> 6.5 | M7: =L7 -> 6.5 | N7: SHORTAGE MATERIAL | O7: SHORTAGE MATERIAL | S7: =COUNTIF(A:A,C7&D7) -> 1
A8: =C8&D8 -> 4544629286 | B8: =IF(AND(J8>=TIME(7,30,0),J8<=TIME(16,30,0)),"PAGI","MALAM") -> PAGI | C8: 45446 | D8: 29286 | E8: TITIN AGUSTINA | F8: C1 | G8: DL | H8: CV M03 | I8: B | J8: 0.375 | K8: =IF(J8="","",IF(AND(B8="PAGI",J8<=TIME(14,0,0)),(J8-TIME(7,30,0))*24,IF(AND(B8="PAGI",J8>TIME(14,0,0)),((J8-TIME(7,30,0))*24)-1,IF(AND(B8="malam",J8<TIME(3,0,0)),3.75+(J8*24)-0.5,IF(AND(B8="malam",J8<TIME(5,5,0)),3.75+(J8*24)-0.75,(J8-TIME(20,0,0))*24))))) -> 1.5 | L8: =IFERROR(8-K8,"") -> 6.5 | M8: =L8 -> 6.5 | N8: SHORTAGE MATERIAL | O8: SHORTAGE MATERIAL | S8: =COUNTIF(A:A,C8&D8) -> 1
A9: =C9&D9 -> 45446B03009 | B9: =IF(AND(J9>=TIME(7,30,0),J9<=TIME(16,30,0)),"PAGI","MALAM") -> PAGI | C9: 45446 | D9: B03009 | E9: ANDI PRASETYO | F9: PRM | G9: DL | H9: CV M03 | I9: B | J9: 0.375 | K9: =IF(J9="","",IF(AND(B9="PAGI",J9<=TIME(14,0,0)),(J9-TIME(7,30,0))*24,IF(AND(B9="PAGI",J9>TIME(14,0,0)),((J9-TIME(7,30,0))*24)-1,IF(AND(B9="malam",J9<TIME(3,0,0)),3.75+(J9*24)-0.5,IF(AND(B9="malam",J9<TIME(5,5,0)),3.75+(J9*24)-0.75,(J9-TIME(20,0,0))*24))))) -> 1.5 | L9: =IFERROR(8-K9,"") -> 6.5 | M9: =L9 -> 6.5 | N9: SHORTAGE MATERIAL | O9: SHORTAGE MATERIAL | S9: =COUNTIF(A:A,C9&D9) -> 1
A10: =C10&D10 -> 4544628840 | B10: =IF(AND(J10>=TIME(7,30,0),J10<=TIME(16,30,0)),"PAGI","MALAM") -> PAGI | C10: 45446 | D10: 28840 | E10: SEVY NUR INDAH SARY | F10: C2 | G10: PI | H10: CV M03 | I10: B | J10: 0.375 | K10: =IF(J10="","",IF(AND(B10="PAGI",J10<=TIME(14,0,0)),(J10-TIME(7,30,0))*24,IF(AND(B10="PAGI",J10>TIME(14,0,0)),((J10-TIME(7,30,0))*24)-1,IF(AND(B10="malam",J10<TIME(3,0,0)),3.75+(J10*24)-0.5,IF(AND(B10="malam",J10<TIME(5,5,0)),3.75+(J10*24)-0.75,(J10-TIME(20,0,0))*24))))) -> 1.5 | L10: =IFERROR(8-K10,"") -> 6.5 | M10: =L10 -> 6.5 | N10: SHORTAGE MATERIAL | O10: SHORTAGE MATERIAL | S10: =COUNTIF(A:A,C10&D10) -> 1
A11: =C11&D11 -> 4544628574 | B11: =IF(AND(J11>=TIME(7,30,0),J11<=TIME(16,30,0)),"PAGI","MALAM") -> PAGI | C11: 45446 | D11: 28574 | E11: SEPTI LAELA SARI | F11: C2 | G11: DL | H11: CV M03 | I11: B | J11: 0.375 | K11: =IF(J11="","",IF(AND(B11="PAGI",J11<=TIME(14,0,0)),(J11-TIME(7,30,0))*24,IF(AND(B11="PAGI",J11>TIME(14,0,0)),((J11-TIME(7,30,0))*24)-1,IF(AND(B11="malam",J11<TIME(3,0,0)),3.75+(J11*24)-0.5,IF(AND(B11="malam",J11<TIME(5,5,0)),3.75+(J11*24)-0.75,(J11-TIME(20,0,0))*24))))) -> 1.5 | L11: =IFERROR(8-K11,"") -> 6.5 | M11: =L11 -> 6.5 | N11: SHORTAGE MATERIAL | O11: SHORTAGE MATERIAL | S11: =COUNTIF(A:A,C11&D11) -> 1
A12: =C12&D12 -> 4544628779 | B12: =IF(AND(J12>=TIME(7,30,0),J12<=TIME(16,30,0)),"PAGI","MALAM") -> PAGI | C12: 45446 | D12: 28779 | E12: NUR OCTAVIA ROMADHONI | F12: C2 | G12: DL | H12: CV M03 | I12: B | J12: 0.375 | K12: =IF(J12="","",IF(AND(B12="PAGI",J12<=TIME(14,0,0)),(J12-TIME(7,30,0))*24,IF(AND(B12="PAGI",J12>TIME(14,0,0)),((J12-TIME(7,30,0))*24)-1,IF(AND(B12="malam",J12<TIME(3,0,0)),3.75+(J12*24)-0.5,IF(AND(B12="malam",J12<TIME(5,5,0)),3.75+(J12*24)-0.75,(J12-TIME(20,0,0))*24))))) -> 1.5 | L12: =IFERROR(8-K12,"") -> 6.5 | M12: =L12 -> 6.5 | N12: SHORTAGE MATERIAL | O12: SHORTAGE MATERIAL | S12: =COUNTIF(A:A,C12&D12) -> 1
A13: =C13&D13 -> 4544628542 | B13: =IF(AND(J13>=TIME(7,30,0),J13<=TIME(16,30,0)),"PAGI","MALAM") -> PAGI | C13: 45446 | D13: 28542 | E13: FAIZUL ADHINA | F13: C2 | G13: DL | H13: CV M03 | I13: B | J13: 0.375 | K13: =IF(J13="","",IF(AND(B13="PAGI",J13<=TIME(14,0,0)),(J13-TIME(7,30,0))*24,IF(AND(B13="PAGI",J13>TIME(14,0,0)),((J13-TIME(7,30,0))*24)-1,IF(AND(B13="malam",J13<TIME(3,0,0)),3.75+(J13*24)-0.5,IF(AND(B13="malam",J13<TIME(5,5,0)),3.75+(J13*24)-0.75,(J13-TIME(20,0,0))*24))))) -> 1.5 | L13: =IFERROR(8-K13,"") -> 6.5 | M13: =L13 -> 6.5 | N13: SHORTAGE MATERIAL | O13: SHORTAGE MATERIAL | S13: =COUNTIF(A:A,C13&D13) -> 1
A14: =C14&D14 -> 454465783 | B14: =IF(AND(J14>=TIME(7,30,0),J14<=TIME(16,30,0)),"PAGI","MALAM") -> PAGI | C14: 45446 | D14: 5783 | E14: MARIYATUN | F14: PRM | G14: DL | H14: CV M03 | I14: B | J14: 0.375 | K14: =IF(J14="","",IF(AND(B14="PAGI",J14<=TIME(14,0,0)),(J14-TIME(7,30,0))*24,IF(AND(B14="PAGI",J14>TIME(14,0,0)),((J14-TIME(7,30,0))*24)-1,IF(AND(B14="malam",J14<TIME(3,0,0)),3.75+(J14*24)-0.5,IF(AND(B14="malam",J14<TIME(5,5,0)),3.75+(J14*24)-0.75,(J14-TIME(20,0,0))*24))))) -> 1.5 | L14: =IFERROR(8-K14,"") -> 6.5 | M14: =L14 -> 6.5 | N14: SHORTAGE MATERIAL | O14: SHORTAGE MATERIAL | S14: =COUNTIF(A:A,C14&D14) -> 1
A15: =C15&D15 -> 4544629678 | B15: =IF(AND(J15>=TIME(7,30,0),J15<=TIME(16,30,0)),"PAGI","MALAM") -> PAGI | C15: 45446 | D15: 29678 | E15: ALFREDO ABY PRAMESTA | F15: C1 | G15: DL | H15: CV M03 | I15: B | J15: 0.375 | K15: =IF(J15="","",IF(AND(B15="PAGI",J15<=TIME(14,0,0)),(J15-TIME(7,30,0))*24,IF(AND(B15="PAGI",J15>TIME(14,0,0)),((J15-TIME(7,30,0))*24)-1,IF(AND(B15="malam",J15<TIME(3,0,0)),3.75+(J15*24)-0.5,IF(AND(B15="malam",J15<TIME(5,5,0)),3.75+(J15*24)-0.75,(J15-TIME(20,0,0))*24))))) -> 1.5 | L15: =IFERROR(8-K15,"") -> 6.5 | M15: =L15 -> 6.5 | N15: SHORTAGE MATERIAL | O15: SHORTAGE MATERIAL | S15: =COUNTIF(A:A,C15&D15) -> 1
A16: =C16&D16 -> 4544612234 | B16: =IF(AND(J16>=TIME(7,30,0),J16<=TIME(16,30,0)),"PAGI","MALAM") -> PAGI | C16: 45446 | D16: 12234 | E16: AHMAD ABDUL GHOFUR | F16: PRM | G16: DL | H16: CV M03 | I16: B | J16: 0.375 | K16: =IF(J16="","",IF(AND(B16="PAGI",J16<=TIME(14,0,0)),(J16-TIME(7,30,0))*24,IF(AND(B16="PAGI",J16>TIME(14,0,0)),((J16-TIME(7,30,0))*24)-1,IF(AND(B16="malam",J16<TIME(3,0,0)),3.75+(J16*24)-0.5,IF(AND(B16="malam",J16<TIME(5,5,0)),3.75+(J16*24)-0.75,(J16-TIME(20,0,0))*24))))) -> 1.5 | L16: =IFERROR(8-K16,"") -> 6.5 | M16: =L16 -> 6.5 | N16: SHORTAGE MATERIAL | O16: SHORTAGE MATERIAL | S16: =COUNTIF(A:A,C16&D16) -> 1
A17: =C17&D17 -> 4544628913 | B17: =IF(AND(J17>=TIME(7,30,0),J17<=TIME(16,30,0)),"PAGI","MALAM") -> PAGI | C17: 45446 | D17: 28913 | E17: FIFI ETIKASARI | F17: C1 | G17: DL | H17: CV M03 | I17: B | J17: 0.375 | K17: =IF(J17="","",IF(AND(B17="PAGI",J17<=TIME(14,0,0)),(J17-TIME(7,30,0))*24,IF(AND(B17="PAGI",J17>TIME(14,0,0)),((J17-TIME(7,30,0))*24)-1,IF(AND(B17="malam",J17<TIME(3,0,0)),3.75+(J17*24)-0.5,IF(AND(B17="malam",J17<TIME(5,5,0)),3.75+(J17*24)-0.75,(J17-TIME(20,0,0))*24))))) -> 1.5 | L17: =IFERROR(8-K17,"") -> 6.5 | M17: =L17 -> 6.5 | N17: SHORTAGE MATERIAL | O17: SHORTAGE MATERIAL | S17: =COUNTIF(A:A,C17&D17) -> 1
A18: =C18&D18 -> 4544628766 | B18: =IF(AND(J18>=TIME(7,30,0),J18<=TIME(16,30,0)),"PAGI","MALAM") -> PAGI | C18: 45446 | D18: 28766 | E18: FIA UDZRI TSURAYYA | F18: C2 | G18: DL | H18: CV M03 | I18: B | J18: 0.375 | K18: =IF(J18="","",IF(AND(B18="PAGI",J18<=TIME(14,0,0)),(J18-TIME(7,30,0))*24,IF(AND(B18="PAGI",J18>TIME(14,0,0)),((J18-TIME(7,30,0))*24)-1,IF(AND(B18="malam",J18<TIME(3,0,0)),3.75+(J18*24)-0.5,IF(AND(B18="malam",J18<TIME(5,5,0)),3.75+(J18*24)-0.75,(J18-TIME(20,0,0))*24))))) -> 1.5 | L18: =IFERROR(8-K18,"") -> 6.5 | M18: =L18 -> 6.5 | N18: SHORTAGE MATERIAL | O18: SHORTAGE MATERIAL | S18: =COUNTIF(A:A,C18&D18) -> 1
A19: =C19&D19 -> 4544628988 | B19: =IF(AND(J19>=TIME(7,30,0),J19<=TIME(16,30,0)),"PAGI","MALAM") -> PAGI | C19: 45446 | D19: 28988 | E19: SALSA CAHYA NINGRUM | F19: C1 | G19: DL | H19: CV M03 | I19: B | J19: 0.375 | K19: =IF(J19="","",IF(AND(B19="PAGI",J19<=TIME(14,0,0)),(J19-TIME(7,30,0))*24,IF(AND(B19="PAGI",J19>TIME(14,0,0)),((J19-TIME(7,30,0))*24)-1,IF(AND(B19="malam",J19<TIME(3,0,0)),3.75+(J19*24)-0.5,IF(AND(B19="malam",J19<TIME(5,5,0)),3.75+(J19*24)-0.75,(J19-TIME(20,0,0))*24))))) -> 1.5 | L19: =IFERROR(8-K19,"") -> 6.5 | M19: =L19 -> 6.5 | N19: SHORTAGE MATERIAL | O19: SHORTAGE MATERIAL | S19: =COUNTIF(A:A,C19&D19) -> 1
A20: =C20&D20 -> 4544629770 | B20: =IF(AND(J20>=TIME(7,30,0),J20<=TIME(16,30,0)),"PAGI","MALAM") -> PAGI | C20: 45446 | D20: 29770 | E20: SITI SA'ADAH | F20: C1 | G20: DL | H20: CV M03 | I20: B | J20: 0.375 | K20: =IF(J20="","",IF(AND(B20="PAGI",J20<=TIME(14,0,0)),(J20-TIME(7,30,0))*24,IF(AND(B20="PAGI",J20>TIME(14,0,0)),((J20-TIME(7,30,0))*24)-1,IF(AND(B20="malam",J20<TIME(3,0,0)),3.75+(J20*24)-0.5,IF(AND(B20="malam",J20<TIME(5,5,0)),3.75+(J20*24)-0.75,(J20-TIME(20,0,0))*24))))) -> 1.5 | L20: =IFERROR(8-K20,"") -> 6.5 | M20: =L20 -> 6.5 | N20: SHORTAGE MATERIAL | O20: SHORTAGE MATERIAL | S20: =COUNTIF(A:A,C20&D20) -> 1
A21: =C21&D21 -> 454469928 | B21: =IF(AND(J21>=TIME(7,30,0),J21<=TIME(16,30,0)),"PAGI","MALAM") -> PAGI | C21: 45446 | D21: 9928 | E21: ELEN NATANIA MANALU | F21: PRM | G21: DL | H21: CV M03 | I21: B | J21: 0.375 | K21: =IF(J21="","",IF(AND(B21="PAGI",J21<=TIME(14,0,0)),(J21-TIME(7,30,0))*24,IF(AND(B21="PAGI",J21>TIME(14,0,0)),((J21-TIME(7,30,0))*24)-1,IF(AND(B21="malam",J21<TIME(3,0,0)),3.75+(J21*24)-0.5,IF(AND(B21="malam",J21<TIME(5,5,0)),3.75+(J21*24)-0.75,(J21-TIME(20,0,0))*24))))) -> 1.5 | L21: =IFERROR(8-K21,"") -> 6.5 | M21: =L21 -> 6.5 | N21: SHORTAGE MATERIAL | O21: SHORTAGE MATERIAL | S21: =COUNTIF(A:A,C21&D21) -> 1
... A67: =C67&D67 -> 4544628599 | B67: =IF(AND(J67>=TIME(7,30,0),J67<=TIME(16,30,0)),"PAGI","MALAM") -> PAGI | C67: 45446 | D67: 28599 | E67: ADI SUCIPTO | F67: C2 | G67: PI | H67: CPA MAZDA | I67: B | J67: 0.375 | K67: =IF(J67="","",IF(AND(B67="PAGI",J67<=TIME(14,0,0)),(J67-TIME(7,30,0))*24,IF(AND(B67="PAGI",J67>TIME(14,0,0)),((J67-TIME(7,30,0))*24)-1,IF(AND(B67="malam",J67<TIME(3,0,0)),3.75+(J67*24)-0.5,IF(AND(B67="malam",J67<TIME(5,5,0)),3.75+(J67*24)-0.75,(J67-TIME(20,0,0))*24))))) -> 1.5 | L67: =IFERROR(8-K67,"") -> 6.5 | M67: =L67 -> 6.5 | N67: PROBLEM MATERIAL CV M03 | O67: SHORTAGE MATERIAL | S67: =COUNTIF(A:A,C67&D67) -> 1
A68: =C68&D68 -> 45446B00759 | B68: =IF(AND(J68>=TIME(7,30,0),J68<=TIME(16,30,0)),"PAGI","MALAM") -> PAGI | C68: 45446 | D68: B00759 | E68: ALFIATU ROCHMANIA | F68: PRM | G68: PI | H68: CPA MAZDA | I68: B | J68: 0.375 | K68: =IF(J68="","",IF(AND(B68="PAGI",J68<=TIME(14,0,0)),(J68-TIME(7,30,0))*24,IF(AND(B68="PAGI",J68>TIME(14,0,0)),((J68-TIME(7,30,0))*24)-1,IF(AND(B68="malam",J68<TIME(3,0,0)),3.75+(J68*24)-0.5,IF(AND(B68="malam",J68<TIME(5,5,0)),3.75+(J68*24)-0.75,(J68-TIME(20,0,0))*24))))) -> 1.5 | L68: =IFERROR(8-K68,"") -> 6.5 | M68: =L68 -> 6.5 | N68: PROBLEM MATERIAL CV M03 | O68: SHORTAGE MATERIAL | S68: =COUNTIF(A:A,C68&D68) -> 1
A69: =C69&D69 -> 45446B00284 | B69: =IF(AND(J69>=TIME(7,30,0),J69<=TIME(16,30,0)),"PAGI","MALAM") -> PAGI | C69: 45446 | D69: B00284 | E69: ESTER SARI SETIYANINGRUM | F69: PRM | G69: PI | H69: CPA MAZDA | I69: B | J69: 0.375 | K69: =IF(J69="","",IF(AND(B69="PAGI",J69<=TIME(14,0,0)),(J69-TIME(7,30,0))*24,IF(AND(B69="PAGI",J69>TIME(14,0,0)),((J69-TIME(7,30,0))*24)-1,IF(AND(B69="malam",J69<TIME(3,0,0)),3.75+(J69*24)-0.5,IF(AND(B69="malam",J69<TIME(5,5,0)),3.75+(J69*24)-0.75,(J69-TIME(20,0,0))*24))))) -> 1.5 | L69: =IFERROR(8-K69,"") -> 6.5 | M69: =L69 -> 6.5 | N69: PROBLEM MATERIAL CV M03 | O69: SHORTAGE MATERIAL | S69: =COUNTIF(A:A,C69&D69) -> 1
A70: =C70&D70 -> 4544629884 | B70: =IF(AND(J70>=TIME(7,30,0),J70<=TIME(16,30,0)),"PAGI","MALAM") -> PAGI | C70: 45446 | D70: 29884 | E70: ABDUL QOHAR | F70: C1 | G70: PI | H70: CPA MAZDA | I70: B | J70: 0.375 | K70: =IF(J70="","",IF(AND(B70="PAGI",J70<=TIME(14,0,0)),(J70-TIME(7,30,0))*24,IF(AND(B70="PAGI",J70>TIME(14,0,0)),((J70-TIME(7,30,0))*24)-1,IF(AND(B70="malam",J70<TIME(3,0,0)),3.75+(J70*24)-0.5,IF(AND(B70="malam",J70<TIME(5,5,0)),3.75+(J70*24)-0.75,(J70-TIME(20,0,0))*24))))) -> 1.5 | L70: =IFERROR(8-K70,"") -> 6.5 | M70: =L70 -> 6.5 | N70: PROBLEM MATERIAL CV M03 | O70: SHORTAGE MATERIAL | S70: =COUNTIF(A:A,C70&D70) -> 1
A71: =C71&D71 -> 4544610513 | B71: =IF(AND(J71>=TIME(7,30,0),J71<=TIME(16,30,0)),"PAGI","MALAM") -> MALAM | C71: 45446 | D71: 10513 | E71: NAJIKHATUL MU'ALIFAH | F71: PRM | G71: DL | H71: CPA MAZDA | I71: A | J71: 0.875 | K71: =IF(J71="","",IF(AND(B71="PAGI",J71<=TIME(14,0,0)),(J71-TIME(7,30,0))*24,IF(AND(B71="PAGI",J71>TIME(14,0,0)),((J71-TIME(7,30,0))*24)-1,IF(AND(B71="malam",J71<TIME(3,0,0)),3.75+(J71*24)-0.5,IF(AND(B71="malam",J71<TIME(5,5,0)),3.75+(J71*24)-0.75,(J71-TIME(20,0,0))*24))))) -> 1 | L71: =IFERROR(8-K71,"") -> 7 | M71: =L71 -> 7 | N71: SHORTAGE MATERIAL | O71: SHORTAGE MATERIAL | S71: =COUNTIF(A:A,C71&D71) -> 1
A72: =C72&D72 -> 4544629818 | B72: =IF(AND(J72>=TIME(7,30,0),J72<=TIME(16,30,0)),"PAGI","MALAM") -> MALAM | C72: 45446 | D72: 29818 | E72: PETI ISMAYANTI | F72: C1 | G72: DL | H72: CPA MAZDA | I72: A | J72: 0.875 | K72: =IF(J72="","",IF(AND(B72="PAGI",J72<=TIME(14,0,0)),(J72-TIME(7,30,0))*24,IF(AND(B72="PAGI",J72>TIME(14,0,0)),((J72-TIME(7,30,0))*24)-1,IF(AND(B72="malam",J72<TIME(3,0,0)),3.75+(J72*24)-0.5,IF(AND(B72="malam",J72<TIME(5,5,0)),3.75+(J72*24)-0.75,(J72-TIME(20,0,0))*24))))) -> 1 | L72: =IFERROR(8-K72,"") -> 7 | M72: =L72 -> 7 | N72: SHORTAGE MATERIAL | O72: SHORTAGE MATERIAL | S72: =COUNTIF(A:A,C72&D72) -> 1
A73: =C73&D73 -> 4544630117 | B73: =IF(AND(J73>=TIME(7,30,0),J73<=TIME(16,30,0)),"PAGI","MALAM") -> MALAM | C73: 45446 | D73: 30117 | E73: DIYAH RETNO WATI | F73: M1 | G73: PI | H73: CPA MAZDA | I73: A | J73: 0.875 | K73: =IF(J73="","",IF(AND(B73="PAGI",J73<=TIME(14,0,0)),(J73-TIME(7,30,0))*24,IF(AND(B73="PAGI",J73>TIME(14,0,0)),((J73-TIME(7,30,0))*24)-1,IF(AND(B73="malam",J73<TIME(3,0,0)),3.75+(J73*24)-0.5,IF(AND(B73="malam",J73<TIME(5,5,0)),3.75+(J73*24)-0.75,(J73-TIME(20,0,0))*24))))) -> 1 | L73: =IFERROR(8-K73,"") -> 7 | M73: =L73 -> 7 | N73: SHORTAGE MATERIAL | O73: SHORTAGE MATERIAL | S73: =COUNTIF(A:A,C73&D73) -> 1
A74: =C74&D74 -> 454469615 | B74: =IF(AND(J74>=TIME(7,30,0),J74<=TIME(16,30,0)),"PAGI","MALAM") -> MALAM | C74: 45446 | D74: 9615 | E74: NANING HASANAH | F74: PRM | G74: DL | H74: CPA MAZDA | I74: A | J74: 0.875 | K74: =IF(J74="","",IF(AND(B74="PAGI",J74<=TIME(14,0,0)),(J74-TIME(7,30,0))*24,IF(AND(B74="PAGI",J74>TIME(14,0,0)),((J74-TIME(7,30,0))*24)-1,IF(AND(B74="malam",J74<TIME(3,0,0)),3.75+(J74*24)-0.5,IF(AND(B74="malam",J74<TIME(5,5,0)),3.75+(J74*24)-0.75,(J74-TIME(20,0,0))*24))))) -> 1 | L74: =IFERROR(8-K74,"") -> 7 | M74: =L74 -> 7 | N74: SHORTAGE MATERIAL | O74: SHORTAGE MATERIAL | S74: =COUNTIF(A:A,C74&D74) -> 1
A75: =C75&D75 -> 4544628523 | B75: =IF(AND(J75>=TIME(7,30,0),J75<=TIME(16,30,0)),"PAGI","MALAM") -> MALAM | C75: 45446 | D75: 28523 | E75: TEGUH RIYAN HIDAYATULLOH | F75: C2 | G75: PI | H75: CPA MAZDA | I75: A | J75: 0.875 | K75: =IF(J75="","",IF(AND(B75="PAGI",J75<=TIME(14,0,0)),(J75-TIME(7,30,0))*24,IF(AND(B75="PAGI",J75>TIME(14,0,0)),((J75-TIME(7,30,0))*24)-1,IF(AND(B75="malam",J75<TIME(3,0,0)),3.75+(J75*24)-0.5,IF(AND(B75="malam",J75<TIME(5,5,0)),3.75+(J75*24)-0.75,(J75-TIME(20,0,0))*24))))) -> 1 | L75: =IFERROR(8-K75,"") -> 7 | M75: =L75 -> 7 | N75: SHORTAGE MATERIAL | O75: SHORTAGE MATERIAL | S75: =COUNTIF(A:A,C75&D75) -> 1
A76: =C76&D76 -> 4544630006 | B76: =IF(AND(J76>=TIME(7,30,0),J76<=TIME(16,30,0)),"PAGI","MALAM") -> MALAM | C76: 45446 | D76: 30006 | E76: RAHMA AYU RIZQIANI | F76: C1 | G76: DL | H76: CPA MAZDA | I76: A | J76: 0.875 | K76: =IF(J76="","",IF(AND(B76="PAGI",J76<=TIME(14,0,0)),(J76-TIME(7,30,0))*24,IF(AND(B76="PAGI",J76>TIME(14,0,0)),((J76-TIME(7,30,0))*24)-1,IF(AND(B76="malam",J76<TIME(3,0,0)),3.75+(J76*24)-0.5,IF(AND(B76="malam",J76<TIME(5,5,0)),3.75+(J76*24)-0.75,(J76-TIME(20,0,0))*24))))) -> 1 | L76: =IFERROR(8-K76,"") -> 7 | M76: =L76 -> 7 | N76: SHORTAGE MATERIAL | O76: SHORTAGE MATERIAL | S76: =COUNTIF(A:A,C76&D76) -> 1
A77: =C77&D77 -> 4544630034 | B77: =IF(AND(J77>=TIME(7,30,0),J77<=TIME(16,30,0)),"PAGI","MALAM") -> MALAM | C77: 45446 | D77: 30034 | E77: AMBAR BAHTIAR | F77: C1 | G77: DL | H77: CPA MAZDA | I77: A | J77: 0.875 | K77: =IF(J77="","",IF(AND(B77="PAGI",J77<=TIME(14,0,0)),(J77-TIME(7,30,0))*24,IF(AND(B77="PAGI",J77>TIME(14,0,0)),((J77-TIME(7,30,0))*24)-1,IF(AND(B77="malam",J77<TIME(3,0,0)),3.75+(J77*24)-0.5,IF(AND(B77="malam",J77<TIME(5,5,0)),3.75+(J77*24)-0.75,(J77-TIME(20,0,0))*24))))) -> 1 | L77: =IFERROR(8-K77,"") -> 7 | M77: =L77 -> 7 | N77: SHORTAGE MATERIAL | O77: SHORTAGE MATERIAL | S77: =COUNTIF(A:A,C77&D77) -> 1
A78: =C78&D78 -> 4544630061 | B78: =IF(AND(J78>=TIME(7,30,0),J78<=TIME(16,30,0)),"PAGI","MALAM") -> MALAM | C78: 45446 | D78: 30061 | E78: INDRIANA DWI ANGGRIANI | F78: C1 | G78: DL | H78: CPA MAZDA | I78: A | J78: 0.875 | K78: =IF(J78="","",IF(AND(B78="PAGI",J78<=TIME(14,0,0)),(J78-TIME(7,30,0))*24,IF(AND(B78="PAGI",J78>TIME(14,0,0)),((J78-TIME(7,30,0))*24)-1,IF(AND(B78="malam",J78<TIME(3,0,0)),3.75+(J78*24)-0.5,IF(AND(B78="malam",J78<TIME(5,5,0)),3.75+(J78*24)-0.75,(J78-TIME(20,0,0))*24))))) -> 1 | L78: =IFERROR(8-K78,"") -> 7 | M78: =L78 -> 7 | N78: SHORTAGE MATERIAL | O78: SHORTAGE MATERIAL | S78: =COUNTIF(A:A,C78&D78) -> 1
A79: =C79&D79 -> 4544628323 | B79: =IF(AND(J79>=TIME(7,30,0),J79<=TIME(16,30,0)),"PAGI","MALAM") -> MALAM | C79: 45446 | D79: 28323 | E79: MUHAMAD IKO AMANDA | F79: C2 | G79: PI | H79: CPA MAZDA | I79: A | J79: 0.875 | K79: =IF(J79="","",IF(AND(B79="PAGI",J79<=TIME(14,0,0)),(J79-TIME(7,30,0))*24,IF(AND(B79="PAGI",J79>TIME(14,0,0)),((J79-TIME(7,30,0))*24)-1,IF(AND(B79="malam",J79<TIME(3,0,0)),3.75+(J79*24)-0.5,IF(AND(B79="malam",J79<TIME(5,5,0)),3.75+(J79*24)-0.75,(J79-TIME(20,0,0))*24))))) -> 1 | L79: =IFERROR(8-K79,"") -> 7 | M79: =L79 -> 7 | N79: SHORTAGE MATERIAL | O79: SHORTAGE MATERIAL | S79: =COUNTIF(A:A,C79&D79) -> 1
A80: =C80&D80 -> 4544629383 | B80: =IF(AND(J80>=TIME(7,30,0),J80<=TIME(16,30,0)),"PAGI","MALAM") -> MALAM | C80: 45446 | D80: 29383 | E80: PUPUT ANASTYA WARDANI | F80: C1 | G80: PI | H80: CPA MAZDA | I80: A | J80: 0.875 | K80: =IF(J80="","",IF(AND(B80="PAGI",J80<=TIME(14,0,0)),(J80-TIME(7,30,0))*24,IF(AND(B80="PAGI",J80>TIME(14,0,0)),((J80-TIME(7,30,0))*24)-1,IF(AND(B80="malam",J80<TIME(3,0,0)),3.75+(J80*24)-0.5,IF(AND(B80="malam",J80<TIME(5,5,0)),3.75+(J80*24)-0.75,(J80-TIME(20,0,0))*24))))) -> 1 | L80: =IFERROR(8-K80,"") -> 7 | M80: =L80 -> 7 | N80: SHORTAGE MATERIAL | O80: SHORTAGE MATERIAL | S80: =COUNTIF(A:A,C80&D80) -> 1
A81: =C81&D81 -> 4544628359 | B81: =IF(AND(J81>=TIME(7,30,0),J81<=TIME(16,30,0)),"PAGI","MALAM") -> MALAM | C81: 45446 | D81: 28359 | E81: DEWI MANDALIKA WIBOWO PUTRI | F81: C2 | G81: PI | H81: CV M03 | I81: A | J81: 0.875 | K81: =IF(J81="","",IF(AND(B81="PAGI",J81<=TIME(14,0,0)),(J81-TIME(7,30,0))*24,IF(AND(B81="PAGI",J81>TIME(14,0,0)),((J81-TIME(7,30,0))*24)-1,IF(AND(B81="malam",J81<TIME(3,0,0)),3.75+(J81*24)-0.5,IF(AND(B81="malam",J81<TIME(5,5,0)),3.75+(J81*24)-0.75,(J81-TIME(20,0,0))*24))))) -> 1 | L81: =IFERROR(8-K81,"") -> 7 | M81: =L81 -> 7 | N81: SHORTAGE MATERIAL | O81: SHORTAGE MATERIAL | S81: =COUNTIF(A:A,C81&D81) -> 1
... A104: =C104&D104 -> 4544628297 | B104: =IF(AND(J104>=TIME(7,30,0),J104<=TIME(16,30,0)),"PAGI","MALAM") -> MALAM | C104: 45446 | D104: 28297 | E104: YUNI LESTARI | F104: C2 | G104: DL | H104: CV M03 | I104: A | J104: 0.875 | K104: =IF(J104="","",IF(AND(B104="PAGI",J104<=TIME(14,0,0)),(J104-TIME(7,30,0))*24,IF(AND(B104="PAGI",J104>TIME(14,0,0)),((J104-TIME(7,30,0))*24)-1,IF(AND(B104="malam",J104<TIME(3,0,0)),3.75+(J104*24)-0.5,IF(AND(B104="malam",J104<TIME(5,5,0)),3.75+(J104*24)-0.75,(J104-TIME(20,0,0))*24))))) -> 1 | L104: =IFERROR(8-K104,"") -> 7 | M104: =L104 -> 7 | N104: SHORTAGE MATERIAL | O104: SHORTAGE MATERIAL | S104: =COUNTIF(A:A,C104&D104) -> 1
A105: =C105&D105 -> 45446B00487 | B105: =IF(AND(J105>=TIME(7,30,0),J105<=TIME(16,30,0)),"PAGI","MALAM") -> MALAM | C105: 45446 | D105: B00487 | E105: TOPAN SAPUTRO | F105: PRM | G105: DL | H105: CV M03 | I105: A | J105: 0.875 | K105: =IF(J105="","",IF(AND(B105="PAGI",J105<=TIME(14,0,0)),(J105-TIME(7,30,0))*24,IF(AND(B105="PAGI",J105>TIME(14,0,0)),((J105-TIME(7,30,0))*24)-1,IF(AND(B105="malam",J105<TIME(3,0,0)),3.75+(J105*24)-0.5,IF(AND(B105="malam",J105<TIME(5,5,0)),3.75+(J105*24)-0.75,(J105-TIME(20,0,0))*24))))) -> 1 | L105: =IFERROR(8-K105,"") -> 7 | M105: =L105 -> 7 | N105: SHORTAGE MATERIAL | O105: SHORTAGE MATERIAL | S105: =COUNTIF(A:A,C105&D105) -> 1
A106: =C106&D106 -> 4544630211 | B106: =IF(AND(J106>=TIME(7,30,0),J106<=TIME(16,30,0)),"PAGI","MALAM") -> MALAM | C106: 45446 | D106: 30211 | E106: MOCHAMMAD ZASMI ZAKKI | F106: M1 | G106: PI | H106: CV M03 | I106: A | J106: 0.875 | K106: =IF(J106="","",IF(AND(B106="PAGI",J106<=TIME(14,0,0)),(J106-TIME(7,30,0))*24,IF(AND(B106="PAGI",J106>TIME(14,0,0)),((J106-TIME(7,30,0))*24)-1,IF(AND(B106="malam",J106<TIME(3,0,0)),3.75+(J106*24)-0.5,IF(AND(B106="malam",J106<TIME(5,5,0)),3.75+(J106*24)-0.75,(J106-TIME(20,0,0))*24))))) -> 1 | L106: =IFERROR(8-K106,"") -> 7 | M106: =L106 -> 7 | N106: SHORTAGE MATERIAL | O106: SHORTAGE MATERIAL | S106: =COUNTIF(A:A,C106&D106) -> 1
A107: =C107&D107 -> 4544630200 | B107: =IF(AND(J107>=TIME(7,30,0),J107<=TIME(16,30,0)),"PAGI","MALAM") -> MALAM | C107: 45446 | D107: 30200 | E107: INDAH PERMATASARI | F107: M1 | G107: PI | H107: CV M03 | I107: A | J107: 0.875 | K107: =IF(J107="","",IF(AND(B107="PAGI",J107<=TIME(14,0,0)),(J107-TIME(7,30,0))*24,IF(AND(B107="PAGI",J107>TIME(14,0,0)),((J107-TIME(7,30,0))*24)-1,IF(AND(B107="malam",J107<TIME(3,0,0)),3.75+(J107*24)-0.5,IF(AND(B107="malam",J107<TIME(5,5,0)),3.75+(J107*24)-0.75,(J107-TIME(20,0,0))*24))))) -> 1 | L107: =IFERROR(8-K107,"") -> 7 | M107: =L107 -> 7 | N107: SHORTAGE MATERIAL | O107: SHORTAGE MATERIAL | S107: =COUNTIF(A:A,C107&D107) -> 1
...

Sheet SUM.PULANG AWAL
A3: ="SUMMARY DATA CV PULANG AWAL BULAN "&'list area'!C1 &" "&'list area'!C2 &" (MAN HOUR)" -> SUMMARY DATA CV PULANG AWAL BULAN JUNI 2024 (MAN HOUR) | AI3: TOTAL/ CV
A5: NO | B5: AREA (CV) | C5: SHIFT | D5: TANGGAL
D6: ='list area'!D1 -> 45444 | E6: =+D6+1 -> 45445 | F6: =+E6+1 -> 45446 | G6: =+F6+1 -> 45447 | H6: =+G6+1 -> 45448 | I6: =+H6+1 -> 45449 | J6: =+I6+1 -> 45450 | K6: =+J6+1 -> 45451 | L6: =+K6+1 -> 45452 | ... AH6: =+AG6+1 -> 45474
A7: 1 | B7: ADM | C7: A | D7: =SUMIFS('INPUT PULANG AWAL'!$M:$M,'INPUT PULANG AWAL'!$C:$C,'SUM.PULANG AWAL'!D$6,'INPUT PULANG AWAL'!$H:$H,'SUM.PULANG AWAL'!$B7:$B9,'INPUT PULANG AWAL'!$I:$I,'SUM.PULANG AWAL'!$C7) -> 0 | E7: =SUMIFS('INPUT PULANG AWAL'!$M:$M,'INPUT PULANG AWAL'!$C:$C,'SUM.PULANG AWAL'!E$6,'INPUT PULANG AWAL'!$H:$H,'SUM.PULANG AWAL'!$B7:$B9,'INPUT PULANG AWAL'!$I:$I,'SUM.PULANG AWAL'!$C7) -> 0 | F7: =SUMIFS('INPUT PULANG AWAL'!$M:$M,'INPUT PULANG AWAL'!$C:$C,'SUM.PULANG AWAL'!F$6,'INPUT PULANG AWAL'!$H:$H,'SUM.PULANG AWAL'!$B7:$B9,'INPUT PULANG AWAL'!$I:$I,'SUM.PULANG AWAL'!$C7) -> 0 | G7: =SUMIFS('INPUT PULANG AWAL'!$M:$M,'INPUT PULANG AWAL'!$C:$C,'SUM.PULANG AWAL'!G$6,'INPUT PULANG AWAL'!$H:$H,'SUM.PULANG AWAL'!$B7:$B9,'INPUT PULANG AWAL'!$I:$I,'SUM.PULANG AWAL'!$C7) -> 0 | H7: =SUMIFS('INPUT PULANG AWAL'!$M:$M,'INPUT PULANG AWAL'!$C:$C,'SUM.PULANG AWAL'!H$6,'INPUT PULANG AWAL'!$H:$H,'SUM.PULANG AWAL'!$B7:$B9,'INPUT PULANG AWAL'!$I:$I,'SUM.PULANG AWAL'!$C7) -> 0 | I7: =SUMIFS('INPUT PULANG AWAL'!$M:$M,'INPUT PULANG AWAL'!$C:$C,'SUM.PULANG AWAL'!I$6,'INPUT PULANG AWAL'!$H:$H,'SUM.PULANG AWAL'!$B7:$B9,'INPUT PULANG AWAL'!$I:$I,'SUM.PULANG AWAL'!$C7) -> 0 | J7: =SUMIFS('INPUT PULANG AWAL'!$M:$M,'INPUT PULANG AWAL'!$C:$C,'SUM.PULANG AWAL'!J$6,'INPUT PULANG AWAL'!$H:$H,'SUM.PULANG AWAL'!$B7:$B9,'INPUT PULANG AWAL'!$I:$I,'SUM.PULANG AWAL'!$C7) -> 0 | K7: =SUMIFS('INPUT PULANG AWAL'!$M:$M,'INPUT PULANG AWAL'!$C:$C,'SUM.PULANG AWAL'!K$6,'INPUT PULANG AWAL'!$H:$H,'SUM.PULANG AWAL'!$B7:$B9,'INPUT PULANG AWAL'!$I:$I,'SUM.PULANG AWAL'!$C7) -> 0 | ... AH7: =SUMIFS('INPUT PULANG AWAL'!$M:$M,'INPUT PULANG AWAL'!$C:$C,'SUM.PULANG AWAL'!AH$6,'INPUT PULANG AWAL'!$H:$H,'SUM.PULANG AWAL'!$B7:$B9,'INPUT PULANG AWAL'!$I:$I,'SUM.PULANG AWAL'!$C7) -> 0 | AI7: =SUM(D7:AH7) -> 0
C8: B | D8: =SUMIFS('INPUT PULANG AWAL'!$M:$M,'INPUT PULANG AWAL'!$C:$C,'SUM.PULANG AWAL'!D$6,'INPUT PULANG AWAL'!$H:$H,'SUM.PULANG AWAL'!$B7,'INPUT PULANG AWAL'!$I:$I,'SUM.PULANG AWAL'!$C8) -> 0 | E8: =SUMIFS('INPUT PULANG AWAL'!$M:$M,'INPUT PULANG AWAL'!$C:$C,'SUM.PULANG AWAL'!E$6,'INPUT PULANG AWAL'!$H:$H,'SUM.PULANG AWAL'!$B7,'INPUT PULANG AWAL'!$I:$I,'SUM.PULANG AWAL'!$C8) -> 0 | F8: =SUMIFS('INPUT PULANG AWAL'!$M:$M,'INPUT PULANG AWAL'!$C:$C,'SUM.PULANG AWAL'!F$6,'INPUT PULANG AWAL'!$H:$H,'SUM.PULANG AWAL'!$B7,'INPUT PULANG AWAL'!$I:$I,'SUM.PULANG AWAL'!$C8) -> 0 | G8: =SUMIFS('INPUT PULANG AWAL'!$M:$M,'INPUT PULANG AWAL'!$C:$C,'SUM.PULANG AWAL'!G$6,'INPUT PULANG AWAL'!$H:$H,'SUM.PULANG AWAL'!$B7,'INPUT PULANG AWAL'!$I:$I,'SUM.PULANG AWAL'!$C8) -> 0 | H8: =SUMIFS('INPUT PULANG AWAL'!$M:$M,'INPUT PULANG AWAL'!$C:$C,'SUM.PULANG AWAL'!H$6,'INPUT PULANG AWAL'!$H:$H,'SUM.PULANG AWAL'!$B7,'INPUT PULANG AWAL'!$I:$I,'SUM.PULANG AWAL'!$C8) -> 0 | I8: =SUMIFS('INPUT PULANG AWAL'!$M:$M,'INPUT PULANG AWAL'!$C:$C,'SUM.PULANG AWAL'!I$6,'INPUT PULANG AWAL'!$H:$H,'SUM.PULANG AWAL'!$B7,'INPUT PULANG AWAL'!$I:$I,'SUM.PULANG AWAL'!$C8) -> 0 | J8: =SUMIFS('INPUT PULANG AWAL'!$M:$M,'INPUT PULANG AWAL'!$C:$C,'SUM.PULANG AWAL'!J$6,'INPUT PULANG AWAL'!$H:$H,'SUM.PULANG AWAL'!$B7,'INPUT PULANG AWAL'!$I:$I,'SUM.PULANG AWAL'!$C8) -> 0 | K8: =SUMIFS('INPUT PULANG AWAL'!$M:$M,'INPUT PULANG AWAL'!$C:$C,'SUM.PULANG AWAL'!K$6,'INPUT PULANG AWAL'!$H:$H,'SUM.PULANG AWAL'!$B7,'INPUT PULANG AWAL'!$I:$I,'SUM.PULANG AWAL'!$C8) -> 0 | ... AH8: =SUMIFS('INPUT PULANG AWAL'!$M:$M,'INPUT PULANG AWAL'!$C:$C,'SUM.PULANG AWAL'!AH$6,'INPUT PULANG AWAL'!$H:$H,'SUM.PULANG AWAL'!$B7,'INPUT PULANG AWAL'!$I:$I,'SUM.PULANG AWAL'!$C8) -> 0 | AI8: =SUM(D8:AH8) -> 0
C9: NS | D9: =SUMIFS('INPUT PULANG AWAL'!$M:$M,'INPUT PULANG AWAL'!$C:$C,'SUM.PULANG AWAL'!D$6,'INPUT PULANG AWAL'!$H:$H,'SUM.PULANG AWAL'!$B7,'INPUT PULANG AWAL'!$I:$I,'SUM.PULANG AWAL'!$C9) -> 0 | E9: =SUMIFS('INPUT PULANG AWAL'!$M:$M,'INPUT PULANG AWAL'!$C:$C,'SUM.PULANG AWAL'!E$6,'INPUT PULANG AWAL'!$H:$H,'SUM.PULANG AWAL'!$B7,'INPUT PULANG AWAL'!$I:$I,'SUM.PULANG AWAL'!$C9) -> 0 | F9: =SUMIFS('INPUT PULANG AWAL'!$M:$M,'INPUT PULANG AWAL'!$C:$C,'SUM.PULANG AWAL'!F$6,'INPUT PULANG AWAL'!$H:$H,'SUM.PULANG AWAL'!$B7,'INPUT PULANG AWAL'!$I:$I,'SUM.PULANG AWAL'!$C9) -> 0 | G9: =SUMIFS('INPUT PULANG AWAL'!$M:$M,'INPUT PULANG AWAL'!$C:$C,'SUM.PULANG AWAL'!G$6,'INPUT PULANG AWAL'!$H:$H,'SUM.PULANG AWAL'!$B7,'INPUT PULANG AWAL'!$I:$I,'SUM.PULANG AWAL'!$C9) -> 0 | H9: =SUMIFS('INPUT PULANG AWAL'!$M:$M,'INPUT PULANG AWAL'!$C:$C,'SUM.PULANG AWAL'!H$6,'INPUT PULANG AWAL'!$H:$H,'SUM.PULANG AWAL'!$B7,'INPUT PULANG AWAL'!$I:$I,'SUM.PULANG AWAL'!$C9) -> 0 | I9: =SUMIFS('INPUT PULANG AWAL'!$M:$M,'INPUT PULANG AWAL'!$C:$C,'SUM.PULANG AWAL'!I$6,'INPUT PULANG AWAL'!$H:$H,'SUM.PULANG AWAL'!$B7,'INPUT PULANG AWAL'!$I:$I,'SUM.PULANG AWAL'!$C9) -> 0 | J9: =SUMIFS('INPUT PULANG AWAL'!$M:$M,'INPUT PULANG AWAL'!$C:$C,'SUM.PULANG AWAL'!J$6,'INPUT PULANG AWAL'!$H:$H,'SUM.PULANG AWAL'!$B7,'INPUT PULANG AWAL'!$I:$I,'SUM.PULANG AWAL'!$C9) -> 0 | K9: =SUMIFS('INPUT PULANG AWAL'!$M:$M,'INPUT PULANG AWAL'!$C:$C,'SUM.PULANG AWAL'!K$6,'INPUT PULANG AWAL'!$H:$H,'SUM.PULANG AWAL'!$B7,'INPUT PULANG AWAL'!$I:$I,'SUM.PULANG AWAL'!$C9) -> 0 | ... AH9: =SUMIFS('INPUT PULANG AWAL'!$M:$M,'INPUT PULANG AWAL'!$C:$C,'SUM.PULANG AWAL'!AH$6,'INPUT PULANG AWAL'!$H:$H,'SUM.PULANG AWAL'!$B7,'INPUT PULANG AWAL'!$I:$I,'SUM.PULANG AWAL'!$C9) -> 0 | AI9: =SUM(D9:AH9) -> 0
A10: 2 | B10: ='list area'!B5 -> BATERAY CABLE NEW | C10: A | D10: =SUMIFS('INPUT PULANG AWAL'!$M:$M,'INPUT PULANG AWAL'!$C:$C,'SUM.PULANG AWAL'!D$6,'INPUT PULANG AWAL'!$H:$H,'SUM.PULANG AWAL'!$B10:$B12,'INPUT PULANG AWAL'!$I:$I,'SUM.PULANG AWAL'!$C10) -> 0 | E10: =SUMIFS('INPUT PULANG AWAL'!$M:$M,'INPUT PULANG AWAL'!$C:$C,'SUM.PULANG AWAL'!E$6,'INPUT PULANG AWAL'!$H:$H,'SUM.PULANG AWAL'!$B10:$B12,'INPUT PULANG AWAL'!$I:$I,'SUM.PULANG AWAL'!$C10) -> 0 | F10: =SUMIFS('INPUT PULANG AWAL'!$M:$M,'INPUT PULANG AWAL'!$C:$C,'SUM.PULANG AWAL'!F$6,'INPUT PULANG AWAL'!$H:$H,'SUM.PULANG AWAL'!$B10:$B12,'INPUT PULANG AWAL'!$I:$I,'SUM.PULANG AWAL'!$C10) -> 0 | G10: =SUMIFS('INPUT PULANG AWAL'!$M:$M,'INPUT PULANG AWAL'!$C:$C,'SUM.PULANG AWAL'!G$6,'INPUT PULANG AWAL'!$H:$H,'SUM.PULANG AWAL'!$B10:$B12,'INPUT PULANG AWAL'!$I:$I,'SUM.PULANG AWAL'!$C10) -> 0 | H10: =SUMIFS('INPUT PULANG AWAL'!$M:$M,'INPUT PULANG AWAL'!$C:$C,'SUM.PULANG AWAL'!H$6,'INPUT PULANG AWAL'!$H:$H,'SUM.PULANG AWAL'!$B10:$B12,'INPUT PULANG AWAL'!$I:$I,'SUM.PULANG AWAL'!$C10) -> 0 | I10: =SUMIFS('INPUT PULANG AWAL'!$M:$M,'INPUT PULANG AWAL'!$C:$C,'SUM.PULANG AWAL'!I$6,'INPUT PULANG AWAL'!$H:$H,'SUM.PULANG AWAL'!$B10:$B12,'INPUT PULANG AWAL'!$I:$I,'SUM.PULANG AWAL'!$C10) -> 0 | J10: =SUMIFS('INPUT PULANG AWAL'!$M:$M,'INPUT PULANG AWAL'!$C:$C,'SUM.PULANG AWAL'!J$6,'INPUT PULANG AWAL'!$H:$H,'SUM.PULANG AWAL'!$B10:$B12,'INPUT PULANG AWAL'!$I:$I,'SUM.PULANG AWAL'!$C10) -> 0 | K10: =SUMIFS('INPUT PULANG AWAL'!$M:$M,'INPUT PULANG AWAL'!$C:$C,'SUM.PULANG AWAL'!K$6,'INPUT PULANG AWAL'!$H:$H,'SUM.PULANG AWAL'!$B10:$B12,'INPUT PULANG AWAL'!$I:$I,'SUM.PULANG AWAL'!$C10) -> 0 | ... AH10: =SUMIFS('INPUT PULANG AWAL'!$M:$M,'INPUT PULANG AWAL'!$C:$C,'SUM.PULANG AWAL'!AH$6,'INPUT PULANG AWAL'!$H:$H,'SUM.PULANG AWAL'!$B10:$B12,'INPUT PULANG AWAL'!$I:$I,'SUM.PULANG AWAL'!$C10) -> 0 | AI10: =SUM(D10:AH10) -> 0
C11: B | D11: =SUMIFS('INPUT PULANG AWAL'!$M:$M,'INPUT PULANG AWAL'!$C:$C,'SUM.PULANG AWAL'!D$6,'INPUT PULANG AWAL'!$H:$H,'SUM.PULANG AWAL'!$B10,'INPUT PULANG AWAL'!$I:$I,'SUM.PULANG AWAL'!$C11) -> 0 | E11: =SUMIFS('INPUT PULANG AWAL'!$M:$M,'INPUT PULANG AWAL'!$C:$C,'SUM.PULANG AWAL'!E$6,'INPUT PULANG AWAL'!$H:$H,'SUM.PULANG AWAL'!$B10,'INPUT PULANG AWAL'!$I:$I,'SUM.PULANG AWAL'!$C11) -> 0 | F11: =SUMIFS('INPUT PULANG AWAL'!$M:$M,'INPUT PULANG AWAL'!$C:$C,'SUM.PULANG AWAL'!F$6,'INPUT PULANG AWAL'!$H:$H,'SUM.PULANG AWAL'!$B10,'INPUT PULANG AWAL'!$I:$I,'SUM.PULANG AWAL'!$C11) -> 0 | G11: =SUMIFS('INPUT PULANG AWAL'!$M:$M,'INPUT PULANG AWAL'!$C:$C,'SUM.PULANG AWAL'!G$6,'INPUT PULANG AWAL'!$H:$H,'SUM.PULANG AWAL'!$B10,'INPUT PULANG AWAL'!$I:$I,'SUM.PULANG AWAL'!$C11) -> 0 | H11: =SUMIFS('INPUT PULANG AWAL'!$M:$M,'INPUT PULANG AWAL'!$C:$C,'SUM.PULANG AWAL'!H$6,'INPUT PULANG AWAL'!$H:$H,'SUM.PULANG AWAL'!$B10,'INPUT PULANG AWAL'!$I:$I,'SUM.PULANG AWAL'!$C11) -> 0 | I11: =SUMIFS('INPUT PULANG AWAL'!$M:$M,'INPUT PULANG AWAL'!$C:$C,'SUM.PULANG AWAL'!I$6,'INPUT PULANG AWAL'!$H:$H,'SUM.PULANG AWAL'!$B10,'INPUT PULANG AWAL'!$I:$I,'SUM.PULANG AWAL'!$C11) -> 0 | J11: =SUMIFS('INPUT PULANG AWAL'!$M:$M,'INPUT PULANG AWAL'!$C:$C,'SUM.PULANG AWAL'!J$6,'INPUT PULANG AWAL'!$H:$H,'SUM.PULANG AWAL'!$B10,'INPUT PULANG AWAL'!$I:$I,'SUM.PULANG AWAL'!$C11) -> 0 | K11: =SUMIFS('INPUT PULANG AWAL'!$M:$M,'INPUT PULANG AWAL'!$C:$C,'SUM.PULANG AWAL'!K$6,'INPUT PULANG AWAL'!$H:$H,'SUM.PULANG AWAL'!$B10,'INPUT PULANG AWAL'!$I:$I,'SUM.PULANG AWAL'!$C11) -> 0 | ... AH11: =SUMIFS('INPUT PULANG AWAL'!$M:$M,'INPUT PULANG AWAL'!$C:$C,'SUM.PULANG AWAL'!AH$6,'INPUT PULANG AWAL'!$H:$H,'SUM.PULANG AWAL'!$B10,'INPUT PULANG AWAL'!$I:$I,'SUM.PULANG AWAL'!$C11) -> 0 | AI11: =SUM(D11:AH11) -> 0
C12: NS | D12: =SUMIFS('INPUT PULANG AWAL'!$M:$M,'INPUT PULANG AWAL'!$C:$C,'SUM.PULANG AWAL'!D$6,'INPUT PULANG AWAL'!$H:$H,'SUM.PULANG AWAL'!$B10,'INPUT PULANG AWAL'!$I:$I,'SUM.PULANG AWAL'!$C12) -> 0 | E12: =SUMIFS('INPUT PULANG AWAL'!$M:$M,'INPUT PULANG AWAL'!$C:$C,'SUM.PULANG AWAL'!E$6,'INPUT PULANG AWAL'!$H:$H,'SUM.PULANG AWAL'!$B10,'INPUT PULANG AWAL'!$I:$I,'SUM.PULANG AWAL'!$C12) -> 0 | F12: =SUMIFS('INPUT PULANG AWAL'!$M:$M,'INPUT PULANG AWAL'!$C:$C,'SUM.PULANG AWAL'!F$6,'INPUT PULANG AWAL'!$H:$H,'SUM.PULANG AWAL'!$B10,'INPUT PULANG AWAL'!$I:$I,'SUM.PULANG AWAL'!$C12) -> 0 | G12: =SUMIFS('INPUT PULANG AWAL'!$M:$M,'INPUT PULANG AWAL'!$C:$C,'SUM.PULANG AWAL'!G$6,'INPUT PULANG AWAL'!$H:$H,'SUM.PULANG AWAL'!$B10,'INPUT PULANG AWAL'!$I:$I,'SUM.PULANG AWAL'!$C12) -> 0 | H12: =SUMIFS('INPUT PULANG AWAL'!$M:$M,'INPUT PULANG AWAL'!$C:$C,'SUM.PULANG AWAL'!H$6,'INPUT PULANG AWAL'!$H:$H,'SUM.PULANG AWAL'!$B10,'INPUT PULANG AWAL'!$I:$I,'SUM.PULANG AWAL'!$C12) -> 0 | I12: =SUMIFS('INPUT PULANG AWAL'!$M:$M,'INPUT PULANG AWAL'!$C:$C,'SUM.PULANG AWAL'!I$6,'INPUT PULANG AWAL'!$H:$H,'SUM.PULANG AWAL'!$B10,'INPUT PULANG AWAL'!$I:$I,'SUM.PULANG AWAL'!$C12) -> 0 | J12: =SUMIFS('INPUT PULANG AWAL'!$M:$M,'INPUT PULANG AWAL'!$C:$C,'SUM.PULANG AWAL'!J$6,'INPUT PULANG AWAL'!$H:$H,'SUM.PULANG AWAL'!$B10,'INPUT PULANG AWAL'!$I:$I,'SUM.PULANG AWAL'!$C12) -> 0 | K12: =SUMIFS('INPUT PULANG AWAL'!$M:$M,'INPUT PULANG AWAL'!$C:$C,'SUM.PULANG AWAL'!K$6,'INPUT PULANG AWAL'!$H:$H,'SUM.PULANG AWAL'!$B10,'INPUT PULANG AWAL'!$I:$I,'SUM.PULANG AWAL'!$C12) -> 0 | ... AH12: =SUMIFS('INPUT PULANG AWAL'!$M:$M,'INPUT PULANG AWAL'!$C:$C,'SUM.PULANG AWAL'!AH$6,'INPUT PULANG AWAL'!$H:$H,'SUM.PULANG AWAL'!$B10,'INPUT PULANG AWAL'!$I:$I,'SUM.PULANG AWAL'!$C12) -> 0 | AI12: =SUM(D12:AH12) -> 0
A13: 3 | B13: ='list area'!B6 -> BUFFER 1 | C13: A | D13: =SUMIFS('INPUT PULANG AWAL'!$M:$M,'INPUT PULANG AWAL'!$C:$C,'SUM.PULANG AWAL'!D$6,'INPUT PULANG AWAL'!$H:$H,'SUM.PULANG AWAL'!$B13:$B15,'INPUT PULANG AWAL'!$I:$I,'SUM.PULANG AWAL'!$C13) -> 0 | E13: =SUMIFS('INPUT PULANG AWAL'!$M:$M,'INPUT PULANG AWAL'!$C:$C,'SUM.PULANG AWAL'!E$6,'INPUT PULANG AWAL'!$H:$H,'SUM.PULANG AWAL'!$B13:$B15,'INPUT PULANG AWAL'!$I:$I,'SUM.PULANG AWAL'!$C13) -> 0 | F13: =SUMIFS('INPUT PULANG AWAL'!$M:$M,'INPUT PULANG AWAL'!$C:$C,'SUM.PULANG AWAL'!F$6,'INPUT PULANG AWAL'!$H:$H,'SUM.PULANG AWAL'!$B13:$B15,'INPUT PULANG AWAL'!$I:$I,'SUM.PULANG AWAL'!$C13) -> 0 | G13: =SUMIFS('INPUT PULANG AWAL'!$M:$M,'INPUT PULANG AWAL'!$C:$C,'SUM.PULANG AWAL'!G$6,'INPUT PULANG AWAL'!$H:$H,'SUM.PULANG AWAL'!$B13:$B15,'INPUT PULANG AWAL'!$I:$I,'SUM.PULANG AWAL'!$C13) -> 0 | H13: =SUMIFS('INPUT PULANG AWAL'!$M:$M,'INPUT PULANG AWAL'!$C:$C,'SUM.PULANG AWAL'!H$6,'INPUT PULANG AWAL'!$H:$H,'SUM.PULANG AWAL'!$B13:$B15,'INPUT PULANG AWAL'!$I:$I,'SUM.PULANG AWAL'!$C13) -> 0 | I13: =SUMIFS('INPUT PULANG AWAL'!$M:$M,'INPUT PULANG AWAL'!$C:$C,'SUM.PULANG AWAL'!I$6,'INPUT PULANG AWAL'!$H:$H,'SUM.PULANG AWAL'!$B13:$B15,'INPUT PULANG AWAL'!$I:$I,'SUM.PULANG AWAL'!$C13) -> 0 | J13: =SUMIFS('INPUT PULANG AWAL'!$M:$M,'INPUT PULANG AWAL'!$C:$C,'SUM.PULANG AWAL'!J$6,'INPUT PULANG AWAL'!$H:$H,'SUM.PULANG AWAL'!$B13:$B15,'INPUT PULANG AWAL'!$I:$I,'SUM.PULANG AWAL'!$C13) -> 0 | K13: =SUMIFS('INPUT PULANG AWAL'!$M:$M,'INPUT PULANG AWAL'!$C:$C,'SUM.PULANG AWAL'!K$6,'INPUT PULANG AWAL'!$H:$H,'SUM.PULANG AWAL'!$B13:$B15,'INPUT PULANG AWAL'!$I:$I,'SUM.PULANG AWAL'!$C13) -> 0 | ... AH13: =SUMIFS('INPUT PULANG AWAL'!$M:$M,'INPUT PULANG AWAL'!$C:$C,'SUM.PULANG AWAL'!AH$6,'INPUT PULANG AWAL'!$H:$H,'SUM.PULANG AWAL'!$B13:$B15,'INPUT PULANG AWAL'!$I:$I,'SUM.PULANG AWAL'!$C13) -> 0 | AI13: =SUM(D13:AH13) -> 0
C14: B | D14: =SUMIFS('INPUT PULANG AWAL'!$M:$M,'INPUT PULANG AWAL'!$C:$C,'SUM.PULANG AWAL'!D$6,'INPUT PULANG AWAL'!$H:$H,'SUM.PULANG AWAL'!$B13,'INPUT PULANG AWAL'!$I:$I,'SUM.PULANG AWAL'!$C14) -> 0 | E14: =SUMIFS('INPUT PULANG AWAL'!$M:$M,'INPUT PULANG AWAL'!$C:$C,'SUM.PULANG AWAL'!E$6,'INPUT PULANG AWAL'!$H:$H,'SUM.PULANG AWAL'!$B13,'INPUT PULANG AWAL'!$I:$I,'SUM.PULANG AWAL'!$C14) -> 0 | F14: =SUMIFS('INPUT PULANG AWAL'!$M:$M,'INPUT PULANG AWAL'!$C:$C,'SUM.PULANG AWAL'!F$6,'INPUT PULANG AWAL'!$H:$H,'SUM.PULANG AWAL'!$B13,'INPUT PULANG AWAL'!$I:$I,'SUM.PULANG AWAL'!$C14) -> 0 | G14: =SUMIFS('INPUT PULANG AWAL'!$M:$M,'INPUT PULANG AWAL'!$C:$C,'SUM.PULANG AWAL'!G$6,'INPUT PULANG AWAL'!$H:$H,'SUM.PULANG AWAL'!$B13,'INPUT PULANG AWAL'!$I:$I,'SUM.PULANG AWAL'!$C14) -> 0 | H14: =SUMIFS('INPUT PULANG AWAL'!$M:$M,'INPUT PULANG AWAL'!$C:$C,'SUM.PULANG AWAL'!H$6,'INPUT PULANG AWAL'!$H:$H,'SUM.PULANG AWAL'!$B13,'INPUT PULANG AWAL'!$I:$I,'SUM.PULANG AWAL'!$C14) -> 0 | I14: =SUMIFS('INPUT PULANG AWAL'!$M:$M,'INPUT PULANG AWAL'!$C:$C,'SUM.PULANG AWAL'!I$6,'INPUT PULANG AWAL'!$H:$H,'SUM.PULANG AWAL'!$B13,'INPUT PULANG AWAL'!$I:$I,'SUM.PULANG AWAL'!$C14) -> 0 | J14: =SUMIFS('INPUT PULANG AWAL'!$M:$M,'INPUT PULANG AWAL'!$C:$C,'SUM.PULANG AWAL'!J$6,'INPUT PULANG AWAL'!$H:$H,'SUM.PULANG AWAL'!$B13,'INPUT PULANG AWAL'!$I:$I,'SUM.PULANG AWAL'!$C14) -> 0 | K14: =SUMIFS('INPUT PULANG AWAL'!$M:$M,'INPUT PULANG AWAL'!$C:$C,'SUM.PULANG AWAL'!K$6,'INPUT PULANG AWAL'!$H:$H,'SUM.PULANG AWAL'!$B13,'INPUT PULANG AWAL'!$I:$I,'SUM.PULANG AWAL'!$C14) -> 0 | ... AH14: =SUMIFS('INPUT PULANG AWAL'!$M:$M,'INPUT PULANG AWAL'!$C:$C,'SUM.PULANG AWAL'!AH$6,'INPUT PULANG AWAL'!$H:$H,'SUM.PULANG AWAL'!$B13,'INPUT PULANG AWAL'!$I:$I,'SUM.PULANG AWAL'!$C14) -> 0 | AI14: =SUM(D14:AH14) -> 0
C15: NS | D15: =SUMIFS('INPUT PULANG AWAL'!$M:$M,'INPUT PULANG AWAL'!$C:$C,'SUM.PULANG AWAL'!D$6,'INPUT PULANG AWAL'!$H:$H,'SUM.PULANG AWAL'!$B13,'INPUT PULANG AWAL'!$I:$I,'SUM.PULANG AWAL'!$C15) -> 0 | E15: =SUMIFS('INPUT PULANG AWAL'!$M:$M,'INPUT PULANG AWAL'!$C:$C,'SUM.PULANG AWAL'!E$6,'INPUT PULANG AWAL'!$H:$H,'SUM.PULANG AWAL'!$B13,'INPUT PULANG AWAL'!$I:$I,'SUM.PULANG AWAL'!$C15) -> 0 | F15: =SUMIFS('INPUT PULANG AWAL'!$M:$M,'INPUT PULANG AWAL'!$C:$C,'SUM.PULANG AWAL'!F$6,'INPUT PULANG AWAL'!$H:$H,'SUM.PULANG AWAL'!$B13,'INPUT PULANG AWAL'!$I:$I,'SUM.PULANG AWAL'!$C15) -> 0 | G15: =SUMIFS('INPUT PULANG AWAL'!$M:$M,'INPUT PULANG AWAL'!$C:$C,'SUM.PULANG AWAL'!G$6,'INPUT PULANG AWAL'!$H:$H,'SUM.PULANG AWAL'!$B13,'INPUT PULANG AWAL'!$I:$I,'SUM.PULANG AWAL'!$C15) -> 0 | H15: =SUMIFS('INPUT PULANG AWAL'!$M:$M,'INPUT PULANG AWAL'!$C:$C,'SUM.PULANG AWAL'!H$6,'INPUT PULANG AWAL'!$H:$H,'SUM.PULANG AWAL'!$B13,'INPUT PULANG AWAL'!$I:$I,'SUM.PULANG AWAL'!$C15) -> 0 | I15: =SUMIFS('INPUT PULANG AWAL'!$M:$M,'INPUT PULANG AWAL'!$C:$C,'SUM.PULANG AWAL'!I$6,'INPUT PULANG AWAL'!$H:$H,'SUM.PULANG AWAL'!$B13,'INPUT PULANG AWAL'!$I:$I,'SUM.PULANG AWAL'!$C15) -> 0 | J15: =SUMIFS('INPUT PULANG AWAL'!$M:$M,'INPUT PULANG AWAL'!$C:$C,'SUM.PULANG AWAL'!J$6,'INPUT PULANG AWAL'!$H:$H,'SUM.PULANG AWAL'!$B13,'INPUT PULANG AWAL'!$I:$I,'SUM.PULANG AWAL'!$C15) -> 0 | K15: =SUMIFS('INPUT PULANG AWAL'!$M:$M,'INPUT PULANG AWAL'!$C:$C,'SUM.PULANG AWAL'!K$6,'INPUT PULANG AWAL'!$H:$H,'SUM.PULANG AWAL'!$B13,'INPUT PULANG AWAL'!$I:$I,'SUM.PULANG AWAL'!$C15) -> 0 | ... AH15: =SUMIFS('INPUT PULANG AWAL'!$M:$M,'INPUT PULANG AWAL'!$C:$C,'SUM.PULANG AWAL'!AH$6,'INPUT PULANG AWAL'!$H:$H,'SUM.PULANG AWAL'!$B13,'INPUT PULANG AWAL'!$I:$I,'SUM.PULANG AWAL'!$C15) -> 0 | AI15: =SUM(D15:AH15) -> 35
A16: 4 | B16: ='list area'!B7 -> BUFFER 2 | C16: A | D16: =SUMIFS('INPUT PULANG AWAL'!$M:$M,'INPUT PULANG AWAL'!$C:$C,'SUM.PULANG AWAL'!D$6,'INPUT PULANG AWAL'!$H:$H,'SUM.PULANG AWAL'!$B16:$B18,'INPUT PULANG AWAL'!$I:$I,'SUM.PULANG AWAL'!$C16) -> 0 | E16: =SUMIFS('INPUT PULANG AWAL'!$M:$M,'INPUT PULANG AWAL'!$C:$C,'SUM.PULANG AWAL'!E$6,'INPUT PULANG AWAL'!$H:$H,'SUM.PULANG AWAL'!$B16:$B18,'INPUT PULANG AWAL'!$I:$I,'SUM.PULANG AWAL'!$C16) -> 0 | F16: =SUMIFS('INPUT PULANG AWAL'!$M:$M,'INPUT PULANG AWAL'!$C:$C,'SUM.PULANG AWAL'!F$6,'INPUT PULANG AWAL'!$H:$H,'SUM.PULANG AWAL'!$B16:$B18,'INPUT PULANG AWAL'!$I:$I,'SUM.PULANG AWAL'!$C16) -> 0 | G16: =SUMIFS('INPUT PULANG AWAL'!$M:$M,'INPUT PULANG AWAL'!$C:$C,'SUM.PULANG AWAL'!G$6,'INPUT PULANG AWAL'!$H:$H,'SUM.PULANG AWAL'!$B16:$B18,'INPUT PULANG AWAL'!$I:$I,'SUM.PULANG AWAL'!$C16) -> 0 | H16: =SUMIFS('INPUT PULANG AWAL'!$M:$M,'INPUT PULANG AWAL'!$C:$C,'SUM.PULANG AWAL'!H$6,'INPUT PULANG AWAL'!$H:$H,'SUM.PULANG AWAL'!$B16:$B18,'INPUT PULANG AWAL'!$I:$I,'SUM.PULANG AWAL'!$C16) -> 0 | I16: =SUMIFS('INPUT PULANG AWAL'!$M:$M,'INPUT PULANG AWAL'!$C:$C,'SUM.PULANG AWAL'!I$6,'INPUT PULANG AWAL'!$H:$H,'SUM.PULANG AWAL'!$B16:$B18,'INPUT PULANG AWAL'!$I:$I,'SUM.PULANG AWAL'!$C16) -> 0 | J16: =SUMIFS('INPUT PULANG AWAL'!$M:$M,'INPUT PULANG AWAL'!$C:$C,'SUM.PULANG AWAL'!J$6,'INPUT PULANG AWAL'!$H:$H,'SUM.PULANG AWAL'!$B16:$B18,'INPUT PULANG AWAL'!$I:$I,'SUM.PULANG AWAL'!$C16) -> 0 | K16: =SUMIFS('INPUT PULANG AWAL'!$M:$M,'INPUT PULANG AWAL'!$C:$C,'SUM.PULANG AWAL'!K$6,'INPUT PULANG AWAL'!$H:$H,'SUM.PULANG AWAL'!$B16:$B18,'INPUT PULANG AWAL'!$I:$I,'SUM.PULANG AWAL'!$C16) -> 0 | ... AH16: =SUMIFS('INPUT PULANG AWAL'!$M:$M,'INPUT PULANG AWAL'!$C:$C,'SUM.PULANG AWAL'!AH$6,'INPUT PULANG AWAL'!$H:$H,'SUM.PULANG AWAL'!$B16:$B18,'INPUT PULANG AWAL'!$I:$I,'SUM.PULANG AWAL'!$C16) -> 0 | AI16: =SUM(D16:AH16) -> 0
C17: B | D17: =SUMIFS('INPUT PULANG AWAL'!$M:$M,'INPUT PULANG AWAL'!$C:$C,'SUM.PULANG AWAL'!D$6,'INPUT PULANG AWAL'!$H:$H,'SUM.PULANG AWAL'!$B16,'INPUT PULANG AWAL'!$I:$I,'SUM.PULANG AWAL'!$C17) -> 0 | E17: =SUMIFS('INPUT PULANG AWAL'!$M:$M,'INPUT PULANG AWAL'!$C:$C,'SUM.PULANG AWAL'!E$6,'INPUT PULANG AWAL'!$H:$H,'SUM.PULANG AWAL'!$B16,'INPUT PULANG AWAL'!$I:$I,'SUM.PULANG AWAL'!$C17) -> 0 | F17: =SUMIFS('INPUT PULANG AWAL'!$M:$M,'INPUT PULANG AWAL'!$C:$C,'SUM.PULANG AWAL'!F$6,'INPUT PULANG AWAL'!$H:$H,'SUM.PULANG AWAL'!$B16,'INPUT PULANG AWAL'!$I:$I,'SUM.PULANG AWAL'!$C17) -> 0 | G17: =SUMIFS('INPUT PULANG AWAL'!$M:$M,'INPUT PULANG AWAL'!$C:$C,'SUM.PULANG AWAL'!G$6,'INPUT PULANG AWAL'!$H:$H,'SUM.PULANG AWAL'!$B16,'INPUT PULANG AWAL'!$I:$I,'SUM.PULANG AWAL'!$C17) -> 0 | H17: =SUMIFS('INPUT PULANG AWAL'!$M:$M,'INPUT PULANG AWAL'!$C:$C,'SUM.PULANG AWAL'!H$6,'INPUT PULANG AWAL'!$H:$H,'SUM.PULANG AWAL'!$B16,'INPUT PULANG AWAL'!$I:$I,'SUM.PULANG AWAL'!$C17) -> 0 | I17: =SUMIFS('INPUT PULANG AWAL'!$M:$M,'INPUT PULANG AWAL'!$C:$C,'SUM.PULANG AWAL'!I$6,'INPUT PULANG AWAL'!$H:$H,'SUM.PULANG AWAL'!$B16,'INPUT PULANG AWAL'!$I:$I,'SUM.PULANG AWAL'!$C17) -> 0 | J17: =SUMIFS('INPUT PULANG AWAL'!$M:$M,'INPUT PULANG AWAL'!$C:$C,'SUM.PULANG AWAL'!J$6,'INPUT PULANG AWAL'!$H:$H,'SUM.PULANG AWAL'!$B16,'INPUT PULANG AWAL'!$I:$I,'SUM.PULANG AWAL'!$C17) -> 0 | K17: =SUMIFS('INPUT PULANG AWAL'!$M:$M,'INPUT PULANG AWAL'!$C:$C,'SUM.PULANG AWAL'!K$6,'INPUT PULANG AWAL'!$H:$H,'SUM.PULANG AWAL'!$B16,'INPUT PULANG AWAL'!$I:$I,'SUM.PULANG AWAL'!$C17) -> 0 | ... AH17: =SUMIFS('INPUT PULANG AWAL'!$M:$M,'INPUT PULANG AWAL'!$C:$C,'SUM.PULANG AWAL'!AH$6,'INPUT PULANG AWAL'!$H:$H,'SUM.PULANG AWAL'!$B16,'INPUT PULANG AWAL'!$I:$I,'SUM.PULANG AWAL'!$C17) -> 0 | AI17: =SUM(D17:AH17) -> 7.5
C18: NS | D18: =SUMIFS('INPUT PULANG AWAL'!$M:$M,'INPUT PULANG AWAL'!$C:$C,'SUM.PULANG AWAL'!D$6,'INPUT PULANG AWAL'!$H:$H,'SUM.PULANG AWAL'!$B16,'INPUT PULANG AWAL'!$I:$I,'SUM.PULANG AWAL'!$C18) -> 0 | E18: =SUMIFS('INPUT PULANG AWAL'!$M:$M,'INPUT PULANG AWAL'!$C:$C,'SUM.PULANG AWAL'!E$6,'INPUT PULANG AWAL'!$H:$H,'SUM.PULANG AWAL'!$B16,'INPUT PULANG AWAL'!$I:$I,'SUM.PULANG AWAL'!$C18) -> 0 | F18: =SUMIFS('INPUT PULANG AWAL'!$M:$M,'INPUT PULANG AWAL'!$C:$C,'SUM.PULANG AWAL'!F$6,'INPUT PULANG AWAL'!$H:$H,'SUM.PULANG AWAL'!$B16,'INPUT PULANG AWAL'!$I:$I,'SUM.PULANG AWAL'!$C18) -> 0 | G18: =SUMIFS('INPUT PULANG AWAL'!$M:$M,'INPUT PULANG AWAL'!$C:$C,'SUM.PULANG AWAL'!G$6,'INPUT PULANG AWAL'!$H:$H,'SUM.PULANG AWAL'!$B16,'INPUT PULANG AWAL'!$I:$I,'SUM.PULANG AWAL'!$C18) -> 0 | H18: =SUMIFS('INPUT PULANG AWAL'!$M:$M,'INPUT PULANG AWAL'!$C:$C,'SUM.PULANG AWAL'!H$6,'INPUT PULANG AWAL'!$H:$H,'SUM.PULANG AWAL'!$B16,'INPUT PULANG AWAL'!$I:$I,'SUM.PULANG AWAL'!$C18) -> 0 | I18: =SUMIFS('INPUT PULANG AWAL'!$M:$M,'INPUT PULANG AWAL'!$C:$C,'SUM.PULANG AWAL'!I$6,'INPUT PULANG AWAL'!$H:$H,'SUM.PULANG AWAL'!$B16,'INPUT PULANG AWAL'!$I:$I,'SUM.PULANG AWAL'!$C18) -> 0 | J18: =SUMIFS('INPUT PULANG AWAL'!$M:$M,'INPUT PULANG AWAL'!$C:$C,'SUM.PULANG AWAL'!J$6,'INPUT PULANG AWAL'!$H:$H,'SUM.PULANG AWAL'!$B16,'INPUT PULANG AWAL'!$I:$I,'SUM.PULANG AWAL'!$C18) -> 0 | K18: =SUMIFS('INPUT PULANG AWAL'!$M:$M,'INPUT PULANG AWAL'!$C:$C,'SUM.PULANG AWAL'!K$6,'INPUT PULANG AWAL'!$H:$H,'SUM.PULANG AWAL'!$B16,'INPUT PULANG AWAL'!$I:$I,'SUM.PULANG AWAL'!$C18) -> 0 | ... AH18: =SUMIFS('INPUT PULANG AWAL'!$M:$M,'INPUT PULANG AWAL'!$C:$C,'SUM.PULANG AWAL'!AH$6,'INPUT PULANG AWAL'!$H:$H,'SUM.PULANG AWAL'!$B16,'INPUT PULANG AWAL'!$I:$I,'SUM.PULANG AWAL'!$C18) -> 0 | AI18: =SUM(D18:AH18) -> 308
A19: 5 | B19: ='list area'!B8 -> CO SPV | C19: A | D19: =SUMIFS('INPUT PULANG AWAL'!$M:$M,'INPUT PULANG AWAL'!$C:$C,'SUM.PULANG AWAL'!D$6,'INPUT PULANG AWAL'!$H:$H,'SUM.PULANG AWAL'!$B19:$B21,'INPUT PULANG AWAL'!$I:$I,'SUM.PULANG AWAL'!$C19) -> 0 | E19: =SUMIFS('INPUT PULANG AWAL'!$M:$M,'INPUT PULANG AWAL'!$C:$C,'SUM.PULANG AWAL'!E$6,'INPUT PULANG AWAL'!$H:$H,'SUM.PULANG AWAL'!$B19:$B21,'INPUT PULANG AWAL'!$I:$I,'SUM.PULANG AWAL'!$C19) -> 0 | F19: =SUMIFS('INPUT PULANG AWAL'!$M:$M,'INPUT PULANG AWAL'!$C:$C,'SUM.PULANG AWAL'!F$6,'INPUT PULANG AWAL'!$H:$H,'SUM.PULANG AWAL'!$B19:$B21,'INPUT PULANG AWAL'!$I:$I,'SUM.PULANG AWAL'!$C19) -> 0 | G19: =SUMIFS('INPUT PULANG AWAL'!$M:$M,'INPUT PULANG AWAL'!$C:$C,'SUM.PULANG AWAL'!G$6,'INPUT PULANG AWAL'!$H:$H,'SUM.PULANG AWAL'!$B19:$B21,'INPUT PULANG AWAL'!$I:$I,'SUM.PULANG AWAL'!$C19) -> 0 | H19: =SUMIFS('INPUT PULANG AWAL'!$M:$M,'INPUT PULANG AWAL'!$C:$C,'SUM.PULANG AWAL'!H$6,'INPUT PULANG AWAL'!$H:$H,'SUM.PULANG AWAL'!$B19:$B21,'INPUT PULANG AWAL'!$I:$I,'SUM.PULANG AWAL'!$C19) -> 0 | I19: =SUMIFS('INPUT PULANG AWAL'!$M:$M,'INPUT PULANG AWAL'!$C:$C,'SUM.PULANG AWAL'!I$6,'INPUT PULANG AWAL'!$H:$H,'SUM.PULANG AWAL'!$B19:$B21,'INPUT PULANG AWAL'!$I:$I,'SUM.PULANG AWAL'!$C19) -> 0 | J19: =SUMIFS('INPUT PULANG AWAL'!$M:$M,'INPUT PULANG AWAL'!$C:$C,'SUM.PULANG AWAL'!J$6,'INPUT PULANG AWAL'!$H:$H,'SUM.PULANG AWAL'!$B19:$B21,'INPUT PULANG AWAL'!$I:$I,'SUM.PULANG AWAL'!$C19) -> 0 | K19: =SUMIFS('INPUT PULANG AWAL'!$M:$M,'INPUT PULANG AWAL'!$C:$C,'SUM.PULANG AWAL'!K$6,'INPUT PULANG AWAL'!$H:$H,'SUM.PULANG AWAL'!$B19:$B21,'INPUT PULANG AWAL'!$I:$I,'SUM.PULANG AWAL'!$C19) -> 0 | ... AH19: =SUMIFS('INPUT PULANG AWAL'!$M:$M,'INPUT PULANG AWAL'!$C:$C,'SUM.PULANG AWAL'!AH$6,'INPUT PULANG AWAL'!$H:$H,'SUM.PULANG AWAL'!$B19:$B21,'INPUT PULANG AWAL'!$I:$I,'SUM.PULANG AWAL'!$C19) -> 0 | AI19: =SUM(D19:AH19) -> 0
C20: B | D20: =SUMIFS('INPUT PULANG AWAL'!$M:$M,'INPUT PULANG AWAL'!$C:$C,'SUM.PULANG AWAL'!D$6,'INPUT PULANG AWAL'!$H:$H,'SUM.PULANG AWAL'!$B19,'INPUT PULANG AWAL'!$I:$I,'SUM.PULANG AWAL'!$C20) -> 0 | E20: =SUMIFS('INPUT PULANG AWAL'!$M:$M,'INPUT PULANG AWAL'!$C:$C,'SUM.PULANG AWAL'!E$6,'INPUT PULANG AWAL'!$H:$H,'SUM.PULANG AWAL'!$B19,'INPUT PULANG AWAL'!$I:$I,'SUM.PULANG AWAL'!$C20) -> 0 | F20: =SUMIFS('INPUT PULANG AWAL'!$M:$M,'INPUT PULANG AWAL'!$C:$C,'SUM.PULANG AWAL'!F$6,'INPUT PULANG AWAL'!$H:$H,'SUM.PULANG AWAL'!$B19,'INPUT PULANG AWAL'!$I:$I,'SUM.PULANG AWAL'!$C20) -> 0 | G20: =SUMIFS('INPUT PULANG AWAL'!$M:$M,'INPUT PULANG AWAL'!$C:$C,'SUM.PULANG AWAL'!G$6,'INPUT PULANG AWAL'!$H:$H,'SUM.PULANG AWAL'!$B19,'INPUT PULANG AWAL'!$I:$I,'SUM.PULANG AWAL'!$C20) -> 0 | H20: =SUMIFS('INPUT PULANG AWAL'!$M:$M,'INPUT PULANG AWAL'!$C:$C,'SUM.PULANG AWAL'!H$6,'INPUT PULANG AWAL'!$H:$H,'SUM.PULANG AWAL'!$B19,'INPUT PULANG AWAL'!$I:$I,'SUM.PULANG AWAL'!$C20) -> 0 | I20: =SUMIFS('INPUT PULANG AWAL'!$M:$M,'INPUT PULANG AWAL'!$C:$C,'SUM.PULANG AWAL'!I$6,'INPUT PULANG AWAL'!$H:$H,'SUM.PULANG AWAL'!$B19,'INPUT PULANG AWAL'!$I:$I,'SUM.PULANG AWAL'!$C20) -> 0 | J20: =SUMIFS('INPUT PULANG AWAL'!$M:$M,'INPUT PULANG AWAL'!$C:$C,'SUM.PULANG AWAL'!J$6,'INPUT PULANG AWAL'!$H:$H,'SUM.PULANG AWAL'!$B19,'INPUT PULANG AWAL'!$I:$I,'SUM.PULANG AWAL'!$C20) -> 0 | K20: =SUMIFS('INPUT PULANG AWAL'!$M:$M,'INPUT PULANG AWAL'!$C:$C,'SUM.PULANG AWAL'!K$6,'INPUT PULANG AWAL'!$H:$H,'SUM.PULANG AWAL'!$B19,'INPUT PULANG AWAL'!$I:$I,'SUM.PULANG AWAL'!$C20) -> 0 | ... AH20: =SUMIFS('INPUT PULANG AWAL'!$M:$M,'INPUT PULANG AWAL'!$C:$C,'SUM.PULANG AWAL'!AH$6,'INPUT PULANG AWAL'!$H:$H,'SUM.PULANG AWAL'!$B19,'INPUT PULANG AWAL'!$I:$I,'SUM.PULANG AWAL'!$C20) -> 0 | AI20: =SUM(D20:AH20) -> 0
C21: NS | D21: =SUMIFS('INPUT PULANG AWAL'!$M:$M,'INPUT PULANG AWAL'!$C:$C,'SUM.PULANG AWAL'!D$6,'INPUT PULANG AWAL'!$H:$H,'SUM.PULANG AWAL'!$B19,'INPUT PULANG AWAL'!$I:$I,'SUM.PULANG AWAL'!$C21) -> 0 | E21: =SUMIFS('INPUT PULANG AWAL'!$M:$M,'INPUT PULANG AWAL'!$C:$C,'SUM.PULANG AWAL'!E$6,'INPUT PULANG AWAL'!$H:$H,'SUM.PULANG AWAL'!$B19,'INPUT PULANG AWAL'!$I:$I,'SUM.PULANG AWAL'!$C21) -> 0 | F21: =SUMIFS('INPUT PULANG AWAL'!$M:$M,'INPUT PULANG AWAL'!$C:$C,'SUM.PULANG AWAL'!F$6,'INPUT PULANG AWAL'!$H:$H,'SUM.PULANG AWAL'!$B19,'INPUT PULANG AWAL'!$I:$I,'SUM.PULANG AWAL'!$C21) -> 0 | G21: =SUMIFS('INPUT PULANG AWAL'!$M:$M,'INPUT PULANG AWAL'!$C:$C,'SUM.PULANG AWAL'!G$6,'INPUT PULANG AWAL'!$H:$H,'SUM.PULANG AWAL'!$B19,'INPUT PULANG AWAL'!$I:$I,'SUM.PULANG AWAL'!$C21) -> 0 | H21: =SUMIFS('INPUT PULANG AWAL'!$M:$M,'INPUT PULANG AWAL'!$C:$C,'SUM.PULANG AWAL'!H$6,'INPUT PULANG AWAL'!$H:$H,'SUM.PULANG AWAL'!$B19,'INPUT PULANG AWAL'!$I:$I,'SUM.PULANG AWAL'!$C21) -> 0 | I21: =SUMIFS('INPUT PULANG AWAL'!$M:$M,'INPUT PULANG AWAL'!$C:$C,'SUM.PULANG AWAL'!I$6,'INPUT PULANG AWAL'!$H:$H,'SUM.PULANG AWAL'!$B19,'INPUT PULANG AWAL'!$I:$I,'SUM.PULANG AWAL'!$C21) -> 0 | J21: =SUMIFS('INPUT PULANG AWAL'!$M:$M,'INPUT PULANG AWAL'!$C:$C,'SUM.PULANG AWAL'!J$6,'INPUT PULANG AWAL'!$H:$H,'SUM.PULANG AWAL'!$B19,'INPUT PULANG AWAL'!$I:$I,'SUM.PULANG AWAL'!$C21) -> 0 | K21: =SUMIFS('INPUT PULANG AWAL'!$M:$M,'INPUT PULANG AWAL'!$C:$C,'SUM.PULANG AWAL'!K$6,'INPUT PULANG AWAL'!$H:$H,'SUM.PULANG AWAL'!$B19,'INPUT PULANG AWAL'!$I:$I,'SUM.PULANG AWAL'!$C21) -> 0 | ... AH21: =SUMIFS('INPUT PULANG AWAL'!$M:$M,'INPUT PULANG AWAL'!$C:$C,'SUM.PULANG AWAL'!AH$6,'INPUT PULANG AWAL'!$H:$H,'SUM.PULANG AWAL'!$B19,'INPUT PULANG AWAL'!$I:$I,'SUM.PULANG AWAL'!$C21) -> 0 | AI21: =SUM(D21:AH21) -> 0
A22: 6 | B22: ='list area'!B9 -> CPA 3MO | C22: A | D22: =SUMIFS('INPUT PULANG AWAL'!$M:$M,'INPUT PULANG AWAL'!$C:$C,'SUM.PULANG AWAL'!D$6,'INPUT PULANG AWAL'!$H:$H,'SUM.PULANG AWAL'!$B22:$B24,'INPUT PULANG AWAL'!$I:$I,'SUM.PULANG AWAL'!$C22) -> 0 | E22: =SUMIFS('INPUT PULANG AWAL'!$M:$M,'INPUT PULANG AWAL'!$C:$C,'SUM.PULANG AWAL'!E$6,'INPUT PULANG AWAL'!$H:$H,'SUM.PULANG AWAL'!$B22:$B24,'INPUT PULANG AWAL'!$I:$I,'SUM.PULANG AWAL'!$C22) -> 0 | F22: =SUMIFS('INPUT PULANG AWAL'!$M:$M,'INPUT PULANG AWAL'!$C:$C,'SUM.PULANG AWAL'!F$6,'INPUT PULANG AWAL'!$H:$H,'SUM.PULANG AWAL'!$B22:$B24,'INPUT PULANG AWAL'!$I:$I,'SUM.PULANG AWAL'!$C22) -> 0 | G22: =SUMIFS('INPUT PULANG AWAL'!$M:$M,'INPUT PULANG AWAL'!$C:$C,'SUM.PULANG AWAL'!G$6,'INPUT PULANG AWAL'!$H:$H,'SUM.PULANG AWAL'!$B22:$B24,'INPUT PULANG AWAL'!$I:$I,'SUM.PULANG AWAL'!$C22) -> 0 | H22: =SUMIFS('INPUT PULANG AWAL'!$M:$M,'INPUT PULANG AWAL'!$C:$C,'SUM.PULANG AWAL'!H$6,'INPUT PULANG AWAL'!$H:$H,'SUM.PULANG AWAL'!$B22:$B24,'INPUT PULANG AWAL'!$I:$I,'SUM.PULANG AWAL'!$C22) -> 0 | I22: =SUMIFS('INPUT PULANG AWAL'!$M:$M,'INPUT PULANG AWAL'!$C:$C,'SUM.PULANG AWAL'!I$6,'INPUT PULANG AWAL'!$H:$H,'SUM.PULANG AWAL'!$B22:$B24,'INPUT PULANG AWAL'!$I:$I,'SUM.PULANG AWAL'!$C22) -> 0 | J22: =SUMIFS('INPUT PULANG AWAL'!$M:$M,'INPUT PULANG AWAL'!$C:$C,'SUM.PULANG AWAL'!J$6,'INPUT PULANG AWAL'!$H:$H,'SUM.PULANG AWAL'!$B22:$B24,'INPUT PULANG AWAL'!$I:$I,'SUM.PULANG AWAL'!$C22) -> 224 | K22: =SUMIFS('INPUT PULANG AWAL'!$M:$M,'INPUT PULANG AWAL'!$C:$C,'SUM.PULANG AWAL'!K$6,'INPUT PULANG AWAL'!$H:$H,'SUM.PULANG AWAL'!$B22:$B24,'INPUT PULANG AWAL'!$I:$I,'SUM.PULANG AWAL'!$C22) -> 0 | ... AH22: =SUMIFS('INPUT PULANG AWAL'!$M:$M,'INPUT PULANG AWAL'!$C:$C,'SUM.PULANG AWAL'!AH$6,'INPUT PULANG AWAL'!$H:$H,'SUM.PULANG AWAL'!$B22:$B24,'INPUT PULANG AWAL'!$I:$I,'SUM.PULANG AWAL'!$C22) -> 0 | AI22: =SUM(D22:AH22) -> 658.5
C23: B | D23: =SUMIFS('INPUT PULANG AWAL'!$M:$M,'INPUT PULANG AWAL'!$C:$C,'SUM.PULANG AWAL'!D$6,'INPUT PULANG AWAL'!$H:$H,'SUM.PULANG AWAL'!$B22,'INPUT PULANG AWAL'!$I:$I,'SUM.PULANG AWAL'!$C23) -> 0 | E23: =SUMIFS('INPUT PULANG AWAL'!$M:$M,'INPUT PULANG AWAL'!$C:$C,'SUM.PULANG AWAL'!E$6,'INPUT PULANG AWAL'!$H:$H,'SUM.PULANG AWAL'!$B22,'INPUT PULANG AWAL'!$I:$I,'SUM.PULANG AWAL'!$C23) -> 0 | F23: =SUMIFS('INPUT PULANG AWAL'!$M:$M,'INPUT PULANG AWAL'!$C:$C,'SUM.PULANG AWAL'!F$6,'INPUT PULANG AWAL'!$H:$H,'SUM.PULANG AWAL'!$B22,'INPUT PULANG AWAL'!$I:$I,'SUM.PULANG AWAL'!$C23) -> 11 | G23: =SUMIFS('INPUT PULANG AWAL'!$M:$M,'INPUT PULANG AWAL'!$C:$C,'SUM.PULANG AWAL'!G$6,'INPUT PULANG AWAL'!$H:$H,'SUM.PULANG AWAL'!$B22,'INPUT PULANG AWAL'!$I:$I,'SUM.PULANG AWAL'!$C23) -> 0 | H23: =SUMIFS('INPUT PULANG AWAL'!$M:$M,'INPUT PULANG AWAL'!$C:$C,'SUM.PULANG AWAL'!H$6,'INPUT PULANG AWAL'!$H:$H,'SUM.PULANG AWAL'!$B22,'INPUT PULANG AWAL'!$I:$I,'SUM.PULANG AWAL'!$C23) -> 196.66667 | I23: =SUMIFS('INPUT PULANG AWAL'!$M:$M,'INPUT PULANG AWAL'!$C:$C,'SUM.PULANG AWAL'!I$6,'INPUT PULANG AWAL'!$H:$H,'SUM.PULANG AWAL'!$B22,'INPUT PULANG AWAL'!$I:$I,'SUM.PULANG AWAL'!$C23) -> 0 | J23: =SUMIFS('INPUT PULANG AWAL'!$M:$M,'INPUT PULANG AWAL'!$C:$C,'SUM.PULANG AWAL'!J$6,'INPUT PULANG AWAL'!$H:$H,'SUM.PULANG AWAL'!$B22,'INPUT PULANG AWAL'!$I:$I,'SUM.PULANG AWAL'!$C23) -> 0 | K23: =SUMIFS('INPUT PULANG AWAL'!$M:$M,'INPUT PULANG AWAL'!$C:$C,'SUM.PULANG AWAL'!K$6,'INPUT PULANG AWAL'!$H:$H,'SUM.PULANG AWAL'!$B22,'INPUT PULANG AWAL'!$I:$I,'SUM.PULANG AWAL'!$C23) -> 0 | ... AH23: =SUMIFS('INPUT PULANG AWAL'!$M:$M,'INPUT PULANG AWAL'!$C:$C,'SUM.PULANG AWAL'!AH$6,'INPUT PULANG AWAL'!$H:$H,'SUM.PULANG AWAL'!$B22,'INPUT PULANG AWAL'!$I:$I,'SUM.PULANG AWAL'!$C23) -> 0 | AI23: =SUM(D23:AH23) -> 1653.9167
C24: NS | D24: =SUMIFS('INPUT PULANG AWAL'!$M:$M,'INPUT PULANG AWAL'!$C:$C,'SUM.PULANG AWAL'!D$6,'INPUT PULANG AWAL'!$H:$H,'SUM.PULANG AWAL'!$B22,'INPUT PULANG AWAL'!$I:$I,'SUM.PULANG AWAL'!$C24) -> 0 | E24: =SUMIFS('INPUT PULANG AWAL'!$M:$M,'INPUT PULANG AWAL'!$C:$C,'SUM.PULANG AWAL'!E$6,'INPUT PULANG AWAL'!$H:$H,'SUM.PULANG AWAL'!$B22,'INPUT PULANG AWAL'!$I:$I,'SUM.PULANG AWAL'!$C24) -> 0 | F24: =SUMIFS('INPUT PULANG AWAL'!$M:$M,'INPUT PULANG AWAL'!$C:$C,'SUM.PULANG AWAL'!F$6,'INPUT PULANG AWAL'!$H:$H,'SUM.PULANG AWAL'!$B22,'INPUT PULANG AWAL'!$I:$I,'SUM.PULANG AWAL'!$C24) -> 0 | G24: =SUMIFS('INPUT PULANG AWAL'!$M:$M,'INPUT PULANG AWAL'!$C:$C,'SUM.PULANG AWAL'!G$6,'INPUT PULANG AWAL'!$H:$H,'SUM.PULANG AWAL'!$B22,'INPUT PULANG AWAL'!$I:$I,'SUM.PULANG AWAL'!$C24) -> 0 | H24: =SUMIFS('INPUT PULANG AWAL'!$M:$M,'INPUT PULANG AWAL'!$C:$C,'SUM.PULANG AWAL'!H$6,'INPUT PULANG AWAL'!$H:$H,'SUM.PULANG AWAL'!$B22,'INPUT PULANG AWAL'!$I:$I,'SUM.PULANG AWAL'!$C24) -> 0 | I24: =SUMIFS('INPUT PULANG AWAL'!$M:$M,'INPUT PULANG AWAL'!$C:$C,'SUM.PULANG AWAL'!I$6,'INPUT PULANG AWAL'!$H:$H,'SUM.PULANG AWAL'!$B22,'INPUT PULANG AWAL'!$I:$I,'SUM.PULANG AWAL'!$C24) -> 0 | J24: =SUMIFS('INPUT PULANG AWAL'!$M:$M,'INPUT PULANG AWAL'!$C:$C,'SUM.PULANG AWAL'!J$6,'INPUT PULANG AWAL'!$H:$H,'SUM.PULANG AWAL'!$B22,'INPUT PULANG AWAL'!$I:$I,'SUM.PULANG AWAL'!$C24) -> 0 | K24: =SUMIFS('INPUT PULANG AWAL'!$M:$M,'INPUT PULANG AWAL'!$C:$C,'SUM.PULANG AWAL'!K$6,'INPUT PULANG AWAL'!$H:$H,'SUM.PULANG AWAL'!$B22,'INPUT PULANG AWAL'!$I:$I,'SUM.PULANG AWAL'!$C24) -> 0 | ... AH24: =SUMIFS('INPUT PULANG AWAL'!$M:$M,'INPUT PULANG AWAL'!$C:$C,'SUM.PULANG AWAL'!AH$6,'INPUT PULANG AWAL'!$H:$H,'SUM.PULANG AWAL'!$B22,'INPUT PULANG AWAL'!$I:$I,'SUM.PULANG AWAL'!$C24) -> 0 | AI24: =SUM(D24:AH24) -> 0
A25: 7 | B25: CPA DYNA | C25: A | D25: =SUMIFS('INPUT PULANG AWAL'!$M:$M,'INPUT PULANG AWAL'!$C:$C,'SUM.PULANG AWAL'!D$6,'INPUT PULANG AWAL'!$H:$H,'SUM.PULANG AWAL'!$B25:$B27,'INPUT PULANG AWAL'!$I:$I,'SUM.PULANG AWAL'!$C25) -> 0 | E25: =SUMIFS('INPUT PULANG AWAL'!$M:$M,'INPUT PULANG AWAL'!$C:$C,'SUM.PULANG AWAL'!E$6,'INPUT PULANG AWAL'!$H:$H,'SUM.PULANG AWAL'!$B25:$B27,'INPUT PULANG AWAL'!$I:$I,'SUM.PULANG AWAL'!$C25) -> 0 | F25: =SUMIFS('INPUT PULANG AWAL'!$M:$M,'INPUT PULANG AWAL'!$C:$C,'SUM.PULANG AWAL'!F$6,'INPUT PULANG AWAL'!$H:$H,'SUM.PULANG AWAL'!$B25:$B27,'INPUT PULANG AWAL'!$I:$I,'SUM.PULANG AWAL'!$C25) -> 0 | G25: =SUMIFS('INPUT PULANG AWAL'!$M:$M,'INPUT PULANG AWAL'!$C:$C,'SUM.PULANG AWAL'!G$6,'INPUT PULANG AWAL'!$H:$H,'SUM.PULANG AWAL'!$B25:$B27,'INPUT PULANG AWAL'!$I:$I,'SUM.PULANG AWAL'!$C25) -> 0 | H25: =SUMIFS('INPUT PULANG AWAL'!$M:$M,'INPUT PULANG AWAL'!$C:$C,'SUM.PULANG AWAL'!H$6,'INPUT PULANG AWAL'!$H:$H,'SUM.PULANG AWAL'!$B25:$B27,'INPUT PULANG AWAL'!$I:$I,'SUM.PULANG AWAL'!$C25) -> 0 | I25: =SUMIFS('INPUT PULANG AWAL'!$M:$M,'INPUT PULANG AWAL'!$C:$C,'SUM.PULANG AWAL'!I$6,'INPUT PULANG AWAL'!$H:$H,'SUM.PULANG AWAL'!$B25:$B27,'INPUT PULANG AWAL'!$I:$I,'SUM.PULANG AWAL'!$C25) -> 0 | J25: =SUMIFS('INPUT PULANG AWAL'!$M:$M,'INPUT PULANG AWAL'!$C:$C,'SUM.PULANG AWAL'!J$6,'INPUT PULANG AWAL'!$H:$H,'SUM.PULANG AWAL'!$B25:$B27,'INPUT PULANG AWAL'!$I:$I,'SUM.PULANG AWAL'!$C25) -> 0 | K25: =SUMIFS('INPUT PULANG AWAL'!$M:$M,'INPUT PULANG AWAL'!$C:$C,'SUM.PULANG AWAL'!K$6,'INPUT PULANG AWAL'!$H:$H,'SUM.PULANG AWAL'!$B25:$B27,'INPUT PULANG AWAL'!$I:$I,'SUM.PULANG AWAL'!$C25) -> 0 | ... AH25: =SUMIFS('INPUT PULANG AWAL'!$M:$M,'INPUT PULANG AWAL'!$C:$C,'SUM.PULANG AWAL'!AH$6,'INPUT PULANG AWAL'!$H:$H,'SUM.PULANG AWAL'!$B25:$B27,'INPUT PULANG AWAL'!$I:$I,'SUM.PULANG AWAL'!$C25) -> 0 | AI25: =SUM(D25:AH25) -> 0
C26: B | D26: =SUMIFS('INPUT PULANG AWAL'!$M:$M,'INPUT PULANG AWAL'!$C:$C,'SUM.PULANG AWAL'!D$6,'INPUT PULANG AWAL'!$H:$H,'SUM.PULANG AWAL'!$B25,'INPUT PULANG AWAL'!$I:$I,'SUM.PULANG AWAL'!$C26) -> 0 | E26: =SUMIFS('INPUT PULANG AWAL'!$M:$M,'INPUT PULANG AWAL'!$C:$C,'SUM.PULANG AWAL'!E$6,'INPUT PULANG AWAL'!$H:$H,'SUM.PULANG AWAL'!$B25,'INPUT PULANG AWAL'!$I:$I,'SUM.PULANG AWAL'!$C26) -> 0 | F26: =SUMIFS('INPUT PULANG AWAL'!$M:$M,'INPUT PULANG AWAL'!$C:$C,'SUM.PULANG AWAL'!F$6,'INPUT PULANG AWAL'!$H:$H,'SUM.PULANG AWAL'!$B25,'INPUT PULANG AWAL'!$I:$I,'SUM.PULANG AWAL'!$C26) -> 0 | G26: =SUMIFS('INPUT PULANG AWAL'!$M:$M,'INPUT PULANG AWAL'!$C:$C,'SUM.PULANG AWAL'!G$6,'INPUT PULANG AWAL'!$H:$H,'SUM.PULANG AWAL'!$B25,'INPUT PULANG AWAL'!$I:$I,'SUM.PULANG AWAL'!$C26) -> 0 | H26: =SUMIFS('INPUT PULANG AWAL'!$M:$M,'INPUT PULANG AWAL'!$C:$C,'SUM.PULANG AWAL'!H$6,'INPUT PULANG AWAL'!$H:$H,'SUM.PULANG AWAL'!$B25,'INPUT PULANG AWAL'!$I:$I,'SUM.PULANG AWAL'!$C26) -> 0 | I26: =SUMIFS('INPUT PULANG AWAL'!$M:$M,'INPUT PULANG AWAL'!$C:$C,'SUM.PULANG AWAL'!I$6,'INPUT PULANG AWAL'!$H:$H,'SUM.PULANG AWAL'!$B25,'INPUT PULANG AWAL'!$I:$I,'SUM.PULANG AWAL'!$C26) -> 0 | J26: =SUMIFS('INPUT PULANG AWAL'!$M:$M,'INPUT PULANG AWAL'!$C:$C,'SUM.PULANG AWAL'!J$6,'INPUT PULANG AWAL'!$H:$H,'SUM.PULANG AWAL'!$B25,'INPUT PULANG AWAL'!$I:$I,'SUM.PULANG AWAL'!$C26) -> 0 | K26: =SUMIFS('INPUT PULANG AWAL'!$M:$M,'INPUT PULANG AWAL'!$C:$C,'SUM.PULANG AWAL'!K$6,'INPUT PULANG AWAL'!$H:$H,'SUM.PULANG AWAL'!$B25,'INPUT PULANG AWAL'!$I:$I,'SUM.PULANG AWAL'!$C26) -> 0 | ... AH26: =SUMIFS('INPUT PULANG AWAL'!$M:$M,'INPUT PULANG AWAL'!$C:$C,'SUM.PULANG AWAL'!AH$6,'INPUT PULANG AWAL'!$H:$H,'SUM.PULANG AWAL'!$B25,'INPUT PULANG AWAL'!$I:$I,'SUM.PULANG AWAL'!$C26) -> 0 | AI26: =SUM(D26:AH26) -> 0
