Workbook
Name __VF2: #REF!
Name _1Excel_BuiltIn_Print_Titles_1_1: '[3]SA-1.1'!#REF!
Name _26_1生_CROSS_クエリー1: #REF!
Name _28_出庫リスト_クエリー: #REF!
Name _pp2_313_クエリー: #REF!
Name _Q: [7]_MISSION!$T$1:$BI$245
Name _生新規部品ﾘｽﾄ_クエリー: #REF!
Name A_K1出庫リスト: #REF!
Name A7_UPL: #REF!
Name ASSET_TYPE: [11]System!$A$32:$A$34
Name B9_: #N/A
Name CETAKUNITKERJA_5: "'file:///D:/DATA-E/My Dokuments/Dept Prod C/Manpower/DATABASE local/DAFTAR UNIT KERJA PROD DOMESTIC REV.xls'#$DETAIL.$#REF!$#REF!"
Name CONCEPT: [11]System!$A$255:$A$256
Name COST_DEPT_CLS_CD: [11]System!$A$20:$A$25
Name D: [13]外注計算!$E$5
Name D10_: #N/A
Name D2_: #REF!
Name D9_: #N/A
Name DASARDATABASE_12: "$'Meninggalkan Pekerjaan'.$#REF!$#REF!:$#REF!$#REF!"
Name DASARNAMABASE: "$#REF!.$B$10:$F$3608"
Name DASARNAMABASE_10: "$#REF!.$B$10:$F$3608"
Name DASARNIKBASE: "$#REF!.$C$10:$F$3608"
Name DASARNIKBASE_10: "$#REF!.$C$10:$F$3608"
Name data: "$#REF!.$A$10:$AB$3608"
Name data_10: "$#REF!.$A$10:$AB$3608"
Name DEHRFH: #REF!
Name DISP_LANG_CANDIDATE: [11]System!$C$42:$C$44
Name DROPDOWNLIST: [11]System!$A$218:$A$252
Name E: #N/A
Name ECRN2: [15]メーカー検索!#REF!
Name Entity: [16]LIST!$A$4:$A$38
Name Excel_BuiltIn__FilterDatabase_1: #REF!
Name Excel_BuiltIn__FilterDatabase_1_1: #REF!
Name Excel_BuiltIn__FilterDatabase_12_1: "$'Meninggalkan Pekerjaan'.$#REF!$#REF!:$#REF!$#REF!"
Name Excel_BuiltIn_Criteria_12_1: "$'Meninggalkan Pekerjaan'.$#REF!$#REF!:$#REF!$#REF!"
Name Excel_BuiltIn_Extract_12: "$'Meninggalkan Pekerjaan'.$#REF!$#REF!:$#REF!$#REF!"
Name Excel_BuiltIn_Print_Area_2: #REF!
Name Excel_BuiltIn_Print_Area_2_1: #REF!
Name Excel_BuiltIn_Print_Titles_1: #REF!
Name EXPDOM_DEST_CARMKR: [11]System!$A$184:$A$213
Name FIX_VAR_CD: [11]System!$A$28:$A$29
Name G_LEADER: "$#REF!.$B$67:$AB$263"
Name G_LEADER_10: "$#REF!.$B$67:$AB$263"
Name GHJ: #REF!
Name HFM_RCR027: [11]System!$C$52
Name HFM_RCR028: [11]System!$C$53
Name HFM_RCR029: [11]System!$C$54
Name HFM_RCR030: [11]System!$C$55
Name HFM_RCR035: [11]System!$C$56
Name HFM_RCR037: [11]System!$C$57
Name HFM_RCR038: [11]System!$C$58
Name HFM_RCR039: [11]System!$C$59
Name HFM_RCR040: [11]System!$C$60
Name HFM_RCR041: [11]System!$C$61
Name HFM_RCR042: [11]System!$C$62
Name HFM_RCR043: [11]System!$C$63
Name HFM_RPL025: [11]System!$C$124
Name HFM_RPL026: [11]System!$C$125
Name HFM_RPL027: [11]System!$C$126
Name HFM_RPL030: [11]System!$C$127

Sheet TAHAP 1
U1: A
B2: PT. SEMARANG AUTOCOMP MANUFACTURING INDONESIA | H2: FORM/CHECKSHEET | I2: NO. DOKUMEN | J2: : 083/PGA/GS/FORM/RPBPD | N2: APPROVED II | P2: APPROVED I | R2: CHECKED | T2: PREPARED
B3: REQUEST PERHITUNGAN BIAYA PERJALANAN DINAS | I3: REVISI | J3: : 0 | N3: APPROVED
I4: TANGGAL | J4: : 05-07-2023
I5: HALAMAN | J5: : 1
I6: MASA BERLAKU | J6: : 04-07-2024 | N6: AWI | P6: FYH | R6: SMK | T6: Renny
B8: TUJUAN PERJALANAN DINAS | G8: : PEMI
B9: KEPENTINGAN | G9: : TRAINING JISHUKEN
B11: 1. MEMBER YANG AKAN PERJALANAN DINAS
B12: NO | C12: TANGGAL | G12: DEPT. / SECT. | I12: JABATAN | K12: NIK | M12: NAMA
B13: 1 | C13: 45530 | D13: s/d | F13: 45569 | G13: NYS/PI | I13: COORD. SPV | K13: 5533 | M13: NANANG YUDI PRASETYO
B14: 2 | C14: 45530 | D14: s/d | F14: 45569 | G14: NYS/PI | I14: SPV | K14: 13647 | M14: ADITYA FAHRIZAL
B15: 3 | D15: s/d
B16: 4 | D16: s/d
B18: 2. TRANSPORTASI
B19: 2.a Pesawat | K19: 2.b Kereta
B20: NO | C20: TANGGAL | E20: AIR PORT | H20: RANGE TIME | K20: NO | L20: TANGGAL | N20: STATION | R20: RANGE TIME
E21: DEPARTURE | G21: ARRIVAL | H21: DEPARTURE | I21: ARRIVAL | N21: DEPARTURE | P21: ARRIVAL | R21: DEPARTURE | T21: ARRIVAL
B22: 1 | K22: 1
B23: 2 | K23: 2
B25: 2.c Mobil / Hi Ace / Bus
B26: NO | C26: TANGGAL | G26: JENIS ARMADA | I26: JUMLAH KURSI (PENUMPANG) | J26: WAKTU KEBERANGKATAN | N26: REQUEST KHUSUS
J27: LOKASI | L27: JAM
B28: 1 | N28: -
B29: NOTE : Standar kelengkapan armada
B30: No | C30: Point | J30: Mobil | M30: Hi Ace | P30: BUS
B31: 1 | C31: Sabuk Pengaman | J31: ● | M31: ● | P31: ●
B32: 2 | C32: Ban Cadangan | J32: ● | M32: ● | P32: ●
B33: 3 | C33: Segitiga Pengaman (Minimal 2 buah, berwarna merah, dapat memantulkan cahaya) | J33: ● | M33: ● | P33: ●
B34: 4 | C34: Dongkrak | J34: ● | M34: ● | P34: ●
B35: 5 | C35: Pembuka Roda dan | J35: ● | M35: ● | P35: ●
B36: 6 | C36: Kotak P3K(Minimal berisi obat antiseptik, kain kassa, kapas, plester) | J36: ● | M36: ● | P36: ●
B37: 7 | C37: Apar | J37: ● (1x M1 berat 1 Kg) | M37: ● (2x M1 berat 1 Kg) | P37: ● (2x M1 berat 1 Kg)
B38: 8 | C38: Ganjal Ban (Wheel Block) | J38: x | M38: ● (Jika > 3,500 Kg) | P38: ● (Jika > 3,500 Kg)
B39: 9 | C39: Perisai Kolong Belakang | J39: x | M39: x | P39: x
B40: 10 | C40: Perisai Kolong Samping | J40: x | M40: x | P40: x
B41: 11 | C41: Alat Pemantul Cahaya | J41: x | M41: x | P41: x
B42: 12 | C42: Pemecah Kaca / Martil | J42: x | M42: x | P42: x
... B44: 14 | C44: Kernet | J44: x | M44: x | P44: x
B45: NOTE : Standar transportasi berdasarkan Prosedur Perjalanan Dinas (PGA-GA.PD.02)
...

Sheet TAPAH 2.2 (Rincian)
O1: A
A2: PT. SEMARANG AUTOCOMP MANUFACTURING INDONESIA - TUGU FACTORY | H2: FORM/CHECKSHEET | I2: NO. DOKUMEN | J2: : 023/PGA/GA/FORM/SPDDN | L2: APPROVED II | M2: APPROVED I | N2: CHECKED | O2: PREPARED
A3: SURAT PERJALANAN DINAS DALAM NEGERI | I3: TANGGAL | J3: : 11-07-2023 | L3: APPROVED
I4: REVISI | J4: : 4
I5: HALAMAN | J5: : 2 / 2
I6: MASA BERLAKU | J6: : 10-07-2024 | L6: AWI | M6: FYH | N6: SMK | O6: RENNY
A8: LAMPIRAN (Rincian) | E8: =+'[25]TAHAP 1'!G9 -> : BENCHMARK
A10: 1. UPD
A11: NOTE : Standar UPD Dalam Negeri berdasarkan Prosedur Perjalanan Dinas (PGA-GA.PD.02)
A12: Golongan | E12: UANG SAKU | F12: BREAKFAST | G12: LUNCH | H12: DINNER
A13: I | E13: 30000 | F13: 12500 | G13: 20000 | H13: 20000
A14: II | E14: 30000 | F14: 12500 | G14: 20000 | H14: 20000
A15: III | E15: 35000 | F15: 12500 | G15: 20000 | H15: 20000
A16: IV | E16: 40000 | F16: 12500 | G16: 27500 | H16: 27500
A17: V | E17: 50000 | F17: 22500 | G17: 30000 | H17: 30000
A18: VI | E18: 60000 | F18: 22500 | G18: 50000 | H18: 50000
A19: VII | E19: 70000 | F19: 22500 | G19: 60000 | H19: 60000
B21: Rincian Golongan | C21: : | D21: IV
A22: NO. | B22: TANGGAL | E22: =+$E$12 -> UANG SAKU | F22: =+$F$12 -> BREAKFAST | G22: =+$G$12 -> LUNCH | H22: =+$H$12 -> DINNER | I22: JUMLAH
A23: 1
A24: 2
A25: 3
A26: TOTAL | I26: =SUM(I23:I25) -> 0
B28: Rincian Golongan | C28: : | D28: II
A29: NO. | B29: TANGGAL | E29: =+$E$12 -> UANG SAKU | F29: =+$F$12 -> BREAKFAST | G29: =+$G$12 -> LUNCH | H29: =+$H$12 -> DINNER | I29: JUMLAH
A30: 1
A31: 2
A32: 3
A33: TOTAL | I33: =SUM(I30:I32) -> 0
A34: UPD
A35: NO. | B35: NAMA | F35: GOL | G35: UPD
A36: 1 | F36: =D21 -> IV | G36: =I26 -> 0
A37: 2 | F37: II | G37: =I33 -> 0
A38: 3 | F38: IV | G38: =I26 -> 0
A39: 4 | F39: IV | G39: =I26 -> 0
A40: TOTAL | G40: =SUM(G36:G39) -> 0
A42: 2. TRANSPORTASI (PIC Perjalanan Dinas tanda tangan pada kolom transportasi yang dipilih atau yang diajukan)
A44: 2.1 PESAWAT | B44: KERETA
A45: NO. | B45: KET. | D45: SCHEDULE | J45: PRICE | K45: QTY | L45: JUMLAH | M45: TOTAL
A46: 1 | B46: BERANGKAT
...

Sheet TAHAP 2.1 (SPD)
W1: A
B2: PT. SEMARANG AUTOCOMP MANUFACTURING INDONESIA | K2: FORM/CHECKSHEET | L2: NO. DOKUMEN | N2: : 023/PGA/GA/FORM/SPDDN | R2: APPROVED II | S2: APPROVED I | T2: CHECKED | V2: PREPARED
B3: SURAT PERJALANAN DINAS DALAM NEGERI | L3: TANGGAL | N3: : 11-07-2023 | R3: APPROVED
L4: REVISI | N4: : 4
L5: HALAMAN | N5: : 1/2
L6: MASA BERLAKU | N6: : 10-07-2024 | R6: AWI | S6: FYH | T6: SMK | V6: Renny
B9: TUJUAN PERJALANAN DINAS | I9: ='TAHAP 1'!G8 -> : PEMI
B10: KEPENTINGAN | I10: ='TAHAP 1'!G9 -> : TRAINING JISHUKEN
B14: 1. PESERTA
B15: NO | C15: TANGGAL | G15: DEPT. / SECT. | I15: JABATAN | K15: NIK | M15: NAMA | P15: 1 | Q15: 2 | R15: 3 | S15: 4 | T15: 5
P16: YANG MENERIMA PERINTAH | Q16: SPV | R16: MGR | S16: FM / DFM | T16: PRESDIR
B19: 1 | C19: ='TAHAP 1'!C13 -> 45530 | D19: s/d | F19: ='TAHAP 1'!F13 -> 45569 | G19: ='TAHAP 1'!G13 -> NYS/PI | I19: ='TAHAP 1'!I13 -> COORD. SPV | K19: ='TAHAP 1'!K13 -> 5533 | M19: ='TAHAP 1'!M13 -> NANANG YUDI PRASETYO | P19: NYP | Q19: - | R19: PAN | S19: MIS | T19: NKA | Y19: =+G19 -> NYS/PI | Z19: =+I19 -> COORD. SPV | AA19: =+K19 -> 5533 | AB19: =+M19 -> NANANG YUDI PRASETYO
B20: 2 | C20: ='TAHAP 1'!C14 -> 45530 | D20: s/d | F20: ='TAHAP 1'!F14 -> 45569 | G20: ='TAHAP 1'!G14 -> NYS/PI | I20: ='TAHAP 1'!I14 -> SPV | K20: ='TAHAP 1'!K14 -> 13647 | M20: ='TAHAP 1'!M14 -> ADITYA FAHRIZAL | P20: AFA | Q20: - | Y20: =+G20 -> NYS/PI | Z20: =+I20 -> SPV | AA20: =+K20 -> 13647 | AB20: =+M20 -> ADITYA FAHRIZAL
B21: 2 | G21: ='TAHAP 1'!G15 -> 0 | I21: ='TAHAP 1'!I15 -> 0 | K21: ='TAHAP 1'!K15 -> 0 | M21: ='TAHAP 1'!M15 -> 0 | Y21: =+G21 -> 0 | Z21: =+I21 -> 0 | AA21: =+K21 -> 0 | AB21: =+M21 -> 0
Y22: =+G22 -> 0 | Z22: =+I22 -> 0 | AA22: =+K22 -> 0 | AB22: =+M22 -> 0
B28: 2. BIAYA PERJALANAN DINAS | L28: UPD | O28: TRANSPORTASI | S28: HOTEL
O29: PESAWAT | Q29: UANG CADANGAN
Q30: * Lokal Transport : 200.000/orang
Q31: * Laundry : 100.000/day
B35: NO | C35: NAMA | G35: NIK | H35: NO. REKENING | L35: PRICE | N35: PERIODE BUDGET | O35: ESTIMATED PRICE | P35: PERIODE BUDGET | Q35: ESTIMATED PRICE | R35: PERIODE BUDGET | S35: ESTIMATED PRICE | T35: PERIODE BUDGET
B36: =+'TAPAH 2.2 (Rincian)'!A36 -> 1 | O36: =+'TAPAH 2.2 (Rincian)'!J48 -> 0 | S36: =+'TAPAH 2.2 (Rincian)'!H81 -> 0
B37: 2 | O37: =+'TAPAH 2.2 (Rincian)'!J48 -> 0 | S37: =+'TAPAH 2.2 (Rincian)'!H82 -> 0
B38: SUB TOTAL | L38: =SUM(L36:M37) -> 0 | O38: =SUM(O36:O37) -> 0 | Q38: =SUM(Q36:Q37) -> 0 | S38: =SUM(S36:S37) -> 0
B39: TOTAL | L39: =SUM(L38:V38) -> 0
B42: NOTE : 1. Ket. Budget di isi bulan periode budget atau di tulis "additional" jika additional budget 2. Approval diproses oleh User 3. Approval pada form ini akan digunakan sebagai jaminan GA dalam melakukan proses issued ticket dan hotel sebelum user melakukan pembuatan PR (purchase requisition). 4. Pembuatan PR setelah proses issued bertujuan agar tidak terjadi selisih harga PR (purchase requisition) dengan actual. | T42: 6. MENGETAHUI MGR FA
T45: BRI
B54: PERLINDUNGAN HAK CIPTA! Dokumen ini adalah milik dan untuk dipergunakan di lingkungan kerja PT. SAMI . Tidak diperkenankan memindahkan, menyalin, atau menggandakan sebagian ataupun seluruhnya isi dokumen ini dalam bentuk dan dengan cara apapun, tanpa izin tertulis dari Wakil manajemen. | I54: Referensi Prosedur/WI/OS/IS/ : PGA-GA.PD.02 : Prosedur Perjalanan Dinas | M54: 4 | N54: Penggabungan approval perjalanan dinas | Q54: 45118 | R54: Renny
M55: 3 | N55: Update Tgl Masa Berlaku & Rev. No. Dok. | Q55: 44702 | R55: Renny
M56: 2 | N56: New Format | Q56: 44314 | R56: Renny | S56: 3 | T56: =+Q54 -> 45118 | W56: FYH
M57: 1 | N57: Add Actual UPD | Q57: 44147 | R57: Renny | S57: 2 | T57: 44702 | W57: WIN
M58: 0 | N58: New Release | Q58: 45113 | R58: LNA | S58: 1 | T58: 44314 | W58: FYH
M59: REV. | N59: ISI PERUBAHAN | Q59: TANGGAL | R59: PIC | S59: REVIEW | T59: TGL | W59: PIC
P79: =102500*60 -> 6150000
